Workbook
Name mygrades: #REF!
Name mygrade: #REF!
Name Grades: #REF!

Sheet CSE4098A_Spring2026_Grade
A1: Capstone Project Grade (CSE 4098A)
A2: Marks Distribution
A3: Spring 2026
A4: Sl | B4: Student ID | C4: Student Name | D4: Report (40%) | E4: Presentation (45%) | F4: Peer (5%) | G4: Weekly Journal (10%) | H4: Total (100%) | I4: Grade | J4: Sup | K4: Title
A5: 1 | B5: 231014004 | C5: Bushra Nusyba Chowdhury | D5: =CSE4098A_Spring2026_Report!AB5 -> 34.18 | E5: =MIN(45, IF(CSE4098A_Spring2026_Presentatio!AA5>1, CSE4098A_Spring2026_Presentatio!AA5, CSE4098A_Spring2026_Presentatio!AA5*45)) -> 41.11 | F5: 5 | G5: 10 | H5: =SUM(D5:G5) -> 90.29 | I5: =IF(H5>=98,"A+",IF(H5>=85,"A",IF(H5>=80,"A-",IF(H5>=75,"B+",IF(H5>=70,"B",IF(H5>=65,"B-",IF(H5>=60,"C+",IF(H5>=55,"C",IF(H5>=50,"D","F"))))))))) -> A | J5: MGK | K5: A Data-Driven Model for Predicting Students’ Intentions to Pursue Higher Studies Abroad
A6: 2 | B6: 231014146 | C6: Tasneem Ahmed | D6: =CSE4098A_Spring2026_Report!AB6 -> 34.18 | E6: =MIN(45, IF(CSE4098A_Spring2026_Presentatio!AA6>1, CSE4098A_Spring2026_Presentatio!AA6, CSE4098A_Spring2026_Presentatio!AA6*45)) -> 36.81 | F6: 3 | G6: 8 | H6: =SUM(D6:G6) -> 81.99 | I6: =IF(H6>=98,"A+",IF(H6>=85,"A",IF(H6>=80,"A-",IF(H6>=75,"B+",IF(H6>=70,"B",IF(H6>=65,"B-",IF(H6>=60,"C+",IF(H6>=55,"C",IF(H6>=50,"D","F"))))))))) -> A-
A7: 3 | B7: 231014006 | C7: Ibnul Haque Chowdhury | D7: =CSE4098A_Spring2026_Report!AB7 -> 34.18 | E7: =MIN(45, IF(CSE4098A_Spring2026_Presentatio!AA7>1, CSE4098A_Spring2026_Presentatio!AA7, CSE4098A_Spring2026_Presentatio!AA7*45)) -> 36.44 | F7: 3 | G7: 8 | H7: =SUM(D7:G7) -> 81.62 | I7: =IF(H7>=98,"A+",IF(H7>=85,"A",IF(H7>=80,"A-",IF(H7>=75,"B+",IF(H7>=70,"B",IF(H7>=65,"B-",IF(H7>=60,"C+",IF(H7>=55,"C",IF(H7>=50,"D","F"))))))))) -> A-
A8: 4 | B8: 231014022 | C8: Rafsan Islam | D8: =CSE4098A_Spring2026_Report!AB8 -> 34.18 | E8: =MIN(45, IF(CSE4098A_Spring2026_Presentatio!AA8>1, CSE4098A_Spring2026_Presentatio!AA8, CSE4098A_Spring2026_Presentatio!AA8*45)) -> 39.7 | F8: 4 | G8: 8 | H8: =SUM(D8:G8) -> 85.88 | I8: =IF(H8>=98,"A+",IF(H8>=85,"A",IF(H8>=80,"A-",IF(H8>=75,"B+",IF(H8>=70,"B",IF(H8>=65,"B-",IF(H8>=60,"C+",IF(H8>=55,"C",IF(H8>=50,"D","F"))))))))) -> A
A9: 5 | B9: 231014042 | C9: Abir Akbar | D9: =CSE4098A_Spring2026_Report!AB9 -> 34.18 | E9: =MIN(45, IF(CSE4098A_Spring2026_Presentatio!AA9>1, CSE4098A_Spring2026_Presentatio!AA9, CSE4098A_Spring2026_Presentatio!AA9*45)) -> 35.93 | F9: 3 | G9: 8 | H9: =SUM(D9:G9) -> 81.11 | I9: =IF(H9>=98,"A+",IF(H9>=85,"A",IF(H9>=80,"A-",IF(H9>=75,"B+",IF(H9>=70,"B",IF(H9>=65,"B-",IF(H9>=60,"C+",IF(H9>=55,"C",IF(H9>=50,"D","F"))))))))) -> A-
A10: 6 | B10: 232014128 | C10: Tonmoy Talukder | D10: =CSE4098A_Spring2026_Report!AB10 -> 35.39 | E10: =MIN(45, IF(CSE4098A_Spring2026_Presentatio!AA10>1, CSE4098A_Spring2026_Presentatio!AA10, CSE4098A_Spring2026_Presentatio!AA10*45)) -> 39.2 | F10: 4 | G10: 8 | H10: =SUM(D10:G10) -> 86.59 | I10: =IF(H10>=98,"A+",IF(H10>=85,"A",IF(H10>=80,"A-",IF(H10>=75,"B+",IF(H10>=70,"B",IF(H10>=65,"B-",IF(H10>=60,"C+",IF(H10>=55,"C",IF(H10>=50,"D","F"))))))))) -> A | J10: RaiK | K10: Measuring Narrative Divergence Across News Outlets: An Event-Aligned Computational Analysis of English Newspapers in Bangladesh
A11: 7 | B11: 231014001 | C11: Md. Aminul Islam Rupak | D11: =CSE4098A_Spring2026_Report!AB11 -> 35.39 | E11: =MIN(45, IF(CSE4098A_Spring2026_Presentatio!AA11>1, CSE4098A_Spring2026_Presentatio!AA11, CSE4098A_Spring2026_Presentatio!AA11*45)) -> 39.2 | F11: 4 | G11: 8 | H11: =SUM(D11:G11) -> 86.59 | I11: =IF(H11>=98,"A+",IF(H11>=85,"A",IF(H11>=80,"A-",IF(H11>=75,"B+",IF(H11>=70,"B",IF(H11>=65,"B-",IF(H11>=60,"C+",IF(H11>=55,"C",IF(H11>=50,"D","F"))))))))) -> A
A12: 8 | B12: 223014100 | C12: Jannatul Tazree | D12: =CSE4098A_Spring2026_Report!AB12 -> 35.39 | E12: =MIN(45, IF(CSE4098A_Spring2026_Presentatio!AA12>1, CSE4098A_Spring2026_Presentatio!AA12, CSE4098A_Spring2026_Presentatio!AA12*45)) -> 42.67 | F12: 4 | G12: 9 | H12: =SUM(D12:G12) -> 91.06 | I12: =IF(H12>=98,"A+",IF(H12>=85,"A",IF(H12>=80,"A-",IF(H12>=75,"B+",IF(H12>=70,"B",IF(H12>=65,"B-",IF(H12>=60,"C+",IF(H12>=55,"C",IF(H12>=50,"D","F"))))))))) -> A
A13: 9 | B13: 232014003 | C13: Tasin Bin Mortoza | D13: =CSE4098A_Spring2026_Report!AB13 -> 35.39 | E13: =MIN(45, IF(CSE4098A_Spring2026_Presentatio!AA13>1, CSE4098A_Spring2026_Presentatio!AA13, CSE4098A_Spring2026_Presentatio!AA13*45)) -> 40.4 | F13: 3 | G13: 7 | H13: =SUM(D13:G13) -> 85.79 | I13: =IF(H13>=98,"A+",IF(H13>=85,"A",IF(H13>=80,"A-",IF(H13>=75,"B+",IF(H13>=70,"B",IF(H13>=65,"B-",IF(H13>=60,"C+",IF(H13>=55,"C",IF(H13>=50,"D","F"))))))))) -> A
A14: 10 | B14: 223014084 | C14: Mirza Mostafa Abrar | D14: =CSE4098A_Spring2026_Report!AB14 -> 34.42 | E14: =MIN(45, IF(CSE4098A_Spring2026_Presentatio!AA14>1, CSE4098A_Spring2026_Presentatio!AA14, CSE4098A_Spring2026_Presentatio!AA14*45)) -> 40.67 | F14: 3 | G14: 6 | H14: =SUM(D14:G14) -> 84.09 | I14: =IF(H14>=98,"A+",IF(H14>=85,"A",IF(H14>=80,"A-",IF(H14>=75,"B+",IF(H14>=70,"B",IF(H14>=65,"B-",IF(H14>=60,"C+",IF(H14>=55,"C",IF(H14>=50,"D","F"))))))))) -> A- | J14: RaiK | K14: BanglaLex-RAG: A Bilingual Hierarchical RAG System for Grounded Legal QA on Bangladesh Labour Law Using Fine-Tuned SLMs
A15: 11 | B15: 223014075 | C15: S M Rahnuma Apshara | D15: =CSE4098A_Spring2026_Report!AB15 -> 34.42 | E15: =MIN(45, IF(CSE4098A_Spring2026_Presentatio!AA15>1, CSE4098A_Spring2026_Presentatio!AA15, CSE4098A_Spring2026_Presentatio!AA15*45)) -> 43.33 | F15: 4 | G15: 8 | H15: =SUM(D15:G15) -> 89.75 | I15: =IF(H15>=98,"A+",IF(H15>=85,"A",IF(H15>=80,"A-",IF(H15>=75,"B+",IF(H15>=70,"B",IF(H15>=65,"B-",IF(H15>=60,"C+",IF(H15>=55,"C",IF(H15>=50,"D","F"))))))))) -> A
A16: 12 | B16: 223014108 | C16: Israt Islam | D16: =CSE4098A_Spring2026_Report!AB16 -> 34.42 | E16: =MIN(45, IF(CSE4098A_Spring2026_Presentatio!AA16>1, CSE4098A_Spring2026_Presentatio!AA16, CSE4098A_Spring2026_Presentatio!AA16*45)) -> 42.67 | F16: 3 | G16: 6 | H16: =SUM(D16:G16) -> 86.09 | I16: =IF(H16>=98,"A+",IF(H16>=85,"A",IF(H16>=80,"A-",IF(H16>=75,"B+",IF(H16>=70,"B",IF(H16>=65,"B-",IF(H16>=60,"C+",IF(H16>=55,"C",IF(H16>=50,"D","F"))))))))) -> A
A17: 13 | B17: 223014090 | C17: Shatabdee Chanda Shruti | D17: =CSE4098A_Spring2026_Report!AB17 -> 34.42 | E17: =MIN(45, IF(CSE4098A_Spring2026_Presentatio!AA17>1, CSE4098A_Spring2026_Presentatio!AA17, CSE4098A_Spring2026_Presentatio!AA17*45)) -> 42 | F17: 3 | G17: 6 | H17: =SUM(D17:G17) -> 85.42 | I17: =IF(H17>=98,"A+",IF(H17>=85,"A",IF(H17>=80,"A-",IF(H17>=75,"B+",IF(H17>=70,"B",IF(H17>=65,"B-",IF(H17>=60,"C+",IF(H17>=55,"C",IF(H17>=50,"D","F"))))))))) -> A
A18: 14 | B18: 223014024 | C18: Piyas Sarkar | D18: =CSE4098A_Spring2026_Report!AB18 -> 31.76 | E18: =MIN(45, IF(CSE4098A_Spring2026_Presentatio!AA18>1, CSE4098A_Spring2026_Presentatio!AA18, CSE4098A_Spring2026_Presentatio!AA18*45)) -> 34.44 | F18: 4 | G18: 8 | H18: =SUM(D18:G18) -> 78.2 | I18: =IF(H18>=98,"A+",IF(H18>=85,"A",IF(H18>=80,"A-",IF(H18>=75,"B+",IF(H18>=70,"B",IF(H18>=65,"B-",IF(H18>=60,"C+",IF(H18>=55,"C",IF(H18>=50,"D","F"))))))))) -> B+ | J18: RHF | K18: GhurbeSobai: An Intelligent Personalized Travel Recommendation and Destination Discovery System for Domestic Tourism in Bangladesh
A19: 15 | B19: 223014112 | C19: Md. Mahmuduzzaman Mollah Rabbee | D19: =CSE4098A_Spring2026_Report!AB19 -> 31.76 | E19: =MIN(45, IF(CSE4098A_Spring2026_Presentatio!AA19>1, CSE4098A_Spring2026_Presentatio!AA19, CSE4098A_Spring2026_Presentatio!AA19*45)) -> 31.11 | F19: 4 | G19: 8 | H19: =SUM(D19:G19) -> 74.87 | I19: =IF(H19>=98,"A+",IF(H19>=85,"A",IF(H19>=80,"A-",IF(H19>=75,"B+",IF(H19>=70,"B",IF(H19>=65,"B-",IF(H19>=60,"C+",IF(H19>=55,"C",IF(H19>=50,"D","F"))))))))) -> B
A20: 16 | B20: 231014136 | C20: Md. Tasdiqur Rahman Khan | D20: =CSE4098A_Spring2026_Report!AB20 -> 31.76 | E20: =MIN(45, IF(CSE4098A_Spring2026_Presentatio!AA20>1, CSE4098A_Spring2026_Presentatio!AA20, CSE4098A_Spring2026_Presentatio!AA20*45)) -> 31.11 | F20: 4 | G20: 6 | H20: =SUM(D20:G20) -> 72.87 | I20: =IF(H20>=98,"A+",IF(H20>=85,"A",IF(H20>=80,"A-",IF(H20>=75,"B+",IF(H20>=70,"B",IF(H20>=65,"B-",IF(H20>=60,"C+",IF(H20>=55,"C",IF(H20>=50,"D","F"))))))))) -> B
A21: 17 | B21: 223014206 | C21: Rafia Haque Arpita | D21: =CSE4098A_Spring2026_Report!AB21 -> 31.76 | E21: =MIN(45, IF(CSE4098A_Spring2026_Presentatio!AA21>1, CSE4098A_Spring2026_Presentatio!AA21, CSE4098A_Spring2026_Presentatio!AA21*45)) -> 33.44 | F21: 4 | G21: 7 | H21: =SUM(D21:G21) -> 76.2 | I21: =IF(H21>=98,"A+",IF(H21>=85,"A",IF(H21>=80,"A-",IF(H21>=75,"B+",IF(H21>=70,"B",IF(H21>=65,"B-",IF(H21>=60,"C+",IF(H21>=55,"C",IF(H21>=50,"D","F"))))))))) -> B+
A22: 18 | B22: 231014010 | C22: Mahmudul Islam Shajib | D22: =CSE4098A_Spring2026_Report!AB22 -> 33.22 | E22: =MIN(45, IF(CSE4098A_Spring2026_Presentatio!AA22>1, CSE4098A_Spring2026_Presentatio!AA22, CSE4098A_Spring2026_Presentatio!AA22*45)) -> 37.02 | F22: 5 | G22: 7 | H22: =SUM(D22:G22) -> 82.24 | I22: =IF(H22>=98,"A+",IF(H22>=85,"A",IF(H22>=80,"A-",IF(H22>=75,"B+",IF(H22>=70,"B",IF(H22>=65,"B-",IF(H22>=60,"C+",IF(H22>=55,"C",IF(H22>=50,"D","F"))))))))) -> A- | J22: RHF | K22: Deep Learning-Based Rice Disease Detection and Pesticide Recommendation System
A23: 19 | B23: 231014082 | C23: Mst. Fahmida Jesmin | D23: =CSE4098A_Spring2026_Report!AB23 -> 33.22 | E23: =MIN(45, IF(CSE4098A_Spring2026_Presentatio!AA23>1, CSE4098A_Spring2026_Presentatio!AA23, CSE4098A_Spring2026_Presentatio!AA23*45)) -> 39.29 | F23: 5 | G23: 7 | H23: =SUM(D23:G23) -> 84.51 | I23: =IF(H23>=98,"A+",IF(H23>=85,"A",IF(H23>=80,"A-",IF(H23>=75,"B+",IF(H23>=70,"B",IF(H23>=65,"B-",IF(H23>=60,"C+",IF(H23>=55,"C",IF(H23>=50,"D","F"))))))))) -> A-
A24: 20 | B24: 231014133 | C24: Md. Eakramul Karim Tarik | D24: =CSE4098A_Spring2026_Report!AB24 -> 33.22 | E24: =MIN(45, IF(CSE4098A_Spring2026_Presentatio!AA24>1, CSE4098A_Spring2026_Presentatio!AA24, CSE4098A_Spring2026_Presentatio!AA24*45)) -> 37.02 | F24: 2 | G24: 7 | H24: =SUM(D24:G24) -> 79.24 | I24: =IF(H24>=98,"A+",IF(H24>=85,"A",IF(H24>=80,"A-",IF(H24>=75,"B+",IF(H24>=70,"B",IF(H24>=65,"B-",IF(H24>=60,"C+",IF(H24>=55,"C",IF(H24>=50,"D","F"))))))))) -> B+
A25: 21 | B25: 231014120 | C25: Md. Abir Hosen | D25: =CSE4098A_Spring2026_Report!AB25 -> 35.64 | E25: =MIN(45, IF(CSE4098A_Spring2026_Presentatio!AA25>1, CSE4098A_Spring2026_Presentatio!AA25, CSE4098A_Spring2026_Presentatio!AA25*45)) -> 40.31 | F25: 5 | G25: 10 | H25: =SUM(D25:G25) -> 90.95 | I25: =IF(H25>=98,"A+",IF(H25>=85,"A",IF(H25>=80,"A-",IF(H25>=75,"B+",IF(H25>=70,"B",IF(H25>=65,"B-",IF(H25>=60,"C+",IF(H25>=55,"C",IF(H25>=50,"D","F"))))))))) -> A | J25: ASU | K25: Balancing Accuracy and Computational Efficiency in Waste Recognition Using a Dual-Backbone Lightweight Deep Learning Architecture
A26: 22 | B26: 231014096 | C26: Md. Rahat Hawlader | D26: =CSE4098A_Spring2026_Report!AB26 -> 35.64 | E26: =MIN(45, IF(CSE4098A_Spring2026_Presentatio!AA26>1, CSE4098A_Spring2026_Presentatio!AA26, CSE4098A_Spring2026_Presentatio!AA26*45)) -> 40.04 | F26: 5 | G26: 10 | H26: =SUM(D26:G26) -> 90.68 | I26: =IF(H26>=98,"A+",IF(H26>=85,"A",IF(H26>=80,"A-",IF(H26>=75,"B+",IF(H26>=70,"B",IF(H26>=65,"B-",IF(H26>=60,"C+",IF(H26>=55,"C",IF(H26>=50,"D","F"))))))))) -> A
A27: 23 | B27: 231014014 | C27: Shahriar Alam Sazzad | D27: =CSE4098A_Spring2026_Report!AB27 -> 35.64 | E27: =MIN(45, IF(CSE4098A_Spring2026_Presentatio!AA27>1, CSE4098A_Spring2026_Presentatio!AA27, CSE4098A_Spring2026_Presentatio!AA27*45)) -> 38.04 | F27: 4 | G27: 9 | H27: =SUM(D27:G27) -> 86.68 | I27: =IF(H27>=98,"A+",IF(H27>=85,"A",IF(H27>=80,"A-",IF(H27>=75,"B+",IF(H27>=70,"B",IF(H27>=65,"B-",IF(H27>=60,"C+",IF(H27>=55,"C",IF(H27>=50,"D","F"))))))))) -> A
A28: 24 | B28: 231014018 | C28: Zubaida Akter Prova | D28: =CSE4098A_Spring2026_Report!AB28 -> 35.64 | E28: =MIN(45, IF(CSE4098A_Spring2026_Presentatio!AA28>1, CSE4098A_Spring2026_Presentatio!AA28, CSE4098A_Spring2026_Presentatio!AA28*45)) -> 37.51 | F28: 4 | G28: 9 | H28: =SUM(D28:G28) -> 86.15 | I28: =IF(H28>=98,"A+",IF(H28>=85,"A",IF(H28>=80,"A-",IF(H28>=75,"B+",IF(H28>=70,"B",IF(H28>=65,"B-",IF(H28>=60,"C+",IF(H28>=55,"C",IF(H28>=50,"D","F"))))))))) -> A
A29: 25 | B29: 231014052 | C29: Md. Shaidur Rahman | D29: =CSE4098A_Spring2026_Report!AB29 -> 25.7 | E29: =MIN(45, IF(CSE4098A_Spring2026_Presentatio!AA29>1, CSE4098A_Spring2026_Presentatio!AA29, CSE4098A_Spring2026_Presentatio!AA29*45)) -> 21.33 | F29: 3 | G29: 6 | H29: =SUM(D29:G29) -> 56.03 | I29: =IF(H29>=98,"A+",IF(H29>=85,"A",IF(H29>=80,"A-",IF(H29>=75,"B+",IF(H29>=70,"B",IF(H29>=65,"B-",IF(H29>=60,"C+",IF(H29>=55,"C",IF(H29>=50,"D","F"))))))))) -> C | J29: NUA | K29: Behavior-Based Network Attack Detection System Using Machine Learning
A30: 26 | B30: 231014131 | C30: Sumia Sharmin Sinthia | D30: =CSE4098A_Spring2026_Report!AB30 -> 25.7 | E30: =MIN(45, IF(CSE4098A_Spring2026_Presentatio!AA30>1, CSE4098A_Spring2026_Presentatio!AA30, CSE4098A_Spring2026_Presentatio!AA30*45)) -> 25.04 | F30: 3 | G30: 6 | H30: =SUM(D30:G30) -> 59.74 | I30: =IF(H30>=98,"A+",IF(H30>=85,"A",IF(H30>=80,"A-",IF(H30>=75,"B+",IF(H30>=70,"B",IF(H30>=65,"B-",IF(H30>=60,"C+",IF(H30>=55,"C",IF(H30>=50,"D","F"))))))))) -> C
A31: 27 | B31: 221014109 | C31: Maharun Nessa Akhi | D31: =CSE4098A_Spring2026_Report!AB31 -> 25.7 | E31: =MIN(45, IF(CSE4098A_Spring2026_Presentatio!AA31>1, CSE4098A_Spring2026_Presentatio!AA31, CSE4098A_Spring2026_Presentatio!AA31*45)) -> 21.7 | F31: 3 | G31: 6 | H31: =SUM(D31:G31) -> 56.4 | I31: =IF(H31>=98,"A+",IF(H31>=85,"A",IF(H31>=80,"A-",IF(H31>=75,"B+",IF(H31>=70,"B",IF(H31>=65,"B-",IF(H31>=60,"C+",IF(H31>=55,"C",IF(H31>=50,"D","F"))))))))) -> C
A32: 28 | B32: 223014088 | C32: Md. Sakib Ishrak | D32: =CSE4098A_Spring2026_Report!AB32 -> 25.7 | E32: =MIN(45, IF(CSE4098A_Spring2026_Presentatio!AA32>1, CSE4098A_Spring2026_Presentatio!AA32, CSE4098A_Spring2026_Presentatio!AA32*45)) -> 21.11 | F32: 3 | G32: 6 | H32: =SUM(D32:G32) -> 55.81 | I32: =IF(H32>=98,"A+",IF(H32>=85,"A",IF(H32>=80,"A-",IF(H32>=75,"B+",IF(H32>=70,"B",IF(H32>=65,"B-",IF(H32>=60,"C+",IF(H32>=55,"C",IF(H32>=50,"D","F"))))))))) -> C
A33: 29 | B33: 231014017 | C33: Md. Jahid Ahamed Jihad | D33: =CSE4098A_Spring2026_Report!AB33 -> 33.7 | E33: =MIN(45, IF(CSE4098A_Spring2026_Presentatio!AA33>1, CSE4098A_Spring2026_Presentatio!AA33, CSE4098A_Spring2026_Presentatio!AA33*45)) -> 36.93 | F33: 4 | G33: 8 | H33: =SUM(D33:G33) -> 82.63 | I33: =IF(H33>=98,"A+",IF(H33>=85,"A",IF(H33>=80,"A-",IF(H33>=75,"B+",IF(H33>=70,"B",IF(H33>=65,"B-",IF(H33>=60,"C+",IF(H33>=55,"C",IF(H33>=50,"D","F"))))))))) -> A- | J33: NUA | K33: KidneyGenZ: A Lightweight Convolutional Neural Network for Multi-Stage Kidney Disease and Renal Cyst Malignancy Classification in CT Imaging
A34: 30 | B34: 231014115 | C34: Iftiker Jahid Moyshun | D34: =CSE4098A_Spring2026_Report!AB34 -> 33.7 | E34: =MIN(45, IF(CSE4098A_Spring2026_Presentatio!AA34>1, CSE4098A_Spring2026_Presentatio!AA34, CSE4098A_Spring2026_Presentatio!AA34*45)) -> 35.02 | F34: 4 | G34: 8 | H34: =SUM(D34:G34) -> 80.72 | I34: =IF(H34>=98,"A+",IF(H34>=85,"A",IF(H34>=80,"A-",IF(H34>=75,"B+",IF(H34>=70,"B",IF(H34>=65,"B-",IF(H34>=60,"C+",IF(H34>=55,"C",IF(H34>=50,"D","F"))))))))) -> A-
A35: 31 | B35: 231014151 | C35: Hasan Uddin Chowdhury | D35: =CSE4098A_Spring2026_Report!AB35 -> 33.7 | E35: =MIN(45, IF(CSE4098A_Spring2026_Presentatio!AA35>1, CSE4098A_Spring2026_Presentatio!AA35, CSE4098A_Spring2026_Presentatio!AA35*45)) -> 29.11 | F35: 3 | G35: 6 | H35: =SUM(D35:G35) -> 71.81 | I35: =IF(H35>=98,"A+",IF(H35>=85,"A",IF(H35>=80,"A-",IF(H35>=75,"B+",IF(H35>=70,"B",IF(H35>=65,"B-",IF(H35>=60,"C+",IF(H35>=55,"C",IF(H35>=50,"D","F"))))))))) -> B
A36: 32 | B36: 231014003 | C36: Md. Arfan Alam | D36: =CSE4098A_Spring2026_Report!AB36 -> 33.7 | E36: =MIN(45, IF(CSE4098A_Spring2026_Presentatio!AA36>1, CSE4098A_Spring2026_Presentatio!AA36, CSE4098A_Spring2026_Presentatio!AA36*45)) -> 36.84 | F36: 5 | G36: 9 | H36: =SUM(D36:G36) -> 84.54 | I36: =IF(H36>=98,"A+",IF(H36>=85,"A",IF(H36>=80,"A-",IF(H36>=75,"B+",IF(H36>=70,"B",IF(H36>=65,"B-",IF(H36>=60,"C+",IF(H36>=55,"C",IF(H36>=50,"D","F"))))))))) -> A-
A37: 33 | B37: 231014147 | C37: Asif Ahmed | D37: =CSE4098A_Spring2026_Report!AB37 -> 33.7 | E37: =MIN(45, IF(CSE4098A_Spring2026_Presentatio!AA37>1, CSE4098A_Spring2026_Presentatio!AA37, CSE4098A_Spring2026_Presentatio!AA37*45)) -> 32.76 | F37: 3 | G37: 5 | H37: =SUM(D37:G37) -> 74.46 | I37: =IF(H37>=98,"A+",IF(H37>=85,"A",IF(H37>=80,"A-",IF(H37>=75,"B+",IF(H37>=70,"B",IF(H37>=65,"B-",IF(H37>=60,"C+",IF(H37>=55,"C",IF(H37>=50,"D","F"))))))))) -> B
A38: 34 | B38: 213014010 | C38: Mozahedur Nur Nishanul Niloy | D38: =CSE4098A_Spring2026_Report!AB38 -> 30.3 | E38: =MIN(45, IF(CSE4098A_Spring2026_Presentatio!AA38>1, CSE4098A_Spring2026_Presentatio!AA38, CSE4098A_Spring2026_Presentatio!AA38*45)) -> 27.78 | F38: 5 | G38: 10 | H38: =SUM(D38:G38) -> 73.08 | I38: =IF(H38>=98,"A+",IF(H38>=85,"A",IF(H38>=80,"A-",IF(H38>=75,"B+",IF(H38>=70,"B",IF(H38>=65,"B-",IF(H38>=60,"C+",IF(H38>=55,"C",IF(H38>=50,"D","F"))))))))) -> B | J38: WFU | K38: Lightweight Bangla Dialect Processing System: Converting Regional Speech to Standard Bangla and English Text with Audio Output
A39: 35 | B39: 221014096 | C39: Md. Nasimuzzaman Setu | D39: =CSE4098A_Spring2026_Report!AB39 -> 30.3 | E39: =MIN(45, IF(CSE4098A_Spring2026_Presentatio!AA39>1, CSE4098A_Spring2026_Presentatio!AA39, CSE4098A_Spring2026_Presentatio!AA39*45)) -> 27.6 | F39: 4 | G39: 9 | H39: =SUM(D39:G39) -> 70.9 | I39: =IF(H39>=98,"A+",IF(H39>=85,"A",IF(H39>=80,"A-",IF(H39>=75,"B+",IF(H39>=70,"B",IF(H39>=65,"B-",IF(H39>=60,"C+",IF(H39>=55,"C",IF(H39>=50,"D","F"))))))))) -> B
A40: 36 | B40: 221014061 | C40: Mirazul Islam Turag | D40: =CSE4098A_Spring2026_Report!AB40 -> 30.3 | E40: =MIN(45, IF(CSE4098A_Spring2026_Presentatio!AA40>1, CSE4098A_Spring2026_Presentatio!AA40, CSE4098A_Spring2026_Presentatio!AA40*45)) -> 27.6 | F40: 4 | G40: 9 | H40: =SUM(D40:G40) -> 70.9 | I40: =IF(H40>=98,"A+",IF(H40>=85,"A",IF(H40>=80,"A-",IF(H40>=75,"B+",IF(H40>=70,"B",IF(H40>=65,"B-",IF(H40>=60,"C+",IF(H40>=55,"C",IF(H40>=50,"D","F"))))))))) -> B
...

Sheet CO_PO_Attainment_Analysis 
AU1: Mapping of COs to POs
C2: Assessment Items | D2: CO1 | E2: CO2 | F2: CO3 | G2: CO4 | H2: CO5 | I2: CO6 | AT2: PO1 | AU2: PO2 | AV2: PO3 | AW2: PO4 | AX2: PO5 | AY2: PO6 | AZ2: PO7 | BA2: PO8 | BB2: PO9 | BC2: PO10 | BD2: PO11 | BE2: PO12
C3: Report | D3: 15 | E3: 3 | F3: 3 | AS3: CO1 | AT3: 0 | AU3: 1 | AV3: 0 | AW3: 0 | AX3: 0 | AY3: 0 | AZ3: 0 | BA3: 0 | BB3: 0 | BC3: 0 | BD3: 0 | BE3: 0
C4: Peer | G4: 5 | AS4: CO2 | AT4: 0 | AU4: 0 | AV4: 0 | AW4: 0 | AX4: 0 | AY4: 0 | AZ4: 0 | BA4: 0 | BB4: 0 | BC4: 0 | BD4: 0 | BE4: 1
C5: Term Final Presentation | H5: 10 | AS5: CO3 | AT5: 0 | AU5: 0 | AV5: 0 | AW5: 0 | AX5: 0 | AY5: 0 | AZ5: 0 | BA5: 0 | BB5: 0 | BC5: 0 | BD5: 1 | BE5: 0
AS6: CO4 | AT6: 0 | AU6: 0 | AV6: 0 | AW6: 0 | AX6: 0 | AY6: 0 | AZ6: 0 | BA6: 0 | BB6: 1 | BC6: 0 | BD6: 0 | BE6: 0
C7: Total | D7: =SUM(D3:D6) -> 15 | E7: =SUM(E3:E6) -> 3 | F7: =SUM(F3:F6) -> 3 | G7: =SUM(G3:G6) -> 5 | H7: =SUM(H3:H6) -> 10 | I7: =SUM(I3:I6) -> 0 | AS7: CO5 | AT7: 0 | AU7: 0 | AV7: 0 | AW7: 0 | AX7: 0 | AY7: 0 | AZ7: 0 | BA7: 0 | BB7: 0 | BC7: 1 | BD7: 0 | BE7: 0
AS8: CO6 | AT8: 0 | AU8: 0 | AV8: 0 | AW8: 0 | AX8: 0 | AY8: 0 | AZ8: 0 | BA8: 0 | BB8: 0 | BC8: 0 | BD8: 0 | BE8: 0
AS9: Total | AT9: =SUM(AT3:AT8) -> 0 | AU9: =SUM(AU3:AU8) -> 1 | AV9: =SUM(AV3:AV8) -> 0 | AW9: =SUM(AW3:AW8) -> 0 | AX9: =SUM(AX3:AX8) -> 0 | AY9: =SUM(AY3:AY8) -> 0 | AZ9: =SUM(AZ3:AZ8) -> 0 | BA9: =SUM(BA3:BA8) -> 0 | ... BE9: =SUM(BE3:BE8) -> 1
A11: CO Attainment Analysis CSE 4098A [Spring 2026] | AB11: CO Attainment Analysis | AU11: PO Attainment Analysis
D12: =C3 -> Report | J12: =C4 -> Peer | P12: Presentation | V12: Project | AB12: Total Marks | AH12: Percentage | AN12: CO Attainment | AU12: Percentage | BG12: PO Attainment
D13: CO1 | E13: CO2 | F13: CO3 | G13: CO4 | H13: CO5 | I13: CO6 | J13: CO1 | K13: CO2 | L13: CO3 | M13: CO4 | N13: CO5 | O13: CO6 | P13: CO1 | Q13: CO2 | R13: CO3 | S13: CO4 | T13: CO5 | U13: CO6 | V13: CO1 | W13: CO2 | X13: CO3 | Y13: CO4 | Z13: CO5 | AA13: CO6 | AB13: CO1 | AC13: CO2 | AD13: CO3 | AE13: CO4 | AF13: CO5 | AG13: CO6 | AH13: CO1 | AI13: CO2 | AJ13: CO3 | AK13: CO4 | AL13: CO5 | AM13: CO6 | AN13: CO1 | AO13: CO2 | AP13: CO3 | AQ13: CO4 | AR13: CO5 | AS13: CO6 | AU13: PO1 | AV13: PO2 | AW13: PO3 | AX13: PO4 | AY13: PO5 | AZ13: PO6 | BA13: PO7 | BB13: PO8 | BC13: PO9 | BD13: PO10 | BE13: PO11 | BF13: PO12 | BG13: PO1 | BH13: PO2 | BI13: PO3 | BJ13: PO4 | BK13: PO5 | BL13: PO6 | BM13: PO7 | BN13: PO8 | BO13: PO9 | BP13: PO10 | BQ13: PO11 | BR13: PO12
A14: S/N | B14: Student ID | C14: Name | D14: =D3 -> 15 | E14: =E3 -> 3 | F14: =F3 -> 3 | G14: =G3 | H14: =H3 | I14: =I3 | J14: =D4 | K14: =E4 | L14: =F4 | M14: =G4 -> 5 | N14: =H4 | O14: =I4 | P14: =D5 | Q14: =E5 | R14: =F5 | S14: =G5 | T14: =H5 -> 10 | U14: =I5 | V14: =D6 | W14: =E6 | X14: =F6 | Y14: =G6 | Z14: =H6 | AA14: =I6 | AB14: =SUM(P14,D14,J14) -> 15 | AC14: =SUM(K14,E14,Q14) -> 3 | AD14: =SUM(L14,F14,R14) -> 3 | AE14: =SUM(M14,G14,S14) -> 5 | AF14: =SUM(N14,H14,T14) -> 10 | AG14: =SUM(O14,I14,U14) -> 0 | AH14: 1 | AI14: 1 | AJ14: 1 | AK14: 1 | AL14: 1 | AM14: 1 | AN14: If CO achieved (≥55%) then 1, else 0 | AU14: 1 | AV14: 1 | AW14: 1 | AX14: 1 | AY14: 1 | AZ14: 1 | BA14: 1 | BB14: 1 | BC14: 1 | BD14: 1 | BE14: 1 | BF14: 1 | BG14: If PO achieved (≥55%) then 1, else 0
A15: 1 | B15: =CSE4098A_Spring2026_Grade!B5 -> 231014004 | C15: =CSE4098A_Spring2026_Grade!C5 -> Bushra Nusyba Chowdhury | D15: ='CO_Report Evaluation'!P3 -> 12.666667 | E15: ='CO_Report Evaluation'!Q3 -> 2.6666667 | F15: ='CO_Report Evaluation'!R3 -> 2.3333333 | M15: 2 | T15: =((CSE4098A_Spring2026_Grade!E5)*10)/45 -> 9.1355556 | AB15: =SUM(V15,D15,J15) -> 12.666667 | AC15: =SUM(Q15, W15,E15,K15) -> 2.6666667 | AD15: =SUM(R15, X15,F15,L15) -> 2.3333333 | AE15: =SUM(S15, Y15,G15,M15) -> 2 | AF15: =SUM(T15,H15,N15) -> 9.1355556 | AG15: =SUM(AA15,I15,O15) -> 0 | AH15: =IF(AB15 = 0, 0, AB15/AB$14) -> 0.84444444 | AI15: =IF(AC15 = 0, 0, AC15/AC$14) -> 0.88888889 | AJ15: =IF(AD15 = 0, 0, AD15/AD$14) -> 0.77777778 | AK15: =IF(AE15 = 0, 0, AE15/AE$14) -> 0.4 | AL15: =IF(AF15 = 0, 0, AF15/AF$14) -> 0.91355556 | AM15: =IF(AG15 = 0, 0, AG15/AG$14) -> 0 | AN15: =IF(OR(CSE4098A_Spring2026_Grade!$I5="W (Withdrawn)", CSE4098A_Spring2026_Grade!$I5="I (Incomplete)"), 0, IF(AH15>=55%, 1, 0)) -> 1 | AO15: =IF(OR(CSE4098A_Spring2026_Grade!$I5="W (Withdrawn)", CSE4098A_Spring2026_Grade!I5="I (Incomplete)"), 0, IF(AI15>=55%, 1, 0)) -> 1 | AP15: =IF(OR(CSE4098A_Spring2026_Grade!$I5="W (Withdrawn)", CSE4098A_Spring2026_Grade!$I5="I (Incomplete)"), 0, IF(AJ15>=55%, 1, 0)) -> 1 | AQ15: =IF(OR(CSE4098A_Spring2026_Grade!$I5="W (Withdrawn)", CSE4098A_Spring2026_Grade!$I5="I (Incomplete)"), 0, IF(AK15>=55%, 1, 0)) -> 0 | AR15: =IF(OR(CSE4098A_Spring2026_Grade!$I5="W (Withdrawn)", CSE4098A_Spring2026_Grade!$I5="I (Incomplete)"), 0, IF(AL15>=55%, 1, 0)) -> 1 | AS15: =IF(OR(CSE4098A_Spring2026_Grade!$I5="W (Withdrawn)", CSE4098A_Spring2026_Grade!$I5="I (Incomplete)"), 0, IF(AM15>=55%, 1, 0)) -> 0 | AU15: =IF($AT$9=0,0,MMULT($AH15:$AM15, AT$3:AT$8)/$AT$9) -> 0 | AV15: =IF($AU$9=0,0,MMULT($AH15:$AM15, AU$3:AU$8)/$AU$9) -> 0.84444444 | AW15: {=IF($AV$9=0,0,MMULT($AH15:$AM15, AV$3:AV$8)/$AV$9)} -> 0 | AX15: {=IF($AW$9=0,0,MMULT($AH15:$AM15, AW$3:AW$8)/$AW$9)} -> 0 | AY15: =IF($AX$9=0,0,MMULT($AH15:$AM15, AX$3:AX$8)/$AX$9) -> 0 | AZ15: {=IF($AY$9=0,0,MMULT($AH15:$AM15, AY$3:AY$8)/$AY$9)} -> 0 | BA15: {=IF($AZ$9=0,0,MMULT($AH15:$AM15, AZ$3:AZ$8)/$AZ$9)} -> 0 | BB15: {=IF($BA$9=0,0,MMULT($AH15:$AM15, BA$3:BA$8)/$BA$9)} -> 0 | BC15: {=IF($BB$9=0,0,MMULT($AH15:$AM15, BB$3:BB$8)/$BB$9)} -> 0.4 | BD15: {=IF($BC$9=0,0,MMULT($AH15:$AM15, BC$3:BC$8)/$BC$9)} -> 0.91355556 | BE15: =IF($BD$9=0,0,MMULT($AH15:$AM15, BD$3:BD$8)/$BD$9) -> 0.77777778 | BF15: =IF($BE$9=0,0,MMULT($AH15:$AM15, BE$3:BE$8)/$BE$9) -> 0.88888889 | BG15: =IF(OR(GradeSheet!$M10="W (Withdrawn)", GradeSheet!$M10="I (Incomplete)"), 0, IF(AU15>=55%, 1, 0)) -> #REF! | BH15: =IF(OR(CSE4098A_Spring2026_Grade!$I5="W (Withdrawn)", CSE4098A_Spring2026_Grade!$I5="I (Incomplete)"), 0, IF(AV15>=55%, 1, 0)) -> 1 | BI15: =IF(OR(GradeSheet!$M10="W (Withdrawn)", GradeSheet!$M10="I (Incomplete)"), 0, IF(AW15>=55%, 1, 0)) -> #REF! | BJ15: =IF(OR(GradeSheet!$M10="W (Withdrawn)", GradeSheet!$M10="I (Incomplete)"), 0, IF(AX15>=55%, 1, 0)) -> #REF! | BK15: =IF(OR(GradeSheet!$M10="W (Withdrawn)", GradeSheet!$M10="I (Incomplete)"), 0, IF(AY15>=55%, 1, 0)) -> #REF! | BL15: =IF(OR(GradeSheet!$M10="W (Withdrawn)", GradeSheet!$M10="I (Incomplete)"), 0, IF(AZ15>=55%, 1, 0)) -> #REF! | BM15: =IF(OR(GradeSheet!$M10="W (Withdrawn)", GradeSheet!$M10="I (Incomplete)"), 0, IF(BA15>=55%, 1, 0)) -> #REF! | BN15: =IF(OR(GradeSheet!$M10="W (Withdrawn)", GradeSheet!$M10="I (Incomplete)"), 0, IF(BB15>=55%, 1, 0)) -> #REF! | BO15: =IF(OR(CSE4098A_Spring2026_Grade!$I5="W (Withdrawn)", CSE4098A_Spring2026_Grade!$I5="I (Incomplete)"), 0, IF(BC15>=55%, 1, 0)) -> 0 | BP15: =IF(OR(CSE4098A_Spring2026_Grade!$I5="W (Withdrawn)", CSE4098A_Spring2026_Grade!$I5="I (Incomplete)"), 0, IF(BD15>=55%, 1, 0)) -> 1 | BQ15: =IF(OR(CSE4098A_Spring2026_Grade!$I5="W (Withdrawn)", CSE4098A_Spring2026_Grade!$I5="I (Incomplete)"), 0, IF(BE15>=55%, 1, 0)) -> 1 | BR15: =IF(OR(CSE4098A_Spring2026_Grade!$I5="W (Withdrawn)", CSE4098A_Spring2026_Grade!$I5="I (Incomplete)"), 0, IF(BF15>=55%, 1, 0)) -> 1
A16: 2 | B16: =CSE4098A_Spring2026_Grade!B6 -> 231014146 | C16: =CSE4098A_Spring2026_Grade!C6 -> Tasneem Ahmed | D16: ='CO_Report Evaluation'!P4 -> 12.666667 | E16: ='CO_Report Evaluation'!Q4 -> 2.6666667 | F16: ='CO_Report Evaluation'!R4 -> 2.3333333 | M16: 2 | T16: =((CSE4098A_Spring2026_Grade!E6)*10)/45 -> 8.18 | AB16: =SUM(V16,D16,J16) -> 12.666667 | AC16: =SUM(Q16, W16,E16,K16) -> 2.6666667 | AD16: =SUM(R16, X16,F16,L16) -> 2.3333333 | AE16: =SUM(S16, Y16,G16,M16) -> 2 | AF16: =SUM(T16,H16,N16) -> 8.18 | AG16: =SUM(AA16,I16,O16) -> 0 | AH16: =IF(AB16 = 0, 0, AB16/AB$14) -> 0.84444444 | AI16: =IF(AC16 = 0, 0, AC16/AC$14) -> 0.88888889 | AJ16: =IF(AD16 = 0, 0, AD16/AD$14) -> 0.77777778 | AK16: =IF(AE16 = 0, 0, AE16/AE$14) -> 0.4 | AL16: =IF(AF16 = 0, 0, AF16/AF$14) -> 0.818 | AM16: =IF(AG16 = 0, 0, AG16/AG$14) -> 0 | AN16: =IF(OR(CSE4098A_Spring2026_Grade!$I6="W (Withdrawn)", CSE4098A_Spring2026_Grade!$I6="I (Incomplete)"), 0, IF(AH16>=55%, 1, 0)) -> 1 | AO16: =IF(OR(CSE4098A_Spring2026_Grade!$I6="W (Withdrawn)", CSE4098A_Spring2026_Grade!I6="I (Incomplete)"), 0, IF(AI16>=55%, 1, 0)) -> 1 | AP16: =IF(OR(CSE4098A_Spring2026_Grade!$I6="W (Withdrawn)", CSE4098A_Spring2026_Grade!$I6="I (Incomplete)"), 0, IF(AJ16>=55%, 1, 0)) -> 1 | AQ16: =IF(OR(CSE4098A_Spring2026_Grade!$I6="W (Withdrawn)", CSE4098A_Spring2026_Grade!$I6="I (Incomplete)"), 0, IF(AK16>=55%, 1, 0)) -> 0 | AR16: =IF(OR(CSE4098A_Spring2026_Grade!$I6="W (Withdrawn)", CSE4098A_Spring2026_Grade!$I6="I (Incomplete)"), 0, IF(AL16>=55%, 1, 0)) -> 1 | AS16: =IF(OR(CSE4098A_Spring2026_Grade!$I6="W (Withdrawn)", CSE4098A_Spring2026_Grade!$I6="I (Incomplete)"), 0, IF(AM16>=55%, 1, 0)) -> 0 | AU16: =IF($AT$9=0,0,MMULT($AH16:$AM16, AT$3:AT$8)/$AT$9) -> 0 | AV16: =IF($AU$9=0,0,MMULT($AH16:$AM16, AU$3:AU$8)/$AU$9) -> 0.84444444 | AW16: {=IF($AV$9=0,0,MMULT($AH16:$AM16, AV$3:AV$8)/$AV$9)} -> 0 | AX16: {=IF($AW$9=0,0,MMULT($AH16:$AM16, AW$3:AW$8)/$AW$9)} -> 0 | AY16: =IF($AX$9=0,0,MMULT($AH16:$AM16, AX$3:AX$8)/$AX$9) -> 0 | AZ16: {=IF($AY$9=0,0,MMULT($AH16:$AM16, AY$3:AY$8)/$AY$9)} -> 0 | BA16: {=IF($AZ$9=0,0,MMULT($AH16:$AM16, AZ$3:AZ$8)/$AZ$9)} -> 0 | BB16: {=IF($BA$9=0,0,MMULT($AH16:$AM16, BA$3:BA$8)/$BA$9)} -> 0 | BC16: {=IF($BB$9=0,0,MMULT($AH16:$AM16, BB$3:BB$8)/$BB$9)} -> 0.4 | BD16: {=IF($BC$9=0,0,MMULT($AH16:$AM16, BC$3:BC$8)/$BC$9)} -> 0.818 | BE16: =IF($BD$9=0,0,MMULT($AH16:$AM16, BD$3:BD$8)/$BD$9) -> 0.77777778 | BF16: =IF($BE$9=0,0,MMULT($AH16:$AM16, BE$3:BE$8)/$BE$9) -> 0.88888889 | BG16: =IF(OR(GradeSheet!$M11="W (Withdrawn)", GradeSheet!$M11="I (Incomplete)"), 0, IF(AU16>=55%, 1, 0)) -> #REF! | BH16: =IF(OR(CSE4098A_Spring2026_Grade!$I6="W (Withdrawn)", CSE4098A_Spring2026_Grade!$I6="I (Incomplete)"), 0, IF(AV16>=55%, 1, 0)) -> 1 | BI16: =IF(OR(GradeSheet!$M11="W (Withdrawn)", GradeSheet!$M11="I (Incomplete)"), 0, IF(AW16>=55%, 1, 0)) -> #REF! | BJ16: =IF(OR(GradeSheet!$M11="W (Withdrawn)", GradeSheet!$M11="I (Incomplete)"), 0, IF(AX16>=55%, 1, 0)) -> #REF! | BK16: =IF(OR(GradeSheet!$M11="W (Withdrawn)", GradeSheet!$M11="I (Incomplete)"), 0, IF(AY16>=55%, 1, 0)) -> #REF! | BL16: =IF(OR(GradeSheet!$M11="W (Withdrawn)", GradeSheet!$M11="I (Incomplete)"), 0, IF(AZ16>=55%, 1, 0)) -> #REF! | BM16: =IF(OR(GradeSheet!$M11="W (Withdrawn)", GradeSheet!$M11="I (Incomplete)"), 0, IF(BA16>=55%, 1, 0)) -> #REF! | BN16: =IF(OR(GradeSheet!$M11="W (Withdrawn)", GradeSheet!$M11="I (Incomplete)"), 0, IF(BB16>=55%, 1, 0)) -> #REF! | BO16: =IF(OR(CSE4098A_Spring2026_Grade!$I6="W (Withdrawn)", CSE4098A_Spring2026_Grade!$I6="I (Incomplete)"), 0, IF(BC16>=55%, 1, 0)) -> 0 | BP16: =IF(OR(CSE4098A_Spring2026_Grade!$I6="W (Withdrawn)", CSE4098A_Spring2026_Grade!$I6="I (Incomplete)"), 0, IF(BD16>=55%, 1, 0)) -> 1 | BQ16: =IF(OR(CSE4098A_Spring2026_Grade!$I6="W (Withdrawn)", CSE4098A_Spring2026_Grade!$I6="I (Incomplete)"), 0, IF(BE16>=55%, 1, 0)) -> 1 | BR16: =IF(OR(CSE4098A_Spring2026_Grade!$I6="W (Withdrawn)", CSE4098A_Spring2026_Grade!$I6="I (Incomplete)"), 0, IF(BF16>=55%, 1, 0)) -> 1
A17: 3 | B17: =CSE4098A_Spring2026_Grade!B7 -> 231014006 | C17: =CSE4098A_Spring2026_Grade!C7 -> Ibnul Haque Chowdhury | D17: ='CO_Report Evaluation'!P5 -> 12.666667 | E17: ='CO_Report Evaluation'!Q5 -> 2.6666667 | F17: ='CO_Report Evaluation'!R5 -> 2.3333333 | M17: 2 | T17: =((CSE4098A_Spring2026_Grade!E7)*10)/45 -> 8.0977778 | AB17: =SUM(V17,D17,J17) -> 12.666667 | AC17: =SUM(Q17, W17,E17,K17) -> 2.6666667 | AD17: =SUM(R17, X17,F17,L17) -> 2.3333333 | AE17: =SUM(S17, Y17,G17,M17) -> 2 | AF17: =SUM(T17,H17,N17) -> 8.0977778 | AG17: =SUM(AA17,I17,O17) -> 0 | AH17: =IF(AB17 = 0, 0, AB17/AB$14) -> 0.84444444 | AI17: =IF(AC17 = 0, 0, AC17/AC$14) -> 0.88888889 | AJ17: =IF(AD17 = 0, 0, AD17/AD$14) -> 0.77777778 | AK17: =IF(AE17 = 0, 0, AE17/AE$14) -> 0.4 | AL17: =IF(AF17 = 0, 0, AF17/AF$14) -> 0.80977778 | AM17: =IF(AG17 = 0, 0, AG17/AG$14) -> 0 | AN17: =IF(OR(CSE4098A_Spring2026_Grade!$I7="W (Withdrawn)", CSE4098A_Spring2026_Grade!$I7="I (Incomplete)"), 0, IF(AH17>=55%, 1, 0)) -> 1 | AO17: =IF(OR(CSE4098A_Spring2026_Grade!$I7="W (Withdrawn)", CSE4098A_Spring2026_Grade!I7="I (Incomplete)"), 0, IF(AI17>=55%, 1, 0)) -> 1 | AP17: =IF(OR(CSE4098A_Spring2026_Grade!$I7="W (Withdrawn)", CSE4098A_Spring2026_Grade!$I7="I (Incomplete)"), 0, IF(AJ17>=55%, 1, 0)) -> 1 | AQ17: =IF(OR(CSE4098A_Spring2026_Grade!$I7="W (Withdrawn)", CSE4098A_Spring2026_Grade!$I7="I (Incomplete)"), 0, IF(AK17>=55%, 1, 0)) -> 0 | AR17: =IF(OR(CSE4098A_Spring2026_Grade!$I7="W (Withdrawn)", CSE4098A_Spring2026_Grade!$I7="I (Incomplete)"), 0, IF(AL17>=55%, 1, 0)) -> 1 | AS17: =IF(OR(CSE4098A_Spring2026_Grade!$I7="W (Withdrawn)", CSE4098A_Spring2026_Grade!$I7="I (Incomplete)"), 0, IF(AM17>=55%, 1, 0)) -> 0 | AU17: =IF($AT$9=0,0,MMULT($AH17:$AM17, AT$3:AT$8)/$AT$9) -> 0 | AV17: =IF($AU$9=0,0,MMULT($AH17:$AM17, AU$3:AU$8)/$AU$9) -> 0.84444444 | AW17: {=IF($AV$9=0,0,MMULT($AH17:$AM17, AV$3:AV$8)/$AV$9)} -> 0 | AX17: {=IF($AW$9=0,0,MMULT($AH17:$AM17, AW$3:AW$8)/$AW$9)} -> 0 | AY17: =IF($AX$9=0,0,MMULT($AH17:$AM17, AX$3:AX$8)/$AX$9) -> 0 | AZ17: {=IF($AY$9=0,0,MMULT($AH17:$AM17, AY$3:AY$8)/$AY$9)} -> 0 | BA17: {=IF($AZ$9=0,0,MMULT($AH17:$AM17, AZ$3:AZ$8)/$AZ$9)} -> 0 | BB17: {=IF($BA$9=0,0,MMULT($AH17:$AM17, BA$3:BA$8)/$BA$9)} -> 0 | BC17: {=IF($BB$9=0,0,MMULT($AH17:$AM17, BB$3:BB$8)/$BB$9)} -> 0.4 | BD17: {=IF($BC$9=0,0,MMULT($AH17:$AM17, BC$3:BC$8)/$BC$9)} -> 0.80977778 | BE17: =IF($BD$9=0,0,MMULT($AH17:$AM17, BD$3:BD$8)/$BD$9) -> 0.77777778 | BF17: =IF($BE$9=0,0,MMULT($AH17:$AM17, BE$3:BE$8)/$BE$9) -> 0.88888889 | BG17: =IF(OR(GradeSheet!$M12="W (Withdrawn)", GradeSheet!$M12="I (Incomplete)"), 0, IF(AU17>=55%, 1, 0)) -> #REF! | BH17: =IF(OR(CSE4098A_Spring2026_Grade!$I7="W (Withdrawn)", CSE4098A_Spring2026_Grade!$I7="I (Incomplete)"), 0, IF(AV17>=55%, 1, 0)) -> 1 | BI17: =IF(OR(GradeSheet!$M12="W (Withdrawn)", GradeSheet!$M12="I (Incomplete)"), 0, IF(AW17>=55%, 1, 0)) -> #REF! | BJ17: =IF(OR(GradeSheet!$M12="W (Withdrawn)", GradeSheet!$M12="I (Incomplete)"), 0, IF(AX17>=55%, 1, 0)) -> #REF! | BK17: =IF(OR(GradeSheet!$M12="W (Withdrawn)", GradeSheet!$M12="I (Incomplete)"), 0, IF(AY17>=55%, 1, 0)) -> #REF! | BL17: =IF(OR(GradeSheet!$M12="W (Withdrawn)", GradeSheet!$M12="I (Incomplete)"), 0, IF(AZ17>=55%, 1, 0)) -> #REF! | BM17: =IF(OR(GradeSheet!$M12="W (Withdrawn)", GradeSheet!$M12="I (Incomplete)"), 0, IF(BA17>=55%, 1, 0)) -> #REF! | BN17: =IF(OR(GradeSheet!$M12="W (Withdrawn)", GradeSheet!$M12="I (Incomplete)"), 0, IF(BB17>=55%, 1, 0)) -> #REF! | BO17: =IF(OR(CSE4098A_Spring2026_Grade!$I7="W (Withdrawn)", CSE4098A_Spring2026_Grade!$I7="I (Incomplete)"), 0, IF(BC17>=55%, 1, 0)) -> 0 | BP17: =IF(OR(CSE4098A_Spring2026_Grade!$I7="W (Withdrawn)", CSE4098A_Spring2026_Grade!$I7="I (Incomplete)"), 0, IF(BD17>=55%, 1, 0)) -> 1 | BQ17: =IF(OR(CSE4098A_Spring2026_Grade!$I7="W (Withdrawn)", CSE4098A_Spring2026_Grade!$I7="I (Incomplete)"), 0, IF(BE17>=55%, 1, 0)) -> 1 | BR17: =IF(OR(CSE4098A_Spring2026_Grade!$I7="W (Withdrawn)", CSE4098A_Spring2026_Grade!$I7="I (Incomplete)"), 0, IF(BF17>=55%, 1, 0)) -> 1
A18: 4 | B18: =CSE4098A_Spring2026_Grade!B8 -> 231014022 | C18: =CSE4098A_Spring2026_Grade!C8 -> Rafsan Islam | D18: ='CO_Report Evaluation'!P6 -> 12.666667 | E18: ='CO_Report Evaluation'!Q6 -> 2.6666667 | F18: ='CO_Report Evaluation'!R6 -> 2.3333333 | M18: 2 | T18: =((CSE4098A_Spring2026_Grade!E8)*10)/45 -> 8.8222222 | AB18: =SUM(V18,D18,J18) -> 12.666667 | AC18: =SUM(Q18, W18,E18,K18) -> 2.6666667 | AD18: =SUM(R18, X18,F18,L18) -> 2.3333333 | AE18: =SUM(S18, Y18,G18,M18) -> 2 | AF18: =SUM(T18,H18,N18) -> 8.8222222 | AG18: =SUM(AA18,I18,O18) -> 0 | AH18: =IF(AB18 = 0, 0, AB18/AB$14) -> 0.84444444 | AI18: =IF(AC18 = 0, 0, AC18/AC$14) -> 0.88888889 | AJ18: =IF(AD18 = 0, 0, AD18/AD$14) -> 0.77777778 | AK18: =IF(AE18 = 0, 0, AE18/AE$14) -> 0.4 | AL18: =IF(AF18 = 0, 0, AF18/AF$14) -> 0.88222222 | AM18: =IF(AG18 = 0, 0, AG18/AG$14) -> 0 | AN18: =IF(OR(CSE4098A_Spring2026_Grade!$I8="W (Withdrawn)", CSE4098A_Spring2026_Grade!$I8="I (Incomplete)"), 0, IF(AH18>=55%, 1, 0)) -> 1 | AO18: =IF(OR(CSE4098A_Spring2026_Grade!$I8="W (Withdrawn)", CSE4098A_Spring2026_Grade!I8="I (Incomplete)"), 0, IF(AI18>=55%, 1, 0)) -> 1 | AP18: =IF(OR(CSE4098A_Spring2026_Grade!$I8="W (Withdrawn)", CSE4098A_Spring2026_Grade!$I8="I (Incomplete)"), 0, IF(AJ18>=55%, 1, 0)) -> 1 | AQ18: =IF(OR(CSE4098A_Spring2026_Grade!$I8="W (Withdrawn)", CSE4098A_Spring2026_Grade!$I8="I (Incomplete)"), 0, IF(AK18>=55%, 1, 0)) -> 0 | AR18: =IF(OR(CSE4098A_Spring2026_Grade!$I8="W (Withdrawn)", CSE4098A_Spring2026_Grade!$I8="I (Incomplete)"), 0, IF(AL18>=55%, 1, 0)) -> 1 | AS18: =IF(OR(CSE4098A_Spring2026_Grade!$I8="W (Withdrawn)", CSE4098A_Spring2026_Grade!$I8="I (Incomplete)"), 0, IF(AM18>=55%, 1, 0)) -> 0 | AU18: =IF($AT$9=0,0,MMULT($AH18:$AM18, AT$3:AT$8)/$AT$9) -> 0 | AV18: =IF($AU$9=0,0,MMULT($AH18:$AM18, AU$3:AU$8)/$AU$9) -> 0.84444444 | AW18: {=IF($AV$9=0,0,MMULT($AH18:$AM18, AV$3:AV$8)/$AV$9)} -> 0 | AX18: {=IF($AW$9=0,0,MMULT($AH18:$AM18, AW$3:AW$8)/$AW$9)} -> 0 | AY18: =IF($AX$9=0,0,MMULT($AH18:$AM18, AX$3:AX$8)/$AX$9) -> 0 | AZ18: {=IF($AY$9=0,0,MMULT($AH18:$AM18, AY$3:AY$8)/$AY$9)} -> 0 | BA18: {=IF($AZ$9=0,0,MMULT($AH18:$AM18, AZ$3:AZ$8)/$AZ$9)} -> 0 | BB18: {=IF($BA$9=0,0,MMULT($AH18:$AM18, BA$3:BA$8)/$BA$9)} -> 0 | BC18: {=IF($BB$9=0,0,MMULT($AH18:$AM18, BB$3:BB$8)/$BB$9)} -> 0.4 | BD18: {=IF($BC$9=0,0,MMULT($AH18:$AM18, BC$3:BC$8)/$BC$9)} -> 0.88222222 | BE18: =IF($BD$9=0,0,MMULT($AH18:$AM18, BD$3:BD$8)/$BD$9) -> 0.77777778 | BF18: =IF($BE$9=0,0,MMULT($AH18:$AM18, BE$3:BE$8)/$BE$9) -> 0.88888889 | BG18: =IF(OR(GradeSheet!$M13="W (Withdrawn)", GradeSheet!$M13="I (Incomplete)"), 0, IF(AU18>=55%, 1, 0)) -> #REF! | BH18: =IF(OR(CSE4098A_Spring2026_Grade!$I8="W (Withdrawn)", CSE4098A_Spring2026_Grade!$I8="I (Incomplete)"), 0, IF(AV18>=55%, 1, 0)) -> 1 | BI18: =IF(OR(GradeSheet!$M13="W (Withdrawn)", GradeSheet!$M13="I (Incomplete)"), 0, IF(AW18>=55%, 1, 0)) -> #REF! | BJ18: =IF(OR(GradeSheet!$M13="W (Withdrawn)", GradeSheet!$M13="I (Incomplete)"), 0, IF(AX18>=55%, 1, 0)) -> #REF! | BK18: =IF(OR(GradeSheet!$M13="W (Withdrawn)", GradeSheet!$M13="I (Incomplete)"), 0, IF(AY18>=55%, 1, 0)) -> #REF! | BL18: =IF(OR(GradeSheet!$M13="W (Withdrawn)", GradeSheet!$M13="I (Incomplete)"), 0, IF(AZ18>=55%, 1, 0)) -> #REF! | BM18: =IF(OR(GradeSheet!$M13="W (Withdrawn)", GradeSheet!$M13="I (Incomplete)"), 0, IF(BA18>=55%, 1, 0)) -> #REF! | BN18: =IF(OR(GradeSheet!$M13="W (Withdrawn)", GradeSheet!$M13="I (Incomplete)"), 0, IF(BB18>=55%, 1, 0)) -> #REF! | BO18: =IF(OR(CSE4098A_Spring2026_Grade!$I8="W (Withdrawn)", CSE4098A_Spring2026_Grade!$I8="I (Incomplete)"), 0, IF(BC18>=55%, 1, 0)) -> 0 | BP18: =IF(OR(CSE4098A_Spring2026_Grade!$I8="W (Withdrawn)", CSE4098A_Spring2026_Grade!$I8="I (Incomplete)"), 0, IF(BD18>=55%, 1, 0)) -> 1 | BQ18: =IF(OR(CSE4098A_Spring2026_Grade!$I8="W (Withdrawn)", CSE4098A_Spring2026_Grade!$I8="I (Incomplete)"), 0, IF(BE18>=55%, 1, 0)) -> 1 | BR18: =IF(OR(CSE4098A_Spring2026_Grade!$I8="W (Withdrawn)", CSE4098A_Spring2026_Grade!$I8="I (Incomplete)"), 0, IF(BF18>=55%, 1, 0)) -> 1
A19: 5 | B19: =CSE4098A_Spring2026_Grade!B9 -> 231014042 | C19: =CSE4098A_Spring2026_Grade!C9 -> Abir Akbar | D19: ='CO_Report Evaluation'!P7 -> 12.666667 | E19: ='CO_Report Evaluation'!Q7 -> 2.6666667 | F19: ='CO_Report Evaluation'!R7 -> 2.3333333 | M19: 3 | T19: =((CSE4098A_Spring2026_Grade!E9)*10)/45 -> 7.9844444 | AB19: =SUM(V19,D19,J19) -> 12.666667 | AC19: =SUM(Q19, W19,E19,K19) -> 2.6666667 | AD19: =SUM(R19, X19,F19,L19) -> 2.3333333 | AE19: =SUM(S19, Y19,G19,M19) -> 3 | AF19: =SUM(T19,H19,N19) -> 7.9844444 | AG19: =SUM(AA19,I19,O19) -> 0 | AH19: =IF(AB19 = 0, 0, AB19/AB$14) -> 0.84444444 | AI19: =IF(AC19 = 0, 0, AC19/AC$14) -> 0.88888889 | AJ19: =IF(AD19 = 0, 0, AD19/AD$14) -> 0.77777778 | AK19: =IF(AE19 = 0, 0, AE19/AE$14) -> 0.6 | AL19: =IF(AF19 = 0, 0, AF19/AF$14) -> 0.79844444 | AM19: =IF(AG19 = 0, 0, AG19/AG$14) -> 0 | AN19: =IF(OR(CSE4098A_Spring2026_Grade!$I9="W (Withdrawn)", CSE4098A_Spring2026_Grade!$I9="I (Incomplete)"), 0, IF(AH19>=55%, 1, 0)) -> 1 | AO19: =IF(OR(CSE4098A_Spring2026_Grade!$I9="W (Withdrawn)", CSE4098A_Spring2026_Grade!I9="I (Incomplete)"), 0, IF(AI19>=55%, 1, 0)) -> 1 | AP19: =IF(OR(CSE4098A_Spring2026_Grade!$I9="W (Withdrawn)", CSE4098A_Spring2026_Grade!$I9="I (Incomplete)"), 0, IF(AJ19>=55%, 1, 0)) -> 1 | AQ19: =IF(OR(CSE4098A_Spring2026_Grade!$I9="W (Withdrawn)", CSE4098A_Spring2026_Grade!$I9="I (Incomplete)"), 0, IF(AK19>=55%, 1, 0)) -> 1 | AR19: =IF(OR(CSE4098A_Spring2026_Grade!$I9="W (Withdrawn)", CSE4098A_Spring2026_Grade!$I9="I (Incomplete)"), 0, IF(AL19>=55%, 1, 0)) -> 1 | AS19: =IF(OR(CSE4098A_Spring2026_Grade!$I9="W (Withdrawn)", CSE4098A_Spring2026_Grade!$I9="I (Incomplete)"), 0, IF(AM19>=55%, 1, 0)) -> 0 | AU19: =IF($AT$9=0,0,MMULT($AH19:$AM19, AT$3:AT$8)/$AT$9) -> 0 | AV19: =IF($AU$9=0,0,MMULT($AH19:$AM19, AU$3:AU$8)/$AU$9) -> 0.84444444 | AW19: {=IF($AV$9=0,0,MMULT($AH19:$AM19, AV$3:AV$8)/$AV$9)} -> 0 | AX19: {=IF($AW$9=0,0,MMULT($AH19:$AM19, AW$3:AW$8)/$AW$9)} -> 0 | AY19: =IF($AX$9=0,0,MMULT($AH19:$AM19, AX$3:AX$8)/$AX$9) -> 0 | AZ19: {=IF($AY$9=0,0,MMULT($AH19:$AM19, AY$3:AY$8)/$AY$9)} -> 0 | BA19: {=IF($AZ$9=0,0,MMULT($AH19:$AM19, AZ$3:AZ$8)/$AZ$9)} -> 0 | BB19: {=IF($BA$9=0,0,MMULT($AH19:$AM19, BA$3:BA$8)/$BA$9)} -> 0 | BC19: {=IF($BB$9=0,0,MMULT($AH19:$AM19, BB$3:BB$8)/$BB$9)} -> 0.6 | BD19: {=IF($BC$9=0,0,MMULT($AH19:$AM19, BC$3:BC$8)/$BC$9)} -> 0.79844444 | BE19: =IF($BD$9=0,0,MMULT($AH19:$AM19, BD$3:BD$8)/$BD$9) -> 0.77777778 | BF19: =IF($BE$9=0,0,MMULT($AH19:$AM19, BE$3:BE$8)/$BE$9) -> 0.88888889 | BG19: =IF(OR(GradeSheet!$M14="W (Withdrawn)", GradeSheet!$M14="I (Incomplete)"), 0, IF(AU19>=55%, 1, 0)) -> #REF! | BH19: =IF(OR(CSE4098A_Spring2026_Grade!$I9="W (Withdrawn)", CSE4098A_Spring2026_Grade!$I9="I (Incomplete)"), 0, IF(AV19>=55%, 1, 0)) -> 1 | BI19: =IF(OR(GradeSheet!$M14="W (Withdrawn)", GradeSheet!$M14="I (Incomplete)"), 0, IF(AW19>=55%, 1, 0)) -> #REF! | BJ19: =IF(OR(GradeSheet!$M14="W (Withdrawn)", GradeSheet!$M14="I (Incomplete)"), 0, IF(AX19>=55%, 1, 0)) -> #REF! | BK19: =IF(OR(GradeSheet!$M14="W (Withdrawn)", GradeSheet!$M14="I (Incomplete)"), 0, IF(AY19>=55%, 1, 0)) -> #REF! | BL19: =IF(OR(GradeSheet!$M14="W (Withdrawn)", GradeSheet!$M14="I (Incomplete)"), 0, IF(AZ19>=55%, 1, 0)) -> #REF! | BM19: =IF(OR(GradeSheet!$M14="W (Withdrawn)", GradeSheet!$M14="I (Incomplete)"), 0, IF(BA19>=55%, 1, 0)) -> #REF! | BN19: =IF(OR(GradeSheet!$M14="W (Withdrawn)", GradeSheet!$M14="I (Incomplete)"), 0, IF(BB19>=55%, 1, 0)) -> #REF! | BO19: =IF(OR(CSE4098A_Spring2026_Grade!$I9="W (Withdrawn)", CSE4098A_Spring2026_Grade!$I9="I (Incomplete)"), 0, IF(BC19>=55%, 1, 0)) -> 1 | BP19: =IF(OR(CSE4098A_Spring2026_Grade!$I9="W (Withdrawn)", CSE4098A_Spring2026_Grade!$I9="I (Incomplete)"), 0, IF(BD19>=55%, 1, 0)) -> 1 | BQ19: =IF(OR(CSE4098A_Spring2026_Grade!$I9="W (Withdrawn)", CSE4098A_Spring2026_Grade!$I9="I (Incomplete)"), 0, IF(BE19>=55%, 1, 0)) -> 1 | BR19: =IF(OR(CSE4098A_Spring2026_Grade!$I9="W (Withdrawn)", CSE4098A_Spring2026_Grade!$I9="I (Incomplete)"), 0, IF(BF19>=55%, 1, 0)) -> 1
A20: 6 | B20: =CSE4098A_Spring2026_Grade!B10 -> 232014128 | C20: =CSE4098A_Spring2026_Grade!C10 -> Tonmoy Talukder | D20: ='CO_Report Evaluation'!P8 -> 12.666667 | E20: ='CO_Report Evaluation'!Q8 -> 2.6666667 | F20: ='CO_Report Evaluation'!R8 -> 2.6666667 | M20: 4 | T20: =((CSE4098A_Spring2026_Grade!E10)*10)/45 -> 8.7111111 | AB20: =SUM(V20,D20,J20) -> 12.666667 | AC20: =SUM(Q20, W20,E20,K20) -> 2.6666667 | AD20: =SUM(R20, X20,F20,L20) -> 2.6666667 | AE20: =SUM(S20, Y20,G20,M20) -> 4 | AF20: =SUM(T20,H20,N20) -> 8.7111111 | AG20: =SUM(AA20,I20,O20) -> 0 | AH20: =IF(AB20 = 0, 0, AB20/AB$14) -> 0.84444444 | AI20: =IF(AC20 = 0, 0, AC20/AC$14) -> 0.88888889 | AJ20: =IF(AD20 = 0, 0, AD20/AD$14) -> 0.88888889 | AK20: =IF(AE20 = 0, 0, AE20/AE$14) -> 0.8 | AL20: =IF(AF20 = 0, 0, AF20/AF$14) -> 0.87111111 | AM20: =IF(AG20 = 0, 0, AG20/AG$14) -> 0 | AN20: =IF(OR(CSE4098A_Spring2026_Grade!$I10="W (Withdrawn)", CSE4098A_Spring2026_Grade!$I10="I (Incomplete)"), 0, IF(AH20>=55%, 1, 0)) -> 1 | AO20: =IF(OR(CSE4098A_Spring2026_Grade!$I10="W (Withdrawn)", CSE4098A_Spring2026_Grade!I10="I (Incomplete)"), 0, IF(AI20>=55%, 1, 0)) -> 1 | AP20: =IF(OR(CSE4098A_Spring2026_Grade!$I10="W (Withdrawn)", CSE4098A_Spring2026_Grade!$I10="I (Incomplete)"), 0, IF(AJ20>=55%, 1, 0)) -> 1 | AQ20: =IF(OR(CSE4098A_Spring2026_Grade!$I10="W (Withdrawn)", CSE4098A_Spring2026_Grade!$I10="I (Incomplete)"), 0, IF(AK20>=55%, 1, 0)) -> 1 | AR20: =IF(OR(CSE4098A_Spring2026_Grade!$I10="W (Withdrawn)", CSE4098A_Spring2026_Grade!$I10="I (Incomplete)"), 0, IF(AL20>=55%, 1, 0)) -> 1 | AS20: =IF(OR(CSE4098A_Spring2026_Grade!$I10="W (Withdrawn)", CSE4098A_Spring2026_Grade!$I10="I (Incomplete)"), 0, IF(AM20>=55%, 1, 0)) -> 0 | AU20: =IF($AT$9=0,0,MMULT($AH20:$AM20, AT$3:AT$8)/$AT$9) -> 0 | AV20: =IF($AU$9=0,0,MMULT($AH20:$AM20, AU$3:AU$8)/$AU$9) -> 0.84444444 | AW20: {=IF($AV$9=0,0,MMULT($AH20:$AM20, AV$3:AV$8)/$AV$9)} -> 0 | AX20: {=IF($AW$9=0,0,MMULT($AH20:$AM20, AW$3:AW$8)/$AW$9)} -> 0 | AY20: =IF($AX$9=0,0,MMULT($AH20:$AM20, AX$3:AX$8)/$AX$9) -> 0 | AZ20: {=IF($AY$9=0,0,MMULT($AH20:$AM20, AY$3:AY$8)/$AY$9)} -> 0 | BA20: {=IF($AZ$9=0,0,MMULT($AH20:$AM20, AZ$3:AZ$8)/$AZ$9)} -> 0 | BB20: {=IF($BA$9=0,0,MMULT($AH20:$AM20, BA$3:BA$8)/$BA$9)} -> 0 | BC20: {=IF($BB$9=0,0,MMULT($AH20:$AM20, BB$3:BB$8)/$BB$9)} -> 0.8 | BD20: {=IF($BC$9=0,0,MMULT($AH20:$AM20, BC$3:BC$8)/$BC$9)} -> 0.87111111 | BE20: =IF($BD$9=0,0,MMULT($AH20:$AM20, BD$3:BD$8)/$BD$9) -> 0.88888889 | BF20: =IF($BE$9=0,0,MMULT($AH20:$AM20, BE$3:BE$8)/$BE$9) -> 0.88888889 | BG20: =IF(OR(GradeSheet!$M15="W (Withdrawn)", GradeSheet!$M15="I (Incomplete)"), 0, IF(AU20>=55%, 1, 0)) -> #REF! | BH20: =IF(OR(CSE4098A_Spring2026_Grade!$I10="W (Withdrawn)", CSE4098A_Spring2026_Grade!$I10="I (Incomplete)"), 0, IF(AV20>=55%, 1, 0)) -> 1 | BI20: =IF(OR(GradeSheet!$M15="W (Withdrawn)", GradeSheet!$M15="I (Incomplete)"), 0, IF(AW20>=55%, 1, 0)) -> #REF! | BJ20: =IF(OR(GradeSheet!$M15="W (Withdrawn)", GradeSheet!$M15="I (Incomplete)"), 0, IF(AX20>=55%, 1, 0)) -> #REF! | BK20: =IF(OR(GradeSheet!$M15="W (Withdrawn)", GradeSheet!$M15="I (Incomplete)"), 0, IF(AY20>=55%, 1, 0)) -> #REF! | BL20: =IF(OR(GradeSheet!$M15="W (Withdrawn)", GradeSheet!$M15="I (Incomplete)"), 0, IF(AZ20>=55%, 1, 0)) -> #REF! | BM20: =IF(OR(GradeSheet!$M15="W (Withdrawn)", GradeSheet!$M15="I (Incomplete)"), 0, IF(BA20>=55%, 1, 0)) -> #REF! | BN20: =IF(OR(GradeSheet!$M15="W (Withdrawn)", GradeSheet!$M15="I (Incomplete)"), 0, IF(BB20>=55%, 1, 0)) -> #REF! | BO20: =IF(OR(CSE4098A_Spring2026_Grade!$I10="W (Withdrawn)", CSE4098A_Spring2026_Grade!$I10="I (Incomplete)"), 0, IF(BC20>=55%, 1, 0)) -> 1 | BP20: =IF(OR(CSE4098A_Spring2026_Grade!$I10="W (Withdrawn)", CSE4098A_Spring2026_Grade!$I10="I (Incomplete)"), 0, IF(BD20>=55%, 1, 0)) -> 1 | BQ20: =IF(OR(CSE4098A_Spring2026_Grade!$I10="W (Withdrawn)", CSE4098A_Spring2026_Grade!$I10="I (Incomplete)"), 0, IF(BE20>=55%, 1, 0)) -> 1 | BR20: =IF(OR(CSE4098A_Spring2026_Grade!$I10="W (Withdrawn)", CSE4098A_Spring2026_Grade!$I10="I (Incomplete)"), 0, IF(BF20>=55%, 1, 0)) -> 1
A21: 7 | B21: =CSE4098A_Spring2026_Grade!B11 -> 231014001 | C21: =CSE4098A_Spring2026_Grade!C11 -> Md. Aminul Islam Rupak | D21: ='CO_Report Evaluation'!P9 -> 12.666667 | E21: ='CO_Report Evaluation'!Q9 -> 2.6666667 | F21: ='CO_Report Evaluation'!R9 -> 2.6666667 | M21: 3 | T21: =((CSE4098A_Spring2026_Grade!E11)*10)/45 -> 8.7111111 | AB21: =SUM(V21,D21,J21) -> 12.666667 | AC21: =SUM(Q21, W21,E21,K21) -> 2.6666667 | AD21: =SUM(R21, X21,F21,L21) -> 2.6666667 | AE21: =SUM(S21, Y21,G21,M21) -> 3 | AF21: =SUM(T21,H21,N21) -> 8.7111111 | AG21: =SUM(AA21,I21,O21) -> 0 | AH21: =IF(AB21 = 0, 0, AB21/AB$14) -> 0.84444444 | AI21: =IF(AC21 = 0, 0, AC21/AC$14) -> 0.88888889 | AJ21: =IF(AD21 = 0, 0, AD21/AD$14) -> 0.88888889 | AK21: =IF(AE21 = 0, 0, AE21/AE$14) -> 0.6 | AL21: =IF(AF21 = 0, 0, AF21/AF$14) -> 0.87111111 | AM21: =IF(AG21 = 0, 0, AG21/AG$14) -> 0 | AN21: =IF(OR(CSE4098A_Spring2026_Grade!$I11="W (Withdrawn)", CSE4098A_Spring2026_Grade!$I11="I (Incomplete)"), 0, IF(AH21>=55%, 1, 0)) -> 1 | AO21: =IF(OR(CSE4098A_Spring2026_Grade!$I11="W (Withdrawn)", CSE4098A_Spring2026_Grade!I11="I (Incomplete)"), 0, IF(AI21>=55%, 1, 0)) -> 1 | AP21: =IF(OR(CSE4098A_Spring2026_Grade!$I11="W (Withdrawn)", CSE4098A_Spring2026_Grade!$I11="I (Incomplete)"), 0, IF(AJ21>=55%, 1, 0)) -> 1 | AQ21: =IF(OR(CSE4098A_Spring2026_Grade!$I11="W (Withdrawn)", CSE4098A_Spring2026_Grade!$I11="I (Incomplete)"), 0, IF(AK21>=55%, 1, 0)) -> 1 | AR21: =IF(OR(CSE4098A_Spring2026_Grade!$I11="W (Withdrawn)", CSE4098A_Spring2026_Grade!$I11="I (Incomplete)"), 0, IF(AL21>=55%, 1, 0)) -> 1 | AS21: =IF(OR(CSE4098A_Spring2026_Grade!$I11="W (Withdrawn)", CSE4098A_Spring2026_Grade!$I11="I (Incomplete)"), 0, IF(AM21>=55%, 1, 0)) -> 0 | AU21: =IF($AT$9=0,0,MMULT($AH21:$AM21, AT$3:AT$8)/$AT$9) -> 0 | AV21: =IF($AU$9=0,0,MMULT($AH21:$AM21, AU$3:AU$8)/$AU$9) -> 0.84444444 | AW21: {=IF($AV$9=0,0,MMULT($AH21:$AM21, AV$3:AV$8)/$AV$9)} -> 0 | AX21: {=IF($AW$9=0,0,MMULT($AH21:$AM21, AW$3:AW$8)/$AW$9)} -> 0 | AY21: =IF($AX$9=0,0,MMULT($AH21:$AM21, AX$3:AX$8)/$AX$9) -> 0 | AZ21: {=IF($AY$9=0,0,MMULT($AH21:$AM21, AY$3:AY$8)/$AY$9)} -> 0 | BA21: {=IF($AZ$9=0,0,MMULT($AH21:$AM21, AZ$3:AZ$8)/$AZ$9)} -> 0 | BB21: {=IF($BA$9=0,0,MMULT($AH21:$AM21, BA$3:BA$8)/$BA$9)} -> 0 | BC21: {=IF($BB$9=0,0,MMULT($AH21:$AM21, BB$3:BB$8)/$BB$9)} -> 0.6 | BD21: {=IF($BC$9=0,0,MMULT($AH21:$AM21, BC$3:BC$8)/$BC$9)} -> 0.87111111 | BE21: =IF($BD$9=0,0,MMULT($AH21:$AM21, BD$3:BD$8)/$BD$9) -> 0.88888889 | BF21: =IF($BE$9=0,0,MMULT($AH21:$AM21, BE$3:BE$8)/$BE$9) -> 0.88888889 | BG21: =IF(OR(GradeSheet!$M16="W (Withdrawn)", GradeSheet!$M16="I (Incomplete)"), 0, IF(AU21>=55%, 1, 0)) -> #REF! | BH21: =IF(OR(CSE4098A_Spring2026_Grade!$I11="W (Withdrawn)", CSE4098A_Spring2026_Grade!$I11="I (Incomplete)"), 0, IF(AV21>=55%, 1, 0)) -> 1 | BI21: =IF(OR(GradeSheet!$M16="W (Withdrawn)", GradeSheet!$M16="I (Incomplete)"), 0, IF(AW21>=55%, 1, 0)) -> #REF! | BJ21: =IF(OR(GradeSheet!$M16="W (Withdrawn)", GradeSheet!$M16="I (Incomplete)"), 0, IF(AX21>=55%, 1, 0)) -> #REF! | BK21: =IF(OR(GradeSheet!$M16="W (Withdrawn)", GradeSheet!$M16="I (Incomplete)"), 0, IF(AY21>=55%, 1, 0)) -> #REF! | BL21: =IF(OR(GradeSheet!$M16="W (Withdrawn)", GradeSheet!$M16="I (Incomplete)"), 0, IF(AZ21>=55%, 1, 0)) -> #REF! | BM21: =IF(OR(GradeSheet!$M16="W (Withdrawn)", GradeSheet!$M16="I (Incomplete)"), 0, IF(BA21>=55%, 1, 0)) -> #REF! | BN21: =IF(OR(GradeSheet!$M16="W (Withdrawn)", GradeSheet!$M16="I (Incomplete)"), 0, IF(BB21>=55%, 1, 0)) -> #REF! | BO21: =IF(OR(CSE4098A_Spring2026_Grade!$I11="W (Withdrawn)", CSE4098A_Spring2026_Grade!$I11="I (Incomplete)"), 0, IF(BC21>=55%, 1, 0)) -> 1 | BP21: =IF(OR(CSE4098A_Spring2026_Grade!$I11="W (Withdrawn)", CSE4098A_Spring2026_Grade!$I11="I (Incomplete)"), 0, IF(BD21>=55%, 1, 0)) -> 1 | BQ21: =IF(OR(CSE4098A_Spring2026_Grade!$I11="W (Withdrawn)", CSE4098A_Spring2026_Grade!$I11="I (Incomplete)"), 0, IF(BE21>=55%, 1, 0)) -> 1 | BR21: =IF(OR(CSE4098A_Spring2026_Grade!$I11="W (Withdrawn)", CSE4098A_Spring2026_Grade!$I11="I (Incomplete)"), 0, IF(BF21>=55%, 1, 0)) -> 1
A22: 8 | B22: =CSE4098A_Spring2026_Grade!B12 -> 223014100 | C22: =CSE4098A_Spring2026_Grade!C12 -> Jannatul Tazree | D22: ='CO_Report Evaluation'!P10 -> 12.666667 | E22: ='CO_Report Evaluation'!Q10 -> 2.6666667 | F22: ='CO_Report Evaluation'!R10 -> 2.6666667 | M22: 2 | T22: =((CSE4098A_Spring2026_Grade!E12)*10)/45 -> 9.4822222 | AB22: =SUM(V22,D22,J22) -> 12.666667 | AC22: =SUM(Q22, W22,E22,K22) -> 2.6666667 | AD22: =SUM(R22, X22,F22,L22) -> 2.6666667 | AE22: =SUM(S22, Y22,G22,M22) -> 2 | AF22: =SUM(T22,H22,N22) -> 9.4822222 | AG22: =SUM(AA22,I22,O22) -> 0 | AH22: =IF(AB22 = 0, 0, AB22/AB$14) -> 0.84444444 | AI22: =IF(AC22 = 0, 0, AC22/AC$14) -> 0.88888889 | AJ22: =IF(AD22 = 0, 0, AD22/AD$14) -> 0.88888889 | AK22: =IF(AE22 = 0, 0, AE22/AE$14) -> 0.4 | AL22: =IF(AF22 = 0, 0, AF22/AF$14) -> 0.94822222 | AM22: =IF(AG22 = 0, 0, AG22/AG$14) -> 0 | AN22: =IF(OR(CSE4098A_Spring2026_Grade!$I12="W (Withdrawn)", CSE4098A_Spring2026_Grade!$I12="I (Incomplete)"), 0, IF(AH22>=55%, 1, 0)) -> 1 | AO22: =IF(OR(CSE4098A_Spring2026_Grade!$I12="W (Withdrawn)", CSE4098A_Spring2026_Grade!I12="I (Incomplete)"), 0, IF(AI22>=55%, 1, 0)) -> 1 | AP22: =IF(OR(CSE4098A_Spring2026_Grade!$I12="W (Withdrawn)", CSE4098A_Spring2026_Grade!$I12="I (Incomplete)"), 0, IF(AJ22>=55%, 1, 0)) -> 1 | AQ22: =IF(OR(CSE4098A_Spring2026_Grade!$I12="W (Withdrawn)", CSE4098A_Spring2026_Grade!$I12="I (Incomplete)"), 0, IF(AK22>=55%, 1, 0)) -> 0 | AR22: =IF(OR(CSE4098A_Spring2026_Grade!$I12="W (Withdrawn)", CSE4098A_Spring2026_Grade!$I12="I (Incomplete)"), 0, IF(AL22>=55%, 1, 0)) -> 1 | AS22: =IF(OR(CSE4098A_Spring2026_Grade!$I12="W (Withdrawn)", CSE4098A_Spring2026_Grade!$I12="I (Incomplete)"), 0, IF(AM22>=55%, 1, 0)) -> 0 | AU22: =IF($AT$9=0,0,MMULT($AH22:$AM22, AT$3:AT$8)/$AT$9) -> 0 | AV22: =IF($AU$9=0,0,MMULT($AH22:$AM22, AU$3:AU$8)/$AU$9) -> 0.84444444 | AW22: {=IF($AV$9=0,0,MMULT($AH22:$AM22, AV$3:AV$8)/$AV$9)} -> 0 | AX22: {=IF($AW$9=0,0,MMULT($AH22:$AM22, AW$3:AW$8)/$AW$9)} -> 0 | AY22: =IF($AX$9=0,0,MMULT($AH22:$AM22, AX$3:AX$8)/$AX$9) -> 0 | AZ22: {=IF($AY$9=0,0,MMULT($AH22:$AM22, AY$3:AY$8)/$AY$9)} -> 0 | BA22: {=IF($AZ$9=0,0,MMULT($AH22:$AM22, AZ$3:AZ$8)/$AZ$9)} -> 0 | BB22: {=IF($BA$9=0,0,MMULT($AH22:$AM22, BA$3:BA$8)/$BA$9)} -> 0 | BC22: {=IF($BB$9=0,0,MMULT($AH22:$AM22, BB$3:BB$8)/$BB$9)} -> 0.4 | BD22: {=IF($BC$9=0,0,MMULT($AH22:$AM22, BC$3:BC$8)/$BC$9)} -> 0.94822222 | BE22: =IF($BD$9=0,0,MMULT($AH22:$AM22, BD$3:BD$8)/$BD$9) -> 0.88888889 | BF22: =IF($BE$9=0,0,MMULT($AH22:$AM22, BE$3:BE$8)/$BE$9) -> 0.88888889 | BG22: =IF(OR(GradeSheet!$M17="W (Withdrawn)", GradeSheet!$M17="I (Incomplete)"), 0, IF(AU22>=55%, 1, 0)) -> #REF! | BH22: =IF(OR(CSE4098A_Spring2026_Grade!$I12="W (Withdrawn)", CSE4098A_Spring2026_Grade!$I12="I (Incomplete)"), 0, IF(AV22>=55%, 1, 0)) -> 1 | BI22: =IF(OR(GradeSheet!$M17="W (Withdrawn)", GradeSheet!$M17="I (Incomplete)"), 0, IF(AW22>=55%, 1, 0)) -> #REF! | BJ22: =IF(OR(GradeSheet!$M17="W (Withdrawn)", GradeSheet!$M17="I (Incomplete)"), 0, IF(AX22>=55%, 1, 0)) -> #REF! | BK22: =IF(OR(GradeSheet!$M17="W (Withdrawn)", GradeSheet!$M17="I (Incomplete)"), 0, IF(AY22>=55%, 1, 0)) -> #REF! | BL22: =IF(OR(GradeSheet!$M17="W (Withdrawn)", GradeSheet!$M17="I (Incomplete)"), 0, IF(AZ22>=55%, 1, 0)) -> #REF! | BM22: =IF(OR(GradeSheet!$M17="W (Withdrawn)", GradeSheet!$M17="I (Incomplete)"), 0, IF(BA22>=55%, 1, 0)) -> #REF! | BN22: =IF(OR(GradeSheet!$M17="W (Withdrawn)", GradeSheet!$M17="I (Incomplete)"), 0, IF(BB22>=55%, 1, 0)) -> #REF! | BO22: =IF(OR(CSE4098A_Spring2026_Grade!$I12="W (Withdrawn)", CSE4098A_Spring2026_Grade!$I12="I (Incomplete)"), 0, IF(BC22>=55%, 1, 0)) -> 0 | BP22: =IF(OR(CSE4098A_Spring2026_Grade!$I12="W (Withdrawn)", CSE4098A_Spring2026_Grade!$I12="I (Incomplete)"), 0, IF(BD22>=55%, 1, 0)) -> 1 | BQ22: =IF(OR(CSE4098A_Spring2026_Grade!$I12="W (Withdrawn)", CSE4098A_Spring2026_Grade!$I12="I (Incomplete)"), 0, IF(BE22>=55%, 1, 0)) -> 1 | BR22: =IF(OR(CSE4098A_Spring2026_Grade!$I12="W (Withdrawn)", CSE4098A_Spring2026_Grade!$I12="I (Incomplete)"), 0, IF(BF22>=55%, 1, 0)) -> 1
A23: 9 | B23: =CSE4098A_Spring2026_Grade!B13 -> 232014003 | C23: =CSE4098A_Spring2026_Grade!C13 -> Tasin Bin Mortoza | D23: ='CO_Report Evaluation'!P11 -> 12.666667 | E23: ='CO_Report Evaluation'!Q11 -> 2.6666667 | F23: ='CO_Report Evaluation'!R11 -> 2.6666667 | M23: 2 | T23: =((CSE4098A_Spring2026_Grade!E13)*10)/45 -> 8.9777778 | AB23: =SUM(V23,D23,J23) -> 12.666667 | AC23: =SUM(Q23, W23,E23,K23) -> 2.6666667 | AD23: =SUM(R23, X23,F23,L23) -> 2.6666667 | AE23: =SUM(S23, Y23,G23,M23) -> 2 | AF23: =SUM(T23,H23,N23) -> 8.9777778 | AG23: =SUM(AA23,I23,O23) -> 0 | AH23: =IF(AB23 = 0, 0, AB23/AB$14) -> 0.84444444 | AI23: =IF(AC23 = 0, 0, AC23/AC$14) -> 0.88888889 | AJ23: =IF(AD23 = 0, 0, AD23/AD$14) -> 0.88888889 | AK23: =IF(AE23 = 0, 0, AE23/AE$14) -> 0.4 | AL23: =IF(AF23 = 0, 0, AF23/AF$14) -> 0.89777778 | AM23: =IF(AG23 = 0, 0, AG23/AG$14) -> 0 | AN23: =IF(OR(CSE4098A_Spring2026_Grade!$I13="W (Withdrawn)", CSE4098A_Spring2026_Grade!$I13="I (Incomplete)"), 0, IF(AH23>=55%, 1, 0)) -> 1 | AO23: =IF(OR(CSE4098A_Spring2026_Grade!$I13="W (Withdrawn)", CSE4098A_Spring2026_Grade!I13="I (Incomplete)"), 0, IF(AI23>=55%, 1, 0)) -> 1 | AP23: =IF(OR(CSE4098A_Spring2026_Grade!$I13="W (Withdrawn)", CSE4098A_Spring2026_Grade!$I13="I (Incomplete)"), 0, IF(AJ23>=55%, 1, 0)) -> 1 | AQ23: =IF(OR(CSE4098A_Spring2026_Grade!$I13="W (Withdrawn)", CSE4098A_Spring2026_Grade!$I13="I (Incomplete)"), 0, IF(AK23>=55%, 1, 0)) -> 0 | AR23: =IF(OR(CSE4098A_Spring2026_Grade!$I13="W (Withdrawn)", CSE4098A_Spring2026_Grade!$I13="I (Incomplete)"), 0, IF(AL23>=55%, 1, 0)) -> 1 | AS23: =IF(OR(CSE4098A_Spring2026_Grade!$I13="W (Withdrawn)", CSE4098A_Spring2026_Grade!$I13="I (Incomplete)"), 0, IF(AM23>=55%, 1, 0)) -> 0 | AU23: =IF($AT$9=0,0,MMULT($AH23:$AM23, AT$3:AT$8)/$AT$9) -> 0 | AV23: =IF($AU$9=0,0,MMULT($AH23:$AM23, AU$3:AU$8)/$AU$9) -> 0.84444444 | AW23: {=IF($AV$9=0,0,MMULT($AH23:$AM23, AV$3:AV$8)/$AV$9)} -> 0 | AX23: {=IF($AW$9=0,0,MMULT($AH23:$AM23, AW$3:AW$8)/$AW$9)} -> 0 | AY23: =IF($AX$9=0,0,MMULT($AH23:$AM23, AX$3:AX$8)/$AX$9) -> 0 | AZ23: {=IF($AY$9=0,0,MMULT($AH23:$AM23, AY$3:AY$8)/$AY$9)} -> 0 | BA23: {=IF($AZ$9=0,0,MMULT($AH23:$AM23, AZ$3:AZ$8)/$AZ$9)} -> 0 | BB23: {=IF($BA$9=0,0,MMULT($AH23:$AM23, BA$3:BA$8)/$BA$9)} -> 0 | BC23: {=IF($BB$9=0,0,MMULT($AH23:$AM23, BB$3:BB$8)/$BB$9)} -> 0.4 | BD23: {=IF($BC$9=0,0,MMULT($AH23:$AM23, BC$3:BC$8)/$BC$9)} -> 0.89777778 | BE23: =IF($BD$9=0,0,MMULT($AH23:$AM23, BD$3:BD$8)/$BD$9) -> 0.88888889 | BF23: =IF($BE$9=0,0,MMULT($AH23:$AM23, BE$3:BE$8)/$BE$9) -> 0.88888889 | BG23: =IF(OR(GradeSheet!$M18="W (Withdrawn)", GradeSheet!$M18="I (Incomplete)"), 0, IF(AU23>=55%, 1, 0)) -> #REF! | BH23: =IF(OR(CSE4098A_Spring2026_Grade!$I13="W (Withdrawn)", CSE4098A_Spring2026_Grade!$I13="I (Incomplete)"), 0, IF(AV23>=55%, 1, 0)) -> 1 | BI23: =IF(OR(GradeSheet!$M18="W (Withdrawn)", GradeSheet!$M18="I (Incomplete)"), 0, IF(AW23>=55%, 1, 0)) -> #REF! | BJ23: =IF(OR(GradeSheet!$M18="W (Withdrawn)", GradeSheet!$M18="I (Incomplete)"), 0, IF(AX23>=55%, 1, 0)) -> #REF! | BK23: =IF(OR(GradeSheet!$M18="W (Withdrawn)", GradeSheet!$M18="I (Incomplete)"), 0, IF(AY23>=55%, 1, 0)) -> #REF! | BL23: =IF(OR(GradeSheet!$M18="W (Withdrawn)", GradeSheet!$M18="I (Incomplete)"), 0, IF(AZ23>=55%, 1, 0)) -> #REF! | BM23: =IF(OR(GradeSheet!$M18="W (Withdrawn)", GradeSheet!$M18="I (Incomplete)"), 0, IF(BA23>=55%, 1, 0)) -> #REF! | BN23: =IF(OR(GradeSheet!$M18="W (Withdrawn)", GradeSheet!$M18="I (Incomplete)"), 0, IF(BB23>=55%, 1, 0)) -> #REF! | BO23: =IF(OR(CSE4098A_Spring2026_Grade!$I13="W (Withdrawn)", CSE4098A_Spring2026_Grade!$I13="I (Incomplete)"), 0, IF(BC23>=55%, 1, 0)) -> 0 | BP23: =IF(OR(CSE4098A_Spring2026_Grade!$I13="W (Withdrawn)", CSE4098A_Spring2026_Grade!$I13="I (Incomplete)"), 0, IF(BD23>=55%, 1, 0)) -> 1 | BQ23: =IF(OR(CSE4098A_Spring2026_Grade!$I13="W (Withdrawn)", CSE4098A_Spring2026_Grade!$I13="I (Incomplete)"), 0, IF(BE23>=55%, 1, 0)) -> 1 | BR23: =IF(OR(CSE4098A_Spring2026_Grade!$I13="W (Withdrawn)", CSE4098A_Spring2026_Grade!$I13="I (Incomplete)"), 0, IF(BF23>=55%, 1, 0)) -> 1
