Workbook
Name mygrade: #REF!
Name Grades: #REF!
Name mygrades: #REF!

Sheet CSE4098B_Spring2026_Grade
A1: Capstone Project Grade (CSE 4098B)
A2: Marks Distribution
A3: Spring 2026
A4: Sl | B4: Student ID | C4: Student Name | D4: Report (40%) | E4: Presentation (45%) | F4: Peer (5%) | G4: Weekly Journal (10%) | H4: Total (100%) | I4: Grade | J4: Supervisor | K4: Title
A5: 1 | B5: 223014152 | C5: Ahadul Islam Rahul | D5: =CSE4098B_Spring2026_Report!AB5 -> 31.43 | E5: =MIN(45, IF(CSE4098B_Spring2026_Presentatio!Z5>1, CSE4098B_Spring2026_Presentatio!Z5, CSE4098B_Spring2026_Presentatio!Z5*45)) -> 36.89 | F5: 2 | G5: 6 | H5: =SUM(D5:G5) -> 76.32 | I5: =IF(H5>=95,"A+",IF(H5>=85,"A",IF(H5>=80,"A-",IF(H5>=75,"B+",IF(H5>=70,"B",IF(H5>=65,"B-",IF(H5>=60,"C+",IF(H5>=55,"C",IF(H5>=50,"D","F"))))))))) -> B+ | J5: MGK | K5: Automated Leather Defect Detection and Classification Using an Ensemble Deep Learning Framework
A6: 2 | B6: 223014049 | C6: Md. Sojib Al Hasan | D6: =CSE4098B_Spring2026_Report!AB6 -> 31.43 | E6: =MIN(45, IF(CSE4098B_Spring2026_Presentatio!Z6>1, CSE4098B_Spring2026_Presentatio!Z6, CSE4098B_Spring2026_Presentatio!Z6*45)) -> 39.67 | F6: 3 | G6: 7 | H6: =SUM(D6:G6) -> 81.1 | I6: =IF(H6>=95,"A+",IF(H6>=85,"A",IF(H6>=80,"A-",IF(H6>=75,"B+",IF(H6>=70,"B",IF(H6>=65,"B-",IF(H6>=60,"C+",IF(H6>=55,"C",IF(H6>=50,"D","F"))))))))) -> A-
A7: 3 | B7: 222014039 | C7: Nadia Akter Jui | D7: =CSE4098B_Spring2026_Report!AB7 -> 31.43 | E7: =MIN(45, IF(CSE4098B_Spring2026_Presentatio!Z7>1, CSE4098B_Spring2026_Presentatio!Z7, CSE4098B_Spring2026_Presentatio!Z7*45)) -> 32.44 | F7: 2 | G7: 4 | H7: =SUM(D7:G7) -> 69.87 | I7: =IF(H7>=95,"A+",IF(H7>=85,"A",IF(H7>=80,"A-",IF(H7>=75,"B+",IF(H7>=70,"B",IF(H7>=65,"B-",IF(H7>=60,"C+",IF(H7>=55,"C",IF(H7>=50,"D","F"))))))))) -> B-
A8: 4 | B8: 222014012 | C8: Md. Minhazul Islam | D8: =CSE4098B_Spring2026_Report!AB8 -> 31.43 | E8: =MIN(45, IF(CSE4098B_Spring2026_Presentatio!Z8>1, CSE4098B_Spring2026_Presentatio!Z8, CSE4098B_Spring2026_Presentatio!Z8*45)) -> 32.89 | F8: 2 | G8: 4 | H8: =SUM(D8:G8) -> 70.32 | I8: =IF(H8>=95,"A+",IF(H8>=85,"A",IF(H8>=80,"A-",IF(H8>=75,"B+",IF(H8>=70,"B",IF(H8>=65,"B-",IF(H8>=60,"C+",IF(H8>=55,"C",IF(H8>=50,"D","F"))))))))) -> B
A9: 5 | B9: 222014096 | C9: Md. Shams Arefin | D9: =CSE4098B_Spring2026_Report!AB9 -> 31.43 | E9: =MIN(45, IF(CSE4098B_Spring2026_Presentatio!Z9>1, CSE4098B_Spring2026_Presentatio!Z9, CSE4098B_Spring2026_Presentatio!Z9*45)) -> 41.44 | F9: 4 | G9: 7 | H9: =SUM(D9:G9) -> 83.87 | I9: =IF(H9>=95,"A+",IF(H9>=85,"A",IF(H9>=80,"A-",IF(H9>=75,"B+",IF(H9>=70,"B",IF(H9>=65,"B-",IF(H9>=60,"C+",IF(H9>=55,"C",IF(H9>=50,"D","F"))))))))) -> A-
A10: 6 | B10: 222014052 | C10: Redwan Ahamad Samir | D10: =CSE4098B_Spring2026_Report!AB10 -> 26.67 | E10: =MIN(45, IF(CSE4098B_Spring2026_Presentatio!Z10>1, CSE4098B_Spring2026_Presentatio!Z10, CSE4098B_Spring2026_Presentatio!Z10*45)) -> 42.67 | F10: 4 | G10: 9 | H10: =SUM(D10:G10) -> 82.34 | I10: =IF(H10>=95,"A+",IF(H10>=85,"A",IF(H10>=80,"A-",IF(H10>=75,"B+",IF(H10>=70,"B",IF(H10>=65,"B-",IF(H10>=60,"C+",IF(H10>=55,"C",IF(H10>=50,"D","F"))))))))) -> A- | J10: RaiK | K10: AdaLLM: Domain adaptation of LLMs and specialization
A11: 7 | B11: 222014009 | C11: Samia Rahman | D11: =CSE4098B_Spring2026_Report!AB11 -> 26.67 | E11: =MIN(45, IF(CSE4098B_Spring2026_Presentatio!Z11>1, CSE4098B_Spring2026_Presentatio!Z11, CSE4098B_Spring2026_Presentatio!Z11*45)) -> 40.67 | F11: 3 | G11: 7 | H11: =SUM(D11:G11) -> 77.34 | I11: =IF(H11>=95,"A+",IF(H11>=85,"A",IF(H11>=80,"A-",IF(H11>=75,"B+",IF(H11>=70,"B",IF(H11>=65,"B-",IF(H11>=60,"C+",IF(H11>=55,"C",IF(H11>=50,"D","F"))))))))) -> B+
A12: 8 | B12: 222014088 | C12: Md. Omur Faruk | D12: =CSE4098B_Spring2026_Report!AB12 -> 26.67 | E12: =MIN(45, IF(CSE4098B_Spring2026_Presentatio!Z12>1, CSE4098B_Spring2026_Presentatio!Z12, CSE4098B_Spring2026_Presentatio!Z12*45)) -> 39.33 | F12: 3 | G12: 5 | H12: =SUM(D12:G12) -> 74 | I12: =IF(H12>=95,"A+",IF(H12>=85,"A",IF(H12>=80,"A-",IF(H12>=75,"B+",IF(H12>=70,"B",IF(H12>=65,"B-",IF(H12>=60,"C+",IF(H12>=55,"C",IF(H12>=50,"D","F"))))))))) -> B
A13: 9 | B13: 231014021 | C13: Raiyan Islam | D13: =CSE4098B_Spring2026_Report!AB13 -> 26.67 | E13: =MIN(45, IF(CSE4098B_Spring2026_Presentatio!Z13>1, CSE4098B_Spring2026_Presentatio!Z13, CSE4098B_Spring2026_Presentatio!Z13*45)) -> 39 | F13: 3 | G13: 5 | H13: =SUM(D13:G13) -> 73.67 | I13: =IF(H13>=95,"A+",IF(H13>=85,"A",IF(H13>=80,"A-",IF(H13>=75,"B+",IF(H13>=70,"B",IF(H13>=65,"B-",IF(H13>=60,"C+",IF(H13>=55,"C",IF(H13>=50,"D","F"))))))))) -> B
A14: 10 | B14: 223014142 | C14: Tamanna Akter | D14: =CSE4098B_Spring2026_Report!AB14 -> 32 | E14: =MIN(45, IF(CSE4098B_Spring2026_Presentatio!Z14>1, CSE4098B_Spring2026_Presentatio!Z14, CSE4098B_Spring2026_Presentatio!Z14*45)) -> 43.41 | F14: 5 | G14: 8 | H14: =SUM(D14:G14) -> 88.41 | I14: =IF(H14>=95,"A+",IF(H14>=85,"A",IF(H14>=80,"A-",IF(H14>=75,"B+",IF(H14>=70,"B",IF(H14>=65,"B-",IF(H14>=60,"C+",IF(H14>=55,"C",IF(H14>=50,"D","F"))))))))) -> A | J14: RHF | K14: Nirbighne: AI-Driven Dynamic Traffic Signal Control System
A15: 11 | B15: 223014204 | C15: Ashrafun Nahar Rahi | D15: =CSE4098B_Spring2026_Report!AB15 -> 32 | E15: =MIN(45, IF(CSE4098B_Spring2026_Presentatio!Z15>1, CSE4098B_Spring2026_Presentatio!Z15, CSE4098B_Spring2026_Presentatio!Z15*45)) -> 43.41 | F15: 5 | G15: 8 | H15: =SUM(D15:G15) -> 88.41 | I15: =IF(H15>=95,"A+",IF(H15>=85,"A",IF(H15>=80,"A-",IF(H15>=75,"B+",IF(H15>=70,"B",IF(H15>=65,"B-",IF(H15>=60,"C+",IF(H15>=55,"C",IF(H15>=50,"D","F"))))))))) -> A
A16: 12 | B16: 213014052 | C16: Khuslima Fardush Mony | D16: =CSE4098B_Spring2026_Report!AB16 -> 32 | E16: =MIN(45, IF(CSE4098B_Spring2026_Presentatio!Z16>1, CSE4098B_Spring2026_Presentatio!Z16, CSE4098B_Spring2026_Presentatio!Z16*45)) -> 40.74 | F16: 4 | G16: 7 | H16: =SUM(D16:G16) -> 83.74 | I16: =IF(H16>=95,"A+",IF(H16>=85,"A",IF(H16>=80,"A-",IF(H16>=75,"B+",IF(H16>=70,"B",IF(H16>=65,"B-",IF(H16>=60,"C+",IF(H16>=55,"C",IF(H16>=50,"D","F"))))))))) -> A-
A17: 13 | B17: 221014035 | C17: Md. Alif Hossain | D17: =CSE4098B_Spring2026_Report!AB17 -> 32 | E17: =MIN(45, IF(CSE4098B_Spring2026_Presentatio!Z17>1, CSE4098B_Spring2026_Presentatio!Z17, CSE4098B_Spring2026_Presentatio!Z17*45)) -> 39.63 | F17: 3 | G17: 7 | H17: =SUM(D17:G17) -> 81.63 | I17: =IF(H17>=95,"A+",IF(H17>=85,"A",IF(H17>=80,"A-",IF(H17>=75,"B+",IF(H17>=70,"B",IF(H17>=65,"B-",IF(H17>=60,"C+",IF(H17>=55,"C",IF(H17>=50,"D","F"))))))))) -> A-
A18: 14 | B18: 223014074 | C18: Salvir Rahman Ratul | D18: =CSE4098B_Spring2026_Report!AB18 -> 34.67 | E18: =MIN(45, IF(CSE4098B_Spring2026_Presentatio!Z18>1, CSE4098B_Spring2026_Presentatio!Z18, CSE4098B_Spring2026_Presentatio!Z18*45)) -> 44.33 | F18: 4 | G18: 9 | H18: =SUM(D18:G18) -> 92 | I18: =IF(H18>=95,"A+",IF(H18>=85,"A",IF(H18>=80,"A-",IF(H18>=75,"B+",IF(H18>=70,"B",IF(H18>=65,"B-",IF(H18>=60,"C+",IF(H18>=55,"C",IF(H18>=50,"D","F"))))))))) -> A | J18: RHF | K18: BioCal RA: A Trustworthy and Explainable Multi-Agent Research Assistant for Biomedical Field.
A19: 15 | B19: 223014133 | C19: Nancy Drong | D19: =CSE4098B_Spring2026_Report!AB19 -> 34.67 | E19: =MIN(45, IF(CSE4098B_Spring2026_Presentatio!Z19>1, CSE4098B_Spring2026_Presentatio!Z19, CSE4098B_Spring2026_Presentatio!Z19*45)) -> 42.78 | F19: 4 | G19: 8 | H19: =SUM(D19:G19) -> 89.45 | I19: =IF(H19>=95,"A+",IF(H19>=85,"A",IF(H19>=80,"A-",IF(H19>=75,"B+",IF(H19>=70,"B",IF(H19>=65,"B-",IF(H19>=60,"C+",IF(H19>=55,"C",IF(H19>=50,"D","F"))))))))) -> A
A20: 16 | B20: 223014052 | C20: Argho Das | D20: =CSE4098B_Spring2026_Report!AB20 -> 34.67 | E20: =MIN(45, IF(CSE4098B_Spring2026_Presentatio!Z20>1, CSE4098B_Spring2026_Presentatio!Z20, CSE4098B_Spring2026_Presentatio!Z20*45)) -> 42.78 | F20: 4 | G20: 8 | H20: =SUM(D20:G20) -> 89.45 | I20: =IF(H20>=95,"A+",IF(H20>=85,"A",IF(H20>=80,"A-",IF(H20>=75,"B+",IF(H20>=70,"B",IF(H20>=65,"B-",IF(H20>=60,"C+",IF(H20>=55,"C",IF(H20>=50,"D","F"))))))))) -> A
A21: 17 | B21: 223014105 | C21: Navid Rahman | D21: =CSE4098B_Spring2026_Report!AB21 -> 34.67 | E21: =MIN(45, IF(CSE4098B_Spring2026_Presentatio!Z21>1, CSE4098B_Spring2026_Presentatio!Z21, CSE4098B_Spring2026_Presentatio!Z21*45)) -> 45 | F21: 5 | G21: 9 | H21: =SUM(D21:G21) -> 93.67 | I21: =IF(H21>=95,"A+",IF(H21>=85,"A",IF(H21>=80,"A-",IF(H21>=75,"B+",IF(H21>=70,"B",IF(H21>=65,"B-",IF(H21>=60,"C+",IF(H21>=55,"C",IF(H21>=50,"D","F"))))))))) -> A
A22: 18 | B22: 223014196 | C22: Shafwan Shadid Khan | D22: =CSE4098B_Spring2026_Report!AB22 -> 34.67 | E22: =MIN(45, IF(CSE4098B_Spring2026_Presentatio!Z22>1, CSE4098B_Spring2026_Presentatio!Z22, CSE4098B_Spring2026_Presentatio!Z22*45)) -> 42.78 | F22: 5 | G22: 9 | H22: =SUM(D22:G22) -> 91.45 | I22: =IF(H22>=95,"A+",IF(H22>=85,"A",IF(H22>=80,"A-",IF(H22>=75,"B+",IF(H22>=70,"B",IF(H22>=65,"B-",IF(H22>=60,"C+",IF(H22>=55,"C",IF(H22>=50,"D","F"))))))))) -> A
A23: 19 | B23: 223014213 | C23: Md. Minhazul Islam | D23: =CSE4098B_Spring2026_Report!AB23 -> 34.86 | E23: =MIN(45, IF(CSE4098B_Spring2026_Presentatio!Z23>1, CSE4098B_Spring2026_Presentatio!Z23, CSE4098B_Spring2026_Presentatio!Z23*45)) -> 42.74 | F23: 5 | G23: 10 | H23: =SUM(D23:G23) -> 92.6 | I23: =IF(H23>=95,"A+",IF(H23>=85,"A",IF(H23>=80,"A-",IF(H23>=75,"B+",IF(H23>=70,"B",IF(H23>=65,"B-",IF(H23>=60,"C+",IF(H23>=55,"C",IF(H23>=50,"D","F"))))))))) -> A | J23: JFR | K23: AI-Enabled Bi-Directional Translation System for Continuous Bengali Sign Language in Daily Conversation
A24: 20 | B24: 223014078 | C24: Shakhar Das Rony | D24: =CSE4098B_Spring2026_Report!AB24 -> 34.86 | E24: =MIN(45, IF(CSE4098B_Spring2026_Presentatio!Z24>1, CSE4098B_Spring2026_Presentatio!Z24, CSE4098B_Spring2026_Presentatio!Z24*45)) -> 43.48 | F24: 5 | G24: 10 | H24: =SUM(D24:G24) -> 93.34 | I24: =IF(H24>=95,"A+",IF(H24>=85,"A",IF(H24>=80,"A-",IF(H24>=75,"B+",IF(H24>=70,"B",IF(H24>=65,"B-",IF(H24>=60,"C+",IF(H24>=55,"C",IF(H24>=50,"D","F"))))))))) -> A
A25: 21 | B25: 223014212 | C25: Md. Tamim Hasan | D25: =CSE4098B_Spring2026_Report!AB25 -> 34.86 | E25: =MIN(45, IF(CSE4098B_Spring2026_Presentatio!Z25>1, CSE4098B_Spring2026_Presentatio!Z25, CSE4098B_Spring2026_Presentatio!Z25*45)) -> 42.74 | F25: 5 | G25: 10 | H25: =SUM(D25:G25) -> 92.6 | I25: =IF(H25>=95,"A+",IF(H25>=85,"A",IF(H25>=80,"A-",IF(H25>=75,"B+",IF(H25>=70,"B",IF(H25>=65,"B-",IF(H25>=60,"C+",IF(H25>=55,"C",IF(H25>=50,"D","F"))))))))) -> A
A26: 22 | B26: 231014049 | C26: Kazi Noor E Saba | D26: =CSE4098B_Spring2026_Report!AB26 -> 36.38 | E26: =MIN(45, IF(CSE4098B_Spring2026_Presentatio!Z26>1, CSE4098B_Spring2026_Presentatio!Z26, CSE4098B_Spring2026_Presentatio!Z26*45)) -> 45 | F26: 5 | G26: 10 | H26: =SUM(D26:G26) -> 96.38 | I26: =IF(H26>=95,"A+",IF(H26>=85,"A",IF(H26>=80,"A-",IF(H26>=75,"B+",IF(H26>=70,"B",IF(H26>=65,"B-",IF(H26>=60,"C+",IF(H26>=55,"C",IF(H26>=50,"D","F"))))))))) -> A+ | J26: NafM | K26: Blockchain Based Bug Bounty System with A Novel Reputation Driven Consensus Mechanism
A27: 23 | B27: 231014016 | C27: Md. Akib Al Mahmud Dihan | D27: =CSE4098B_Spring2026_Report!AB27 -> 36.38 | E27: =MIN(45, IF(CSE4098B_Spring2026_Presentatio!Z27>1, CSE4098B_Spring2026_Presentatio!Z27, CSE4098B_Spring2026_Presentatio!Z27*45)) -> 45 | F27: 5 | G27: 10 | H27: =SUM(D27:G27) -> 96.38 | I27: =IF(H27>=95,"A+",IF(H27>=85,"A",IF(H27>=80,"A-",IF(H27>=75,"B+",IF(H27>=70,"B",IF(H27>=65,"B-",IF(H27>=60,"C+",IF(H27>=55,"C",IF(H27>=50,"D","F"))))))))) -> A+
A28: 24 | B28: 231014125 | C28: Jumana Muntaha | D28: =CSE4098B_Spring2026_Report!AB28 -> 36.38 | E28: =MIN(45, IF(CSE4098B_Spring2026_Presentatio!Z28>1, CSE4098B_Spring2026_Presentatio!Z28, CSE4098B_Spring2026_Presentatio!Z28*45)) -> 45 | F28: 5 | G28: 10 | H28: =SUM(D28:G28) -> 96.38 | I28: =IF(H28>=95,"A+",IF(H28>=85,"A",IF(H28>=80,"A-",IF(H28>=75,"B+",IF(H28>=70,"B",IF(H28>=65,"B-",IF(H28>=60,"C+",IF(H28>=55,"C",IF(H28>=50,"D","F"))))))))) -> A+
A29: 25 | B29: 231014142 | C29: Abida Binte Asif | D29: =CSE4098B_Spring2026_Report!AB29 -> 36.38 | E29: =MIN(45, IF(CSE4098B_Spring2026_Presentatio!Z29>1, CSE4098B_Spring2026_Presentatio!Z29, CSE4098B_Spring2026_Presentatio!Z29*45)) -> 44.33 | F29: 5 | G29: 10 | H29: =SUM(D29:G29) -> 95.71 | I29: =IF(H29>=95,"A+",IF(H29>=85,"A",IF(H29>=80,"A-",IF(H29>=75,"B+",IF(H29>=70,"B",IF(H29>=65,"B-",IF(H29>=60,"C+",IF(H29>=55,"C",IF(H29>=50,"D","F"))))))))) -> A+
A30: 26 | B30: 223014146 | C30: Sami Hossain | D30: =CSE4098B_Spring2026_Report!AB30 -> 36.38 | E30: =MIN(45, IF(CSE4098B_Spring2026_Presentatio!Z30>1, CSE4098B_Spring2026_Presentatio!Z30, CSE4098B_Spring2026_Presentatio!Z30*45)) -> 44 | F30: 5 | G30: 10 | H30: =SUM(D30:G30) -> 95.38 | I30: =IF(H30>=95,"A+",IF(H30>=85,"A",IF(H30>=80,"A-",IF(H30>=75,"B+",IF(H30>=70,"B",IF(H30>=65,"B-",IF(H30>=60,"C+",IF(H30>=55,"C",IF(H30>=50,"D","F"))))))))) -> A+
A31: 27 | B31: 231014024 | C31: Md. Shohanoor Rahman | D31: =CSE4098B_Spring2026_Report!AB31 -> 34.67 | E31: =MIN(45, IF(CSE4098B_Spring2026_Presentatio!Z31>1, CSE4098B_Spring2026_Presentatio!Z31, CSE4098B_Spring2026_Presentatio!Z31*45)) -> 34.33 | F31: 5 | G31: 10 | H31: =SUM(D31:G31) -> 84 | I31: =IF(H31>=95,"A+",IF(H31>=85,"A",IF(H31>=80,"A-",IF(H31>=75,"B+",IF(H31>=70,"B",IF(H31>=65,"B-",IF(H31>=60,"C+",IF(H31>=55,"C",IF(H31>=50,"D","F"))))))))) -> A- | J31: NafM | K31: Design of an Efficient Consensus Mechanism for Transparent Private Blockchain-Based Donation Systems
A32: 28 | B32: 231014064 | C32: Pranto Sikder | D32: =CSE4098B_Spring2026_Report!AB32 -> 34.67 | E32: =MIN(45, IF(CSE4098B_Spring2026_Presentatio!Z32>1, CSE4098B_Spring2026_Presentatio!Z32, CSE4098B_Spring2026_Presentatio!Z32*45)) -> 34.33 | F32: 5 | G32: 10 | H32: =SUM(D32:G32) -> 84 | I32: =IF(H32>=95,"A+",IF(H32>=85,"A",IF(H32>=80,"A-",IF(H32>=75,"B+",IF(H32>=70,"B",IF(H32>=65,"B-",IF(H32>=60,"C+",IF(H32>=55,"C",IF(H32>=50,"D","F"))))))))) -> A-
A33: 29 | B33: 231014050 | C33: Mahmudul Hasan Zeshan | D33: =CSE4098B_Spring2026_Report!AB33 -> 34.67 | E33: =MIN(45, IF(CSE4098B_Spring2026_Presentatio!Z33>1, CSE4098B_Spring2026_Presentatio!Z33, CSE4098B_Spring2026_Presentatio!Z33*45)) -> 34.33 | F33: 5 | G33: 10 | H33: =SUM(D33:G33) -> 84 | I33: =IF(H33>=95,"A+",IF(H33>=85,"A",IF(H33>=80,"A-",IF(H33>=75,"B+",IF(H33>=70,"B",IF(H33>=65,"B-",IF(H33>=60,"C+",IF(H33>=55,"C",IF(H33>=50,"D","F"))))))))) -> A-
A34: 30 | B34: 231014160 | C34: Aysha Siddika Methila | D34: =CSE4098B_Spring2026_Report!AB34 -> 34.67 | E34: =MIN(45, IF(CSE4098B_Spring2026_Presentatio!Z34>1, CSE4098B_Spring2026_Presentatio!Z34, CSE4098B_Spring2026_Presentatio!Z34*45)) -> 34.33 | F34: 5 | G34: 10 | H34: =SUM(D34:G34) -> 84 | I34: =IF(H34>=95,"A+",IF(H34>=85,"A",IF(H34>=80,"A-",IF(H34>=75,"B+",IF(H34>=70,"B",IF(H34>=65,"B-",IF(H34>=60,"C+",IF(H34>=55,"C",IF(H34>=50,"D","F"))))))))) -> A-
A35: 31 | B35: 231014116 | C35: Sukanta Majumder | D35: =CSE4098B_Spring2026_Report!AB35 -> 34.67 | E35: =MIN(45, IF(CSE4098B_Spring2026_Presentatio!Z35>1, CSE4098B_Spring2026_Presentatio!Z35, CSE4098B_Spring2026_Presentatio!Z35*45)) -> 34.33 | F35: 5 | G35: 10 | H35: =SUM(D35:G35) -> 84 | I35: =IF(H35>=95,"A+",IF(H35>=85,"A",IF(H35>=80,"A-",IF(H35>=75,"B+",IF(H35>=70,"B",IF(H35>=65,"B-",IF(H35>=60,"C+",IF(H35>=55,"C",IF(H35>=50,"D","F"))))))))) -> A-
A36: 32 | B36: 212014015 | C36: Md. Arif Hossain Mir | D36: =CSE4098B_Spring2026_Report!AB36 -> 34.47 | E36: =MIN(45, IF(CSE4098B_Spring2026_Presentatio!Z36>1, CSE4098B_Spring2026_Presentatio!Z36, CSE4098B_Spring2026_Presentatio!Z36*45)) -> 39.11 | F36: 4 | G36: 9 | H36: =SUM(D36:G36) -> 86.58 | I36: =IF(H36>=95,"A+",IF(H36>=85,"A",IF(H36>=80,"A-",IF(H36>=75,"B+",IF(H36>=70,"B",IF(H36>=65,"B-",IF(H36>=60,"C+",IF(H36>=55,"C",IF(H36>=50,"D","F"))))))))) -> A | J36: MdKH | K36: Cross-Lingual Abstractive Summarization with Transformers for Bangla and Chinese
A37: 33 | B37: 223014050 | C37: Isnat Jahan Ome | D37: =CSE4098B_Spring2026_Report!AB37 -> 34.47 | E37: =MIN(45, IF(CSE4098B_Spring2026_Presentatio!Z37>1, CSE4098B_Spring2026_Presentatio!Z37, CSE4098B_Spring2026_Presentatio!Z37*45)) -> 36.22 | F37: 4 | G37: 9 | H37: =SUM(D37:G37) -> 83.69 | I37: =IF(H37>=95,"A+",IF(H37>=85,"A",IF(H37>=80,"A-",IF(H37>=75,"B+",IF(H37>=70,"B",IF(H37>=65,"B-",IF(H37>=60,"C+",IF(H37>=55,"C",IF(H37>=50,"D","F"))))))))) -> A-
A38: 34 | B38: 231014075 | C38: Hasib Mahmud | D38: =CSE4098B_Spring2026_Report!AB38 -> 34.47 | E38: =MIN(45, IF(CSE4098B_Spring2026_Presentatio!Z38>1, CSE4098B_Spring2026_Presentatio!Z38, CSE4098B_Spring2026_Presentatio!Z38*45)) -> 36.67 | F38: 4 | G38: 9 | H38: =SUM(D38:G38) -> 84.14 | I38: =IF(H38>=95,"A+",IF(H38>=85,"A",IF(H38>=80,"A-",IF(H38>=75,"B+",IF(H38>=70,"B",IF(H38>=65,"B-",IF(H38>=60,"C+",IF(H38>=55,"C",IF(H38>=50,"D","F"))))))))) -> A-
A39: 35 | B39: 221014135 | C39: Aminul Islam | D39: =CSE4098B_Spring2026_Report!AB39 -> 30.86 | E39: =MIN(45, IF(CSE4098B_Spring2026_Presentatio!Z39>1, CSE4098B_Spring2026_Presentatio!Z39, CSE4098B_Spring2026_Presentatio!Z39*45)) -> 31.56 | F39: 4 | G39: 7 | H39: =SUM(D39:G39) -> 73.42 | I39: =IF(H39>=95,"A+",IF(H39>=85,"A",IF(H39>=80,"A-",IF(H39>=75,"B+",IF(H39>=70,"B",IF(H39>=65,"B-",IF(H39>=60,"C+",IF(H39>=55,"C",IF(H39>=50,"D","F"))))))))) -> B | J39: WFU | K39: An Intelligent CV Screening Model Using NLP And LLM
A40: 36 | B40: 221014018 | C40: Israfill Hossain Mehedi | D40: =CSE4098B_Spring2026_Report!AB40 -> 30.86 | E40: =MIN(45, IF(CSE4098B_Spring2026_Presentatio!Z40>1, CSE4098B_Spring2026_Presentatio!Z40, CSE4098B_Spring2026_Presentatio!Z40*45)) -> 36.44 | F40: 5 | G40: 10 | H40: =SUM(D40:G40) -> 82.3 | I40: =IF(H40>=95,"A+",IF(H40>=85,"A",IF(H40>=80,"A-",IF(H40>=75,"B+",IF(H40>=70,"B",IF(H40>=65,"B-",IF(H40>=60,"C+",IF(H40>=55,"C",IF(H40>=50,"D","F"))))))))) -> A-
...

Sheet CO Report Evaluation
F1: Evaluator 01 | P1: Evaluator 02 | Z1: Supervisor | AI1: Final
A2: S/N | B2: Student ID | C2: Student Name | F2: CO1 | G2: CO2 | H2: CO3 | I2: CO4 | J2: CO5 | K2: CO6 | L2: CO7 | M2: CO8 | N2: CO9 | P2: CO1 | Q2: CO2 | R2: CO3 | S2: CO4 | T2: CO5 | U2: CO6 | V2: CO7 | W2: CO8 | X2: CO9 | Z2: CO1 | AA2: CO2 | AB2: CO3 | AC2: CO4 | AD2: CO5 | AE2: CO6 | AF2: CO7 | AG2: CO8 | AH2: CO9 | AI2: CO1 | AJ2: CO2 | AK2: CO3 | AL2: CO4 | AM2: CO5 | AN2: CO6 | AO2: CO7 | AP2: CO8 | AQ2: CO9
A3: 1 | B3: =CSE4098B_Spring2026_Grade!B5 -> 223014152 | C3: =CSE4098B_Spring2026_Grade!C5 -> Ahadul Islam Rahul | F3: 4 | G3: 2 | H3: 3 | I3: 3 | J3: 3 | K3: 4 | L3: 3 | M3: 3 | N3: 3 | P3: 4 | Q3: 2 | R3: 3 | S3: 3 | T3: 2 | U3: 4 | V3: 2 | W3: 3 | X3: 2 | Z3: 6 | AA3: 3 | AB3: 3 | AC3: 3 | AD3: 2 | AE3: 5 | AF3: 3 | AG3: 3 | AH3: 3 | AI3: =(F3+P3+Z3)/3 -> 4.6666667 | AJ3: =(AA3+Q3+G3)/3 -> 2.3333333 | AK3: =(H3+R3+AB3)/3 -> 3 | AL3: =(I3+S3+AC3)/3 -> 3 | AM3: =(J3+T3+AD3)/3 -> 2.3333333 | AN3: =(K3+U3+AE3)/3 -> 4.3333333 | AO3: =(L3+V3+AF3)/3 -> 2.6666667 | AP3: =(M3+W3+AG3)/3 -> 3 | AQ3: =(N3+X3+AH3)/3 -> 2.6666667
A4: 2 | B4: =CSE4098B_Spring2026_Grade!B6 -> 223014049 | C4: =CSE4098B_Spring2026_Grade!C6 -> Md. Sojib Al Hasan | F4: 4 | G4: 2 | H4: 3 | I4: 3 | J4: 3 | K4: 4 | L4: 3 | M4: 3 | N4: 3 | P4: 4 | Q4: 2 | R4: 3 | S4: 3 | T4: 2 | U4: 4 | V4: 2 | W4: 3 | X4: 2 | Z4: 6 | AA4: 3 | AB4: 3 | AC4: 3 | AD4: 2 | AE4: 5 | AF4: 3 | AG4: 3 | AH4: 3 | AI4: =(F4+P4+Z4)/3 -> 4.6666667 | AJ4: =(AA4+Q4+G4)/3 -> 2.3333333 | AK4: =(H4+R4+AB4)/3 -> 3 | AL4: =(I4+S4+AC4)/3 -> 3 | AM4: =(J4+T4+AD4)/3 -> 2.3333333 | AN4: =(K4+U4+AE4)/3 -> 4.3333333 | AO4: =(L4+V4+AF4)/3 -> 2.6666667 | AP4: =(M4+W4+AG4)/3 -> 3 | AQ4: =(N4+X4+AH4)/3 -> 2.6666667
A5: 3 | B5: =CSE4098B_Spring2026_Grade!B7 -> 222014039 | C5: =CSE4098B_Spring2026_Grade!C7 -> Nadia Akter Jui | F5: 4 | G5: 2 | H5: 3 | I5: 3 | J5: 3 | K5: 4 | L5: 3 | M5: 3 | N5: 3 | P5: 4 | Q5: 2 | R5: 3 | S5: 3 | T5: 2 | U5: 4 | V5: 2 | W5: 3 | X5: 2 | Z5: 6 | AA5: 3 | AB5: 3 | AC5: 3 | AD5: 2 | AE5: 5 | AF5: 3 | AG5: 3 | AH5: 3 | AI5: =(F5+P5+Z5)/3 -> 4.6666667 | AJ5: =(AA5+Q5+G5)/3 -> 2.3333333 | AK5: =(H5+R5+AB5)/3 -> 3 | AL5: =(I5+S5+AC5)/3 -> 3 | AM5: =(J5+T5+AD5)/3 -> 2.3333333 | AN5: =(K5+U5+AE5)/3 -> 4.3333333 | AO5: =(L5+V5+AF5)/3 -> 2.6666667 | AP5: =(M5+W5+AG5)/3 -> 3 | AQ5: =(N5+X5+AH5)/3 -> 2.6666667
A6: 4 | B6: =CSE4098B_Spring2026_Grade!B8 -> 222014012 | C6: =CSE4098B_Spring2026_Grade!C8 -> Md. Minhazul Islam | F6: 4 | G6: 2 | H6: 3 | I6: 3 | J6: 3 | K6: 4 | L6: 3 | M6: 3 | N6: 3 | P6: 4 | Q6: 2 | R6: 3 | S6: 3 | T6: 2 | U6: 4 | V6: 2 | W6: 3 | X6: 2 | Z6: 6 | AA6: 3 | AB6: 3 | AC6: 3 | AD6: 2 | AE6: 5 | AF6: 3 | AG6: 3 | AH6: 3 | AI6: =(F6+P6+Z6)/3 -> 4.6666667 | AJ6: =(AA6+Q6+G6)/3 -> 2.3333333 | AK6: =(H6+R6+AB6)/3 -> 3 | AL6: =(I6+S6+AC6)/3 -> 3 | AM6: =(J6+T6+AD6)/3 -> 2.3333333 | AN6: =(K6+U6+AE6)/3 -> 4.3333333 | AO6: =(L6+V6+AF6)/3 -> 2.6666667 | AP6: =(M6+W6+AG6)/3 -> 3 | AQ6: =(N6+X6+AH6)/3 -> 2.6666667
A7: 5 | B7: =CSE4098B_Spring2026_Grade!B9 -> 222014096 | C7: =CSE4098B_Spring2026_Grade!C9 -> Md. Shams Arefin | F7: 4 | G7: 2 | H7: 3 | I7: 3 | J7: 3 | K7: 4 | L7: 3 | M7: 3 | N7: 3 | P7: 4 | Q7: 2 | R7: 3 | S7: 3 | T7: 2 | U7: 4 | V7: 2 | W7: 3 | X7: 2 | Z7: 6 | AA7: 3 | AB7: 3 | AC7: 3 | AD7: 2 | AE7: 5 | AF7: 3 | AG7: 3 | AH7: 3 | AI7: =(F7+P7+Z7)/3 -> 4.6666667 | AJ7: =(AA7+Q7+G7)/3 -> 2.3333333 | AK7: =(H7+R7+AB7)/3 -> 3 | AL7: =(I7+S7+AC7)/3 -> 3 | AM7: =(J7+T7+AD7)/3 -> 2.3333333 | AN7: =(K7+U7+AE7)/3 -> 4.3333333 | AO7: =(L7+V7+AF7)/3 -> 2.6666667 | AP7: =(M7+W7+AG7)/3 -> 3 | AQ7: =(N7+X7+AH7)/3 -> 2.6666667
A8: 6 | B8: =CSE4098B_Spring2026_Grade!B10 -> 222014052 | C8: =CSE4098B_Spring2026_Grade!C10 -> Redwan Ahamad Samir | F8: 5 | G8: 3 | H8: 2 | I8: 3 | J8: 3 | K8: 6 | L8: 2 | M8: 2 | N8: 2 | P8: 5 | Q8: 3 | R8: 2 | S8: 2 | T8: 2 | U8: 5 | V8: 1 | W8: 1 | X8: 2 | Z8: 5 | AA8: 2 | AB8: 3 | AC8: 3 | AD8: 3 | AE8: 4 | AF8: 3 | AG8: 3 | AH8: 3 | AI8: =(F8+P8+Z8)/3 -> 5 | AJ8: =(AA8+Q8+G8)/3 -> 2.6666667 | AK8: =(H8+R8+AB8)/3 -> 2.3333333 | AL8: =(I8+S8+AC8)/3 -> 2.6666667 | AM8: =(J8+T8+AD8)/3 -> 2.6666667 | AN8: =(K8+U8+AE8)/3 -> 5 | AO8: =(L8+V8+AF8)/3 -> 2 | AP8: =(M8+W8+AG8)/3 -> 2 | AQ8: =(N8+X8+AH8)/3 -> 2.3333333
A9: 7 | B9: =CSE4098B_Spring2026_Grade!B11 -> 222014009 | C9: =CSE4098B_Spring2026_Grade!C11 -> Samia Rahman | F9: 5 | G9: 3 | H9: 2 | I9: 3 | J9: 3 | K9: 6 | L9: 2 | M9: 2 | N9: 2 | P9: 5 | Q9: 3 | R9: 2 | S9: 2 | T9: 2 | U9: 5 | V9: 1 | W9: 1 | X9: 2 | Z9: 5 | AA9: 2 | AB9: 3 | AC9: 3 | AD9: 3 | AE9: 4 | AF9: 3 | AG9: 3 | AH9: 3 | AI9: =(F9+P9+Z9)/3 -> 5 | AJ9: =(AA9+Q9+G9)/3 -> 2.6666667 | AK9: =(H9+R9+AB9)/3 -> 2.3333333 | AL9: =(I9+S9+AC9)/3 -> 2.6666667 | AM9: =(J9+T9+AD9)/3 -> 2.6666667 | AN9: =(K9+U9+AE9)/3 -> 5 | AO9: =(L9+V9+AF9)/3 -> 2 | AP9: =(M9+W9+AG9)/3 -> 2 | AQ9: =(N9+X9+AH9)/3 -> 2.3333333
A10: 8 | B10: =CSE4098B_Spring2026_Grade!B12 -> 222014088 | C10: =CSE4098B_Spring2026_Grade!C12 -> Md. Omur Faruk | F10: 5 | G10: 3 | H10: 2 | I10: 3 | J10: 3 | K10: 6 | L10: 2 | M10: 2 | N10: 2 | P10: 5 | Q10: 3 | R10: 2 | S10: 2 | T10: 2 | U10: 5 | V10: 1 | W10: 1 | X10: 2 | Z10: 5 | AA10: 2 | AB10: 3 | AC10: 3 | AD10: 3 | AE10: 4 | AF10: 3 | AG10: 3 | AH10: 3 | AI10: =(F10+P10+Z10)/3 -> 5 | AJ10: =(AA10+Q10+G10)/3 -> 2.6666667 | AK10: =(H10+R10+AB10)/3 -> 2.3333333 | AL10: =(I10+S10+AC10)/3 -> 2.6666667 | AM10: =(J10+T10+AD10)/3 -> 2.6666667 | AN10: =(K10+U10+AE10)/3 -> 5 | AO10: =(L10+V10+AF10)/3 -> 2 | AP10: =(M10+W10+AG10)/3 -> 2 | AQ10: =(N10+X10+AH10)/3 -> 2.3333333
A11: 9 | B11: =CSE4098B_Spring2026_Grade!B13 -> 231014021 | C11: =CSE4098B_Spring2026_Grade!C13 -> Raiyan Islam | F11: 5 | G11: 3 | H11: 2 | I11: 3 | J11: 3 | K11: 6 | L11: 2 | M11: 2 | N11: 2 | P11: 5 | Q11: 3 | R11: 2 | S11: 2 | T11: 2 | U11: 5 | V11: 1 | W11: 1 | X11: 2 | Z11: 5 | AA11: 2 | AB11: 3 | AC11: 3 | AD11: 3 | AE11: 4 | AF11: 3 | AG11: 3 | AH11: 3 | AI11: =(F11+P11+Z11)/3 -> 5 | AJ11: =(AA11+Q11+G11)/3 -> 2.6666667 | AK11: =(H11+R11+AB11)/3 -> 2.3333333 | AL11: =(I11+S11+AC11)/3 -> 2.6666667 | AM11: =(J11+T11+AD11)/3 -> 2.6666667 | AN11: =(K11+U11+AE11)/3 -> 5 | AO11: =(L11+V11+AF11)/3 -> 2 | AP11: =(M11+W11+AG11)/3 -> 2 | AQ11: =(N11+X11+AH11)/3 -> 2.3333333
A12: 10 | B12: =CSE4098B_Spring2026_Grade!B14 -> 223014142 | C12: =CSE4098B_Spring2026_Grade!C14 -> Tamanna Akter | F12: 5 | G12: 3 | H12: 3 | I12: 3 | J12: 5 | K12: 2 | L12: 3 | M12: 2 | N12: 2 | P12: 5 | Q12: 3 | R12: 3 | S12: 3 | T12: 5 | U12: 2 | V12: 3 | W12: 2 | X12: 2 | Z12: 5 | AA12: 2 | AB12: 2 | AC12: 3 | AD12: 3 | AE12: 4 | AF12: 2 | AG12: 2 | AH12: 2 | AI12: =(F12+P12+Z12)/3 -> 5 | AJ12: =(AA12+Q12+G12)/3 -> 2.6666667 | AK12: =(H12+R12+AB12)/3 -> 2.6666667 | AL12: =(I12+S12+AC12)/3 -> 3 | AM12: =(J12+T12+AD12)/3 -> 4.3333333 | AN12: =(K12+U12+AE12)/3 -> 2.6666667 | AO12: =(L12+V12+AF12)/3 -> 2.6666667 | AP12: =(M12+W12+AG12)/3 -> 2 | AQ12: =(N12+X12+AH12)/3 -> 2
A13: 11 | B13: =CSE4098B_Spring2026_Grade!B15 -> 223014204 | C13: =CSE4098B_Spring2026_Grade!C15 -> Ashrafun Nahar Rahi | F13: 5 | G13: 3 | H13: 3 | I13: 3 | J13: 5 | K13: 2 | L13: 3 | M13: 2 | N13: 2 | P13: 5 | Q13: 3 | R13: 3 | S13: 3 | T13: 5 | U13: 2 | V13: 3 | W13: 2 | X13: 2 | Z13: 5 | AA13: 2 | AB13: 2 | AC13: 3 | AD13: 3 | AE13: 4 | AF13: 2 | AG13: 2 | AH13: 2 | AI13: =(F13+P13+Z13)/3 -> 5 | AJ13: =(AA13+Q13+G13)/3 -> 2.6666667 | AK13: =(H13+R13+AB13)/3 -> 2.6666667 | AL13: =(I13+S13+AC13)/3 -> 3 | AM13: =(J13+T13+AD13)/3 -> 4.3333333 | AN13: =(K13+U13+AE13)/3 -> 2.6666667 | AO13: =(L13+V13+AF13)/3 -> 2.6666667 | AP13: =(M13+W13+AG13)/3 -> 2 | AQ13: =(N13+X13+AH13)/3 -> 2
A14: 12 | B14: =CSE4098B_Spring2026_Grade!B16 -> 213014052 | C14: =CSE4098B_Spring2026_Grade!C16 -> Khuslima Fardush Mony | F14: 5 | G14: 3 | H14: 3 | I14: 3 | J14: 5 | K14: 2 | L14: 3 | M14: 2 | N14: 2 | P14: 5 | Q14: 3 | R14: 3 | S14: 3 | T14: 5 | U14: 2 | V14: 3 | W14: 2 | X14: 2 | Z14: 5 | AA14: 2 | AB14: 2 | AC14: 3 | AD14: 3 | AE14: 4 | AF14: 2 | AG14: 2 | AH14: 2 | AI14: =(F14+P14+Z14)/3 -> 5 | AJ14: =(AA14+Q14+G14)/3 -> 2.6666667 | AK14: =(H14+R14+AB14)/3 -> 2.6666667 | AL14: =(I14+S14+AC14)/3 -> 3 | AM14: =(J14+T14+AD14)/3 -> 4.3333333 | AN14: =(K14+U14+AE14)/3 -> 2.6666667 | AO14: =(L14+V14+AF14)/3 -> 2.6666667 | AP14: =(M14+W14+AG14)/3 -> 2 | AQ14: =(N14+X14+AH14)/3 -> 2
A15: 13 | B15: =CSE4098B_Spring2026_Grade!B17 -> 221014035 | C15: =CSE4098B_Spring2026_Grade!C17 -> Md. Alif Hossain | F15: 5 | G15: 3 | H15: 3 | I15: 3 | J15: 5 | K15: 2 | L15: 3 | M15: 2 | N15: 2 | P15: 5 | Q15: 3 | R15: 3 | S15: 3 | T15: 5 | U15: 2 | V15: 3 | W15: 2 | X15: 2 | Z15: 5 | AA15: 2 | AB15: 2 | AC15: 3 | AD15: 3 | AE15: 4 | AF15: 2 | AG15: 2 | AH15: 2 | AI15: =(F15+P15+Z15)/3 -> 5 | AJ15: =(AA15+Q15+G15)/3 -> 2.6666667 | AK15: =(H15+R15+AB15)/3 -> 2.6666667 | AL15: =(I15+S15+AC15)/3 -> 3 | AM15: =(J15+T15+AD15)/3 -> 4.3333333 | AN15: =(K15+U15+AE15)/3 -> 2.6666667 | AO15: =(L15+V15+AF15)/3 -> 2.6666667 | AP15: =(M15+W15+AG15)/3 -> 2 | AQ15: =(N15+X15+AH15)/3 -> 2
A16: 14 | B16: =CSE4098B_Spring2026_Grade!B18 -> 223014074 | C16: =CSE4098B_Spring2026_Grade!C18 -> Salvir Rahman Ratul | F16: 5 | G16: 3 | H16: 2 | I16: 3 | J16: 2 | K16: 5 | L16: 2 | M16: 3 | N16: 2 | Z16: 6 | AA16: 3 | AB16: 3 | AC16: 3 | AD16: 3 | AE16: 5 | AF16: 2 | AG16: 3 | AH16: 2 | AI16: =(F16+P16+Z16)/3 -> 3.6666667 | AJ16: =(AA16+Q16+G16)/3 -> 2 | AK16: =(H16+R16+AB16)/3 -> 1.6666667 | AL16: =(I16+S16+AC16)/3 -> 2 | AM16: =(J16+T16+AD16)/3 -> 1.6666667 | AN16: =(K16+U16+AE16)/3 -> 3.3333333 | AO16: =(L16+V16+AF16)/3 -> 1.3333333 | AP16: =(M16+W16+AG16)/3 -> 2 | AQ16: =(N16+X16+AH16)/3 -> 1.3333333
A17: 15 | B17: =CSE4098B_Spring2026_Grade!B19 -> 223014133 | C17: =CSE4098B_Spring2026_Grade!C19 -> Nancy Drong | F17: 5 | G17: 3 | H17: 2 | I17: 3 | J17: 2 | K17: 5 | L17: 2 | M17: 3 | N17: 2 | Z17: 6 | AA17: 3 | AB17: 3 | AC17: 3 | AD17: 3 | AE17: 5 | AF17: 2 | AG17: 3 | AH17: 2 | AI17: =(F17+P17+Z17)/3 -> 3.6666667 | AJ17: =(AA17+Q17+G17)/3 -> 2 | AK17: =(H17+R17+AB17)/3 -> 1.6666667 | AL17: =(I17+S17+AC17)/3 -> 2 | AM17: =(J17+T17+AD17)/3 -> 1.6666667 | AN17: =(K17+U17+AE17)/3 -> 3.3333333 | AO17: =(L17+V17+AF17)/3 -> 1.3333333 | AP17: =(M17+W17+AG17)/3 -> 2 | AQ17: =(N17+X17+AH17)/3 -> 1.3333333
A18: 16 | B18: =CSE4098B_Spring2026_Grade!B20 -> 223014052 | C18: =CSE4098B_Spring2026_Grade!C20 -> Argho Das | F18: 5 | G18: 3 | H18: 2 | I18: 3 | J18: 2 | K18: 5 | L18: 2 | M18: 3 | N18: 2 | Z18: 6 | AA18: 3 | AB18: 3 | AC18: 3 | AD18: 3 | AE18: 5 | AF18: 2 | AG18: 3 | AH18: 2 | AI18: =(F18+P18+Z18)/3 -> 3.6666667 | AJ18: =(AA18+Q18+G18)/3 -> 2 | AK18: =(H18+R18+AB18)/3 -> 1.6666667 | AL18: =(I18+S18+AC18)/3 -> 2 | AM18: =(J18+T18+AD18)/3 -> 1.6666667 | AN18: =(K18+U18+AE18)/3 -> 3.3333333 | AO18: =(L18+V18+AF18)/3 -> 1.3333333 | AP18: =(M18+W18+AG18)/3 -> 2 | AQ18: =(N18+X18+AH18)/3 -> 1.3333333
A19: 17 | B19: =CSE4098B_Spring2026_Grade!B21 -> 223014105 | C19: =CSE4098B_Spring2026_Grade!C21 -> Navid Rahman | F19: 5 | G19: 3 | H19: 2 | I19: 3 | J19: 2 | K19: 5 | L19: 2 | M19: 3 | N19: 2 | Z19: 6 | AA19: 3 | AB19: 3 | AC19: 3 | AD19: 3 | AE19: 5 | AF19: 2 | AG19: 3 | AH19: 2 | AI19: =(F19+P19+Z19)/3 -> 3.6666667 | AJ19: =(AA19+Q19+G19)/3 -> 2 | AK19: =(H19+R19+AB19)/3 -> 1.6666667 | AL19: =(I19+S19+AC19)/3 -> 2 | AM19: =(J19+T19+AD19)/3 -> 1.6666667 | AN19: =(K19+U19+AE19)/3 -> 3.3333333 | AO19: =(L19+V19+AF19)/3 -> 1.3333333 | AP19: =(M19+W19+AG19)/3 -> 2 | AQ19: =(N19+X19+AH19)/3 -> 1.3333333
A20: 18 | B20: =CSE4098B_Spring2026_Grade!B22 -> 223014196 | C20: =CSE4098B_Spring2026_Grade!C22 -> Shafwan Shadid Khan | F20: 5 | G20: 3 | H20: 2 | I20: 3 | J20: 2 | K20: 5 | L20: 2 | M20: 3 | N20: 2 | Z20: 6 | AA20: 3 | AB20: 3 | AC20: 3 | AD20: 3 | AE20: 5 | AF20: 2 | AG20: 3 | AH20: 2 | AI20: =(F20+P20+Z20)/3 -> 3.6666667 | AJ20: =(AA20+Q20+G20)/3 -> 2 | AK20: =(H20+R20+AB20)/3 -> 1.6666667 | AL20: =(I20+S20+AC20)/3 -> 2 | AM20: =(J20+T20+AD20)/3 -> 1.6666667 | AN20: =(K20+U20+AE20)/3 -> 3.3333333 | AO20: =(L20+V20+AF20)/3 -> 1.3333333 | AP20: =(M20+W20+AG20)/3 -> 2 | AQ20: =(N20+X20+AH20)/3 -> 1.3333333
A21: 19 | B21: =CSE4098B_Spring2026_Grade!B23 -> 223014213 | C21: =CSE4098B_Spring2026_Grade!C23 -> Md. Minhazul Islam | F21: 5 | G21: 2 | H21: 2 | I21: 3 | J21: 3 | K21: 4 | L21: 2 | M21: 2 | N21: 2 | P21: 5 | Q21: 2 | R21: 3 | S21: 3 | T21: 3 | U21: 5 | V21: 2 | W21: 3 | X21: 2 | Z21: 6 | AA21: 3 | AB21: 3 | AC21: 3 | AD21: 3 | AE21: 5 | AF21: 2 | AG21: 3 | AH21: 2 | AI21: =(F21+P21+Z21)/3 -> 5.3333333 | AJ21: =(AA21+Q21+G21)/3 -> 2.3333333 | AK21: =(H21+R21+AB21)/3 -> 2.6666667 | AL21: =(I21+S21+AC21)/3 -> 3 | AM21: =(J21+T21+AD21)/3 -> 3 | AN21: =(K21+U21+AE21)/3 -> 4.6666667 | AO21: =(L21+V21+AF21)/3 -> 2 | AP21: =(M21+W21+AG21)/3 -> 2.6666667 | AQ21: =(N21+X21+AH21)/3 -> 2
A22: 20 | B22: =CSE4098B_Spring2026_Grade!B24 -> 223014078 | C22: =CSE4098B_Spring2026_Grade!C24 -> Shakhar Das Rony | F22: 5 | G22: 2 | H22: 2 | I22: 3 | J22: 3 | K22: 4 | L22: 2 | M22: 2 | N22: 2 | P22: 5 | Q22: 2 | R22: 3 | S22: 3 | T22: 3 | U22: 5 | V22: 2 | W22: 3 | X22: 2 | Z22: 6 | AA22: 3 | AB22: 3 | AC22: 3 | AD22: 3 | AE22: 5 | AF22: 2 | AG22: 3 | AH22: 2 | AI22: =(F22+P22+Z22)/3 -> 5.3333333 | AJ22: =(AA22+Q22+G22)/3 -> 2.3333333 | AK22: =(H22+R22+AB22)/3 -> 2.6666667 | AL22: =(I22+S22+AC22)/3 -> 3 | AM22: =(J22+T22+AD22)/3 -> 3 | AN22: =(K22+U22+AE22)/3 -> 4.6666667 | AO22: =(L22+V22+AF22)/3 -> 2 | AP22: =(M22+W22+AG22)/3 -> 2.6666667 | AQ22: =(N22+X22+AH22)/3 -> 2
A23: 21 | B23: =CSE4098B_Spring2026_Grade!B25 -> 223014212 | C23: =CSE4098B_Spring2026_Grade!C25 -> Md. Tamim Hasan | F23: 5 | G23: 2 | H23: 2 | I23: 3 | J23: 3 | K23: 4 | L23: 2 | M23: 2 | N23: 2 | P23: 5 | Q23: 2 | R23: 3 | S23: 3 | T23: 3 | U23: 5 | V23: 2 | W23: 3 | X23: 2 | Z23: 6 | AA23: 3 | AB23: 3 | AC23: 3 | AD23: 3 | AE23: 5 | AF23: 2 | AG23: 3 | AH23: 2 | AI23: =(F23+P23+Z23)/3 -> 5.3333333 | AJ23: =(AA23+Q23+G23)/3 -> 2.3333333 | AK23: =(H23+R23+AB23)/3 -> 2.6666667 | AL23: =(I23+S23+AC23)/3 -> 3 | AM23: =(J23+T23+AD23)/3 -> 3 | AN23: =(K23+U23+AE23)/3 -> 4.6666667 | AO23: =(L23+V23+AF23)/3 -> 2 | AP23: =(M23+W23+AG23)/3 -> 2.6666667 | AQ23: =(N23+X23+AH23)/3 -> 2
A24: 22 | B24: =CSE4098B_Spring2026_Grade!B26 -> 231014049 | C24: =CSE4098B_Spring2026_Grade!C26 -> Kazi Noor E Saba | F24: 5 | G24: 3 | H24: 3 | I24: 2 | J24: 3 | K24: 5 | L24: 3 | M24: 2 | N24: 3 | P24: 6 | Q24: 3 | R24: 3 | S24: 2 | T24: 2 | U24: 5 | V24: 3 | W24: 3 | X24: 3 | AI24: =(F24+P24+Z24)/3 -> 3.6666667 | AJ24: =(AA24+Q24+G24)/3 -> 2 | AK24: =(H24+R24+AB24)/3 -> 2 | AL24: =(I24+S24+AC24)/3 -> 1.3333333 | AM24: =(J24+T24+AD24)/3 -> 1.6666667 | AN24: =(K24+U24+AE24)/3 -> 3.3333333 | AO24: =(L24+V24+AF24)/3 -> 2 | AP24: =(M24+W24+AG24)/3 -> 1.6666667 | AQ24: =(N24+X24+AH24)/3 -> 2
A25: 23 | B25: =CSE4098B_Spring2026_Grade!B27 -> 231014016 | C25: =CSE4098B_Spring2026_Grade!C27 -> Md. Akib Al Mahmud Dihan | F25: 5 | G25: 3 | H25: 3 | I25: 2 | J25: 3 | K25: 5 | L25: 3 | M25: 2 | N25: 3 | P25: 6 | Q25: 3 | R25: 3 | S25: 2 | T25: 2 | U25: 5 | V25: 3 | W25: 3 | X25: 3 | AI25: =(F25+P25+Z25)/3 -> 3.6666667 | AJ25: =(AA25+Q25+G25)/3 -> 2 | AK25: =(H25+R25+AB25)/3 -> 2 | AL25: =(I25+S25+AC25)/3 -> 1.3333333 | AM25: =(J25+T25+AD25)/3 -> 1.6666667 | AN25: =(K25+U25+AE25)/3 -> 3.3333333 | AO25: =(L25+V25+AF25)/3 -> 2 | AP25: =(M25+W25+AG25)/3 -> 1.6666667 | AQ25: =(N25+X25+AH25)/3 -> 2
A26: 24 | B26: =CSE4098B_Spring2026_Grade!B28 -> 231014125 | C26: =CSE4098B_Spring2026_Grade!C28 -> Jumana Muntaha | F26: 5 | G26: 3 | H26: 3 | I26: 2 | J26: 3 | K26: 5 | L26: 3 | M26: 2 | N26: 3 | P26: 6 | Q26: 3 | R26: 3 | S26: 2 | T26: 2 | U26: 5 | V26: 3 | W26: 3 | X26: 3 | AI26: =(F26+P26+Z26)/3 -> 3.6666667 | AJ26: =(AA26+Q26+G26)/3 -> 2 | AK26: =(H26+R26+AB26)/3 -> 2 | AL26: =(I26+S26+AC26)/3 -> 1.3333333 | AM26: =(J26+T26+AD26)/3 -> 1.6666667 | AN26: =(K26+U26+AE26)/3 -> 3.3333333 | AO26: =(L26+V26+AF26)/3 -> 2 | AP26: =(M26+W26+AG26)/3 -> 1.6666667 | AQ26: =(N26+X26+AH26)/3 -> 2
A27: 25 | B27: =CSE4098B_Spring2026_Grade!B29 -> 231014142 | C27: =CSE4098B_Spring2026_Grade!C29 -> Abida Binte Asif | F27: 5 | G27: 3 | H27: 3 | I27: 2 | J27: 3 | K27: 5 | L27: 3 | M27: 2 | N27: 3 | P27: 6 | Q27: 3 | R27: 3 | S27: 2 | T27: 2 | U27: 5 | V27: 3 | W27: 3 | X27: 3 | AI27: =(F27+P27+Z27)/3 -> 3.6666667 | AJ27: =(AA27+Q27+G27)/3 -> 2 | AK27: =(H27+R27+AB27)/3 -> 2 | AL27: =(I27+S27+AC27)/3 -> 1.3333333 | AM27: =(J27+T27+AD27)/3 -> 1.6666667 | AN27: =(K27+U27+AE27)/3 -> 3.3333333 | AO27: =(L27+V27+AF27)/3 -> 2 | AP27: =(M27+W27+AG27)/3 -> 1.6666667 | AQ27: =(N27+X27+AH27)/3 -> 2
A28: 26 | B28: =CSE4098B_Spring2026_Grade!B30 -> 223014146 | C28: =CSE4098B_Spring2026_Grade!C30 -> Sami Hossain | F28: 5 | G28: 3 | H28: 3 | I28: 2 | J28: 3 | K28: 5 | L28: 3 | M28: 2 | N28: 3 | P28: 6 | Q28: 3 | R28: 3 | S28: 2 | T28: 2 | U28: 5 | V28: 3 | W28: 3 | X28: 3 | AI28: =(F28+P28+Z28)/3 -> 3.6666667 | AJ28: =(AA28+Q28+G28)/3 -> 2 | AK28: =(H28+R28+AB28)/3 -> 2 | AL28: =(I28+S28+AC28)/3 -> 1.3333333 | AM28: =(J28+T28+AD28)/3 -> 1.6666667 | AN28: =(K28+U28+AE28)/3 -> 3.3333333 | AO28: =(L28+V28+AF28)/3 -> 2 | AP28: =(M28+W28+AG28)/3 -> 1.6666667 | AQ28: =(N28+X28+AH28)/3 -> 2
A29: 27 | B29: =CSE4098B_Spring2026_Grade!B31 -> 231014024 | C29: =CSE4098B_Spring2026_Grade!C31 -> Md. Shohanoor Rahman | F29: 5 | G29: 3 | H29: 3 | I29: 3 | J29: 3 | K29: 2 | L29: 2 | M29: 1 | N29: 3 | P29: 5 | Q29: 3 | R29: 3 | S29: 2 | T29: 3 | U29: 5 | V29: 3 | W29: 2 | X29: 3 | AI29: =(F29+P29+Z29)/3 -> 3.3333333 | AJ29: =(AA29+Q29+G29)/3 -> 2 | AK29: =(H29+R29+AB29)/3 -> 2 | AL29: =(I29+S29+AC29)/3 -> 1.6666667 | AM29: =(J29+T29+AD29)/3 -> 2 | AN29: =(K29+U29+AE29)/3 -> 2.3333333 | AO29: =(L29+V29+AF29)/3 -> 1.6666667 | AP29: =(M29+W29+AG29)/3 -> 1 | AQ29: =(N29+X29+AH29)/3 -> 2
A30: 28 | B30: =CSE4098B_Spring2026_Grade!B32 -> 231014064 | C30: =CSE4098B_Spring2026_Grade!C32 -> Pranto Sikder | F30: 5 | G30: 3 | H30: 3 | I30: 3 | J30: 3 | K30: 2 | L30: 2 | M30: 1 | N30: 3 | P30: 5 | Q30: 3 | R30: 3 | S30: 2 | T30: 3 | U30: 5 | V30: 3 | W30: 2 | X30: 3 | AI30: =(F30+P30+Z30)/3 -> 3.3333333 | AJ30: =(AA30+Q30+G30)/3 -> 2 | AK30: =(H30+R30+AB30)/3 -> 2 | AL30: =(I30+S30+AC30)/3 -> 1.6666667 | AM30: =(J30+T30+AD30)/3 -> 2 | AN30: =(K30+U30+AE30)/3 -> 2.3333333 | AO30: =(L30+V30+AF30)/3 -> 1.6666667 | AP30: =(M30+W30+AG30)/3 -> 1 | AQ30: =(N30+X30+AH30)/3 -> 2
A31: 29 | B31: =CSE4098B_Spring2026_Grade!B33 -> 231014050 | C31: =CSE4098B_Spring2026_Grade!C33 -> Mahmudul Hasan Zeshan | F31: 5 | G31: 3 | H31: 3 | I31: 3 | J31: 3 | K31: 2 | L31: 2 | M31: 1 | N31: 3 | P31: 5 | Q31: 3 | R31: 3 | S31: 2 | T31: 3 | U31: 5 | V31: 3 | W31: 2 | X31: 3 | AI31: =(F31+P31+Z31)/3 -> 3.3333333 | AJ31: =(AA31+Q31+G31)/3 -> 2 | AK31: =(H31+R31+AB31)/3 -> 2 | AL31: =(I31+S31+AC31)/3 -> 1.6666667 | AM31: =(J31+T31+AD31)/3 -> 2 | AN31: =(K31+U31+AE31)/3 -> 2.3333333 | AO31: =(L31+V31+AF31)/3 -> 1.6666667 | AP31: =(M31+W31+AG31)/3 -> 1 | AQ31: =(N31+X31+AH31)/3 -> 2
A32: 30 | B32: =CSE4098B_Spring2026_Grade!B34 -> 231014160 | C32: =CSE4098B_Spring2026_Grade!C34 -> Aysha Siddika Methila | F32: 5 | G32: 3 | H32: 3 | I32: 3 | J32: 3 | K32: 2 | L32: 2 | M32: 1 | N32: 3 | P32: 5 | Q32: 3 | R32: 3 | S32: 2 | T32: 3 | U32: 5 | V32: 3 | W32: 2 | X32: 3 | AI32: =(F32+P32+Z32)/3 -> 3.3333333 | AJ32: =(AA32+Q32+G32)/3 -> 2 | AK32: =(H32+R32+AB32)/3 -> 2 | AL32: =(I32+S32+AC32)/3 -> 1.6666667 | AM32: =(J32+T32+AD32)/3 -> 2 | AN32: =(K32+U32+AE32)/3 -> 2.3333333 | AO32: =(L32+V32+AF32)/3 -> 1.6666667 | AP32: =(M32+W32+AG32)/3 -> 1 | AQ32: =(N32+X32+AH32)/3 -> 2
A33: 31 | B33: =CSE4098B_Spring2026_Grade!B35 -> 231014116 | C33: =CSE4098B_Spring2026_Grade!C35 -> Sukanta Majumder | F33: 5 | G33: 3 | H33: 3 | I33: 3 | J33: 3 | K33: 2 | L33: 2 | M33: 1 | N33: 3 | P33: 5 | Q33: 3 | R33: 3 | S33: 2 | T33: 3 | U33: 5 | V33: 3 | W33: 2 | X33: 3 | AI33: =(F33+P33+Z33)/3 -> 3.3333333 | AJ33: =(AA33+Q33+G33)/3 -> 2 | AK33: =(H33+R33+AB33)/3 -> 2 | AL33: =(I33+S33+AC33)/3 -> 1.6666667 | AM33: =(J33+T33+AD33)/3 -> 2 | AN33: =(K33+U33+AE33)/3 -> 2.3333333 | AO33: =(L33+V33+AF33)/3 -> 1.6666667 | AP33: =(M33+W33+AG33)/3 -> 1 | AQ33: =(N33+X33+AH33)/3 -> 2
A34: 32 | B34: =CSE4098B_Spring2026_Grade!B36 -> 212014015 | C34: =CSE4098B_Spring2026_Grade!C36 -> Md. Arif Hossain Mir | P34: 6 | Q34: 2 | R34: 2 | S34: 2 | T34: 3 | U34: 4 | V34: 2 | W34: 3 | X34: 3 | Z34: 6 | AA34: 2 | AB34: 2 | AC34: 3 | AD34: 2 | AE34: 6 | AF34: 2 | AG34: 2 | AH34: 3 | AI34: =(F34+P34+Z34)/3 -> 4 | AJ34: =(AA34+Q34+G34)/3 -> 1.3333333 | AK34: =(H34+R34+AB34)/3 -> 1.3333333 | AL34: =(I34+S34+AC34)/3 -> 1.6666667 | AM34: =(J34+T34+AD34)/3 -> 1.6666667 | AN34: =(K34+U34+AE34)/3 -> 3.3333333 | AO34: =(L34+V34+AF34)/3 -> 1.3333333 | AP34: =(M34+W34+AG34)/3 -> 1.6666667 | AQ34: =(N34+X34+AH34)/3 -> 2
A35: 33 | B35: =CSE4098B_Spring2026_Grade!B37 -> 223014050 | C35: =CSE4098B_Spring2026_Grade!C37 -> Isnat Jahan Ome | P35: 6 | Q35: 2 | R35: 2 | S35: 2 | T35: 3 | U35: 4 | V35: 2 | W35: 3 | X35: 3 | Z35: 6 | AA35: 2 | AB35: 2 | AC35: 3 | AD35: 2 | AE35: 6 | AF35: 2 | AG35: 2 | AH35: 3 | AI35: =(F35+P35+Z35)/3 -> 4 | AJ35: =(AA35+Q35+G35)/3 -> 1.3333333 | AK35: =(H35+R35+AB35)/3 -> 1.3333333 | AL35: =(I35+S35+AC35)/3 -> 1.6666667 | AM35: =(J35+T35+AD35)/3 -> 1.6666667 | AN35: =(K35+U35+AE35)/3 -> 3.3333333 | AO35: =(L35+V35+AF35)/3 -> 1.3333333 | AP35: =(M35+W35+AG35)/3 -> 1.6666667 | AQ35: =(N35+X35+AH35)/3 -> 2
A36: 34 | B36: =CSE4098B_Spring2026_Grade!B38 -> 231014075 | C36: =CSE4098B_Spring2026_Grade!C38 -> Hasib Mahmud | P36: 6 | Q36: 2 | R36: 2 | S36: 2 | T36: 3 | U36: 4 | V36: 2 | W36: 3 | X36: 3 | Z36: 6 | AA36: 2 | AB36: 2 | AC36: 3 | AD36: 2 | AE36: 6 | AF36: 2 | AG36: 2 | AH36: 3 | AI36: =(F36+P36+Z36)/3 -> 4 | AJ36: =(AA36+Q36+G36)/3 -> 1.3333333 | AK36: =(H36+R36+AB36)/3 -> 1.3333333 | AL36: =(I36+S36+AC36)/3 -> 1.6666667 | AM36: =(J36+T36+AD36)/3 -> 1.6666667 | AN36: =(K36+U36+AE36)/3 -> 3.3333333 | AO36: =(L36+V36+AF36)/3 -> 1.3333333 | AP36: =(M36+W36+AG36)/3 -> 1.6666667 | AQ36: =(N36+X36+AH36)/3 -> 2
A37: 35 | B37: =CSE4098B_Spring2026_Grade!B39 -> 221014135 | C37: =CSE4098B_Spring2026_Grade!C39 -> Aminul Islam | F37: 4 | G37: 2 | H37: 2 | I37: 2 | J37: 2 | K37: 4 | L37: 2 | M37: 2 | N37: 2 | P37: 4 | Q37: 2 | R37: 2 | S37: 3 | T37: 3 | U37: 4 | V37: 2 | W37: 3 | X37: 3 | Z37: 6 | AA37: 2 | AB37: 2 | AC37: 2 | AD37: 3 | AE37: 5 | AF37: 3 | AG37: 3 | AH37: 3 | AI37: =(F37+P37+Z37)/3 -> 4.6666667 | AJ37: =(AA37+Q37+G37)/3 -> 2 | AK37: =(H37+R37+AB37)/3 -> 2 | AL37: =(I37+S37+AC37)/3 -> 2.3333333 | AM37: =(J37+T37+AD37)/3 -> 2.6666667 | AN37: =(K37+U37+AE37)/3 -> 4.3333333 | AO37: =(L37+V37+AF37)/3 -> 2.3333333 | AP37: =(M37+W37+AG37)/3 -> 2.6666667 | AQ37: =(N37+X37+AH37)/3 -> 2.6666667
A38: 36 | B38: =CSE4098B_Spring2026_Grade!B40 -> 221014018 | C38: =CSE4098B_Spring2026_Grade!C40 -> Israfill Hossain Mehedi | F38: 4 | G38: 2 | H38: 2 | I38: 2 | J38: 2 | K38: 4 | L38: 2 | M38: 2 | N38: 2 | P38: 4 | Q38: 2 | R38: 2 | S38: 3 | T38: 3 | U38: 4 | V38: 2 | W38: 3 | X38: 3 | Z38: 6 | AA38: 2 | AB38: 2 | AC38: 2 | AD38: 3 | AE38: 5 | AF38: 3 | AG38: 3 | AH38: 3 | AI38: =(F38+P38+Z38)/3 -> 4.6666667 | AJ38: =(AA38+Q38+G38)/3 -> 2 | AK38: =(H38+R38+AB38)/3 -> 2 | AL38: =(I38+S38+AC38)/3 -> 2.3333333 | AM38: =(J38+T38+AD38)/3 -> 2.6666667 | AN38: =(K38+U38+AE38)/3 -> 4.3333333 | AO38: =(L38+V38+AF38)/3 -> 2.3333333 | AP38: =(M38+W38+AG38)/3 -> 2.6666667 | AQ38: =(N38+X38+AH38)/3 -> 2.6666667
A39: 37 | B39: =CSE4098B_Spring2026_Grade!B41 -> 221014008 | C39: =CSE4098B_Spring2026_Grade!C41 -> Mahmudul Hasan Dipto | F39: 4 | G39: 2 | H39: 2 | I39: 2 | J39: 2 | K39: 4 | L39: 2 | M39: 2 | N39: 2 | P39: 4 | Q39: 2 | R39: 2 | S39: 3 | T39: 3 | U39: 4 | V39: 2 | W39: 3 | X39: 3 | Z39: 6 | AA39: 2 | AB39: 2 | AC39: 2 | AD39: 3 | AE39: 5 | AF39: 3 | AG39: 3 | AH39: 3 | AI39: =(F39+P39+Z39)/3 -> 4.6666667 | AJ39: =(AA39+Q39+G39)/3 -> 2 | AK39: =(H39+R39+AB39)/3 -> 2 | AL39: =(I39+S39+AC39)/3 -> 2.3333333 | AM39: =(J39+T39+AD39)/3 -> 2.6666667 | AN39: =(K39+U39+AE39)/3 -> 4.3333333 | AO39: =(L39+V39+AF39)/3 -> 2.3333333 | AP39: =(M39+W39+AG39)/3 -> 2.6666667 | AQ39: =(N39+X39+AH39)/3 -> 2.6666667
A40: 38 | B40: =CSE4098B_Spring2026_Grade!B42 -> 223014086 | C40: =CSE4098B_Spring2026_Grade!C42 -> Talat Mahmud Lam | F40: 5 | G40: 3 | H40: 2 | I40: 3 | J40: 2 | K40: 2 | L40: 2 | M40: 2 | N40: 2 | P40: 5 | Q40: 2 | R40: 2 | S40: 2 | T40: 3 | U40: 4 | V40: 3 | W40: 3 | X40: 3 | Z40: 6 | AA40: 3 | AB40: 3 | AC40: 3 | AD40: 2 | AE40: 5 | AF40: 3 | AG40: 3 | AH40: 3 | AI40: =(F40+P40+Z40)/3 -> 5.3333333 | AJ40: =(AA40+Q40+G40)/3 -> 2.6666667 | AK40: =(H40+R40+AB40)/3 -> 2.3333333 | AL40: =(I40+S40+AC40)/3 -> 2.6666667 | AM40: =(J40+T40+AD40)/3 -> 2.3333333 | AN40: =(K40+U40+AE40)/3 -> 3.6666667 | AO40: =(L40+V40+AF40)/3 -> 2.6666667 | AP40: =(M40+W40+AG40)/3 -> 2.6666667 | AQ40: =(N40+X40+AH40)/3 -> 2.6666667
...

Sheet CO-PO Attainment Analysis
BB1: Mapping of COs to POs
C2: Assessment Items | D2: CO1 | E2: CO2 | F2: CO3 | G2: CO4 | H2: CO5 | I2: CO6 | J2: CO7 | K2: CO8 | L2: CO9 | M2: CO10 | N2: CO11 | BA2: PO1 | BB2: PO2 | BC2: PO3 | BD2: PO4 | BE2: PO5 | BF2: PO6 | BG2: PO7 | BH2: PO8 | BI2: PO9 | BJ2: PO10 | BK2: PO11 | BL2: PO12
C3: Report | D3: 6 | E3: 3 | F3: 3 | G3: 3 | H3: 3 | I3: 6 | J3: 3 | K3: 3 | L3: 3 | AZ3: CO1 | BA3: 0 | BB3: 0 | BC3: 0 | BD3: 0 | BE3: 0 | BF3: 0 | BG3: 0 | BH3: 0 | BI3: 0 | BJ3: 0 | BK3: 0 | BL3: 1
C4: Peer | M4: 5 | AZ4: CO2 | BA4: 0 | BB4: 1 | BC4: 0 | BD4: 0 | BE4: 0 | BF4: 0 | BG4: 0 | BH4: 0 | BI4: 0 | BJ4: 0 | BK4: 0 | BL4: 0
C5: Term Final Presentation | N5: 10 | AZ5: CO3 | BA5: 0 | BB5: 0 | BC5: 0 | BD5: 0 | BE5: 0 | BF5: 0 | BG5: 0 | BH5: 0 | BI5: 0 | BJ5: 0 | BK5: 1 | BL5: 0
AZ6: CO4 | BA6: 0 | BB6: 0 | BC6: 0 | BD6: 0 | BE6: 1 | BF6: 0 | BG6: 0 | BH6: 0 | BI6: 0 | BJ6: 0 | BK6: 0 | BL6: 0
C7: Total | D7: =SUM(D3:D6) -> 6 | E7: =SUM(E3:E6) -> 3 | F7: =SUM(F3:F6) -> 3 | G7: =SUM(G3:G6) -> 3 | H7: =SUM(H3:H6) -> 3 | I7: =SUM(I3:I6) -> 6 | J7: =SUM(J3:J6) -> 3 | K7: =SUM(K3:K6) -> 3 | ... N7: =SUM(N3:N6) -> 10 | AZ7: CO5 | BA7: 0 | BB7: 0 | BC7: 1 | BD7: 0 | BE7: 0 | BF7: 0 | BG7: 0 | BH7: 0 | BI7: 0 | BJ7: 0 | BK7: 0 | BL7: 0
AZ8: CO6 | BA8: 0 | BB8: 0 | BC8: 0 | BD8: 1 | BE8: 0 | BF8: 0 | BG8: 0 | BH8: 0 | BI8: 0 | BJ8: 0 | BK8: 0 | BL8: 0
AZ9: CO7 | BA9: 0 | BB9: 0 | BC9: 0 | BD9: 0 | BE9: 0 | BF9: 1 | BG9: 0 | BH9: 0 | BI9: 0 | BJ9: 0 | BK9: 0 | BL9: 0
AZ10: CO8 | BA10: 0 | BB10: 0 | BC10: 0 | BD10: 0 | BE10: 0 | BF10: 0 | BG10: 1 | BH10: 0 | BI10: 0 | BJ10: 0 | BK10: 0 | BL10: 0
AZ11: CO9 | BA11: 0 | BB11: 0 | BC11: 0 | BD11: 0 | BE11: 0 | BF11: 0 | BG11: 0 | BH11: 1 | BI11: 0 | BJ11: 0 | BK11: 0 | BL11: 0
AZ12: CO10 | BA12: 0 | BB12: 0 | BC12: 0 | BD12: 0 | BE12: 0 | BF12: 0 | BG12: 0 | BH12: 0 | BI12: 1 | BJ12: 0 | BK12: 0 | BL12: 0
AZ13: CO11 | BA13: 0 | BB13: 0 | BC13: 0 | BD13: 0 | BE13: 0 | BF13: 0 | BG13: 0 | BH13: 0 | BI13: 0 | BJ13: 1 | BK13: 0 | BL13: 0
AZ14: Total | BA14: =SUM(BA3:BA13) -> 0 | BB14: =SUM(BB3:BB13) -> 1 | BC14: =SUM(BC3:BC13) -> 1 | BD14: =SUM(BD3:BD13) -> 1 | BE14: =SUM(BE3:BE13) -> 1 | BF14: =SUM(BF3:BF13) -> 1 | BG14: =SUM(BG3:BG13) -> 1 | BH14: =SUM(BH3:BH13) -> 1 | ... BL14: =SUM(BL3:BL13) -> 1
A16: CO Attainment Analysis CSE 4098B [Spring 2026] | T16: CO Attainment Analysis | BB16: PO Attainment Analysis
D17: =C3 -> Report | M17: =C4 -> Peer | S17: =C5 -> Term Final Presentation | T17: Total Marks | AE17: Percentage | AP17: CO Attainment | BB17: Percentage | BN17: PO Attainment
D18: CO1 | E18: CO2 | F18: CO3 | G18: CO4 | H18: CO5 | I18: CO6 | J18: CO7 | K18: CO8 | L18: CO9 | M18: CO1 | N18: CO2 | O18: CO3 | P18: CO4 | Q18: CO5 | R18: CO10 | S18: CO11 | T18: CO1 | U18: CO2 | V18: CO3 | W18: CO4 | X18: CO5 | Y18: CO6 | Z18: CO7 | AA18: CO8 | AB18: CO9 | AC18: CO10 | AD18: CO11 | AE18: CO1 | AF18: CO2 | AG18: CO3 | AH18: CO4 | AI18: CO5 | AJ18: CO6 | AK18: CO7 | AL18: CO8 | AM18: CO9 | AN18: CO10 | AO18: CO11 | AP18: CO1 | AQ18: CO2 | AR18: CO3 | AS18: CO4 | AT18: CO5 | AU18: CO6 | AV18: CO7 | AW18: CO8 | AX18: CO9 | AY18: CO10 | AZ18: CO11 | BB18: PO1 | BC18: PO2 | BD18: PO3 | BE18: PO4 | BF18: PO5 | BG18: PO6 | BH18: PO7 | BI18: PO8 | BJ18: PO9 | BK18: PO10 | BL18: PO11 | BM18: PO12 | BN18: PO1 | BO18: PO2 | BP18: PO3 | BQ18: PO4 | BR18: PO5 | BS18: PO6 | BT18: PO7 | BU18: PO8 | BV18: PO9 | BW18: PO10 | BX18: PO11 | BY18: PO12
A19: S/N | B19: Student ID | C19: Name | D19: =D3 -> 6 | E19: =E3 -> 3 | F19: =F3 -> 3 | G19: =G3 -> 3 | H19: =H3 -> 3 | I19: =I3 -> 6 | J19: =J3 -> 3 | K19: =K3 -> 3 | L19: =L3 -> 3 | M19: =D4 | N19: =E4 | O19: =F4 | P19: =G4 | Q19: =H4 | R19: =M4 -> 5 | S19: =N5 -> 10 | T19: =D19 -> 6 | U19: =E19 -> 3 | V19: =F19 -> 3 | W19: =G19 -> 3 | X19: =H19 -> 3 | Y19: =I19 -> 6 | Z19: =J19 -> 3 | AA19: =K19 -> 3 | AB19: =L19 -> 3 | AC19: =R19 -> 5 | AD19: =S19 -> 10 | AE19: 1 | AF19: 1 | AG19: 1 | AH19: 1 | AI19: 1 | AJ19: 1 | AK19: 1 | AL19: 1 | AM19: 1 | AN19: 1 | AO19: 1 | AP19: If CO achieved (≥55%) then 1, else 0 | BB19: 1 | BC19: 1 | BD19: 1 | BE19: 1 | BF19: 1 | BG19: 1 | BH19: 1 | BI19: 1 | BJ19: 1 | BK19: 1 | BL19: 1 | BM19: 1 | BN19: If PO achieved (≥55%) then 1, else 0
A20: 1 | B20: =CSE4098B_Spring2026_Grade!B5 -> 223014152 | C20: =CSE4098B_Spring2026_Grade!C5 -> Ahadul Islam Rahul | D20: ='CO Report Evaluation'!AI3 -> 4.6666667 | E20: ='CO Report Evaluation'!AJ3 -> 2.3333333 | F20: ='CO Report Evaluation'!AK3 -> 3 | G20: ='CO Report Evaluation'!AL3 -> 3 | H20: ='CO Report Evaluation'!AM3 -> 2.3333333 | I20: ='CO Report Evaluation'!AN3 -> 4.3333333 | J20: ='CO Report Evaluation'!AO3 -> 2.6666667 | K20: ='CO Report Evaluation'!AP3 -> 3 | L20: ='CO Report Evaluation'!AQ3 -> 2.6666667 | R20: =CSE4098B_Spring2026_Grade!F5 -> 2 | S20: =((CSE4098B_Spring2026_Grade!E5)*10)/45 -> 8.1977778 | T20: =D20 -> 4.6666667 | U20: =E20 -> 2.3333333 | V20: =F20 -> 3 | W20: =G20 -> 3 | X20: =H20 -> 2.3333333 | Y20: =I20 -> 4.3333333 | Z20: =J20 -> 2.6666667 | AA20: =K20 -> 3 | AB20: =L20 -> 2.6666667 | AC20: =R20 -> 2 | AD20: =S20 -> 8.1977778 | AE20: =IF(T20 = 0, 0, T20/T$19) -> 0.77777778 | AF20: =IF(U20 = 0, 0, U20/U$19) -> 0.77777778 | AG20: =IF(V20 = 0, 0, V20/V$19) -> 1 | AH20: =IF(W20 = 0, 0, W20/W$19) -> 1 | AI20: =IF(X20 = 0, 0, X20/X$19) -> 0.77777778 | AJ20: =IF(Y20 = 0, 0, Y20/Y$19) -> 0.72222222 | AK20: =IF(Z20 = 0, 0, Z20/Z$19) -> 0.88888889 | AL20: =IF(AA20 = 0, 0, AA20/AA$19) -> 1 | ... AO20: =IF(AD20 = 0, 0, AD20/AD$19) -> 0.81977778 | AP20: =IF(OR(CSE4098B_Spring2026_Grade!$I5="W (Withdrawn)", CSE4098B_Spring2026_Grade!$I5="I (Incomplete)"), 0, IF(AE20>=55%, 1, 0)) -> 1 | AQ20: =IF(OR(CSE4098B_Spring2026_Grade!$I5="W (Withdrawn)", CSE4098B_Spring2026_Grade!$I5="I (Incomplete)"), 0, IF(AF20>=55%, 1, 0)) -> 1 | AR20: =IF(OR(CSE4098B_Spring2026_Grade!$I5="W (Withdrawn)", CSE4098B_Spring2026_Grade!$I5="I (Incomplete)"), 0, IF(AG20>=55%, 1, 0)) -> 1 | AS20: =IF(OR(CSE4098B_Spring2026_Grade!$I5="W (Withdrawn)", CSE4098B_Spring2026_Grade!$I5="I (Incomplete)"), 0, IF(AH20>=55%, 1, 0)) -> 1 | AT20: =IF(OR(CSE4098B_Spring2026_Grade!$I5="W (Withdrawn)", CSE4098B_Spring2026_Grade!$I5="I (Incomplete)"), 0, IF(AI20>=55%, 1, 0)) -> 1 | AU20: =IF(OR(CSE4098B_Spring2026_Grade!$I5="W (Withdrawn)", CSE4098B_Spring2026_Grade!$I5="I (Incomplete)"), 0, IF(AJ20>=55%, 1, 0)) -> 1 | AV20: =IF(OR(CSE4098B_Spring2026_Grade!$I5="W (Withdrawn)", CSE4098B_Spring2026_Grade!$I5="I (Incomplete)"), 0, IF(AK20>=55%, 1, 0)) -> 1 | AW20: =IF(OR(CSE4098B_Spring2026_Grade!$I5="W (Withdrawn)", CSE4098B_Spring2026_Grade!$I5="I (Incomplete)"), 0, IF(AL20>=55%, 1, 0)) -> 1 | ... AZ20: =IF(OR(CSE4098B_Spring2026_Grade!$I5="W (Withdrawn)", CSE4098B_Spring2026_Grade!$I5="I (Incomplete)"), 0, IF(AO20>=55%, 1, 0)) -> 1 | BB20: =IF($BA$14=0,0,MMULT($AE20:$AO20, BA$3:BA$13)/$BA$14) -> 0 | BC20: =IF($BB$14=0,0,MMULT($AE20:$AO20, BB$3:BB$13)/$BB$14) -> 0.77777778 | BD20: {=IF($BC$14=0,0,MMULT($AE20:$AO20, BC$3:BC$13)/$BC$14)} -> 0.77777778 | BE20: {=IF($BD$14=0,0,MMULT($AE20:$AO20, BD$3:BD$13)/$BD$14)} -> 0.72222222 | BF20: =IF($BE$14=0,0,MMULT($AE20:$AO20, BE$3:BE$13)/$BE$14) -> 1 | BG20: {=IF($BF$14=0,0,MMULT($AE20:$AO20, BF$3:BF$13)/$BF$14)} -> 0.88888889 | BH20: {=IF($BG$14=0,0,MMULT($AE20:$AO20, BG$3:BG$13)/$BG$14)} -> 1 | BI20: {=IF($BH$14=0,0,MMULT($AE20:$AO20, BH$3:BH$13)/$BH$14)} -> 0.88888889 | BJ20: {=IF($BI$14=0,0,MMULT($AE20:$AO20, BI$3:BI$13)/$BI$14)} -> 0.4 | BK20: {=IF($BJ$14=0,0,MMULT($AE20:$AO20, BJ$3:BJ$13)/$BJ$14)} -> 0.81977778 | BL20: =IF($BK$14=0,0,MMULT($AE20:$AO20, BK$3:BK$13)/$BK$14) -> 1 | BM20: =IF($BL$14=0,0,MMULT($AE20:$AO20, BL$3:BL$13)/$BL$14) -> 0.77777778 | BN20: =IF(OR(CSE4098B_Spring2026_Grade!$I5="W (Withdrawn)", CSE4098B_Spring2026_Grade!$I5="I (Incomplete)"), 0, IF(BB20>=55%, 1, 0)) -> 0 | BO20: =IF(OR(CSE4098B_Spring2026_Grade!$I5="W (Withdrawn)", CSE4098B_Spring2026_Grade!$I5="I (Incomplete)"), 0, IF(BC20>=55%, 1, 0)) -> 1 | BP20: =IF(OR(CSE4098B_Spring2026_Grade!$I5="W (Withdrawn)", CSE4098B_Spring2026_Grade!$I5="I (Incomplete)"), 0, IF(BD20>=55%, 1, 0)) -> 1 | BQ20: =IF(OR(CSE4098B_Spring2026_Grade!$I5="W (Withdrawn)", CSE4098B_Spring2026_Grade!$I5="I (Incomplete)"), 0, IF(BE20>=55%, 1, 0)) -> 1 | BR20: =IF(OR(CSE4098B_Spring2026_Grade!$I5="W (Withdrawn)", CSE4098B_Spring2026_Grade!$I5="I (Incomplete)"), 0, IF(BF20>=55%, 1, 0)) -> 1 | BS20: =IF(OR(CSE4098B_Spring2026_Grade!$I5="W (Withdrawn)", CSE4098B_Spring2026_Grade!$I5="I (Incomplete)"), 0, IF(BG20>=55%, 1, 0)) -> 1 | BT20: =IF(OR(CSE4098B_Spring2026_Grade!$I5="W (Withdrawn)", CSE4098B_Spring2026_Grade!$I5="I (Incomplete)"), 0, IF(BH20>=55%, 1, 0)) -> 1 | BU20: =IF(OR(CSE4098B_Spring2026_Grade!$I5="W (Withdrawn)", CSE4098B_Spring2026_Grade!$I5="I (Incomplete)"), 0, IF(BI20>=55%, 1, 0)) -> 1 | ... BY20: =IF(OR(CSE4098B_Spring2026_Grade!$I5="W (Withdrawn)", CSE4098B_Spring2026_Grade!$I5="I (Incomplete)"), 0, IF(BM20>=55%, 1, 0)) -> 1
A21: 2 | B21: =CSE4098B_Spring2026_Grade!B6 -> 223014049 | C21: =CSE4098B_Spring2026_Grade!C6 -> Md. Sojib Al Hasan | D21: ='CO Report Evaluation'!AI4 -> 4.6666667 | E21: ='CO Report Evaluation'!AJ4 -> 2.3333333 | F21: ='CO Report Evaluation'!AK4 -> 3 | G21: ='CO Report Evaluation'!AL4 -> 3 | H21: ='CO Report Evaluation'!AM4 -> 2.3333333 | I21: ='CO Report Evaluation'!AN4 -> 4.3333333 | J21: ='CO Report Evaluation'!AO4 -> 2.6666667 | K21: ='CO Report Evaluation'!AP4 -> 3 | L21: ='CO Report Evaluation'!AQ4 -> 2.6666667 | R21: =CSE4098B_Spring2026_Grade!F6 -> 3 | S21: =((CSE4098B_Spring2026_Grade!E6)*10)/45 -> 8.8155556 | T21: =D21 -> 4.6666667 | U21: =E21 -> 2.3333333 | V21: =F21 -> 3 | W21: =G21 -> 3 | X21: =H21 -> 2.3333333 | Y21: =I21 -> 4.3333333 | Z21: =J21 -> 2.6666667 | AA21: =K21 -> 3 | AB21: =L21 -> 2.6666667 | AC21: =R21 -> 3 | AD21: =S21 -> 8.8155556 | AE21: =IF(T21 = 0, 0, T21/T$19) -> 0.77777778 | AF21: =IF(U21 = 0, 0, U21/U$19) -> 0.77777778 | AG21: =IF(V21 = 0, 0, V21/V$19) -> 1 | AH21: =IF(W21 = 0, 0, W21/W$19) -> 1 | AI21: =IF(X21 = 0, 0, X21/X$19) -> 0.77777778 | AJ21: =IF(Y21 = 0, 0, Y21/Y$19) -> 0.72222222 | AK21: =IF(Z21 = 0, 0, Z21/Z$19) -> 0.88888889 | AL21: =IF(AA21 = 0, 0, AA21/AA$19) -> 1 | ... AO21: =IF(AD21 = 0, 0, AD21/AD$19) -> 0.88155556 | AP21: =IF(OR(CSE4098B_Spring2026_Grade!$I6="W (Withdrawn)", CSE4098B_Spring2026_Grade!$I6="I (Incomplete)"), 0, IF(AE21>=55%, 1, 0)) -> 1 | AQ21: =IF(OR(CSE4098B_Spring2026_Grade!$I6="W (Withdrawn)", CSE4098B_Spring2026_Grade!$I6="I (Incomplete)"), 0, IF(AF21>=55%, 1, 0)) -> 1 | AR21: =IF(OR(CSE4098B_Spring2026_Grade!$I6="W (Withdrawn)", CSE4098B_Spring2026_Grade!$I6="I (Incomplete)"), 0, IF(AG21>=55%, 1, 0)) -> 1 | AS21: =IF(OR(CSE4098B_Spring2026_Grade!$I6="W (Withdrawn)", CSE4098B_Spring2026_Grade!$I6="I (Incomplete)"), 0, IF(AH21>=55%, 1, 0)) -> 1 | AT21: =IF(OR(CSE4098B_Spring2026_Grade!$I6="W (Withdrawn)", CSE4098B_Spring2026_Grade!$I6="I (Incomplete)"), 0, IF(AI21>=55%, 1, 0)) -> 1 | AU21: =IF(OR(CSE4098B_Spring2026_Grade!$I6="W (Withdrawn)", CSE4098B_Spring2026_Grade!$I6="I (Incomplete)"), 0, IF(AJ21>=55%, 1, 0)) -> 1 | AV21: =IF(OR(CSE4098B_Spring2026_Grade!$I6="W (Withdrawn)", CSE4098B_Spring2026_Grade!$I6="I (Incomplete)"), 0, IF(AK21>=55%, 1, 0)) -> 1 | AW21: =IF(OR(CSE4098B_Spring2026_Grade!$I6="W (Withdrawn)", CSE4098B_Spring2026_Grade!$I6="I (Incomplete)"), 0, IF(AL21>=55%, 1, 0)) -> 1 | ... AZ21: =IF(OR(CSE4098B_Spring2026_Grade!$I6="W (Withdrawn)", CSE4098B_Spring2026_Grade!$I6="I (Incomplete)"), 0, IF(AO21>=55%, 1, 0)) -> 1 | BB21: =IF($BA$14=0,0,MMULT($AE21:$AO21, BA$3:BA$13)/$BA$14) -> 0 | BC21: =IF($BB$14=0,0,MMULT($AE21:$AO21, BB$3:BB$13)/$BB$14) -> 0.77777778 | BD21: {=IF($BC$14=0,0,MMULT($AE21:$AO21, BC$3:BC$13)/$BC$14)} -> 0.77777778 | BE21: {=IF($BD$14=0,0,MMULT($AE21:$AO21, BD$3:BD$13)/$BD$14)} -> 0.72222222 | BF21: =IF($BE$14=0,0,MMULT($AE21:$AO21, BE$3:BE$13)/$BE$14) -> 1 | BG21: {=IF($BF$14=0,0,MMULT($AE21:$AO21, BF$3:BF$13)/$BF$14)} -> 0.88888889 | BH21: {=IF($BG$14=0,0,MMULT($AE21:$AO21, BG$3:BG$13)/$BG$14)} -> 1 | BI21: {=IF($BH$14=0,0,MMULT($AE21:$AO21, BH$3:BH$13)/$BH$14)} -> 0.88888889 | BJ21: {=IF($BI$14=0,0,MMULT($AE21:$AO21, BI$3:BI$13)/$BI$14)} -> 0.6 | BK21: {=IF($BJ$14=0,0,MMULT($AE21:$AO21, BJ$3:BJ$13)/$BJ$14)} -> 0.88155556 | BL21: =IF($BK$14=0,0,MMULT($AE21:$AO21, BK$3:BK$13)/$BK$14) -> 1 | BM21: =IF($BL$14=0,0,MMULT($AE21:$AO21, BL$3:BL$13)/$BL$14) -> 0.77777778 | BN21: =IF(OR(CSE4098B_Spring2026_Grade!$I6="W (Withdrawn)", CSE4098B_Spring2026_Grade!$I6="I (Incomplete)"), 0, IF(BB21>=55%, 1, 0)) -> 0 | BO21: =IF(OR(CSE4098B_Spring2026_Grade!$I6="W (Withdrawn)", CSE4098B_Spring2026_Grade!$I6="I (Incomplete)"), 0, IF(BC21>=55%, 1, 0)) -> 1 | BP21: =IF(OR(CSE4098B_Spring2026_Grade!$I6="W (Withdrawn)", CSE4098B_Spring2026_Grade!$I6="I (Incomplete)"), 0, IF(BD21>=55%, 1, 0)) -> 1 | BQ21: =IF(OR(CSE4098B_Spring2026_Grade!$I6="W (Withdrawn)", CSE4098B_Spring2026_Grade!$I6="I (Incomplete)"), 0, IF(BE21>=55%, 1, 0)) -> 1 | BR21: =IF(OR(CSE4098B_Spring2026_Grade!$I6="W (Withdrawn)", CSE4098B_Spring2026_Grade!$I6="I (Incomplete)"), 0, IF(BF21>=55%, 1, 0)) -> 1 | BS21: =IF(OR(CSE4098B_Spring2026_Grade!$I6="W (Withdrawn)", CSE4098B_Spring2026_Grade!$I6="I (Incomplete)"), 0, IF(BG21>=55%, 1, 0)) -> 1 | BT21: =IF(OR(CSE4098B_Spring2026_Grade!$I6="W (Withdrawn)", CSE4098B_Spring2026_Grade!$I6="I (Incomplete)"), 0, IF(BH21>=55%, 1, 0)) -> 1 | BU21: =IF(OR(CSE4098B_Spring2026_Grade!$I6="W (Withdrawn)", CSE4098B_Spring2026_Grade!$I6="I (Incomplete)"), 0, IF(BI21>=55%, 1, 0)) -> 1 | ... BY21: =IF(OR(CSE4098B_Spring2026_Grade!$I6="W (Withdrawn)", CSE4098B_Spring2026_Grade!$I6="I (Incomplete)"), 0, IF(BM21>=55%, 1, 0)) -> 1
