Workbook
Name Grades: #REF!
Name mygrade: #REF!
Name mygrades: #REF!

Sheet CSE4098C_Summer2026_Grade
A1: Capstone Project Grade (CSE 4098C)
A2: Marks Distribution
A3: Summer 2026
A4: Sl | B4: Student ID | C4: Student Name | D4: Report (40%) | E4: Presentation (25%) | F4: Poster (20%) | G4: Peer (5%) | H4: Weekly Journal (10%) | I4: Total (100%) | J4: Grade
A5: 1 | B5: 223014152 | C5: Ahadul Islam Rahul | D5: =CSE4098C_Summer2026_Report!AA5 -> #DIV/0! | E5: =ROUND((CSE4098C_Spring26_Presentation!Z5/50)*25,2) -> 4 | F5: =ROUND((CSE4098C_Summer2026_Poster!AA5/50)*20,2) -> #DIV/0! | I5: =SUM(D5:H5) -> #DIV/0! | J5: =IF(I5>=95,"A+",IF(I5>=85,"A",IF(I5>=80,"A-",IF(I5>=75,"B+",IF(I5>=70,"B",IF(I5>=65,"B-",IF(I5>=60,"C+",IF(I5>=55,"C",IF(I5>=50,"D","F"))))))))) -> #DIV/0!
A6: =A5+1 -> 2 | B6: 223014049 | C6: Md. Sojib Al Hasan | D6: =CSE4098C_Summer2026_Report!AA6 -> #DIV/0! | E6: =ROUND((CSE4098C_Spring26_Presentation!Z6/50)*25,2) -> 4 | F6: =ROUND((CSE4098C_Summer2026_Poster!AA6/50)*20,2) -> #DIV/0! | I6: =SUM(D6:H6) -> #DIV/0! | J6: =IF(I6>=95,"A+",IF(I6>=85,"A",IF(I6>=80,"A-",IF(I6>=75,"B+",IF(I6>=70,"B",IF(I6>=65,"B-",IF(I6>=60,"C+",IF(I6>=55,"C",IF(I6>=50,"D","F"))))))))) -> #DIV/0!
A7: =A6+1 -> 3 | B7: 222014039 | C7: Nadia Akter Jui | D7: =CSE4098C_Summer2026_Report!AA7 -> #DIV/0! | E7: =ROUND((CSE4098C_Spring26_Presentation!Z7/50)*25,2) -> 3.67 | F7: =ROUND((CSE4098C_Summer2026_Poster!AA7/50)*20,2) -> #DIV/0! | I7: =SUM(D7:H7) -> #DIV/0! | J7: =IF(I7>=95,"A+",IF(I7>=85,"A",IF(I7>=80,"A-",IF(I7>=75,"B+",IF(I7>=70,"B",IF(I7>=65,"B-",IF(I7>=60,"C+",IF(I7>=55,"C",IF(I7>=50,"D","F"))))))))) -> #DIV/0!
A8: =A7+1 -> 4 | B8: 222014012 | C8: Md. Minhazul Islam | D8: =CSE4098C_Summer2026_Report!AA8 -> #DIV/0! | E8: =ROUND((CSE4098C_Spring26_Presentation!Z8/50)*25,2) -> 4 | F8: =ROUND((CSE4098C_Summer2026_Poster!AA8/50)*20,2) -> #DIV/0! | I8: =SUM(D8:H8) -> #DIV/0! | J8: =IF(I8>=95,"A+",IF(I8>=85,"A",IF(I8>=80,"A-",IF(I8>=75,"B+",IF(I8>=70,"B",IF(I8>=65,"B-",IF(I8>=60,"C+",IF(I8>=55,"C",IF(I8>=50,"D","F"))))))))) -> #DIV/0!
A9: =A8+1 -> 5 | B9: 222014096 | C9: Md. Shams Arefin | D9: =CSE4098C_Summer2026_Report!AA9 -> #DIV/0! | E9: =ROUND((CSE4098C_Spring26_Presentation!Z9/50)*25,2) -> 4.34 | F9: =ROUND((CSE4098C_Summer2026_Poster!AA9/50)*20,2) -> #DIV/0! | I9: =SUM(D9:H9) -> #DIV/0! | J9: =IF(I9>=95,"A+",IF(I9>=85,"A",IF(I9>=80,"A-",IF(I9>=75,"B+",IF(I9>=70,"B",IF(I9>=65,"B-",IF(I9>=60,"C+",IF(I9>=55,"C",IF(I9>=50,"D","F"))))))))) -> #DIV/0!
A10: =A9+1 -> 6 | B10: 221014135 | C10: Aminul Islam | D10: =CSE4098C_Summer2026_Report!AA10 -> #DIV/0! | E10: =ROUND((CSE4098C_Spring26_Presentation!Z10/50)*25,2) -> 17.11 | F10: =ROUND((CSE4098C_Summer2026_Poster!AA10/50)*20,2) -> #DIV/0! | I10: =SUM(D10:H10) -> #DIV/0! | J10: =IF(I10>=95,"A+",IF(I10>=85,"A",IF(I10>=80,"A-",IF(I10>=75,"B+",IF(I10>=70,"B",IF(I10>=65,"B-",IF(I10>=60,"C+",IF(I10>=55,"C",IF(I10>=50,"D","F"))))))))) -> #DIV/0!
A11: =A10+1 -> 7 | B11: 221014018 | C11: Israfill Hossain Mehedi | D11: =CSE4098C_Summer2026_Report!AA11 -> #DIV/0! | E11: =ROUND((CSE4098C_Spring26_Presentation!Z11/50)*25,2) -> 17.26 | F11: =ROUND((CSE4098C_Summer2026_Poster!AA11/50)*20,2) -> #DIV/0! | I11: =SUM(D11:H11) -> #DIV/0! | J11: =IF(I11>=95,"A+",IF(I11>=85,"A",IF(I11>=80,"A-",IF(I11>=75,"B+",IF(I11>=70,"B",IF(I11>=65,"B-",IF(I11>=60,"C+",IF(I11>=55,"C",IF(I11>=50,"D","F"))))))))) -> #DIV/0!
A12: =A11+1 -> 8 | B12: 221014008 | C12: Mahmudul Hasan Dipto | D12: =CSE4098C_Summer2026_Report!AA12 -> #DIV/0! | E12: =ROUND((CSE4098C_Spring26_Presentation!Z12/50)*25,2) -> 17.11 | F12: =ROUND((CSE4098C_Summer2026_Poster!AA12/50)*20,2) -> #DIV/0! | I12: =SUM(D12:H12) -> #DIV/0! | J12: =IF(I12>=95,"A+",IF(I12>=85,"A",IF(I12>=80,"A-",IF(I12>=75,"B+",IF(I12>=70,"B",IF(I12>=65,"B-",IF(I12>=60,"C+",IF(I12>=55,"C",IF(I12>=50,"D","F"))))))))) -> #DIV/0!
A13: =A12+1 -> 9 | B13: 223014142 | C13: Tamanna Akter | D13: =CSE4098C_Summer2026_Report!AA13 -> #DIV/0! | E13: =ROUND((CSE4098C_Spring26_Presentation!Z13/50)*25,2) -> 15.56 | F13: =ROUND((CSE4098C_Summer2026_Poster!AA13/50)*20,2) -> #DIV/0! | I13: =SUM(D13:H13) -> #DIV/0! | J13: =IF(I13>=95,"A+",IF(I13>=85,"A",IF(I13>=80,"A-",IF(I13>=75,"B+",IF(I13>=70,"B",IF(I13>=65,"B-",IF(I13>=60,"C+",IF(I13>=55,"C",IF(I13>=50,"D","F"))))))))) -> #DIV/0!
A14: =A13+1 -> 10 | B14: 223014204 | C14: Ashrafun Nahar Rahi | D14: =CSE4098C_Summer2026_Report!AA14 -> #DIV/0! | E14: =ROUND((CSE4098C_Spring26_Presentation!Z14/50)*25,2) -> 16.89 | F14: =ROUND((CSE4098C_Summer2026_Poster!AA14/50)*20,2) -> #DIV/0! | I14: =SUM(D14:H14) -> #DIV/0! | J14: =IF(I14>=95,"A+",IF(I14>=85,"A",IF(I14>=80,"A-",IF(I14>=75,"B+",IF(I14>=70,"B",IF(I14>=65,"B-",IF(I14>=60,"C+",IF(I14>=55,"C",IF(I14>=50,"D","F"))))))))) -> #DIV/0!
A15: =A14+1 -> 11 | B15: 213014052 | C15: Khuslima Fardush Mony | D15: =CSE4098C_Summer2026_Report!AA15 -> #DIV/0! | E15: =ROUND((CSE4098C_Spring26_Presentation!Z15/50)*25,2) -> 14.22 | F15: =ROUND((CSE4098C_Summer2026_Poster!AA15/50)*20,2) -> #DIV/0! | I15: =SUM(D15:H15) -> #DIV/0! | J15: =IF(I15>=95,"A+",IF(I15>=85,"A",IF(I15>=80,"A-",IF(I15>=75,"B+",IF(I15>=70,"B",IF(I15>=65,"B-",IF(I15>=60,"C+",IF(I15>=55,"C",IF(I15>=50,"D","F"))))))))) -> #DIV/0!
A16: =A15+1 -> 12 | B16: 221014035 | C16: Md. Alif Hossain | D16: =CSE4098C_Summer2026_Report!AA16 -> #DIV/0! | E16: =ROUND((CSE4098C_Spring26_Presentation!Z16/50)*25,2) -> 14.89 | F16: =ROUND((CSE4098C_Summer2026_Poster!AA16/50)*20,2) -> #DIV/0! | I16: =SUM(D16:H16) -> #DIV/0! | J16: =IF(I16>=95,"A+",IF(I16>=85,"A",IF(I16>=80,"A-",IF(I16>=75,"B+",IF(I16>=70,"B",IF(I16>=65,"B-",IF(I16>=60,"C+",IF(I16>=55,"C",IF(I16>=50,"D","F"))))))))) -> #DIV/0!
A17: =A16+1 -> 13 | B17: 223014074 | C17: Salvir Rahman Ratul | D17: =CSE4098C_Summer2026_Report!AA17 -> #DIV/0! | E17: =ROUND((CSE4098C_Spring26_Presentation!Z17/50)*25,2) -> 22.67 | F17: =ROUND((CSE4098C_Summer2026_Poster!AA17/50)*20,2) -> #DIV/0! | I17: =SUM(D17:H17) -> #DIV/0! | J17: =IF(I17>=95,"A+",IF(I17>=85,"A",IF(I17>=80,"A-",IF(I17>=75,"B+",IF(I17>=70,"B",IF(I17>=65,"B-",IF(I17>=60,"C+",IF(I17>=55,"C",IF(I17>=50,"D","F"))))))))) -> #DIV/0!
... A69: =A68+1 -> 65 | B69: 231014116 | C69: Sukanta Majumder | D69: =CSE4098C_Summer2026_Report!AA69 -> #DIV/0! | E69: =ROUND((CSE4098C_Spring26_Presentation!Z69/50)*25,2) -> 6.58 | F69: =ROUND((CSE4098C_Summer2026_Poster!AA69/50)*20,2) -> #DIV/0! | I69: =SUM(D69:H69) -> #DIV/0! | J69: =IF(I69>=95,"A+",IF(I69>=85,"A",IF(I69>=80,"A-",IF(I69>=75,"B+",IF(I69>=70,"B",IF(I69>=65,"B-",IF(I69>=60,"C+",IF(I69>=55,"C",IF(I69>=50,"D","F"))))))))) -> #DIV/0!
I72: Grade Summery
I73: A+ | J73: =COUNTIF(J$5:J$69, "A+") -> 0
I74: A | J74: =COUNTIF(J$5:J$69, "A") -> 0
I75: A- | J75: =COUNTIF(J$5:J$69, "A-") -> 0
I76: B+ | J76: =COUNTIF(J$5:J$69, "B+") -> 0
I77: B | J77: =COUNTIF(J$5:J$69, "B") -> 0
I78: B- | J78: =COUNTIF(J$5:J$69, "B-") -> 0
I79: C+ | J79: =COUNTIF(J$5:J$69, "C+") -> 0
I80: C | J80: =COUNTIF(J$5:J$69, "C") -> 0
I81: D | J81: =COUNTIF(J$5:J$69, "D") -> 0
I82: F | J82: =COUNTIF(J$5:J$69, "F") -> 0
I83: Total | J83: =SUM(J73:J82) -> 0
C95: Muhammad Golam Kibria, PhD, SMIEEE
C96: Professor & Head
C97: Department of CSE, ULAB

Sheet CSE4098C_Summer2026_Report
A1: Capstone Project Report (CSE 4098C)
A2: Marks Distribution
C3: Summer 2026 | D3: Supervisor | F3: Evaluator's Marks (Provided in Rubrics: 39)
A4: Sl | B4: Student ID | C4: Student Name | D4: Supervisor (Provided in Rubrics: 39) | E4: Supervisor Marks (40%) | F4: MGK | G4: NafM | H4: MdKH | I4: RwaiK | J4: RaiK | K4: NUA | L4: RHF | M4: WFU | N4: ASU | O4: SJSQ | P4: SviA | Q4: ASR | R4: FSAh | S4: JFR | T4: FK | U4: SBMM | V4: MAWA | W4: DAMT | X4: ABY | Y4: MNMA | Z4: Evaluator's Mark (40%) | AA4: Total (Supervisor: 60% + Evaluator: 40%)
A5: 1 | B5: =CSE4098C_Summer2026_Grade!B5 -> 223014152 | C5: =CSE4098C_Summer2026_Grade!C5 -> Ahadul Islam Rahul | D5: 0 | E5: =ROUND((40*D5)/39,2) -> 0 | Z5: =ROUND((40*AVERAGE(F5:Y5))/39,2) -> #DIV/0! | AA5: =ROUND((E5*60%+Z5*40%),2) -> #DIV/0!
A6: =A5+1 -> 2 | B6: =CSE4098C_Summer2026_Grade!B6 -> 223014049 | C6: =CSE4098C_Summer2026_Grade!C6 -> Md. Sojib Al Hasan | D6: 0 | E6: =ROUND((40*D6)/39,2) -> 0 | Z6: =ROUND((40*AVERAGE(F6:Y6))/39,2) -> #DIV/0! | AA6: =ROUND((E6*60%+Z6*40%),2) -> #DIV/0!
A7: =A6+1 -> 3 | B7: =CSE4098C_Summer2026_Grade!B7 -> 222014039 | C7: =CSE4098C_Summer2026_Grade!C7 -> Nadia Akter Jui | D7: 0 | E7: =ROUND((40*D7)/39,2) -> 0 | Z7: =ROUND((40*AVERAGE(F7:Y7))/39,2) -> #DIV/0! | AA7: =ROUND((E7*60%+Z7*40%),2) -> #DIV/0!
A8: =A7+1 -> 4 | B8: =CSE4098C_Summer2026_Grade!B8 -> 222014012 | C8: =CSE4098C_Summer2026_Grade!C8 -> Md. Minhazul Islam | D8: 0 | E8: =ROUND((40*D8)/39,2) -> 0 | Z8: =ROUND((40*AVERAGE(F8:Y8))/39,2) -> #DIV/0! | AA8: =ROUND((E8*60%+Z8*40%),2) -> #DIV/0!
A9: =A8+1 -> 5 | B9: =CSE4098C_Summer2026_Grade!B9 -> 222014096 | C9: =CSE4098C_Summer2026_Grade!C9 -> Md. Shams Arefin | D9: 0 | E9: =ROUND((40*D9)/39,2) -> 0 | Z9: =ROUND((40*AVERAGE(F9:Y9))/39,2) -> #DIV/0! | AA9: =ROUND((E9*60%+Z9*40%),2) -> #DIV/0!
A10: =A9+1 -> 6 | B10: =CSE4098C_Summer2026_Grade!B10 -> 221014135 | C10: =CSE4098C_Summer2026_Grade!C10 -> Aminul Islam | D10: 0 | E10: =ROUND((40*D10)/39,2) -> 0 | Z10: =ROUND((40*AVERAGE(F10:Y10))/39,2) -> #DIV/0! | AA10: =ROUND((E10*60%+Z10*40%),2) -> #DIV/0!
A11: =A10+1 -> 7 | B11: =CSE4098C_Summer2026_Grade!B11 -> 221014018 | C11: =CSE4098C_Summer2026_Grade!C11 -> Israfill Hossain Mehedi | D11: 0 | E11: =ROUND((40*D11)/39,2) -> 0 | Z11: =ROUND((40*AVERAGE(F11:Y11))/39,2) -> #DIV/0! | AA11: =ROUND((E11*60%+Z11*40%),2) -> #DIV/0!
A12: =A11+1 -> 8 | B12: =CSE4098C_Summer2026_Grade!B12 -> 221014008 | C12: =CSE4098C_Summer2026_Grade!C12 -> Mahmudul Hasan Dipto | D12: 0 | E12: =ROUND((40*D12)/39,2) -> 0 | Z12: =ROUND((40*AVERAGE(F12:Y12))/39,2) -> #DIV/0! | AA12: =ROUND((E12*60%+Z12*40%),2) -> #DIV/0!
A13: =A12+1 -> 9 | B13: =CSE4098C_Summer2026_Grade!B13 -> 223014142 | C13: =CSE4098C_Summer2026_Grade!C13 -> Tamanna Akter | D13: 0 | E13: =ROUND((40*D13)/39,2) -> 0 | Z13: =ROUND((40*AVERAGE(F13:Y13))/39,2) -> #DIV/0! | AA13: =ROUND((E13*60%+Z13*40%),2) -> #DIV/0!
A14: =A13+1 -> 10 | B14: =CSE4098C_Summer2026_Grade!B14 -> 223014204 | C14: =CSE4098C_Summer2026_Grade!C14 -> Ashrafun Nahar Rahi | D14: 0 | E14: =ROUND((40*D14)/39,2) -> 0 | Z14: =ROUND((40*AVERAGE(F14:Y14))/39,2) -> #DIV/0! | AA14: =ROUND((E14*60%+Z14*40%),2) -> #DIV/0!
A15: =A14+1 -> 11 | B15: =CSE4098C_Summer2026_Grade!B15 -> 213014052 | C15: =CSE4098C_Summer2026_Grade!C15 -> Khuslima Fardush Mony | D15: 0 | E15: =ROUND((40*D15)/39,2) -> 0 | Z15: =ROUND((40*AVERAGE(F15:Y15))/39,2) -> #DIV/0! | AA15: =ROUND((E15*60%+Z15*40%),2) -> #DIV/0!
A16: =A15+1 -> 12 | B16: =CSE4098C_Summer2026_Grade!B16 -> 221014035 | C16: =CSE4098C_Summer2026_Grade!C16 -> Md. Alif Hossain | D16: 0 | E16: =ROUND((40*D16)/39,2) -> 0 | Z16: =ROUND((40*AVERAGE(F16:Y16))/39,2) -> #DIV/0! | AA16: =ROUND((E16*60%+Z16*40%),2) -> #DIV/0!
A17: =A16+1 -> 13 | B17: =CSE4098C_Summer2026_Grade!B17 -> 223014074 | C17: =CSE4098C_Summer2026_Grade!C17 -> Salvir Rahman Ratul | D17: 0 | E17: =ROUND((40*D17)/39,2) -> 0 | Z17: =ROUND((40*AVERAGE(F17:Y17))/39,2) -> #DIV/0! | AA17: =ROUND((E17*60%+Z17*40%),2) -> #DIV/0!
... A69: =A68+1 -> 65 | B69: =CSE4098C_Summer2026_Grade!B69 -> 231014116 | C69: =CSE4098C_Summer2026_Grade!C69 -> Sukanta Majumder | D69: 0 | E69: =ROUND((40*D69)/39,2) -> 0 | Z69: =ROUND((40*AVERAGE(F69:Y69))/39,2) -> #DIV/0! | AA69: =ROUND((E69*60%+Z69*40%),2) -> #DIV/0!

Sheet CSE4098C_Summer2026_Poster
A1: Capstone Poster Presentation (CSE 4098C)
A2: Marks Distribution
C3: Summer 2026 | D3: Supervisor | F3: Evaluator's Marks (Provided in Rubrics: 12)
A4: Sl | B4: Student ID | C4: Student Name | D4: Supervisor (Provided in Rubrics: 12) | E4: Supervisor Marks (50%) | F4: MGK | G4: NafM | H4: MdKH | I4: RaiK | J4: RHF | K4: SviA | L4: SBMM | M4: JFR | N4: ASU | O4: NUA | P4: FK | Q4: ASR | R4: WFU | S4: DAMT | T4: MAWA | U4: SJSQ | V4: MNMA | W4: FSAh | X4: AATL | Y4: Ashraful Kadir | Z4: Evaluator's Marks (50%) | AA4: Total (Supervisor: 60% + Evaluator: 40%)
A5: 1 | B5: =CSE4098C_Summer2026_Grade!B5 -> 223014152 | C5: =CSE4098C_Summer2026_Grade!C5 -> Ahadul Islam Rahul | D5: 0 | E5: =ROUND((50*D5)/12,2) -> 0 | Z5: =ROUND((50*AVERAGE(F5:V5))/12,2) -> #DIV/0! | AA5: =ROUND((E5*60%+Z5*40%),2) -> #DIV/0!
A6: =A5+1 -> 2 | B6: =CSE4098C_Summer2026_Grade!B6 -> 223014049 | C6: =CSE4098C_Summer2026_Grade!C6 -> Md. Sojib Al Hasan | D6: 0 | E6: =ROUND((50*D6)/12,2) -> 0 | Z6: =ROUND((50*AVERAGE(F6:V6))/12,2) -> #DIV/0! | AA6: =ROUND((E6*60%+Z6*40%),2) -> #DIV/0!
A7: =A6+1 -> 3 | B7: =CSE4098C_Summer2026_Grade!B7 -> 222014039 | C7: =CSE4098C_Summer2026_Grade!C7 -> Nadia Akter Jui | D7: 0 | E7: =ROUND((50*D7)/12,2) -> 0 | Z7: =ROUND((50*AVERAGE(F7:V7))/12,2) -> #DIV/0! | AA7: =ROUND((E7*60%+Z7*40%),2) -> #DIV/0!
A8: =A7+1 -> 4 | B8: =CSE4098C_Summer2026_Grade!B8 -> 222014012 | C8: =CSE4098C_Summer2026_Grade!C8 -> Md. Minhazul Islam | D8: 0 | E8: =ROUND((50*D8)/12,2) -> 0 | Z8: =ROUND((50*AVERAGE(F8:V8))/12,2) -> #DIV/0! | AA8: =ROUND((E8*60%+Z8*40%),2) -> #DIV/0!
A9: =A8+1 -> 5 | B9: =CSE4098C_Summer2026_Grade!B9 -> 222014096 | C9: =CSE4098C_Summer2026_Grade!C9 -> Md. Shams Arefin | D9: 0 | E9: =ROUND((50*D9)/12,2) -> 0 | Z9: =ROUND((50*AVERAGE(F9:V9))/12,2) -> #DIV/0! | AA9: =ROUND((E9*60%+Z9*40%),2) -> #DIV/0!
A10: =A9+1 -> 6 | B10: =CSE4098C_Summer2026_Grade!B10 -> 221014135 | C10: =CSE4098C_Summer2026_Grade!C10 -> Aminul Islam | D10: 0 | E10: =ROUND((50*D10)/12,2) -> 0 | Z10: =ROUND((50*AVERAGE(F10:V10))/12,2) -> #DIV/0! | AA10: =ROUND((E10*60%+Z10*40%),2) -> #DIV/0!
A11: =A10+1 -> 7 | B11: =CSE4098C_Summer2026_Grade!B11 -> 221014018 | C11: =CSE4098C_Summer2026_Grade!C11 -> Israfill Hossain Mehedi | D11: 0 | E11: =ROUND((50*D11)/12,2) -> 0 | Z11: =ROUND((50*AVERAGE(F11:V11))/12,2) -> #DIV/0! | AA11: =ROUND((E11*60%+Z11*40%),2) -> #DIV/0!
A12: =A11+1 -> 8 | B12: =CSE4098C_Summer2026_Grade!B12 -> 221014008 | C12: =CSE4098C_Summer2026_Grade!C12 -> Mahmudul Hasan Dipto | D12: 0 | E12: =ROUND((50*D12)/12,2) -> 0 | Z12: =ROUND((50*AVERAGE(F12:V12))/12,2) -> #DIV/0! | AA12: =ROUND((E12*60%+Z12*40%),2) -> #DIV/0!
A13: =A12+1 -> 9 | B13: =CSE4098C_Summer2026_Grade!B13 -> 223014142 | C13: =CSE4098C_Summer2026_Grade!C13 -> Tamanna Akter | D13: 0 | E13: =ROUND((50*D13)/12,2) -> 0 | Z13: =ROUND((50*AVERAGE(F13:V13))/12,2) -> #DIV/0! | AA13: =ROUND((E13*60%+Z13*40%),2) -> #DIV/0!
A14: =A13+1 -> 10 | B14: =CSE4098C_Summer2026_Grade!B14 -> 223014204 | C14: =CSE4098C_Summer2026_Grade!C14 -> Ashrafun Nahar Rahi | D14: 0 | E14: =ROUND((50*D14)/12,2) -> 0 | Z14: =ROUND((50*AVERAGE(F14:V14))/12,2) -> #DIV/0! | AA14: =ROUND((E14*60%+Z14*40%),2) -> #DIV/0!
A15: =A14+1 -> 11 | B15: =CSE4098C_Summer2026_Grade!B15 -> 213014052 | C15: =CSE4098C_Summer2026_Grade!C15 -> Khuslima Fardush Mony | D15: 0 | E15: =ROUND((50*D15)/12,2) -> 0 | Z15: =ROUND((50*AVERAGE(F15:V15))/12,2) -> #DIV/0! | AA15: =ROUND((E15*60%+Z15*40%),2) -> #DIV/0!
A16: =A15+1 -> 12 | B16: =CSE4098C_Summer2026_Grade!B16 -> 221014035 | C16: =CSE4098C_Summer2026_Grade!C16 -> Md. Alif Hossain | D16: 0 | E16: =ROUND((50*D16)/12,2) -> 0 | Z16: =ROUND((50*AVERAGE(F16:V16))/12,2) -> #DIV/0! | AA16: =ROUND((E16*60%+Z16*40%),2) -> #DIV/0!
A17: =A16+1 -> 13 | B17: =CSE4098C_Summer2026_Grade!B17 -> 223014074 | C17: =CSE4098C_Summer2026_Grade!C17 -> Salvir Rahman Ratul | D17: 0 | E17: =ROUND((50*D17)/12,2) -> 0 | Z17: =ROUND((50*AVERAGE(F17:V17))/12,2) -> #DIV/0! | AA17: =ROUND((E17*60%+Z17*40%),2) -> #DIV/0!
... A69: =A68+1 -> 65 | B69: =CSE4098C_Summer2026_Grade!B69 -> 231014116 | C69: =CSE4098C_Summer2026_Grade!C69 -> Sukanta Majumder | D69: 0 | E69: =ROUND((50*D69)/12,2) -> 0 | Z69: =ROUND((50*AVERAGE(F69:V69))/12,2) -> #DIV/0! | AA69: =ROUND((E69*60%+Z69*40%),2) -> #DIV/0!

Sheet CSE4098C_Spring26_Presentation
A1: Capstone Final Presentation (CSE 4098C)
A2: Marks Distribution
C3: Summer 2026 | D3: Supervisor | F3: Evaluator's Marks (Provided in Rubrics: 45)
A4: Sl | B4: Student ID | C4: Student Name | D4: Supervisor (Provided in Rubrics: 45) | E4: Supervisor Marks (50%) | F4: MGK | G4: NafM | H4: AATL | I4: MdKH | J4: RaiK | K4: RHF | L4: SviA | M4: JFR | N4: SJSQ | O4: NUA | P4: DAMT | Q4: FK | R4: MAWA | S4: RwaiK | T4: AAS | U4: ASR | V4: WFU | W4: MTK | X4: MNMA | Y4: Evaluator's Marks (50%) | Z4: Total (Supervisor: 60% + Evaluator: 40%)
A5: 1 | B5: =CSE4098C_Summer2026_Grade!B5 -> 223014152 | C5: =CSE4098C_Summer2026_Grade!C5 -> Ahadul Islam Rahul | D5: 0 | E5: =ROUND((D5/45)*50,2) -> 0 | P5: 21 | T5: 15 | Y5: =ROUND((50*AVERAGE(F5:X5))/45,2) -> 20 | Z5: =ROUND((E5*60%+Y5*40%),2) -> 8
A6: =A5+1 -> 2 | B6: =CSE4098C_Summer2026_Grade!B6 -> 223014049 | C6: =CSE4098C_Summer2026_Grade!C6 -> Md. Sojib Al Hasan | D6: 0 | E6: =ROUND((D6/45)*50,2) -> 0 | P6: 21 | T6: 15 | Y6: =ROUND((50*AVERAGE(F6:X6))/45,2) -> 20 | Z6: =ROUND((E6*60%+Y6*40%),2) -> 8
A7: =A6+1 -> 3 | B7: =CSE4098C_Summer2026_Grade!B7 -> 222014039 | C7: =CSE4098C_Summer2026_Grade!C7 -> Nadia Akter Jui | D7: 0 | E7: =ROUND((D7/45)*50,2) -> 0 | P7: 18 | T7: 15 | Y7: =ROUND((50*AVERAGE(F7:X7))/45,2) -> 18.33 | Z7: =ROUND((E7*60%+Y7*40%),2) -> 7.33
A8: =A7+1 -> 4 | B8: =CSE4098C_Summer2026_Grade!B8 -> 222014012 | C8: =CSE4098C_Summer2026_Grade!C8 -> Md. Minhazul Islam | D8: 0 | E8: =ROUND((D8/45)*50,2) -> 0 | P8: 21 | T8: 15 | Y8: =ROUND((50*AVERAGE(F8:X8))/45,2) -> 20 | Z8: =ROUND((E8*60%+Y8*40%),2) -> 8
A9: =A8+1 -> 5 | B9: =CSE4098C_Summer2026_Grade!B9 -> 222014096 | C9: =CSE4098C_Summer2026_Grade!C9 -> Md. Shams Arefin | D9: 0 | E9: =ROUND((D9/45)*50,2) -> 0 | P9: 24 | T9: 15 | Y9: =ROUND((50*AVERAGE(F9:X9))/45,2) -> 21.67 | Z9: =ROUND((E9*60%+Y9*40%),2) -> 8.67
A10: =A9+1 -> 6 | B10: =CSE4098C_Summer2026_Grade!B10 -> 221014135 | C10: =CSE4098C_Summer2026_Grade!C10 -> Aminul Islam | D10: 36 | E10: =ROUND((D10/45)*50,2) -> 40 | J10: 30 | O10: 18 | W10: 21 | Y10: =ROUND((50*AVERAGE(F10:X10))/45,2) -> 25.56 | Z10: =ROUND((E10*60%+Y10*40%),2) -> 34.22
A11: =A10+1 -> 7 | B11: =CSE4098C_Summer2026_Grade!B11 -> 221014018 | C11: =CSE4098C_Summer2026_Grade!C11 -> Israfill Hossain Mehedi | D11: 36 | E11: =ROUND((D11/45)*50,2) -> 40 | J11: 29 | O11: 18 | W11: 24 | Y11: =ROUND((50*AVERAGE(F11:X11))/45,2) -> 26.3 | Z11: =ROUND((E11*60%+Y11*40%),2) -> 34.52
A12: =A11+1 -> 8 | B12: =CSE4098C_Summer2026_Grade!B12 -> 221014008 | C12: =CSE4098C_Summer2026_Grade!C12 -> Mahmudul Hasan Dipto | D12: 36 | E12: =ROUND((D12/45)*50,2) -> 40 | J12: 30 | O12: 18 | W12: 21 | Y12: =ROUND((50*AVERAGE(F12:X12))/45,2) -> 25.56 | Z12: =ROUND((E12*60%+Y12*40%),2) -> 34.22
A13: =A12+1 -> 9 | B13: =CSE4098C_Summer2026_Grade!B13 -> 223014142 | C13: =CSE4098C_Summer2026_Grade!C13 -> Tamanna Akter | D13: 34 | E13: =ROUND((D13/45)*50,2) -> 37.78 | I13: 15 | P13: 24 | T13: 18 | Y13: =ROUND((50*AVERAGE(F13:X13))/45,2) -> 21.11 | Z13: =ROUND((E13*60%+Y13*40%),2) -> 31.11
A14: =A13+1 -> 10 | B14: =CSE4098C_Summer2026_Grade!B14 -> 223014204 | C14: =CSE4098C_Summer2026_Grade!C14 -> Ashrafun Nahar Rahi | D14: 38 | E14: =ROUND((D14/45)*50,2) -> 42.22 | I14: 15 | P14: 24 | T14: 18 | Y14: =ROUND((50*AVERAGE(F14:X14))/45,2) -> 21.11 | Z14: =ROUND((E14*60%+Y14*40%),2) -> 33.78
A15: =A14+1 -> 11 | B15: =CSE4098C_Summer2026_Grade!B15 -> 213014052 | C15: =CSE4098C_Summer2026_Grade!C15 -> Khuslima Fardush Mony | D15: 30 | E15: =ROUND((D15/45)*50,2) -> 33.33 | I15: 15 | P15: 24 | T15: 18 | Y15: =ROUND((50*AVERAGE(F15:X15))/45,2) -> 21.11 | Z15: =ROUND((E15*60%+Y15*40%),2) -> 28.44
A16: =A15+1 -> 12 | B16: =CSE4098C_Summer2026_Grade!B16 -> 221014035 | C16: =CSE4098C_Summer2026_Grade!C16 -> Md. Alif Hossain | D16: 32 | E16: =ROUND((D16/45)*50,2) -> 35.56 | I16: 15 | P16: 24 | T16: 18 | Y16: =ROUND((50*AVERAGE(F16:X16))/45,2) -> 21.11 | Z16: =ROUND((E16*60%+Y16*40%),2) -> 29.78
A17: =A16+1 -> 13 | B17: =CSE4098C_Summer2026_Grade!B17 -> 223014074 | C17: =CSE4098C_Summer2026_Grade!C17 -> Salvir Rahman Ratul | D17: 42 | E17: =ROUND((D17/45)*50,2) -> 46.67 | I17: 36 | M17: 42 | P17: 39 | T17: 39 | Y17: =ROUND((50*AVERAGE(F17:X17))/45,2) -> 43.33 | Z17: =ROUND((E17*60%+Y17*40%),2) -> 45.33
A18: =A17+1 -> 14 | B18: =CSE4098C_Summer2026_Grade!B18 -> 223014133 | C18: =CSE4098C_Summer2026_Grade!C18 -> Nancy Drong | D18: 42 | E18: =ROUND((D18/45)*50,2) -> 46.67 | I18: 36 | M18: 42 | P18: 39 | T18: 39 | Y18: =ROUND((50*AVERAGE(F18:X18))/45,2) -> 43.33 | Z18: =ROUND((E18*60%+Y18*40%),2) -> 45.33
A19: =A18+1 -> 15 | B19: =CSE4098C_Summer2026_Grade!B19 -> 223014052 | C19: =CSE4098C_Summer2026_Grade!C19 -> Argho Das | D19: 42 | E19: =ROUND((D19/45)*50,2) -> 46.67 | I19: 36 | M19: 42 | P19: 39 | T19: 39 | Y19: =ROUND((50*AVERAGE(F19:X19))/45,2) -> 43.33 | Z19: =ROUND((E19*60%+Y19*40%),2) -> 45.33
A20: =A19+1 -> 16 | B20: =CSE4098C_Summer2026_Grade!B20 -> 223014105 | C20: =CSE4098C_Summer2026_Grade!C20 -> Navid Rahman | D20: 43 | E20: =ROUND((D20/45)*50,2) -> 47.78 | I20: 33 | M20: 42 | P20: 39 | T20: 39 | Y20: =ROUND((50*AVERAGE(F20:X20))/45,2) -> 42.5 | Z20: =ROUND((E20*60%+Y20*40%),2) -> 45.67
A21: =A20+1 -> 17 | B21: =CSE4098C_Summer2026_Grade!B21 -> 223014196 | C21: =CSE4098C_Summer2026_Grade!C21 -> Shafwan Shadid Khan | D21: 42 | E21: =ROUND((D21/45)*50,2) -> 46.67 | I21: 33 | M21: 42 | P21: 39 | T21: 39 | Y21: =ROUND((50*AVERAGE(F21:X21))/45,2) -> 42.5 | Z21: =ROUND((E21*60%+Y21*40%),2) -> 45
A22: =A21+1 -> 18 | B22: =CSE4098C_Summer2026_Grade!B22 -> 201014026 | C22: =CSE4098C_Summer2026_Grade!C22 -> Sabbir Hossain | D22: 39 | E22: =ROUND((D22/45)*50,2) -> 43.33 | H22: 30 | N22: 26 | U22: 24 | X22: 30 | Y22: =ROUND((50*AVERAGE(F22:X22))/45,2) -> 30.56 | Z22: =ROUND((E22*60%+Y22*40%),2) -> 38.22
A23: =A22+1 -> 19 | B23: =CSE4098C_Summer2026_Grade!B23 -> 173014054 | C23: =CSE4098C_Summer2026_Grade!C23 -> Pranto Sarkar | D23: 33 | E23: =ROUND((D23/45)*50,2) -> 36.67 | H23: 18 | N23: 18 | U23: 0 | X23: 15 | Y23: =ROUND((50*AVERAGE(F23:X23))/45,2) -> 14.17 | Z23: =ROUND((E23*60%+Y23*40%),2) -> 27.67
A24: =A23+1 -> 20 | B24: =CSE4098C_Summer2026_Grade!B24 -> 201014068 | C24: =CSE4098C_Summer2026_Grade!C24 -> Shatabdi Mondal Shila | D24: 33 | E24: =ROUND((D24/45)*50,2) -> 36.67 | H24: 18 | N24: 18 | U24: 6 | X24: 15 | Y24: =ROUND((50*AVERAGE(F24:X24))/45,2) -> 15.83 | Z24: =ROUND((E24*60%+Y24*40%),2) -> 28.33
A25: =A24+1 -> 21 | B25: =CSE4098C_Summer2026_Grade!B25 -> 201014030 | C25: =CSE4098C_Summer2026_Grade!C25 -> Md. Asiful Islam | D25: 33 | E25: =ROUND((D25/45)*50,2) -> 36.67 | H25: 18 | N25: 18 | U25: 6 | X25: 15 | Y25: =ROUND((50*AVERAGE(F25:X25))/45,2) -> 15.83 | Z25: =ROUND((E25*60%+Y25*40%),2) -> 28.33
A26: =A25+1 -> 22 | B26: =CSE4098C_Summer2026_Grade!B26 -> 201014050 | C26: =CSE4098C_Summer2026_Grade!C26 -> Dip Kumar Mondal | D26: 33 | E26: =ROUND((D26/45)*50,2) -> 36.67 | Y26: =ROUND((50*AVERAGE(F26:X26))/45,2) -> #DIV/0! | Z26: =ROUND((E26*60%+Y26*40%),2) -> #DIV/0!
A27: =A26+1 -> 23 | B27: =CSE4098C_Summer2026_Grade!B27 -> 223014213 | C27: =CSE4098C_Summer2026_Grade!C27 -> Md. Minhazul Islam | D27: 39 | E27: =ROUND((D27/45)*50,2) -> 43.33 | I27: 30 | K27: 35 | P27: 24 | T27: 15 | Y27: =ROUND((50*AVERAGE(F27:X27))/45,2) -> 28.89 | Z27: =ROUND((E27*60%+Y27*40%),2) -> 37.55
A28: =A27+1 -> 24 | B28: =CSE4098C_Summer2026_Grade!B28 -> 223014078 | C28: =CSE4098C_Summer2026_Grade!C28 -> Shakhar Das Rony | D28: 39 | E28: =ROUND((D28/45)*50,2) -> 43.33 | I28: 30 | K28: 34 | P28: 24 | T28: 15 | Y28: =ROUND((50*AVERAGE(F28:X28))/45,2) -> 28.61 | Z28: =ROUND((E28*60%+Y28*40%),2) -> 37.44
A29: =A28+1 -> 25 | B29: =CSE4098C_Summer2026_Grade!B29 -> 223014212 | C29: =CSE4098C_Summer2026_Grade!C29 -> Md. Tamim Hasan | D29: 39 | E29: =ROUND((D29/45)*50,2) -> 43.33 | I29: 30 | K29: 35 | P29: 24 | T29: 15 | Y29: =ROUND((50*AVERAGE(F29:X29))/45,2) -> 28.89 | Z29: =ROUND((E29*60%+Y29*40%),2) -> 37.55
A30: =A29+1 -> 26 | B30: =CSE4098C_Summer2026_Grade!B30 -> 223014110 | C30: =CSE4098C_Summer2026_Grade!C30 -> Md. Maruf Hossain | D30: 42 | E30: =ROUND((D30/45)*50,2) -> 46.67 | J30: 36 | V30: 36 | W30: 36 | Y30: =ROUND((50*AVERAGE(F30:X30))/45,2) -> 40 | Z30: =ROUND((E30*60%+Y30*40%),2) -> 44
A31: =A30+1 -> 27 | B31: =CSE4098C_Summer2026_Grade!B31 -> 223014135 | C31: =CSE4098C_Summer2026_Grade!C31 -> Rakibul Hasan | D31: 45 | E31: =ROUND((D31/45)*50,2) -> 50 | J31: 36 | V31: 39 | W31: 39 | Y31: =ROUND((50*AVERAGE(F31:X31))/45,2) -> 42.22 | Z31: =ROUND((E31*60%+Y31*40%),2) -> 46.89
A32: =A31+1 -> 28 | B32: =CSE4098C_Summer2026_Grade!B32 -> 223014122 | C32: =CSE4098C_Summer2026_Grade!C32 -> Rabbi Sadnan Khan | D32: 45 | E32: =ROUND((D32/45)*50,2) -> 50 | J32: 38 | V32: 39 | W32: 42 | Y32: =ROUND((50*AVERAGE(F32:X32))/45,2) -> 44.07 | Z32: =ROUND((E32*60%+Y32*40%),2) -> 47.63
A33: =A32+1 -> 29 | B33: =CSE4098C_Summer2026_Grade!B33 -> 212014030 | C33: =CSE4098C_Summer2026_Grade!C33 -> Faria Islam Sara | D33: 45 | E33: =ROUND((D33/45)*50,2) -> 50 | J33: 36 | V33: 36 | W33: 42 | Y33: =ROUND((50*AVERAGE(F33:X33))/45,2) -> 42.22 | Z33: =ROUND((E33*60%+Y33*40%),2) -> 46.89
A34: =A33+1 -> 30 | B34: =CSE4098C_Summer2026_Grade!B34 -> 222014072 | C34: =CSE4098C_Summer2026_Grade!C34 -> Md. Rahat Pervez | D34: 33 | E34: =ROUND((D34/45)*50,2) -> 36.67 | J34: 29 | V34: 30 | W34: 24 | Y34: =ROUND((50*AVERAGE(F34:X34))/45,2) -> 30.74 | Z34: =ROUND((E34*60%+Y34*40%),2) -> 34.3
A35: =A34+1 -> 31 | B35: =CSE4098C_Summer2026_Grade!B35 -> 222014097 | C35: =CSE4098C_Summer2026_Grade!C35 -> Md. Abul Hashem | D35: 33 | E35: =ROUND((D35/45)*50,2) -> 36.67 | J35: 28 | V35: 30 | W35: 24 | Y35: =ROUND((50*AVERAGE(F35:X35))/45,2) -> 30.37 | Z35: =ROUND((E35*60%+Y35*40%),2) -> 34.15
A36: =A35+1 -> 32 | B36: =CSE4098C_Summer2026_Grade!B36 -> 222014040 | C36: =CSE4098C_Summer2026_Grade!C36 -> Md. Fiaz Anam Tasfi | D36: 24 | E36: =ROUND((D36/45)*50,2) -> 26.67 | J36: 28 | V36: 27 | W36: 24 | Y36: =ROUND((50*AVERAGE(F36:X36))/45,2) -> 29.26 | Z36: =ROUND((E36*60%+Y36*40%),2) -> 27.71
A37: =A36+1 -> 33 | B37: =CSE4098C_Summer2026_Grade!B37 -> 222014071 | C37: =CSE4098C_Summer2026_Grade!C37 -> Kasfia Hossain | D37: 24 | E37: =ROUND((D37/45)*50,2) -> 26.67 | J37: 29 | V37: 27 | W37: 24 | Y37: =ROUND((50*AVERAGE(F37:X37))/45,2) -> 29.63 | Z37: =ROUND((E37*60%+Y37*40%),2) -> 27.85
A38: =A37+1 -> 34 | B38: =CSE4098C_Summer2026_Grade!B38 -> 223014195 | C38: =CSE4098C_Summer2026_Grade!C38 -> Md. Rashedul Islam | D38: 27 | E38: =ROUND((D38/45)*50,2) -> 30 | J38: 28 | V38: 30 | W38: 24 | Y38: =ROUND((50*AVERAGE(F38:X38))/45,2) -> 30.37 | Z38: =ROUND((E38*60%+Y38*40%),2) -> 30.15
A39: =A38+1 -> 35 | B39: =CSE4098C_Summer2026_Grade!B39 -> 223014143 | C39: =CSE4098C_Summer2026_Grade!C39 -> Upoma Paul | D39: 30 | E39: =ROUND((D39/45)*50,2) -> 33.33 | H39: 12 | U39: 27 | X39: 15 | Y39: =ROUND((50*AVERAGE(F39:X39))/45,2) -> 20 | Z39: =ROUND((E39*60%+Y39*40%),2) -> 28
A40: =A39+1 -> 36 | B40: =CSE4098C_Summer2026_Grade!B40 -> 231014167 | C40: =CSE4098C_Summer2026_Grade!C40 -> Fariha Ahmed | D40: 36 | E40: =ROUND((D40/45)*50,2) -> 40 | H40: 21 | U40: 36 | X40: 30 | Y40: =ROUND((50*AVERAGE(F40:X40))/45,2) -> 32.22 | Z40: =ROUND((E40*60%+Y40*40%),2) -> 36.89
...

Sheet CO_PO_Attainment_Analysis
AX1: Mapping of COs to POs
C2: Assessment Items | D2: CO1 | E2: CO2 | F2: CO3 | G2: CO4 | H2: CO5 | I2: CO6 | J2: CO7 | K2: CO8 | L2: CO9 | M2: CO10 | AY2: PO1 | AZ2: PO2 | BA2: PO3 | BB2: PO4 | BC2: PO5 | BD2: PO6 | BE2: PO7 | BF2: PO8 | BG2: PO9 | BH2: PO10 | BI2: PO11 | BJ2: PO12
C3: Report | D3: 6 | E3: 3 | F3: 3 | G3: 3 | H3: 6 | I3: 3 | J3: 3 | K3: 3 | AX3: CO1 | AY3: 0 | AZ3: 0 | BA3: 0 | BB3: 0 | BC3: 0 | BD3: 0 | BE3: 0 | BF3: 0 | BG3: 0 | BH3: 0 | BI3: 0 | BJ3: 1
C4: Peer | L4: 5 | AX4: CO2 | AY4: 0 | AZ4: 0 | BA4: 0 | BB4: 0 | BC4: 0 | BD4: 0 | BE4: 0 | BF4: 0 | BG4: 0 | BH4: 0 | BI4: 1 | BJ4: 0
C5: Term Final Presentation | M5: 10 | AX5: CO3 | AY5: 0 | AZ5: 0 | BA5: 0 | BB5: 0 | BC5: 1 | BD5: 0 | BE5: 0 | BF5: 0 | BG5: 0 | BH5: 0 | BI5: 0 | BJ5: 0
C6: Poster | H6: 20 | AX6: CO4 | AY6: 0 | AZ6: 0 | BA6: 1 | BB6: 0 | BC6: 0 | BD6: 0 | BE6: 0 | BF6: 0 | BG6: 0 | BH6: 0 | BI6: 0 | BJ6: 0
C7: Total | D7: =SUM(D3:D6) -> 6 | E7: =SUM(E3:E6) -> 3 | F7: =SUM(F3:F6) -> 3 | G7: =SUM(G3:G6) -> 3 | H7: =SUM(H3:H6) -> 26 | I7: =SUM(I3:I6) -> 3 | J7: =SUM(J3:J6) -> 3 | K7: =SUM(K3:K6) -> 3 | ... M7: =SUM(M3:M6) -> 10 | AX7: CO5 | AY7: 0 | AZ7: 0 | BA7: 0 | BB7: 1 | BC7: 0 | BD7: 0 | BE7: 0 | BF7: 0 | BG7: 0 | BH7: 0 | BI7: 0 | BJ7: 0
AX8: CO6 | AY8: 0 | AZ8: 0 | BA8: 0 | BB8: 0 | BC8: 0 | BD8: 1 | BE8: 0 | BF8: 0 | BG8: 0 | BH8: 0 | BI8: 0 | BJ8: 0
AX9: CO7 | AY9: 0 | AZ9: 0 | BA9: 0 | BB9: 0 | BC9: 0 | BD9: 0 | BE9: 1 | BF9: 0 | BG9: 0 | BH9: 0 | BI9: 0 | BJ9: 0
AX10: CO8 | AY10: 0 | AZ10: 0 | BA10: 0 | BB10: 0 | BC10: 0 | BD10: 0 | BE10: 0 | BF10: 1 | BG10: 0 | BH10: 0 | BI10: 0 | BJ10: 0
AX11: CO9 | AY11: 0 | AZ11: 0 | BA11: 0 | BB11: 0 | BC11: 0 | BD11: 0 | BE11: 0 | BF11: 0 | BG11: 1 | BH11: 0 | BI11: 0 | BJ11: 0
AX12: CO10 | AY12: 0 | AZ12: 0 | BA12: 0 | BB12: 0 | BC12: 0 | BD12: 0 | BE12: 0 | BF12: 0 | BG12: 0 | BH12: 1 | BI12: 0 | BJ12: 0
AX13: Total | AY13: =SUM(AY3:AY12) -> 0 | AZ13: =SUM(AZ3:AZ12) -> 0 | BA13: =SUM(BA3:BA12) -> 1 | BB13: =SUM(BB3:BB12) -> 1 | BC13: =SUM(BC3:BC12) -> 1 | BD13: =SUM(BD3:BD12) -> 1 | BE13: =SUM(BE3:BE12) -> 1 | BF13: =SUM(BF3:BF12) -> 1 | ... BJ13: =SUM(BJ3:BJ12) -> 1
A15: CO Attainment Analysis CSE 4098C [Summer 2026] | S15: CO Attainment Analysis | AX15: PO Attainment Analysis
D16: =C3 -> Report | L16: Peer | N16: Presentation | P16: Poster | S16: Total Marks | AC16: Percentage | AM16: CO Attainment | AX16: Percentage | BJ16: PO Attainment
D17: CO1 | E17: CO2 | F17: CO3 | G17: CO4 | H17: CO5 | I17: CO6 | J17: CO7 | K17: CO8 | L17: CO9 | M17: CO10 | N17: CO10 | O17: CO11 | P17: CO4 | Q17: CO5 | R17: CO6 | S17: CO1 | T17: CO2 | U17: CO3 | V17: CO4 | W17: CO5 | X17: CO6 | Y17: CO7 | Z17: CO8 | AA17: CO9 | AB17: CO10 | AC17: CO1 | AD17: CO2 | AE17: CO3 | AF17: CO4 | AG17: CO5 | AH17: CO6 | AI17: CO7 | AJ17: CO8 | AK17: CO9 | AL17: CO10 | AM17: CO1 | AN17: CO2 | AO17: CO3 | AP17: CO4 | AQ17: CO5 | AR17: CO6 | AS17: CO7 | AT17: CO8 | AU17: CO9 | AV17: CO10 | AX17: PO1 | AY17: PO2 | AZ17: PO3 | BA17: PO4 | BB17: PO5 | BC17: PO6 | BD17: PO7 | BE17: PO8 | BF17: PO9 | BG17: PO10 | BH17: PO11 | BI17: PO12 | BJ17: PO1 | BK17: PO2 | BL17: PO3 | BM17: PO4 | BN17: PO5 | BO17: PO6 | BP17: PO7 | BQ17: PO8 | BR17: PO9 | BS17: PO10 | BT17: PO11 | BU17: PO12
A18: S/N | B18: Student ID | C18: Name | D18: =D3 -> 6 | E18: =E3 -> 3 | F18: =F3 -> 3 | G18: =G3 -> 3 | H18: =H3 -> 6 | I18: =I3 -> 3 | J18: =J3 -> 3 | K18: =K3 -> 3 | L18: =L4 -> 5 | M18: =H4 -> 0 | N18: =M5 -> 10 | O18: =I5 -> 0 | P18: =G6 -> 0 | Q18: =H6 -> 20 | R18: =I6 -> 0 | S18: =D18 -> 6 | T18: =E7 -> 3 | U18: =F7 -> 3 | V18: =G7 -> 3 | W18: =H7 -> 26 | X18: =I7 -> 3 | Y18: =J7 -> 3 | Z18: =K7 -> 3 | AA18: =L7 -> 5 | AB18: =M7 -> 10 | AC18: 1 | AD18: 1 | AE18: 1 | AF18: 1 | AG18: 1 | AH18: 1 | AI18: 1 | AJ18: 1 | AK18: 1 | AL18: 1 | AM18: If CO achieved (≥55%) then 1, else 0 | AX18: 1 | AY18: 1 | AZ18: 1 | BA18: 1 | BB18: 1 | BC18: 1 | BD18: 1 | BE18: 1 | BF18: 1 | BG18: 1 | BH18: 1 | BI18: 1 | BJ18: If PO achieved (≥55%) then 1, else 0
A19: 1 | B19: 201014036 | C19: Ahadul Islam Rahul | D19: =CO_Report_Evaluation!AG4 -> 0 | E19: =CO_Report_Evaluation!AH4 -> 0 | F19: =CO_Report_Evaluation!AI4 -> 0 | G19: =CO_Report_Evaluation!AJ4 -> 0 | H19: =CO_Report_Evaluation!AK4 -> 0 | I19: =CO_Report_Evaluation!AL4 -> 0 | J19: =CO_Report_Evaluation!AM4 -> 0 | K19: =CO_Report_Evaluation!AN4 -> 0 | L19: =CSE4098C_Summer2026_Grade!G5 -> 0 | N19: =((CSE4098C_Summer2026_Grade!E5)*10)/25 -> 1.6 | Q19: 16.11 | S19: =D19 -> 0 | T19: =E19 -> 0 | U19: =F19 -> 0 | V19: =SUM(G19,P19) -> 0 | W19: =SUM(H19,Q19) -> 16.11 | X19: =SUM(I19,R19) -> 0 | Y19: =J19 -> 0 | Z19: =K19 -> 0 | AA19: =L19 -> 0 | AB19: =SUM(M19,N19) -> 1.6 | AC19: =IF(S19 = 0, 0, S19/S$18) -> 0 | AD19: =IF(T19 = 0, 0, T19/T$18) -> 0 | AE19: =IF(U19 = 0, 0, U19/U$18) -> 0 | AF19: =IF(V19 = 0, 0, V19/V$18) -> 0 | AG19: =IF(W19 = 0, 0, W19/W$18) -> 0.61961538 | AH19: =IF(X19 = 0, 0, X19/X$18) -> 0 | AI19: =IF(Y19 = 0, 0, Y19/Y$18) -> 0 | AJ19: =IF(Z19 = 0, 0, Z19/Z$18) -> 0 | ... AL19: =IF(AB19 = 0, 0, AB19/AB$18) -> 0.16 | AM19: =IF(OR(CSE4098C_Summer2026_Grade!$J5="W (Withdrawn)", CSE4098C_Summer2026_Grade!$J5="I (Incomplete)"), 0, IF(AC19>=55%, 1, 0)) -> #DIV/0! | AN19: =IF(OR(CSE4098C_Summer2026_Grade!$J5="W (Withdrawn)", CSE4098C_Summer2026_Grade!$J5="I (Incomplete)"), 0, IF(AD19>=55%, 1, 0)) -> #DIV/0! | AO19: =IF(OR(CSE4098C_Summer2026_Grade!$J5="W (Withdrawn)", CSE4098C_Summer2026_Grade!$J5="I (Incomplete)"), 0, IF(AE19>=55%, 1, 0)) -> #DIV/0! | AP19: =IF(OR(CSE4098C_Summer2026_Grade!$J5="W (Withdrawn)", CSE4098C_Summer2026_Grade!$J5="I (Incomplete)"), 0, IF(AF19>=55%, 1, 0)) -> #DIV/0! | AQ19: =IF(OR(CSE4098C_Summer2026_Grade!$J5="W (Withdrawn)", CSE4098C_Summer2026_Grade!$J5="I (Incomplete)"), 0, IF(AG19>=55%, 1, 0)) -> #DIV/0! | AR19: =IF(OR(CSE4098C_Summer2026_Grade!$J5="W (Withdrawn)", CSE4098C_Summer2026_Grade!$J5="I (Incomplete)"), 0, IF(AH19>=55%, 1, 0)) -> #DIV/0! | AS19: =IF(OR(CSE4098C_Summer2026_Grade!$J5="W (Withdrawn)", CSE4098C_Summer2026_Grade!$J5="I (Incomplete)"), 0, IF(AI19>=55%, 1, 0)) -> #DIV/0! | AT19: =IF(OR(CSE4098C_Summer2026_Grade!$J5="W (Withdrawn)", CSE4098C_Summer2026_Grade!$J5="I (Incomplete)"), 0, IF(AJ19>=55%, 1, 0)) -> #DIV/0! | ... AV19: =IF(OR(CSE4098C_Summer2026_Grade!$J5="W (Withdrawn)", CSE4098C_Summer2026_Grade!$J5="I (Incomplete)"), 0, IF(AL19>=55%, 1, 0)) -> #DIV/0! | AX19: {=IF($AY$13=0,0,MMULT($AC19:$AL19, AY$3:AY$12)/$AY$13)} -> 0 | AY19: {=IF($AZ$13=0,0,MMULT($AC19:$AL19, AZ$3:AZ$12)/$AZ$13)} -> 0 | AZ19: {=IF($BA$13=0,0,MMULT($AC19:$AL19, BA$3:BA$12)/$BA$13)} -> 0 | BA19: {=IF($BB$13=0,0,MMULT($AC19:$AL19, BB$3:BB$12)/$BB$13)} -> 0.61961538 | BB19: {=IF($BC$13=0,0,MMULT($AC19:$AL19, BC$3:BC$12)/$BC$13)} -> 0 | BC19: {=IF($BD$13=0,0,MMULT($AC19:$AL19, BD$3:BD$12)/$BD$13)} -> 0 | BD19: {=IF($BE$13=0,0,MMULT($AC19:$AL19, BE$3:BE$12)/$BE$13)} -> 0 | BE19: {=IF($BF$13=0,0,MMULT($AC19:$AL19, BF$3:BF$12)/$BF$13)} -> 0 | BF19: {=IF($BG$13=0,0,MMULT($AC19:$AL19, BG$3:BG$12)/$BG$13)} -> 0 | BG19: {=IF($BH$13=0,0,MMULT($AC19:$AL19, BH$3:BH$12)/$BH$13)} -> 0.16 | BH19: {=IF($BI$13=0,0,MMULT($AC19:$AL19, BI$3:BI$12)/$BI$13)} -> 0 | BI19: {=IF($BJ$13=0,0,MMULT($AC19:$AL19, BJ$3:BJ$12)/$BJ$13)} -> 0 | BJ19: =IF(OR(CSE4098C_Summer2026_Grade!$J5="W (Withdrawn)", CSE4098C_Summer2026_Grade!$J5="I (Incomplete)"), 0, IF(AX19>=55%, 1, 0)) -> #DIV/0! | BK19: =IF(OR(CSE4098C_Summer2026_Grade!$J5="W (Withdrawn)", CSE4098C_Summer2026_Grade!$J5="I (Incomplete)"), 0, IF(AY19>=55%, 1, 0)) -> #DIV/0! | BL19: =IF(OR(CSE4098C_Summer2026_Grade!$J5="W (Withdrawn)", CSE4098C_Summer2026_Grade!$J5="I (Incomplete)"), 0, IF(AZ19>=55%, 1, 0)) -> #DIV/0! | BM19: =IF(OR(CSE4098C_Summer2026_Grade!$J5="W (Withdrawn)", CSE4098C_Summer2026_Grade!$J5="I (Incomplete)"), 0, IF(BA19>=55%, 1, 0)) -> #DIV/0! | BN19: =IF(OR(CSE4098C_Summer2026_Grade!$J5="W (Withdrawn)", CSE4098C_Summer2026_Grade!$J5="I (Incomplete)"), 0, IF(BB19>=55%, 1, 0)) -> #DIV/0! | BO19: =IF(OR(CSE4098C_Summer2026_Grade!$J5="W (Withdrawn)", CSE4098C_Summer2026_Grade!$J5="I (Incomplete)"), 0, IF(BC19>=55%, 1, 0)) -> #DIV/0! | BP19: =IF(OR(CSE4098C_Summer2026_Grade!$J5="W (Withdrawn)", CSE4098C_Summer2026_Grade!$J5="I (Incomplete)"), 0, IF(BD19>=55%, 1, 0)) -> #DIV/0! | BQ19: =IF(OR(CSE4098C_Summer2026_Grade!$J5="W (Withdrawn)", CSE4098C_Summer2026_Grade!$J5="I (Incomplete)"), 0, IF(BE19>=55%, 1, 0)) -> #DIV/0! | ... BU19: =IF(OR(CSE4098C_Summer2026_Grade!$J5="W (Withdrawn)", CSE4098C_Summer2026_Grade!$J5="I (Incomplete)"), 0, IF(BI19>=55%, 1, 0)) -> #DIV/0!
A20: =A19+1 -> 2 | B20: 201014080 | C20: Md. Sojib Al Hasan | D20: =CO_Report_Evaluation!AG5 -> 0 | E20: =CO_Report_Evaluation!AH5 -> 0 | F20: =CO_Report_Evaluation!AI5 -> 0 | G20: =CO_Report_Evaluation!AJ5 -> 0 | H20: =CO_Report_Evaluation!AK5 -> 0 | I20: =CO_Report_Evaluation!AL5 -> 0 | J20: =CO_Report_Evaluation!AM5 -> 0 | K20: =CO_Report_Evaluation!AN5 -> 0 | L20: =CSE4098C_Summer2026_Grade!G6 -> 0 | N20: =((CSE4098C_Summer2026_Grade!E6)*10)/25 -> 1.6 | Q20: 16.11 | S20: =D20 -> 0 | T20: =E20 -> 0 | U20: =F20 -> 0 | V20: =SUM(G20,P20) -> 0 | W20: =SUM(H20,Q20) -> 16.11 | X20: =SUM(I20,R20) -> 0 | Y20: =J20 -> 0 | Z20: =K20 -> 0 | AA20: =L20 -> 0 | AB20: =SUM(M20,N20) -> 1.6 | AC20: =IF(S20 = 0, 0, S20/S$18) -> 0 | AD20: =IF(T20 = 0, 0, T20/T$18) -> 0 | AE20: =IF(U20 = 0, 0, U20/U$18) -> 0 | AF20: =IF(V20 = 0, 0, V20/V$18) -> 0 | AG20: =IF(W20 = 0, 0, W20/W$18) -> 0.61961538 | AH20: =IF(X20 = 0, 0, X20/X$18) -> 0 | AI20: =IF(Y20 = 0, 0, Y20/Y$18) -> 0 | AJ20: =IF(Z20 = 0, 0, Z20/Z$18) -> 0 | ... AL20: =IF(AB20 = 0, 0, AB20/AB$18) -> 0.16 | AM20: =IF(OR(CSE4098C_Summer2026_Grade!$J6="W (Withdrawn)", CSE4098C_Summer2026_Grade!$J6="I (Incomplete)"), 0, IF(AC20>=55%, 1, 0)) -> #DIV/0! | AN20: =IF(OR(CSE4098C_Summer2026_Grade!$J6="W (Withdrawn)", CSE4098C_Summer2026_Grade!$J6="I (Incomplete)"), 0, IF(AD20>=55%, 1, 0)) -> #DIV/0! | AO20: =IF(OR(CSE4098C_Summer2026_Grade!$J6="W (Withdrawn)", CSE4098C_Summer2026_Grade!$J6="I (Incomplete)"), 0, IF(AE20>=55%, 1, 0)) -> #DIV/0! | AP20: =IF(OR(CSE4098C_Summer2026_Grade!$J6="W (Withdrawn)", CSE4098C_Summer2026_Grade!$J6="I (Incomplete)"), 0, IF(AF20>=55%, 1, 0)) -> #DIV/0! | AQ20: =IF(OR(CSE4098C_Summer2026_Grade!$J6="W (Withdrawn)", CSE4098C_Summer2026_Grade!$J6="I (Incomplete)"), 0, IF(AG20>=55%, 1, 0)) -> #DIV/0! | AR20: =IF(OR(CSE4098C_Summer2026_Grade!$J6="W (Withdrawn)", CSE4098C_Summer2026_Grade!$J6="I (Incomplete)"), 0, IF(AH20>=55%, 1, 0)) -> #DIV/0! | AS20: =IF(OR(CSE4098C_Summer2026_Grade!$J6="W (Withdrawn)", CSE4098C_Summer2026_Grade!$J6="I (Incomplete)"), 0, IF(AI20>=55%, 1, 0)) -> #DIV/0! | AT20: =IF(OR(CSE4098C_Summer2026_Grade!$J6="W (Withdrawn)", CSE4098C_Summer2026_Grade!$J6="I (Incomplete)"), 0, IF(AJ20>=55%, 1, 0)) -> #DIV/0! | ... AV20: =IF(OR(CSE4098C_Summer2026_Grade!$J6="W (Withdrawn)", CSE4098C_Summer2026_Grade!$J6="I (Incomplete)"), 0, IF(AL20>=55%, 1, 0)) -> #DIV/0! | AX20: {=IF($AY$13=0,0,MMULT($AC20:$AL20, AY$3:AY$12)/$AY$13)} -> 0 | AY20: {=IF($AZ$13=0,0,MMULT($AC20:$AL20, AZ$3:AZ$12)/$AZ$13)} -> 0 | AZ20: {=IF($BA$13=0,0,MMULT($AC20:$AL20, BA$3:BA$12)/$BA$13)} -> 0 | BA20: {=IF($BB$13=0,0,MMULT($AC20:$AL20, BB$3:BB$12)/$BB$13)} -> 0.61961538 | BB20: {=IF($BC$13=0,0,MMULT($AC20:$AL20, BC$3:BC$12)/$BC$13)} -> 0 | BC20: {=IF($BD$13=0,0,MMULT($AC20:$AL20, BD$3:BD$12)/$BD$13)} -> 0 | BD20: {=IF($BE$13=0,0,MMULT($AC20:$AL20, BE$3:BE$12)/$BE$13)} -> 0 | BE20: {=IF($BF$13=0,0,MMULT($AC20:$AL20, BF$3:BF$12)/$BF$13)} -> 0 | BF20: {=IF($BG$13=0,0,MMULT($AC20:$AL20, BG$3:BG$12)/$BG$13)} -> 0 | BG20: {=IF($BH$13=0,0,MMULT($AC20:$AL20, BH$3:BH$12)/$BH$13)} -> 0.16 | BH20: {=IF($BI$13=0,0,MMULT($AC20:$AL20, BI$3:BI$12)/$BI$13)} -> 0 | BI20: {=IF($BJ$13=0,0,MMULT($AC20:$AL20, BJ$3:BJ$12)/$BJ$13)} -> 0 | BJ20: =IF(OR(CSE4098C_Summer2026_Grade!$J6="W (Withdrawn)", CSE4098C_Summer2026_Grade!$J6="I (Incomplete)"), 0, IF(AX20>=55%, 1, 0)) -> #DIV/0! | BK20: =IF(OR(CSE4098C_Summer2026_Grade!$J6="W (Withdrawn)", CSE4098C_Summer2026_Grade!$J6="I (Incomplete)"), 0, IF(AY20>=55%, 1, 0)) -> #DIV/0! | BL20: =IF(OR(CSE4098C_Summer2026_Grade!$J6="W (Withdrawn)", CSE4098C_Summer2026_Grade!$J6="I (Incomplete)"), 0, IF(AZ20>=55%, 1, 0)) -> #DIV/0! | BM20: =IF(OR(CSE4098C_Summer2026_Grade!$J6="W (Withdrawn)", CSE4098C_Summer2026_Grade!$J6="I (Incomplete)"), 0, IF(BA20>=55%, 1, 0)) -> #DIV/0! | BN20: =IF(OR(CSE4098C_Summer2026_Grade!$J6="W (Withdrawn)", CSE4098C_Summer2026_Grade!$J6="I (Incomplete)"), 0, IF(BB20>=55%, 1, 0)) -> #DIV/0! | BO20: =IF(OR(CSE4098C_Summer2026_Grade!$J6="W (Withdrawn)", CSE4098C_Summer2026_Grade!$J6="I (Incomplete)"), 0, IF(BC20>=55%, 1, 0)) -> #DIV/0! | BP20: =IF(OR(CSE4098C_Summer2026_Grade!$J6="W (Withdrawn)", CSE4098C_Summer2026_Grade!$J6="I (Incomplete)"), 0, IF(BD20>=55%, 1, 0)) -> #DIV/0! | BQ20: =IF(OR(CSE4098C_Summer2026_Grade!$J6="W (Withdrawn)", CSE4098C_Summer2026_Grade!$J6="I (Incomplete)"), 0, IF(BE20>=55%, 1, 0)) -> #DIV/0! | ... BU20: =IF(OR(CSE4098C_Summer2026_Grade!$J6="W (Withdrawn)", CSE4098C_Summer2026_Grade!$J6="I (Incomplete)"), 0, IF(BI20>=55%, 1, 0)) -> #DIV/0!
A21: =A20+1 -> 3 | B21: 201014035 | C21: Nadia Akter Jui | D21: =CO_Report_Evaluation!AG6 -> 0 | E21: =CO_Report_Evaluation!AH6 -> 0 | F21: =CO_Report_Evaluation!AI6 -> 0 | G21: =CO_Report_Evaluation!AJ6 -> 0 | H21: =CO_Report_Evaluation!AK6 -> 0 | I21: =CO_Report_Evaluation!AL6 -> 0 | J21: =CO_Report_Evaluation!AM6 -> 0 | K21: =CO_Report_Evaluation!AN6 -> 0 | L21: =CSE4098C_Summer2026_Grade!G7 -> 0 | N21: =((CSE4098C_Summer2026_Grade!E7)*10)/25 -> 1.468 | Q21: 16.11 | S21: =D21 -> 0 | T21: =E21 -> 0 | U21: =F21 -> 0 | V21: =SUM(G21,P21) -> 0 | W21: =SUM(H21,Q21) -> 16.11 | X21: =SUM(I21,R21) -> 0 | Y21: =J21 -> 0 | Z21: =K21 -> 0 | AA21: =L21 -> 0 | AB21: =SUM(M21,N21) -> 1.468 | AC21: =IF(S21 = 0, 0, S21/S$18) -> 0 | AD21: =IF(T21 = 0, 0, T21/T$18) -> 0 | AE21: =IF(U21 = 0, 0, U21/U$18) -> 0 | AF21: =IF(V21 = 0, 0, V21/V$18) -> 0 | AG21: =IF(W21 = 0, 0, W21/W$18) -> 0.61961538 | AH21: =IF(X21 = 0, 0, X21/X$18) -> 0 | AI21: =IF(Y21 = 0, 0, Y21/Y$18) -> 0 | AJ21: =IF(Z21 = 0, 0, Z21/Z$18) -> 0 | ... AL21: =IF(AB21 = 0, 0, AB21/AB$18) -> 0.1468 | AM21: =IF(OR(CSE4098C_Summer2026_Grade!$J7="W (Withdrawn)", CSE4098C_Summer2026_Grade!$J7="I (Incomplete)"), 0, IF(AC21>=55%, 1, 0)) -> #DIV/0! | AN21: =IF(OR(CSE4098C_Summer2026_Grade!$J7="W (Withdrawn)", CSE4098C_Summer2026_Grade!$J7="I (Incomplete)"), 0, IF(AD21>=55%, 1, 0)) -> #DIV/0! | AO21: =IF(OR(CSE4098C_Summer2026_Grade!$J7="W (Withdrawn)", CSE4098C_Summer2026_Grade!$J7="I (Incomplete)"), 0, IF(AE21>=55%, 1, 0)) -> #DIV/0! | AP21: =IF(OR(CSE4098C_Summer2026_Grade!$J7="W (Withdrawn)", CSE4098C_Summer2026_Grade!$J7="I (Incomplete)"), 0, IF(AF21>=55%, 1, 0)) -> #DIV/0! | AQ21: =IF(OR(CSE4098C_Summer2026_Grade!$J7="W (Withdrawn)", CSE4098C_Summer2026_Grade!$J7="I (Incomplete)"), 0, IF(AG21>=55%, 1, 0)) -> #DIV/0! | AR21: =IF(OR(CSE4098C_Summer2026_Grade!$J7="W (Withdrawn)", CSE4098C_Summer2026_Grade!$J7="I (Incomplete)"), 0, IF(AH21>=55%, 1, 0)) -> #DIV/0! | AS21: =IF(OR(CSE4098C_Summer2026_Grade!$J7="W (Withdrawn)", CSE4098C_Summer2026_Grade!$J7="I (Incomplete)"), 0, IF(AI21>=55%, 1, 0)) -> #DIV/0! | AT21: =IF(OR(CSE4098C_Summer2026_Grade!$J7="W (Withdrawn)", CSE4098C_Summer2026_Grade!$J7="I (Incomplete)"), 0, IF(AJ21>=55%, 1, 0)) -> #DIV/0! | ... AV21: =IF(OR(CSE4098C_Summer2026_Grade!$J7="W (Withdrawn)", CSE4098C_Summer2026_Grade!$J7="I (Incomplete)"), 0, IF(AL21>=55%, 1, 0)) -> #DIV/0! | AX21: {=IF($AY$13=0,0,MMULT($AC21:$AL21, AY$3:AY$12)/$AY$13)} -> 0 | AY21: {=IF($AZ$13=0,0,MMULT($AC21:$AL21, AZ$3:AZ$12)/$AZ$13)} -> 0 | AZ21: {=IF($BA$13=0,0,MMULT($AC21:$AL21, BA$3:BA$12)/$BA$13)} -> 0 | BA21: {=IF($BB$13=0,0,MMULT($AC21:$AL21, BB$3:BB$12)/$BB$13)} -> 0.61961538 | BB21: {=IF($BC$13=0,0,MMULT($AC21:$AL21, BC$3:BC$12)/$BC$13)} -> 0 | BC21: {=IF($BD$13=0,0,MMULT($AC21:$AL21, BD$3:BD$12)/$BD$13)} -> 0 | BD21: {=IF($BE$13=0,0,MMULT($AC21:$AL21, BE$3:BE$12)/$BE$13)} -> 0 | BE21: {=IF($BF$13=0,0,MMULT($AC21:$AL21, BF$3:BF$12)/$BF$13)} -> 0 | BF21: {=IF($BG$13=0,0,MMULT($AC21:$AL21, BG$3:BG$12)/$BG$13)} -> 0 | BG21: {=IF($BH$13=0,0,MMULT($AC21:$AL21, BH$3:BH$12)/$BH$13)} -> 0.1468 | BH21: {=IF($BI$13=0,0,MMULT($AC21:$AL21, BI$3:BI$12)/$BI$13)} -> 0 | BI21: {=IF($BJ$13=0,0,MMULT($AC21:$AL21, BJ$3:BJ$12)/$BJ$13)} -> 0 | BJ21: =IF(OR(CSE4098C_Summer2026_Grade!$J7="W (Withdrawn)", CSE4098C_Summer2026_Grade!$J7="I (Incomplete)"), 0, IF(AX21>=55%, 1, 0)) -> #DIV/0! | BK21: =IF(OR(CSE4098C_Summer2026_Grade!$J7="W (Withdrawn)", CSE4098C_Summer2026_Grade!$J7="I (Incomplete)"), 0, IF(AY21>=55%, 1, 0)) -> #DIV/0! | BL21: =IF(OR(CSE4098C_Summer2026_Grade!$J7="W (Withdrawn)", CSE4098C_Summer2026_Grade!$J7="I (Incomplete)"), 0, IF(AZ21>=55%, 1, 0)) -> #DIV/0! | BM21: =IF(OR(CSE4098C_Summer2026_Grade!$J7="W (Withdrawn)", CSE4098C_Summer2026_Grade!$J7="I (Incomplete)"), 0, IF(BA21>=55%, 1, 0)) -> #DIV/0! | BN21: =IF(OR(CSE4098C_Summer2026_Grade!$J7="W (Withdrawn)", CSE4098C_Summer2026_Grade!$J7="I (Incomplete)"), 0, IF(BB21>=55%, 1, 0)) -> #DIV/0! | BO21: =IF(OR(CSE4098C_Summer2026_Grade!$J7="W (Withdrawn)", CSE4098C_Summer2026_Grade!$J7="I (Incomplete)"), 0, IF(BC21>=55%, 1, 0)) -> #DIV/0! | BP21: =IF(OR(CSE4098C_Summer2026_Grade!$J7="W (Withdrawn)", CSE4098C_Summer2026_Grade!$J7="I (Incomplete)"), 0, IF(BD21>=55%, 1, 0)) -> #DIV/0! | BQ21: =IF(OR(CSE4098C_Summer2026_Grade!$J7="W (Withdrawn)", CSE4098C_Summer2026_Grade!$J7="I (Incomplete)"), 0, IF(BE21>=55%, 1, 0)) -> #DIV/0! | ... BU21: =IF(OR(CSE4098C_Summer2026_Grade!$J7="W (Withdrawn)", CSE4098C_Summer2026_Grade!$J7="I (Incomplete)"), 0, IF(BI21>=55%, 1, 0)) -> #DIV/0!
A22: =A21+1 -> 4 | B22: 223014152 | C22: Md. Minhazul Islam | D22: =CO_Report_Evaluation!AG7 -> 0 | E22: =CO_Report_Evaluation!AH7 -> 0 | F22: =CO_Report_Evaluation!AI7 -> 0 | G22: =CO_Report_Evaluation!AJ7 -> 0 | H22: =CO_Report_Evaluation!AK7 -> 0 | I22: =CO_Report_Evaluation!AL7 -> 0 | J22: =CO_Report_Evaluation!AM7 -> 0 | K22: =CO_Report_Evaluation!AN7 -> 0 | L22: =CSE4098C_Summer2026_Grade!G8 -> 0 | N22: =((CSE4098C_Summer2026_Grade!E8)*10)/25 -> 1.6 | Q22: 16.11 | S22: =D22 -> 0 | T22: =E22 -> 0 | U22: =F22 -> 0 | V22: =SUM(G22,P22) -> 0 | W22: =SUM(H22,Q22) -> 16.11 | X22: =SUM(I22,R22) -> 0 | Y22: =J22 -> 0 | Z22: =K22 -> 0 | AA22: =L22 -> 0 | AB22: =SUM(M22,N22) -> 1.6 | AC22: =IF(S22 = 0, 0, S22/S$18) -> 0 | AD22: =IF(T22 = 0, 0, T22/T$18) -> 0 | AE22: =IF(U22 = 0, 0, U22/U$18) -> 0 | AF22: =IF(V22 = 0, 0, V22/V$18) -> 0 | AG22: =IF(W22 = 0, 0, W22/W$18) -> 0.61961538 | AH22: =IF(X22 = 0, 0, X22/X$18) -> 0 | AI22: =IF(Y22 = 0, 0, Y22/Y$18) -> 0 | AJ22: =IF(Z22 = 0, 0, Z22/Z$18) -> 0 | ... AL22: =IF(AB22 = 0, 0, AB22/AB$18) -> 0.16 | AM22: =IF(OR(CSE4098C_Summer2026_Grade!$J8="W (Withdrawn)", CSE4098C_Summer2026_Grade!$J8="I (Incomplete)"), 0, IF(AC22>=55%, 1, 0)) -> #DIV/0! | AN22: =IF(OR(CSE4098C_Summer2026_Grade!$J8="W (Withdrawn)", CSE4098C_Summer2026_Grade!$J8="I (Incomplete)"), 0, IF(AD22>=55%, 1, 0)) -> #DIV/0! | AO22: =IF(OR(CSE4098C_Summer2026_Grade!$J8="W (Withdrawn)", CSE4098C_Summer2026_Grade!$J8="I (Incomplete)"), 0, IF(AE22>=55%, 1, 0)) -> #DIV/0! | AP22: =IF(OR(CSE4098C_Summer2026_Grade!$J8="W (Withdrawn)", CSE4098C_Summer2026_Grade!$J8="I (Incomplete)"), 0, IF(AF22>=55%, 1, 0)) -> #DIV/0! | AQ22: =IF(OR(CSE4098C_Summer2026_Grade!$J8="W (Withdrawn)", CSE4098C_Summer2026_Grade!$J8="I (Incomplete)"), 0, IF(AG22>=55%, 1, 0)) -> #DIV/0! | AR22: =IF(OR(CSE4098C_Summer2026_Grade!$J8="W (Withdrawn)", CSE4098C_Summer2026_Grade!$J8="I (Incomplete)"), 0, IF(AH22>=55%, 1, 0)) -> #DIV/0! | AS22: =IF(OR(CSE4098C_Summer2026_Grade!$J8="W (Withdrawn)", CSE4098C_Summer2026_Grade!$J8="I (Incomplete)"), 0, IF(AI22>=55%, 1, 0)) -> #DIV/0! | AT22: =IF(OR(CSE4098C_Summer2026_Grade!$J8="W (Withdrawn)", CSE4098C_Summer2026_Grade!$J8="I (Incomplete)"), 0, IF(AJ22>=55%, 1, 0)) -> #DIV/0! | ... AV22: =IF(OR(CSE4098C_Summer2026_Grade!$J8="W (Withdrawn)", CSE4098C_Summer2026_Grade!$J8="I (Incomplete)"), 0, IF(AL22>=55%, 1, 0)) -> #DIV/0! | AX22: {=IF($AY$13=0,0,MMULT($AC22:$AL22, AY$3:AY$12)/$AY$13)} -> 0 | AY22: {=IF($AZ$13=0,0,MMULT($AC22:$AL22, AZ$3:AZ$12)/$AZ$13)} -> 0 | AZ22: {=IF($BA$13=0,0,MMULT($AC22:$AL22, BA$3:BA$12)/$BA$13)} -> 0 | BA22: {=IF($BB$13=0,0,MMULT($AC22:$AL22, BB$3:BB$12)/$BB$13)} -> 0.61961538 | BB22: {=IF($BC$13=0,0,MMULT($AC22:$AL22, BC$3:BC$12)/$BC$13)} -> 0 | BC22: {=IF($BD$13=0,0,MMULT($AC22:$AL22, BD$3:BD$12)/$BD$13)} -> 0 | BD22: {=IF($BE$13=0,0,MMULT($AC22:$AL22, BE$3:BE$12)/$BE$13)} -> 0 | BE22: {=IF($BF$13=0,0,MMULT($AC22:$AL22, BF$3:BF$12)/$BF$13)} -> 0 | BF22: {=IF($BG$13=0,0,MMULT($AC22:$AL22, BG$3:BG$12)/$BG$13)} -> 0 | BG22: {=IF($BH$13=0,0,MMULT($AC22:$AL22, BH$3:BH$12)/$BH$13)} -> 0.16 | BH22: {=IF($BI$13=0,0,MMULT($AC22:$AL22, BI$3:BI$12)/$BI$13)} -> 0 | BI22: {=IF($BJ$13=0,0,MMULT($AC22:$AL22, BJ$3:BJ$12)/$BJ$13)} -> 0 | BJ22: =IF(OR(CSE4098C_Summer2026_Grade!$J8="W (Withdrawn)", CSE4098C_Summer2026_Grade!$J8="I (Incomplete)"), 0, IF(AX22>=55%, 1, 0)) -> #DIV/0! | BK22: =IF(OR(CSE4098C_Summer2026_Grade!$J8="W (Withdrawn)", CSE4098C_Summer2026_Grade!$J8="I (Incomplete)"), 0, IF(AY22>=55%, 1, 0)) -> #DIV/0! | BL22: =IF(OR(CSE4098C_Summer2026_Grade!$J8="W (Withdrawn)", CSE4098C_Summer2026_Grade!$J8="I (Incomplete)"), 0, IF(AZ22>=55%, 1, 0)) -> #DIV/0! | BM22: =IF(OR(CSE4098C_Summer2026_Grade!$J8="W (Withdrawn)", CSE4098C_Summer2026_Grade!$J8="I (Incomplete)"), 0, IF(BA22>=55%, 1, 0)) -> #DIV/0! | BN22: =IF(OR(CSE4098C_Summer2026_Grade!$J8="W (Withdrawn)", CSE4098C_Summer2026_Grade!$J8="I (Incomplete)"), 0, IF(BB22>=55%, 1, 0)) -> #DIV/0! | BO22: =IF(OR(CSE4098C_Summer2026_Grade!$J8="W (Withdrawn)", CSE4098C_Summer2026_Grade!$J8="I (Incomplete)"), 0, IF(BC22>=55%, 1, 0)) -> #DIV/0! | BP22: =IF(OR(CSE4098C_Summer2026_Grade!$J8="W (Withdrawn)", CSE4098C_Summer2026_Grade!$J8="I (Incomplete)"), 0, IF(BD22>=55%, 1, 0)) -> #DIV/0! | BQ22: =IF(OR(CSE4098C_Summer2026_Grade!$J8="W (Withdrawn)", CSE4098C_Summer2026_Grade!$J8="I (Incomplete)"), 0, IF(BE22>=55%, 1, 0)) -> #DIV/0! | ... BU22: =IF(OR(CSE4098C_Summer2026_Grade!$J8="W (Withdrawn)", CSE4098C_Summer2026_Grade!$J8="I (Incomplete)"), 0, IF(BI22>=55%, 1, 0)) -> #DIV/0!
A23: =A22+1 -> 5 | B23: 223014049 | C23: Md. Shams Arefin | D23: =CO_Report_Evaluation!AG8 -> 0 | E23: =CO_Report_Evaluation!AH8 -> 0 | F23: =CO_Report_Evaluation!AI8 -> 0 | G23: =CO_Report_Evaluation!AJ8 -> 0 | H23: =CO_Report_Evaluation!AK8 -> 0 | I23: =CO_Report_Evaluation!AL8 -> 0 | J23: =CO_Report_Evaluation!AM8 -> 0 | K23: =CO_Report_Evaluation!AN8 -> 0 | L23: =CSE4098C_Summer2026_Grade!G9 -> 0 | N23: =((CSE4098C_Summer2026_Grade!E9)*10)/25 -> 1.736 | Q23: 16.11 | S23: =D23 -> 0 | T23: =E23 -> 0 | U23: =F23 -> 0 | V23: =SUM(G23,P23) -> 0 | W23: =SUM(H23,Q23) -> 16.11 | X23: =SUM(I23,R23) -> 0 | Y23: =J23 -> 0 | Z23: =K23 -> 0 | AA23: =L23 -> 0 | AB23: =SUM(M23,N23) -> 1.736 | AC23: =IF(S23 = 0, 0, S23/S$18) -> 0 | AD23: =IF(T23 = 0, 0, T23/T$18) -> 0 | AE23: =IF(U23 = 0, 0, U23/U$18) -> 0 | AF23: =IF(V23 = 0, 0, V23/V$18) -> 0 | AG23: =IF(W23 = 0, 0, W23/W$18) -> 0.61961538 | AH23: =IF(X23 = 0, 0, X23/X$18) -> 0 | AI23: =IF(Y23 = 0, 0, Y23/Y$18) -> 0 | AJ23: =IF(Z23 = 0, 0, Z23/Z$18) -> 0 | ... AL23: =IF(AB23 = 0, 0, AB23/AB$18) -> 0.1736 | AM23: =IF(OR(CSE4098C_Summer2026_Grade!$J9="W (Withdrawn)", CSE4098C_Summer2026_Grade!$J9="I (Incomplete)"), 0, IF(AC23>=55%, 1, 0)) -> #DIV/0! | AN23: =IF(OR(CSE4098C_Summer2026_Grade!$J9="W (Withdrawn)", CSE4098C_Summer2026_Grade!$J9="I (Incomplete)"), 0, IF(AD23>=55%, 1, 0)) -> #DIV/0! | AO23: =IF(OR(CSE4098C_Summer2026_Grade!$J9="W (Withdrawn)", CSE4098C_Summer2026_Grade!$J9="I (Incomplete)"), 0, IF(AE23>=55%, 1, 0)) -> #DIV/0! | AP23: =IF(OR(CSE4098C_Summer2026_Grade!$J9="W (Withdrawn)", CSE4098C_Summer2026_Grade!$J9="I (Incomplete)"), 0, IF(AF23>=55%, 1, 0)) -> #DIV/0! | AQ23: =IF(OR(CSE4098C_Summer2026_Grade!$J9="W (Withdrawn)", CSE4098C_Summer2026_Grade!$J9="I (Incomplete)"), 0, IF(AG23>=55%, 1, 0)) -> #DIV/0! | AR23: =IF(OR(CSE4098C_Summer2026_Grade!$J9="W (Withdrawn)", CSE4098C_Summer2026_Grade!$J9="I (Incomplete)"), 0, IF(AH23>=55%, 1, 0)) -> #DIV/0! | AS23: =IF(OR(CSE4098C_Summer2026_Grade!$J9="W (Withdrawn)", CSE4098C_Summer2026_Grade!$J9="I (Incomplete)"), 0, IF(AI23>=55%, 1, 0)) -> #DIV/0! | AT23: =IF(OR(CSE4098C_Summer2026_Grade!$J9="W (Withdrawn)", CSE4098C_Summer2026_Grade!$J9="I (Incomplete)"), 0, IF(AJ23>=55%, 1, 0)) -> #DIV/0! | ... AV23: =IF(OR(CSE4098C_Summer2026_Grade!$J9="W (Withdrawn)", CSE4098C_Summer2026_Grade!$J9="I (Incomplete)"), 0, IF(AL23>=55%, 1, 0)) -> #DIV/0! | AX23: {=IF($AY$13=0,0,MMULT($AC23:$AL23, AY$3:AY$12)/$AY$13)} -> 0 | AY23: {=IF($AZ$13=0,0,MMULT($AC23:$AL23, AZ$3:AZ$12)/$AZ$13)} -> 0 | AZ23: {=IF($BA$13=0,0,MMULT($AC23:$AL23, BA$3:BA$12)/$BA$13)} -> 0 | BA23: {=IF($BB$13=0,0,MMULT($AC23:$AL23, BB$3:BB$12)/$BB$13)} -> 0.61961538 | BB23: {=IF($BC$13=0,0,MMULT($AC23:$AL23, BC$3:BC$12)/$BC$13)} -> 0 | BC23: {=IF($BD$13=0,0,MMULT($AC23:$AL23, BD$3:BD$12)/$BD$13)} -> 0 | BD23: {=IF($BE$13=0,0,MMULT($AC23:$AL23, BE$3:BE$12)/$BE$13)} -> 0 | BE23: {=IF($BF$13=0,0,MMULT($AC23:$AL23, BF$3:BF$12)/$BF$13)} -> 0 | BF23: {=IF($BG$13=0,0,MMULT($AC23:$AL23, BG$3:BG$12)/$BG$13)} -> 0 | BG23: {=IF($BH$13=0,0,MMULT($AC23:$AL23, BH$3:BH$12)/$BH$13)} -> 0.1736 | BH23: {=IF($BI$13=0,0,MMULT($AC23:$AL23, BI$3:BI$12)/$BI$13)} -> 0 | BI23: {=IF($BJ$13=0,0,MMULT($AC23:$AL23, BJ$3:BJ$12)/$BJ$13)} -> 0 | BJ23: =IF(OR(CSE4098C_Summer2026_Grade!$J9="W (Withdrawn)", CSE4098C_Summer2026_Grade!$J9="I (Incomplete)"), 0, IF(AX23>=55%, 1, 0)) -> #DIV/0! | BK23: =IF(OR(CSE4098C_Summer2026_Grade!$J9="W (Withdrawn)", CSE4098C_Summer2026_Grade!$J9="I (Incomplete)"), 0, IF(AY23>=55%, 1, 0)) -> #DIV/0! | BL23: =IF(OR(CSE4098C_Summer2026_Grade!$J9="W (Withdrawn)", CSE4098C_Summer2026_Grade!$J9="I (Incomplete)"), 0, IF(AZ23>=55%, 1, 0)) -> #DIV/0! | BM23: =IF(OR(CSE4098C_Summer2026_Grade!$J9="W (Withdrawn)", CSE4098C_Summer2026_Grade!$J9="I (Incomplete)"), 0, IF(BA23>=55%, 1, 0)) -> #DIV/0! | BN23: =IF(OR(CSE4098C_Summer2026_Grade!$J9="W (Withdrawn)", CSE4098C_Summer2026_Grade!$J9="I (Incomplete)"), 0, IF(BB23>=55%, 1, 0)) -> #DIV/0! | BO23: =IF(OR(CSE4098C_Summer2026_Grade!$J9="W (Withdrawn)", CSE4098C_Summer2026_Grade!$J9="I (Incomplete)"), 0, IF(BC23>=55%, 1, 0)) -> #DIV/0! | BP23: =IF(OR(CSE4098C_Summer2026_Grade!$J9="W (Withdrawn)", CSE4098C_Summer2026_Grade!$J9="I (Incomplete)"), 0, IF(BD23>=55%, 1, 0)) -> #DIV/0! | BQ23: =IF(OR(CSE4098C_Summer2026_Grade!$J9="W (Withdrawn)", CSE4098C_Summer2026_Grade!$J9="I (Incomplete)"), 0, IF(BE23>=55%, 1, 0)) -> #DIV/0! | ... BU23: =IF(OR(CSE4098C_Summer2026_Grade!$J9="W (Withdrawn)", CSE4098C_Summer2026_Grade!$J9="I (Incomplete)"), 0, IF(BI23>=55%, 1, 0)) -> #DIV/0!
A24: =A23+1 -> 6 | B24: 222014039 | C24: Aminul Islam | D24: =CO_Report_Evaluation!AG9 -> 0 | E24: =CO_Report_Evaluation!AH9 -> 0 | F24: =CO_Report_Evaluation!AI9 -> 0 | G24: =CO_Report_Evaluation!AJ9 -> 0 | H24: =CO_Report_Evaluation!AK9 -> 0 | I24: =CO_Report_Evaluation!AL9 -> 0 | J24: =CO_Report_Evaluation!AM9 -> 0 | K24: =CO_Report_Evaluation!AN9 -> 0 | L24: =CSE4098C_Summer2026_Grade!G10 -> 0 | N24: =((CSE4098C_Summer2026_Grade!E10)*10)/25 -> 6.844 | Q24: 15 | S24: =D24 -> 0 | T24: =E24 -> 0 | U24: =F24 -> 0 | V24: =SUM(G24,P24) -> 0 | W24: =SUM(H24,Q24) -> 15 | X24: =SUM(I24,R24) -> 0 | Y24: =J24 -> 0 | Z24: =K24 -> 0 | AA24: =L24 -> 0 | AB24: =SUM(M24,N24) -> 6.844 | AC24: =IF(S24 = 0, 0, S24/S$18) -> 0 | AD24: =IF(T24 = 0, 0, T24/T$18) -> 0 | AE24: =IF(U24 = 0, 0, U24/U$18) -> 0 | AF24: =IF(V24 = 0, 0, V24/V$18) -> 0 | AG24: =IF(W24 = 0, 0, W24/W$18) -> 0.57692308 | AH24: =IF(X24 = 0, 0, X24/X$18) -> 0 | AI24: =IF(Y24 = 0, 0, Y24/Y$18) -> 0 | AJ24: =IF(Z24 = 0, 0, Z24/Z$18) -> 0 | ... AL24: =IF(AB24 = 0, 0, AB24/AB$18) -> 0.6844 | AM24: =IF(OR(CSE4098C_Summer2026_Grade!$J10="W (Withdrawn)", CSE4098C_Summer2026_Grade!$J10="I (Incomplete)"), 0, IF(AC24>=55%, 1, 0)) -> #DIV/0! | AN24: =IF(OR(CSE4098C_Summer2026_Grade!$J10="W (Withdrawn)", CSE4098C_Summer2026_Grade!$J10="I (Incomplete)"), 0, IF(AD24>=55%, 1, 0)) -> #DIV/0! | AO24: =IF(OR(CSE4098C_Summer2026_Grade!$J10="W (Withdrawn)", CSE4098C_Summer2026_Grade!$J10="I (Incomplete)"), 0, IF(AE24>=55%, 1, 0)) -> #DIV/0! | AP24: =IF(OR(CSE4098C_Summer2026_Grade!$J10="W (Withdrawn)", CSE4098C_Summer2026_Grade!$J10="I (Incomplete)"), 0, IF(AF24>=55%, 1, 0)) -> #DIV/0! | AQ24: =IF(OR(CSE4098C_Summer2026_Grade!$J10="W (Withdrawn)", CSE4098C_Summer2026_Grade!$J10="I (Incomplete)"), 0, IF(AG24>=55%, 1, 0)) -> #DIV/0! | AR24: =IF(OR(CSE4098C_Summer2026_Grade!$J10="W (Withdrawn)", CSE4098C_Summer2026_Grade!$J10="I (Incomplete)"), 0, IF(AH24>=55%, 1, 0)) -> #DIV/0! | AS24: =IF(OR(CSE4098C_Summer2026_Grade!$J10="W (Withdrawn)", CSE4098C_Summer2026_Grade!$J10="I (Incomplete)"), 0, IF(AI24>=55%, 1, 0)) -> #DIV/0! | AT24: =IF(OR(CSE4098C_Summer2026_Grade!$J10="W (Withdrawn)", CSE4098C_Summer2026_Grade!$J10="I (Incomplete)"), 0, IF(AJ24>=55%, 1, 0)) -> #DIV/0! | ... AV24: =IF(OR(CSE4098C_Summer2026_Grade!$J10="W (Withdrawn)", CSE4098C_Summer2026_Grade!$J10="I (Incomplete)"), 0, IF(AL24>=55%, 1, 0)) -> #DIV/0! | AX24: {=IF($AY$13=0,0,MMULT($AC24:$AL24, AY$3:AY$12)/$AY$13)} -> 0 | AY24: {=IF($AZ$13=0,0,MMULT($AC24:$AL24, AZ$3:AZ$12)/$AZ$13)} -> 0 | AZ24: {=IF($BA$13=0,0,MMULT($AC24:$AL24, BA$3:BA$12)/$BA$13)} -> 0 | BA24: {=IF($BB$13=0,0,MMULT($AC24:$AL24, BB$3:BB$12)/$BB$13)} -> 0.57692308 | BB24: {=IF($BC$13=0,0,MMULT($AC24:$AL24, BC$3:BC$12)/$BC$13)} -> 0 | BC24: {=IF($BD$13=0,0,MMULT($AC24:$AL24, BD$3:BD$12)/$BD$13)} -> 0 | BD24: {=IF($BE$13=0,0,MMULT($AC24:$AL24, BE$3:BE$12)/$BE$13)} -> 0 | BE24: {=IF($BF$13=0,0,MMULT($AC24:$AL24, BF$3:BF$12)/$BF$13)} -> 0 | BF24: {=IF($BG$13=0,0,MMULT($AC24:$AL24, BG$3:BG$12)/$BG$13)} -> 0 | BG24: {=IF($BH$13=0,0,MMULT($AC24:$AL24, BH$3:BH$12)/$BH$13)} -> 0.6844 | BH24: {=IF($BI$13=0,0,MMULT($AC24:$AL24, BI$3:BI$12)/$BI$13)} -> 0 | BI24: {=IF($BJ$13=0,0,MMULT($AC24:$AL24, BJ$3:BJ$12)/$BJ$13)} -> 0 | BJ24: =IF(OR(CSE4098C_Summer2026_Grade!$J10="W (Withdrawn)", CSE4098C_Summer2026_Grade!$J10="I (Incomplete)"), 0, IF(AX24>=55%, 1, 0)) -> #DIV/0! | BK24: =IF(OR(CSE4098C_Summer2026_Grade!$J10="W (Withdrawn)", CSE4098C_Summer2026_Grade!$J10="I (Incomplete)"), 0, IF(AY24>=55%, 1, 0)) -> #DIV/0! | BL24: =IF(OR(CSE4098C_Summer2026_Grade!$J10="W (Withdrawn)", CSE4098C_Summer2026_Grade!$J10="I (Incomplete)"), 0, IF(AZ24>=55%, 1, 0)) -> #DIV/0! | BM24: =IF(OR(CSE4098C_Summer2026_Grade!$J10="W (Withdrawn)", CSE4098C_Summer2026_Grade!$J10="I (Incomplete)"), 0, IF(BA24>=55%, 1, 0)) -> #DIV/0! | BN24: =IF(OR(CSE4098C_Summer2026_Grade!$J10="W (Withdrawn)", CSE4098C_Summer2026_Grade!$J10="I (Incomplete)"), 0, IF(BB24>=55%, 1, 0)) -> #DIV/0! | BO24: =IF(OR(CSE4098C_Summer2026_Grade!$J10="W (Withdrawn)", CSE4098C_Summer2026_Grade!$J10="I (Incomplete)"), 0, IF(BC24>=55%, 1, 0)) -> #DIV/0! | BP24: =IF(OR(CSE4098C_Summer2026_Grade!$J10="W (Withdrawn)", CSE4098C_Summer2026_Grade!$J10="I (Incomplete)"), 0, IF(BD24>=55%, 1, 0)) -> #DIV/0! | BQ24: =IF(OR(CSE4098C_Summer2026_Grade!$J10="W (Withdrawn)", CSE4098C_Summer2026_Grade!$J10="I (Incomplete)"), 0, IF(BE24>=55%, 1, 0)) -> #DIV/0! | ... BU24: =IF(OR(CSE4098C_Summer2026_Grade!$J10="W (Withdrawn)", CSE4098C_Summer2026_Grade!$J10="I (Incomplete)"), 0, IF(BI24>=55%, 1, 0)) -> #DIV/0!
