Workbook

Sheet GradeSheet
D2: Course Code | E2: CSE 4460 | G2: Section | H2: 2
D3: Course Title | E3: Big Data Analytics Lab | G3: Semester | H3: Spring 2026
D4: Credit | E4: 1 | L4: W (Withdrawn)
D5: Instructor | E5: Foysal Ahmed
A7: =CONCATENATE("Grade Sheet of ",GradeSheet!$E$2, " [",GradeSheet!$E$3, "] ", "(Section ",GradeSheet!$H$2, ") ", "[Semester - ",GradeSheet!$H$3,"]" ) -> Grade Sheet of CSE 4460 [Big Data Analytics Lab] (Section 2) [Semester - Spring 2026]
L8: Lab Submission | M8: Lab Test | N8: Attendance | O8: Open Ended Lab | P8: Mid | Q8: Final
A9: No. | B9: Student ID | C9: Name | D9: =CONCATENATE("Continuous Lab Performance (",GradeSheet!$C$60, ")") -> Continuous Lab Performance (30) | E9: =CONCATENATE("Open Ended Lab (",GradeSheet!$C$59, ")") -> Open Ended Lab (40) | F9: =CONCATENATE("Final (",GradeSheet!$C$61, ")") -> Final (30) | G9: Exam Total (100) | H9: Percent Total (100%) | I9: Grade | L9: 15 | M9: 10 | N9: 5 | O9: 40 | P9: 0 | Q9: 30 | R9: Name | S9: Student ID
A10: 1 | B10: =RawMarks!B2 -> 201014102 | C10: =RawMarks!C2 -> Most. Zarin Tasnim Rifa | D10: =RawMarks!K2 -> 19 | E10: =RawMarks!L2 -> 32 | F10: =RawMarks!M2 -> 25 | G10: =SUM(D10:F10) -> 76 | H10: =G10/100 -> 0.76 | I10: =VLOOKUP(G10,GradingPolicy!$B$2:$C$11,2) -> B+ (Plus) | L10: 8 | M10: 6 | N10: 5 | O10: 32 | Q10: 25 | R10: Most. Zarin Tasnim Rifa | S10: 201014102
A11: 2 | B11: =RawMarks!B3 -> 213014022 | C11: =RawMarks!C3 -> Mohammad Asif Mahmud | D11: =RawMarks!K3 -> 22 | E11: =RawMarks!L3 -> 25 | F11: =RawMarks!M3 -> 20 | G11: =SUM(D11:F11) -> 67 | H11: =G11/100 -> 0.67 | I11: =VLOOKUP(G11,GradingPolicy!$B$2:$C$11,2) -> B- (Minus) | L11: 10 | M11: 7 | N11: 5 | O11: 25 | Q11: 20 | R11: Mohammad Asif Mahmud | S11: 213014022
A12: 3 | B12: =RawMarks!B4 -> 221014083 | C12: =RawMarks!C4 -> Salina Akter | D12: =RawMarks!K4 -> 12 | E12: 0 | F12: 0 | G12: =SUM(D12:F12) -> 12 | H12: =G12/100 -> 0.12 | I12: =VLOOKUP(G12,GradingPolicy!$B$2:$C$11,2) -> F (Fail) | L12: 12 | M12: 0 | N12: 0 | O12: 0 | Q12: 0 | R12: Salina Akter | S12: 221014083
A13: 4 | B13: =RawMarks!B5 -> 221014111 | C13: =RawMarks!C5 -> Abdullah Bin Noor Tazim | D13: =RawMarks!K5 -> 11 | E13: =RawMarks!L5 -> 30 | F13: =RawMarks!M5 -> 24 | G13: =SUM(D13:F13) -> 65 | H13: =G13/100 -> 0.65 | I13: =VLOOKUP(G13,GradingPolicy!$B$2:$C$11,2) -> B- (Minus) | L13: 0 | M13: 6 | N13: 5 | O13: 30 | Q13: 24 | R13: Abdullah Bin Noor Tazim | S13: 221014111
A14: 5 | B14: =RawMarks!B6 -> 221014129 | C14: =RawMarks!C6 -> Fuyad Hasan Bhoyan | D14: =RawMarks!K6 -> 4 | E14: 0 | F14: 0 | G14: =SUM(D14:F14) -> 4 | H14: =G14/100 -> 0.04 | I14: W (Withdrawn) | L14: 4 | M14: 0 | N14: 0 | O14: 0 | Q14: 0 | R14: Fuyad Hasan Bhoyan | S14: 221014129
A15: 6 | B15: =RawMarks!B7 -> 221014136 | C15: =RawMarks!C7 -> Prashanta Sarker | D15: =RawMarks!K7 -> 27 | E15: =RawMarks!L7 -> 30 | F15: =RawMarks!M7 -> 28 | G15: =SUM(D15:F15) -> 85 | H15: =G15/100 -> 0.85 | I15: =VLOOKUP(G15,GradingPolicy!$B$2:$C$11,2) -> A (Plain) | L15: 12 | M15: 10 | N15: 5 | O15: 30 | Q15: 28 | R15: Prashanta Sarker | S15: 221014136
A16: 7 | B16: =RawMarks!B8 -> 222014021 | C16: =RawMarks!C8 -> Rasel Rahman | D16: =RawMarks!K8 -> 14 | E16: =RawMarks!L8 -> 25 | F16: =RawMarks!M8 -> 22 | G16: =SUM(D16:F16) -> 61 | H16: =G16/100 -> 0.61 | I16: =VLOOKUP(G16,GradingPolicy!$B$2:$C$11,2) -> C+ (Plus) | L16: 4 | M16: 5 | N16: 5 | O16: 25 | Q16: 22 | R16: Rasel Rahman | S16: 222014021
A17: 8 | B17: =RawMarks!B9 -> 222014031 | C17: =RawMarks!C9 -> Raian Zaman | D17: =RawMarks!K9 -> 29 | E17: =RawMarks!L9 -> 35 | F17: =RawMarks!M9 -> 26 | G17: =SUM(D17:F17) -> 90 | H17: =G17/100 -> 0.9 | I17: =VLOOKUP(G17,GradingPolicy!$B$2:$C$11,2) -> A (Plain) | L17: 14 | M17: 10 | N17: 5 | O17: 35 | Q17: 26 | R17: Raian Zaman | S17: 222014031
A18: 9 | B18: =RawMarks!B10 -> 222014057 | C18: =RawMarks!C10 -> Nur Shahad Srabon | D18: =RawMarks!K10 -> 0 | E18: 0 | F18: 0 | G18: =SUM(D18:F18) -> 0 | H18: =G18/100 -> 0 | I18: W (Withdrawn) | L18: 0 | M18: 0 | N18: 0 | O18: 0 | Q18: 0 | R18: Nur Shahad Srabon | S18: 222014057
A19: 10 | B19: =RawMarks!B11 -> 222014059 | C19: =RawMarks!C11 -> Sohan Sheikh | D19: =RawMarks!K11 -> 0 | E19: 0 | F19: 0 | G19: =SUM(D19:F19) -> 0 | H19: =G19/100 -> 0 | I19: W (Withdrawn) | L19: 0 | M19: 0 | N19: 0 | O19: 0 | Q19: 0 | R19: Sohan Sheikh | S19: 222014059
A20: 11 | B20: =RawMarks!B12 -> 222014090 | C20: =RawMarks!C12 -> Asifuzzaman Shishir | D20: =RawMarks!K12 -> 12 | E20: =RawMarks!L12 -> 25 | F20: =RawMarks!M12 -> 24 | G20: =SUM(D20:F20) -> 61 | H20: =G20/100 -> 0.61 | I20: =VLOOKUP(G20,GradingPolicy!$B$2:$C$11,2) -> C+ (Plus) | L20: 2 | M20: 5 | N20: 5 | O20: 25 | Q20: 24 | R20: Asifuzzaman Shishir | S20: 222014090
A21: 12 | B21: =RawMarks!B13 -> 222014097 | C21: =RawMarks!C13 -> Md Abul Hashem | D21: =RawMarks!K13 -> 13 | E21: =RawMarks!L13 -> 25 | F21: =RawMarks!M13 -> 14 | G21: =SUM(D21:F21) -> 52 | H21: =G21/100 -> 0.52 | I21: =VLOOKUP(G21,GradingPolicy!$B$2:$C$11,2) -> D (Plain) | L21: 8 | M21: 0 | N21: 5 | O21: 25 | Q21: 14 | R21: Md Abul Hashem | S21: 222014097
A22: 13 | B22: =RawMarks!B14 -> 223014012 | C22: =RawMarks!C14 -> Md Yusuf | D22: =RawMarks!K14 -> 5 | E22: =RawMarks!L14 -> 25 | F22: =RawMarks!M14 -> 28 | G22: =SUM(D22:F22) -> 58 | H22: =G22/100 -> 0.58 | I22: =VLOOKUP(G22,GradingPolicy!$B$2:$C$11,2) -> C (Plain) | L22: 0 | M22: 0 | N22: 5 | O22: 25 | Q22: 28 | R22: Md Yusuf | S22: 223014012
A23: 14 | B23: =RawMarks!B15 -> 223014025 | C23: =RawMarks!C15 -> Fahim Shihab Touhid | D23: =RawMarks!K15 -> 29 | E23: =RawMarks!L15 -> 35 | F23: =RawMarks!M15 -> 25 | G23: =SUM(D23:F23) -> 89 | H23: =G23/100 -> 0.89 | I23: =VLOOKUP(G23,GradingPolicy!$B$2:$C$11,2) -> A (Plain) | L23: 14 | M23: 10 | N23: 5 | O23: 35 | Q23: 25 | R23: Fahim Shihab Touhid | S23: 223014025
A24: 15 | B24: =RawMarks!B16 -> 223014061 | C24: =RawMarks!C16 -> Md. Shihab Hasan Shishir | D24: =RawMarks!K16 -> 19 | E24: =RawMarks!L16 -> 20 | F24: =RawMarks!M16 -> 26 | G24: =SUM(D24:F24) -> 65 | H24: =G24/100 -> 0.65 | I24: =VLOOKUP(G24,GradingPolicy!$B$2:$C$11,2) -> B- (Minus) | L24: 8 | M24: 6 | N24: 5 | O24: 20 | Q24: 26 | R24: Md. Shihab Hasan Shishir | S24: 223014061
A25: 16 | B25: =RawMarks!B17 -> 223014085 | C25: =RawMarks!C17 -> Md. Naeem Rahman | D25: =RawMarks!K17 -> 14 | E25: =RawMarks!L17 -> 20 | F25: =RawMarks!M17 -> 24 | G25: =SUM(D25:F25) -> 58 | H25: =G25/100 -> 0.58 | I25: =VLOOKUP(G25,GradingPolicy!$B$2:$C$11,2) -> C (Plain) | L25: 4 | M25: 5 | N25: 5 | O25: 20 | Q25: 24 | R25: Md. Naeem Rahman | S25: 223014085
A26: 17 | B26: =RawMarks!B18 -> 223014088 | C26: =RawMarks!C18 -> Md. Sakib Ishrak | D26: =RawMarks!K18 -> 17 | E26: =RawMarks!L18 -> 35 | F26: =RawMarks!M18 -> 26 | G26: =SUM(D26:F26) -> 78 | H26: =G26/100 -> 0.78 | I26: =VLOOKUP(G26,GradingPolicy!$B$2:$C$11,2) -> B+ (Plus) | L26: 12 | M26: 0 | N26: 5 | O26: 35 | Q26: 26 | R26: Md. Sakib Ishrak | S26: 223014088
A27: 18 | B27: =RawMarks!B19 -> 223014116 | C27: =RawMarks!C19 -> Nusrat Jannat Tithy | D27: =RawMarks!K19 -> 29 | E27: =RawMarks!L19 -> 32 | F27: =RawMarks!M19 -> 24 | G27: =SUM(D27:F27) -> 85 | H27: =G27/100 -> 0.85 | I27: =VLOOKUP(G27,GradingPolicy!$B$2:$C$11,2) -> A (Plain) | L27: 15 | M27: 9 | N27: 5 | O27: 32 | Q27: 24 | R27: Nusrat Jannat Tithy | S27: 223014116
A28: 19 | B28: =RawMarks!B20 -> 223014120 | C28: =RawMarks!C20 -> Meheraj Hossain Jibon | D28: =RawMarks!K20 -> 13 | E28: =RawMarks!L20 -> 25 | F28: =RawMarks!M20 -> 12 | G28: =SUM(D28:F28) -> 50 | H28: =G28/100 -> 0.5 | I28: =VLOOKUP(G28,GradingPolicy!$B$2:$C$11,2) -> D (Plain) | L28: 8 | M28: 0 | N28: 5 | O28: 25 | Q28: 12 | R28: Meheraj Hossain Jibon | S28: 223014120
A29: 20 | B29: =RawMarks!B21 -> 223014176 | C29: =RawMarks!C21 -> Md. Samiul Alam | D29: =RawMarks!K21 -> 18 | E29: =RawMarks!L21 -> 25 | F29: =RawMarks!M21 -> 28 | G29: =SUM(D29:F29) -> 71 | H29: =G29/100 -> 0.71 | I29: =VLOOKUP(G29,GradingPolicy!$B$2:$C$11,2) -> B (Plain) | L29: 8 | M29: 5 | N29: 5 | O29: 25 | Q29: 28 | R29: Md. Samiul Alam | S29: 223014176
A30: 21 | B30: =RawMarks!B22 -> 223014219 | C30: =RawMarks!C22 -> Meherun Nessa Eva | D30: =RawMarks!K22 -> 26 | E30: =RawMarks!L22 -> 32 | F30: =RawMarks!M22 -> 25 | G30: =SUM(D30:F30) -> 83 | H30: =G30/100 -> 0.83 | I30: =VLOOKUP(G30,GradingPolicy!$B$2:$C$11,2) -> A- (Minus) | L30: 15 | M30: 6 | N30: 5 | O30: 32 | Q30: 25 | R30: Meherun Nessa Eva | S30: 223014219
A31: 22 | B31: =RawMarks!B23 -> 231014003 | C31: =RawMarks!C23 -> Md. Arfan Alam | D31: =RawMarks!K23 -> 19 | E31: =RawMarks!L23 -> 35 | F31: =RawMarks!M23 -> 24 | G31: =SUM(D31:F31) -> 78 | H31: =G31/100 -> 0.78 | I31: =VLOOKUP(G31,GradingPolicy!$B$2:$C$11,2) -> B+ (Plus) | L31: 8 | M31: 6 | N31: 5 | O31: 35 | Q31: 24 | R31: Md. Arfan Alam | S31: 231014003
... A34: 25 | B34: =RawMarks!B26 -> 231014059 | C34: =RawMarks!C26 -> Tonmoy Chatterjee | D34: =RawMarks!K26 -> 14 | E34: =RawMarks!L26 -> 35 | F34: =RawMarks!M26 -> 24 | G34: =SUM(D34:F34) -> 73 | H34: =G34/100 -> 0.73 | I34: =VLOOKUP(G34,GradingPolicy!$B$2:$C$11,2) -> B (Plain) | L34: 4 | M34: 5 | N34: 5 | O34: 35 | Q34: 24 | R34: Tonmoy Chatterjee | S34: 231014059
A35: 26 | B35: =RawMarks!B27 -> 231014097 | C35: =RawMarks!C27 -> Fahmida Alamgir | D35: =RawMarks!K27 -> 0 | E35: 0 | F35: 0 | G35: =SUM(D35:F35) -> 0 | H35: =G35/100 -> 0 | I35: W (Withdrawn) | L35: 0 | M35: 0 | N35: 0 | O35: 0 | Q35: 0 | R35: Fahmida Alamgir | S35: 231014097
A36: 27 | B36: =RawMarks!B28 -> 231014101 | C36: =RawMarks!C28 -> Puja Karmokar | D36: =RawMarks!K28 -> 20 | E36: =RawMarks!L28 -> 20 | F36: =RawMarks!M28 -> 10 | G36: =SUM(D36:F36) -> 50 | H36: =G36/100 -> 0.5 | I36: =VLOOKUP(G36,GradingPolicy!$B$2:$C$11,2) -> D (Plain) | L36: 10 | M36: 5 | N36: 5 | O36: 20 | Q36: 10 | R36: Puja Karmokar | S36: 231014101
A37: 28 | B37: =RawMarks!B29 -> 231014102 | C37: =RawMarks!C29 -> Nadia Akter | D37: =RawMarks!K29 -> 0 | E37: 0 | F37: 0 | G37: =SUM(D37:F37) -> 0 | H37: =G37/100 -> 0 | I37: W (Withdrawn) | L37: 0 | M37: 0 | N37: 0 | O37: 0 | Q37: 0 | R37: Nadia Akter | S37: 231014102
A38: 29 | B38: =RawMarks!B30 -> 231014136 | C38: =RawMarks!C30 -> Md. Tasdiqur Rahman Khan | D38: =RawMarks!K30 -> 0 | E38: 0 | F38: 0 | G38: =SUM(D38:F38) -> 0 | H38: =G38/100 -> 0 | I38: W (Withdrawn) | L38: 0 | M38: 0 | N38: 0 | O38: 0 | Q38: 0 | R38: Md. Tasdiqur Rahman Khan | S38: 231014136
A39: 30 | B39: =RawMarks!B31 -> 231014148 | C39: =RawMarks!C31 -> Shihab Ahmed Sakib | D39: =RawMarks!K31 -> 13 | E39: =RawMarks!L31 -> 20 | F39: =RawMarks!M31 -> 25 | G39: =SUM(D39:F39) -> 58 | H39: =G39/100 -> 0.58 | I39: =VLOOKUP(G39,GradingPolicy!$B$2:$C$11,2) -> C (Plain) | L39: 8 | M39: 0 | N39: 5 | O39: 20 | Q39: 25 | R39: Shihab Ahmed Sakib | S39: 231014148
A40: 31 | B40: =RawMarks!B32 -> 232014029 | C40: =RawMarks!C32 -> Sanjida Akter | D40: =RawMarks!K32 -> 21 | E40: =RawMarks!L32 -> 32 | F40: =RawMarks!M32 -> 24 | G40: =SUM(D40:F40) -> 77 | H40: =G40/100 -> 0.77 | I40: =VLOOKUP(G40,GradingPolicy!$B$2:$C$11,2) -> B+ (Plus) | L40: 10 | M40: 6 | N40: 5 | O40: 32 | Q40: 24 | R40: Sanjida Akter | S40: 232014029
A41: 32 | B41: =RawMarks!B33 -> 232014033 | C41: =RawMarks!C33 -> Morium Rahman | D41: =RawMarks!K33 -> 25 | E41: =RawMarks!L33 -> 35 | F41: =RawMarks!M33 -> 25 | G41: =SUM(D41:F41) -> 85 | H41: =G41/100 -> 0.85 | I41: =VLOOKUP(G41,GradingPolicy!$B$2:$C$11,2) -> A (Plain) | L41: 14 | M41: 6 | N41: 5 | O41: 35 | Q41: 25 | R41: Morium Rahman | S41: 232014033
A42: 33 | B42: =RawMarks!B34 -> 232014036 | C42: =RawMarks!C34 -> Esrat Jahan Emu | D42: =RawMarks!K34 -> 22 | E42: =RawMarks!L34 -> 32 | F42: =RawMarks!M34 -> 2 | G42: =SUM(D42:F42) -> 56 | H42: =G42/100 -> 0.56 | I42: =VLOOKUP(G42,GradingPolicy!$B$2:$C$11,2) -> C (Plain) | L42: 12 | M42: 5 | N42: 5 | O42: 32 | Q42: 2 | R42: Esrat Jahan Emu | S42: 232014036
A43: 34 | B43: =RawMarks!B35 -> 232014062 | C43: =RawMarks!C35 -> Sayeda Sanzida Hoque | D43: =RawMarks!K35 -> 26 | E43: =RawMarks!L35 -> 32 | F43: =RawMarks!M35 -> 15 | G43: =SUM(D43:F43) -> 73 | H43: =G43/100 -> 0.73 | I43: =VLOOKUP(G43,GradingPolicy!$B$2:$C$11,2) -> B (Plain) | L43: 15 | M43: 6 | N43: 5 | O43: 32 | Q43: 15 | R43: Sayeda Sanzida Hoque | S43: 232014062
A44: 35 | B44: =RawMarks!B36 -> 232014106 | C44: =RawMarks!C36 -> Lubaba Nishat Nirupoma | D44: =RawMarks!K36 -> 23 | E44: =RawMarks!L36 -> 32 | F44: =RawMarks!M36 -> 20 | G44: =SUM(D44:F44) -> 75 | H44: =G44/100 -> 0.75 | I44: =VLOOKUP(G44,GradingPolicy!$B$2:$C$11,2) -> B+ (Plus) | L44: 12 | M44: 6 | N44: 5 | O44: 32 | Q44: 20 | R44: Lubaba Nishat Nirupoma | S44: 232014106
...

Sheet GradingPolicy
A1: Numerical Grade | B1: Minimum Number | C1: Letter Grade
A2: Below 50% | B2: 0 | C2: F (Fail)
A3: 50% to 54% | B3: 50 | C3: D (Plain)
A4: 55% to 59% | B4: 55 | C4: C (Plain)
A5: 60% to 64% | B5: 60 | C5: C+ (Plus)
A6: 65% to 69% | B6: 65 | C6: B- (Minus)
A7: 70% to 74% | B7: 70 | C7: B (Plain)
A8: 75% to 79% | B8: 75 | C8: B+ (Plus)
A9: 80% to 84% | B9: 80 | C9: A- (Minus)
A10: 85% to 94% | B10: 85 | C10: A (Plain)
A11: 95% and above | B11: 95 | C11: A+ (Plus)

Sheet CourseSummary
B2: Course Code | E2: =GradeSheet!$E$2 -> CSE 4460 | O2: =CONCATENATE("Section ", GradeSheet!$H$2,) -> Section 2 | T2: Course Topic/Content Covered
B3: Course Title | E3: =GradeSheet!$E$3 -> Big Data Analytics Lab | O3: =CONCATENATE(GradeSheet!$E$67," students") -> 36 students | T3: Topics Taught (based on course outline) | AG3: Number of Sessions
B4: Credit | E4: =GradeSheet!$E$4 -> 1 | O4: =GradeSheet!$H$3 -> Spring 2026 | T4: 1 | AG4: 4
T5: 2 | AG5: 4
T6: 3 | AG6: 5
T7: 4 | AG7: 5
T8: 5 | AG8: 6
T14: What percentage of topics/content planned were actually taught?
U15: a. | V15: >90% | Y15: √ | AB15: b. | AC15: 70%-90% | AJ15: c. | AK15: <70%
T16: If <70%, please write the reason for not teaching all topics/content planned
T21: Teaching and Learning Methods
B22: Grade Distribution | T22: Teaching Methods | AG22: Number of Sessions | AL22: Percentage
B23: A+ | C23: A | D23: A- | E23: B+ | F23: B | G23: B- | H23: C+ | I23: C | J23: D | K23: F | L23: I | M23: W | N23: Total | T23: Lectures | AG23: 20 | AL23: =AG23/P33 -> 1.0526316
B24: =GradeSheet!$E$55 -> 1 | C24: =GradeSheet!$E$56 -> 6 | D24: =GradeSheet!$E$57 -> 1 | E24: =GradeSheet!$E$58 -> 6 | F24: =GradeSheet!$E$59 -> 3 | G24: =GradeSheet!$E$60 -> 3 | H24: =GradeSheet!$E$61 -> 2 | I24: =GradeSheet!$E$62 -> 4 | J24: =GradeSheet!$E$63 -> 3 | K24: =GradeSheet!$E$64 -> 1 | L24: =GradeSheet!$E$65 -> 0 | M24: =GradeSheet!$E$66 -> 6 | N24: =SUM(B24:M24) -> 36 | T24: Group Discussion | AG24: 10 | AL24: =AG24/P33 -> 0.52631579
B25: =B24/GradeSheet!$E$67 -> 0.027777778 | C25: =C24/GradeSheet!$E$67 -> 0.16666667 | D25: =D24/GradeSheet!$E$67 -> 0.027777778 | E25: =E24/GradeSheet!$E$67 -> 0.16666667 | F25: =F24/GradeSheet!$E$67 -> 0.083333333 | G25: =G24/GradeSheet!$E$67 -> 0.083333333 | H25: =H24/GradeSheet!$E$67 -> 0.055555556 | I25: =I24/GradeSheet!$E$67 -> 0.11111111 | ... M25: =M24/GradeSheet!$E$67 -> 0.16666667 | N25: =SUM(B25:M25) -> 1 | T25: Presentation | AG25: 0 | AL25: =AG25/P33 -> 0
T26: Classwork | AG26: 8 | AL26: =AG26/P33 -> 0.42105263
B27: Statistical Information
G29: No. | H29: % | P29: No | Q29: %
B30: Students enrolled | G30: =GradeSheet!$E$67 -> 36 | H30: =G30/G30 -> 1 | J30: Session Planned | P30: 20 | Q30: =P30/P30 -> 1 | T30: Active Learning | AG30: Number of Sessions | AL30: Percentage
B31: Students who withdrew | G31: =GradeSheet!$E$66 -> 6 | H31: =G31/G30 -> 0.16666667 | J31: Sessions Missed | P31: 0 | Q31: =P31/P30 -> 0 | T31: Classwork | AG31: 8 | AL31: =AG31/P33 -> 0.42105263
B32: Students who took final exam | G32: 41 | H32: =G32/G30 -> 1.1388889 | J32: Sessions Made Up | P32: 0 | Q32: =P32/P30 -> 0 | T32: Group Discussion | AG32: 10 | AL32: =AG32/P33 -> 0.52631579
B33: Students passed | G33: =GradeSheet!$E$67-(GradeSheet!$E$64+GradeSheet!$E$65+GradeSheet!$E$66) -> 29 | H33: =G33/G30 -> 0.80555556 | J33: Total Sessions Conducted (excluding midterm and final exams) | P33: 19 | Q33: =P33/P30 -> 0.95
B37: Average Number Per Session | P37: No | T37: Teaching Aids | AG37: Number of Sessions | AL37: Percentage
B38: Tardy Students | G38: 2 | J38: Guest Lectures Invited | P38: N/A | T38: Whiteboard | AG38: 0 | AL38: =AG38/P33 -> 0
B39: Absent Students | G39: 3 | J39: Field Trips Taken | P39: N/A | T39: Computer | AG39: 20 | AL39: =AG39/P33 -> 1.0526316
T40: Handout | AG40: 12 | AL40: =AG40/P33 -> 0.63157895
T41: Video and Audio | AG41: 0 | AL41: =AG41/P33 -> 0
U47: Signature of the Course Instructor
B51: Course Code | E51: =GradeSheet!$E$2 -> CSE 4460 | O51: =CONCATENATE("Section ", GradeSheet!$H$2,) -> Section 2
B52: Course Title | E52: =GradeSheet!$E$3 -> Big Data Analytics Lab | O52: =CONCATENATE(GradeSheet!$E$67," students") -> 36 students
B53: Credit | E53: =GradeSheet!$E$4 -> 1 | O53: =GradeSheet!$H$3 -> Spring 2026
E57: Summary of Cos
H58: CO1 | I58: CO2 | J58: CO3 | K58: CO4 | L58: CO5 | M58: CO6
E59: Number of Studens | H59: =CO_PO_AttainmentAnalysis!AN58 -> 26 | I59: =CO_PO_AttainmentAnalysis!AO58 -> 25 | J59: =CO_PO_AttainmentAnalysis!AP58 -> 0 | K59: =CO_PO_AttainmentAnalysis!AQ58 -> 0 | L59: =CO_PO_AttainmentAnalysis!AR58 -> 0 | M59: =CO_PO_AttainmentAnalysis!AS58 -> 0
E60: Average Score | H60: =CO_PO_AttainmentAnalysis!AH58 -> 0.58994709 | I60: =CO_PO_AttainmentAnalysis!AI58 -> 0.57423372 | J60: =CO_PO_AttainmentAnalysis!AJ58 -> 0 | K60: =CO_PO_AttainmentAnalysis!AK58 -> 0 | L60: =CO_PO_AttainmentAnalysis!AL58 -> 0 | M60: =CO_PO_AttainmentAnalysis!AM58 -> 0

Sheet CO_PO_AttainmentAnalysis
AU1: Mapping of COs to POs
C2: Assessment Items | D2: CO1 | E2: CO2 | F2: CO3 | G2: CO4 | H2: CO5 | I2: CO6 | AT2: PO1 | AU2: PO2 | AV2: PO3 | AW2: PO4 | AX2: PO5 | AY2: PO6 | AZ2: PO7 | BA2: PO8 | BB2: PO9 | BC2: PO10 | BD2: PO11 | BE2: PO12
C3: Continuous Lab Performance | D3: 12 | E3: 18 | AS3: CO1 | AT3: 0 | AU3: 0 | AV3: 0 | AW3: 0 | AX3: 0 | AY3: 0 | AZ3: 0 | BA3: 0 | BB3: 0 | BC3: 0 | BD3: 0 | BE3: 0
C4: Open Ended Lab | D4: 20 | E4: 20 | AS4: CO2 | AT4: 0 | AU4: 0 | AV4: 0 | AW4: 0 | AX4: 0 | AY4: 0 | AZ4: 0 | BA4: 0 | BB4: 0 | BC4: 0 | BD4: 0 | BE4: 0
C5: Lab Final | D5: 10 | E5: 20 | AS5: CO3 | AT5: 0 | AU5: 0 | AV5: 0 | AW5: 0 | AX5: 0 | AY5: 0 | AZ5: 0 | BA5: 0 | BB5: 0 | BC5: 0 | BD5: 0 | BE5: 0
C6: Presentation | AS6: CO4 | AT6: 0 | AU6: 0 | AV6: 0 | AW6: 0 | AX6: 0 | AY6: 0 | AZ6: 0 | BA6: 0 | BB6: 0 | BC6: 0 | BD6: 0 | BE6: 0
C7: Total | D7: =SUM(D3:D6) -> 42 | E7: =SUM(E3:E6) -> 58 | F7: =SUM(F3:F6) -> 0 | G7: =SUM(G3:G6) -> 0 | H7: =SUM(H3:H6) -> 0 | I7: =SUM(I3:I6) -> 0 | AS7: CO5 | AT7: 0 | AU7: 0 | AV7: 0 | AW7: 0 | AX7: 0 | AY7: 0 | AZ7: 0 | BA7: 0 | BB7: 0 | BC7: 0 | BD7: 0 | BE7: 0
AT8: 0 | AU8: 0 | AV8: 0 | AW8: 0 | AX8: 0 | AY8: 0 | AZ8: 0 | BA8: 0 | BB8: 0 | BC8: 0 | BD8: 0 | BE8: 0
AS9: Total | AT9: =SUM(AT3:AT8) -> 0 | AU9: =SUM(AU3:AU8) -> 0 | AV9: =SUM(AV3:AV8) -> 0 | AW9: =SUM(AW3:AW8) -> 0 | AX9: =SUM(AX3:AX8) -> 0 | AY9: =SUM(AY3:AY8) -> 0 | AZ9: =SUM(AZ3:AZ8) -> 0 | BA9: =SUM(BA3:BA8) -> 0 | ... BE9: =SUM(BE3:BE8) -> 0
A11: =CONCATENATE("Course Outcome (CO) Attainment Analysis of ",GradeSheet!$E$2, " [",GradeSheet!$E$3, "] ", "(Section ",GradeSheet!$H$2, ") ", "[Semester - ",GradeSheet!$H$3,"]" ) -> Course Outcome (CO) Attainment Analysis of CSE 4460 [Big Data Analytics Lab] (Section 2) [Semester - Spring 2026] | AB11: CO Attainment Analysis | AU11: PO Attainment Analysis
D12: =C3 -> Continuous Lab Performance | J12: =C4 -> Open Ended Lab | P12: =C5 -> Lab Final | V12: =C6 -> Presentation | AB12: Total Marks | AH12: Percentage | AN12: CO Attainment | AU12: Percentage | BG12: PO Attainment
D13: CO1 | E13: CO2 | F13: CO3 | G13: CO4 | H13: CO5 | I13: CO6 | J13: CO1 | K13: CO2 | L13: CO3 | M13: CO4 | N13: CO5 | O13: CO6 | P13: CO1 | Q13: CO2 | R13: CO3 | S13: CO4 | T13: CO5 | U13: CO6 | V13: CO1 | W13: CO2 | X13: CO3 | Y13: CO4 | Z13: CO5 | AA13: CO6 | AB13: CO1 | AC13: CO2 | AD13: CO3 | AE13: CO4 | AF13: CO5 | AG13: CO6 | AH13: CO1 | AI13: CO2 | AJ13: CO3 | AK13: CO4 | AL13: CO5 | AM13: CO6 | AN13: CO1 | AO13: CO2 | AP13: CO3 | AQ13: CO4 | AR13: CO5 | AS13: CO6 | AU13: PO1 | AV13: PO2 | AW13: PO3 | AX13: PO4 | AY13: PO5 | AZ13: PO6 | BA13: PO7 | BB13: PO8 | BC13: PO9 | BD13: PO10 | BE13: PO11 | BF13: PO12 | BG13: PO1 | BH13: PO2 | BI13: PO3 | BJ13: PO4 | BK13: PO5 | BL13: PO6 | BM13: PO7 | BN13: PO8 | BO13: PO9 | BP13: PO10 | BQ13: PO11 | BR13: PO12
A14: S/N | B14: Student ID | C14: Name | D14: =D3 -> 12 | E14: =E3 -> 18 | F14: =F3 | G14: =G3 | H14: =H3 | I14: =I3 | J14: =D4 -> 20 | K14: =E4 -> 20 | L14: =F4 | M14: =G4 | N14: =H4 | O14: =I4 | P14: =D5 -> 10 | Q14: =E5 -> 20 | R14: =F5 | S14: =G5 | T14: =H5 | U14: =I5 | V14: =D6 | W14: =E6 | X14: =F6 | Y14: =G6 | Z14: =H6 | AA14: =I6 | AB14: =SUM(P14,D14,J14) -> 42 | AC14: =SUM(K14,E14,Q14) -> 58 | AD14: =SUM(L14,F14,R14) -> 0 | AE14: =SUM(M14,G14,S14) -> 0 | AF14: =SUM(N14,H14,T14) -> 0 | AG14: =SUM(O14,I14,U14) -> 0 | AH14: 1 | AI14: 1 | AJ14: 1 | AK14: 1 | AL14: 1 | AM14: 1 | AN14: If CO achieved (≥55%) then 1, else 0 | AU14: 1 | AV14: 1 | AW14: 1 | AX14: 1 | AY14: 1 | AZ14: 1 | BA14: 1 | BB14: 1 | BC14: 1 | BD14: 1 | BE14: 1 | BF14: 1 | BG14: If PO achieved (≥55%) then 1, else 0
A15: 1 | B15: 201014102 | C15: Most. Zarin Tasnim Rifa | D15: =ROUNDUP((GradeSheet!D10/30)*12,0) -> 8 | E15: =GradeSheet!D10-D15 -> 11 | J15: =INT(GradeSheet!E10/2) -> 16 | K15: =GradeSheet!E10-J15 -> 16 | P15: =ROUNDUP((RawMarks!M2/30)*10,0) -> 9 | Q15: =GradeSheet!F10-P15 -> 16 | AB15: =SUM(P15,D15,J15) -> 33 | AC15: =SUM(W15,E15,K15,Q15) -> 43 | AD15: =SUM(X15,F15,L15) -> 0 | AE15: =SUM(Y15,G15,M15) -> 0 | AF15: =SUM(T15,H15,N15) -> 0 | AG15: =SUM(AA15,I15,O15) -> 0 | AH15: =IF(AB15 = 0, 0, AB15/AB$14) -> 0.78571429 | AI15: =IF(AC15 = 0, 0, AC15/AC$14) -> 0.74137931 | AJ15: =IF(AD15 = 0, 0, AD15/AD$14) -> 0 | AK15: =IF(AE15 = 0, 0, AE15/AE$14) -> 0 | AL15: =IF(AF15 = 0, 0, AF15/AF$14) -> 0 | AM15: =IF(AG15 = 0, 0, AG15/AG$14) -> 0 | AN15: =IF(OR(GradeSheet!$I10="W (Withdrawn)", GradeSheet!$I10="I (Incomplete)"), 0, IF(AH15>=55%, 1, 0)) -> 1 | AO15: =IF(OR(GradeSheet!$I10="W (Withdrawn)", GradeSheet!$I10="I (Incomplete)"), 0, IF(AI15>=55%, 1, 0)) -> 1 | AP15: =IF(OR(GradeSheet!$I10="W (Withdrawn)", GradeSheet!$I10="I (Incomplete)"), 0, IF(AJ15>=55%, 1, 0)) -> 0 | AQ15: =IF(OR(GradeSheet!$I10="W (Withdrawn)", GradeSheet!$I10="I (Incomplete)"), 0, IF(AK15>=55%, 1, 0)) -> 0 | AR15: =IF(OR(GradeSheet!$I10="W (Withdrawn)", GradeSheet!$I10="I (Incomplete)"), 0, IF(AL15>=55%, 1, 0)) -> 0 | AS15: =IF(OR(GradeSheet!$I10="W (Withdrawn)", GradeSheet!$I10="I (Incomplete)"), 0, IF(AM15>=55%, 1, 0)) -> 0 | AU15: =IF($AT$9=0,0,MMULT($AH15:$AM15, AT$3:AT$8)/$AT$9) -> 0 | AV15: =IF($AU$9=0,0,MMULT($AH15:$AM15, AU$3:AU$8)/$AU$9) -> 0 | AW15: {=IF($AV$9=0,0,MMULT($AH15:$AM15, AV$3:AV$8)/$AV$9)} -> 0 | AX15: {=IF($AW$9=0,0,MMULT($AH15:$AM15, AW$3:AW$8)/$AW$9)} -> 0 | AY15: =IF($AX$9=0,0,MMULT($AH15:$AM15, AX$3:AX$8)/$AX$9) -> 0 | AZ15: {=IF($AY$9=0,0,MMULT($AH15:$AM15, AY$3:AY$8)/$AY$9)} -> 0 | BA15: {=IF($AZ$9=0,0,MMULT($AH15:$AM15, AZ$3:AZ$8)/$AZ$9)} -> 0 | BB15: {=IF($BA$9=0,0,MMULT($AH15:$AM15, BA$3:BA$8)/$BA$9)} -> 0 | BC15: {=IF($BB$9=0,0,MMULT($AH15:$AM15, BB$3:BB$8)/$BB$9)} -> 0 | BD15: {=IF($BC$9=0,0,MMULT($AH15:$AM15, BC$3:BC$8)/$BC$9)} -> 0 | BE15: =IF($BD$9=0,0,MMULT($AH15:$AM15, BD$3:BD$8)/$BD$9) -> 0 | BF15: =IF($BE$9=0,0,MMULT($AH15:$AM15, BE$3:BE$8)/$BE$9) -> 0 | BG15: =IF(OR(GradeSheet!$I10="W (Withdrawn)", GradeSheet!$I10="I (Incomplete)"), 0, IF(AU15>=65%, 1, 0)) -> 0 | BH15: =IF(OR(GradeSheet!$I10="W (Withdrawn)", GradeSheet!$I10="I (Incomplete)"), 0, IF(AV15>=65%, 1, 0)) -> 0 | BI15: =IF(OR(GradeSheet!$I10="W (Withdrawn)", GradeSheet!$I10="I (Incomplete)"), 0, IF(AW15>=65%, 1, 0)) -> 0 | BJ15: =IF(OR(GradeSheet!$I10="W (Withdrawn)", GradeSheet!$I10="I (Incomplete)"), 0, IF(AX15>=65%, 1, 0)) -> 0 | BK15: =IF(OR(GradeSheet!$I10="W (Withdrawn)", GradeSheet!$I10="I (Incomplete)"), 0, IF(AY15>=65%, 1, 0)) -> 0 | BL15: =IF(OR(GradeSheet!$I10="W (Withdrawn)", GradeSheet!$I10="I (Incomplete)"), 0, IF(AZ15>=65%, 1, 0)) -> 0 | BM15: =IF(OR(GradeSheet!$I10="W (Withdrawn)", GradeSheet!$I10="I (Incomplete)"), 0, IF(BA15>=65%, 1, 0)) -> 0 | BN15: =IF(OR(GradeSheet!$I10="W (Withdrawn)", GradeSheet!$I10="I (Incomplete)"), 0, IF(BB15>=65%, 1, 0)) -> 0 | ... BR15: =IF(OR(GradeSheet!$I10="W (Withdrawn)", GradeSheet!$I10="I (Incomplete)"), 0, IF(BF15>=65%, 1, 0)) -> 0
A16: 2 | B16: 213014022 | C16: Mohammad Asif Mahmud | D16: =ROUNDUP((GradeSheet!D11/30)*12,0) -> 9 | E16: =GradeSheet!D11-D16 -> 13 | J16: =INT(GradeSheet!E11/2) -> 12 | K16: =GradeSheet!E11-J16 -> 13 | P16: =ROUNDUP((RawMarks!M3/30)*10,0) -> 7 | Q16: =GradeSheet!F11-P16 -> 13 | AB16: =SUM(P16,D16,J16) -> 28 | AC16: =SUM(W16,E16,K16,Q16) -> 39 | AD16: =SUM(X16,F16,L16) -> 0 | AE16: =SUM(Y16,G16,M16) -> 0 | AF16: =SUM(T16,H16,N16) -> 0 | AG16: =SUM(AA16,I16,O16) -> 0 | AH16: =IF(AB16 = 0, 0, AB16/AB$14) -> 0.66666667 | AI16: =IF(AC16 = 0, 0, AC16/AC$14) -> 0.67241379 | AJ16: =IF(AD16 = 0, 0, AD16/AD$14) -> 0 | AK16: =IF(AE16 = 0, 0, AE16/AE$14) -> 0 | AL16: =IF(AF16 = 0, 0, AF16/AF$14) -> 0 | AM16: =IF(AG16 = 0, 0, AG16/AG$14) -> 0 | AN16: =IF(OR(GradeSheet!$I11="W (Withdrawn)", GradeSheet!$I11="I (Incomplete)"), 0, IF(AH16>=55%, 1, 0)) -> 1 | AO16: =IF(OR(GradeSheet!$I11="W (Withdrawn)", GradeSheet!$I11="I (Incomplete)"), 0, IF(AI16>=55%, 1, 0)) -> 1 | AP16: =IF(OR(GradeSheet!$I11="W (Withdrawn)", GradeSheet!$I11="I (Incomplete)"), 0, IF(AJ16>=55%, 1, 0)) -> 0 | AQ16: =IF(OR(GradeSheet!$I11="W (Withdrawn)", GradeSheet!$I11="I (Incomplete)"), 0, IF(AK16>=55%, 1, 0)) -> 0 | AR16: =IF(OR(GradeSheet!$I11="W (Withdrawn)", GradeSheet!$I11="I (Incomplete)"), 0, IF(AL16>=55%, 1, 0)) -> 0 | AS16: =IF(OR(GradeSheet!$I11="W (Withdrawn)", GradeSheet!$I11="I (Incomplete)"), 0, IF(AM16>=55%, 1, 0)) -> 0 | AU16: =IF($AT$9=0,0,MMULT($AH16:$AM16, AT$3:AT$8)/$AT$9) -> 0 | AV16: =IF($AU$9=0,0,MMULT($AH16:$AM16, AU$3:AU$8)/$AU$9) -> 0 | AW16: {=IF($AV$9=0,0,MMULT($AH16:$AM16, AV$3:AV$8)/$AV$9)} -> 0 | AX16: {=IF($AW$9=0,0,MMULT($AH16:$AM16, AW$3:AW$8)/$AW$9)} -> 0 | AY16: =IF($AX$9=0,0,MMULT($AH16:$AM16, AX$3:AX$8)/$AX$9) -> 0 | AZ16: {=IF($AY$9=0,0,MMULT($AH16:$AM16, AY$3:AY$8)/$AY$9)} -> 0 | BA16: {=IF($AZ$9=0,0,MMULT($AH16:$AM16, AZ$3:AZ$8)/$AZ$9)} -> 0 | BB16: {=IF($BA$9=0,0,MMULT($AH16:$AM16, BA$3:BA$8)/$BA$9)} -> 0 | BC16: {=IF($BB$9=0,0,MMULT($AH16:$AM16, BB$3:BB$8)/$BB$9)} -> 0 | BD16: {=IF($BC$9=0,0,MMULT($AH16:$AM16, BC$3:BC$8)/$BC$9)} -> 0 | BE16: =IF($BD$9=0,0,MMULT($AH16:$AM16, BD$3:BD$8)/$BD$9) -> 0 | BF16: =IF($BE$9=0,0,MMULT($AH16:$AM16, BE$3:BE$8)/$BE$9) -> 0 | BG16: =IF(OR(GradeSheet!$I11="W (Withdrawn)", GradeSheet!$I11="I (Incomplete)"), 0, IF(AU16>=65%, 1, 0)) -> 0 | BH16: =IF(OR(GradeSheet!$I11="W (Withdrawn)", GradeSheet!$I11="I (Incomplete)"), 0, IF(AV16>=65%, 1, 0)) -> 0 | BI16: =IF(OR(GradeSheet!$I11="W (Withdrawn)", GradeSheet!$I11="I (Incomplete)"), 0, IF(AW16>=65%, 1, 0)) -> 0 | BJ16: =IF(OR(GradeSheet!$I11="W (Withdrawn)", GradeSheet!$I11="I (Incomplete)"), 0, IF(AX16>=65%, 1, 0)) -> 0 | BK16: =IF(OR(GradeSheet!$I11="W (Withdrawn)", GradeSheet!$I11="I (Incomplete)"), 0, IF(AY16>=65%, 1, 0)) -> 0 | BL16: =IF(OR(GradeSheet!$I11="W (Withdrawn)", GradeSheet!$I11="I (Incomplete)"), 0, IF(AZ16>=65%, 1, 0)) -> 0 | BM16: =IF(OR(GradeSheet!$I11="W (Withdrawn)", GradeSheet!$I11="I (Incomplete)"), 0, IF(BA16>=65%, 1, 0)) -> 0 | BN16: =IF(OR(GradeSheet!$I11="W (Withdrawn)", GradeSheet!$I11="I (Incomplete)"), 0, IF(BB16>=65%, 1, 0)) -> 0 | ... BR16: =IF(OR(GradeSheet!$I11="W (Withdrawn)", GradeSheet!$I11="I (Incomplete)"), 0, IF(BF16>=65%, 1, 0)) -> 0
A17: 3 | B17: 221014083 | C17: Salina Akter | D17: =ROUNDUP((GradeSheet!D12/30)*12,0) -> 5 | E17: =GradeSheet!D12-D17 -> 7 | J17: =INT(GradeSheet!E12/2) -> 0 | K17: =GradeSheet!E12-J17 -> 0 | P17: =ROUNDUP((RawMarks!M4/30)*10,0) -> 0 | Q17: =GradeSheet!F12-P17 -> 0 | AB17: =SUM(P17,D17,J17) -> 5 | AC17: =SUM(W17,E17,K17,Q17) -> 7 | AD17: =SUM(X17,F17,L17) -> 0 | AE17: =SUM(Y17,G17,M17) -> 0 | AF17: =SUM(T17,H17,N17) -> 0 | AG17: =SUM(AA17,I17,O17) -> 0 | AH17: =IF(AB17 = 0, 0, AB17/AB$14) -> 0.11904762 | AI17: =IF(AC17 = 0, 0, AC17/AC$14) -> 0.12068966 | AJ17: =IF(AD17 = 0, 0, AD17/AD$14) -> 0 | AK17: =IF(AE17 = 0, 0, AE17/AE$14) -> 0 | AL17: =IF(AF17 = 0, 0, AF17/AF$14) -> 0 | AM17: =IF(AG17 = 0, 0, AG17/AG$14) -> 0 | AN17: =IF(OR(GradeSheet!$I12="W (Withdrawn)", GradeSheet!$I12="I (Incomplete)"), 0, IF(AH17>=55%, 1, 0)) -> 0 | AO17: =IF(OR(GradeSheet!$I12="W (Withdrawn)", GradeSheet!$I12="I (Incomplete)"), 0, IF(AI17>=55%, 1, 0)) -> 0 | AP17: =IF(OR(GradeSheet!$I12="W (Withdrawn)", GradeSheet!$I12="I (Incomplete)"), 0, IF(AJ17>=55%, 1, 0)) -> 0 | AQ17: =IF(OR(GradeSheet!$I12="W (Withdrawn)", GradeSheet!$I12="I (Incomplete)"), 0, IF(AK17>=55%, 1, 0)) -> 0 | AR17: =IF(OR(GradeSheet!$I12="W (Withdrawn)", GradeSheet!$I12="I (Incomplete)"), 0, IF(AL17>=55%, 1, 0)) -> 0 | AS17: =IF(OR(GradeSheet!$I12="W (Withdrawn)", GradeSheet!$I12="I (Incomplete)"), 0, IF(AM17>=55%, 1, 0)) -> 0 | AU17: =IF($AT$9=0,0,MMULT($AH17:$AM17, AT$3:AT$8)/$AT$9) -> 0 | AV17: =IF($AU$9=0,0,MMULT($AH17:$AM17, AU$3:AU$8)/$AU$9) -> 0 | AW17: {=IF($AV$9=0,0,MMULT($AH17:$AM17, AV$3:AV$8)/$AV$9)} -> 0 | AX17: {=IF($AW$9=0,0,MMULT($AH17:$AM17, AW$3:AW$8)/$AW$9)} -> 0 | AY17: =IF($AX$9=0,0,MMULT($AH17:$AM17, AX$3:AX$8)/$AX$9) -> 0 | AZ17: {=IF($AY$9=0,0,MMULT($AH17:$AM17, AY$3:AY$8)/$AY$9)} -> 0 | BA17: {=IF($AZ$9=0,0,MMULT($AH17:$AM17, AZ$3:AZ$8)/$AZ$9)} -> 0 | BB17: {=IF($BA$9=0,0,MMULT($AH17:$AM17, BA$3:BA$8)/$BA$9)} -> 0 | BC17: {=IF($BB$9=0,0,MMULT($AH17:$AM17, BB$3:BB$8)/$BB$9)} -> 0 | BD17: {=IF($BC$9=0,0,MMULT($AH17:$AM17, BC$3:BC$8)/$BC$9)} -> 0 | BE17: =IF($BD$9=0,0,MMULT($AH17:$AM17, BD$3:BD$8)/$BD$9) -> 0 | BF17: =IF($BE$9=0,0,MMULT($AH17:$AM17, BE$3:BE$8)/$BE$9) -> 0 | BG17: =IF(OR(GradeSheet!$I12="W (Withdrawn)", GradeSheet!$I12="I (Incomplete)"), 0, IF(AU17>=65%, 1, 0)) -> 0 | BH17: =IF(OR(GradeSheet!$I12="W (Withdrawn)", GradeSheet!$I12="I (Incomplete)"), 0, IF(AV17>=65%, 1, 0)) -> 0 | BI17: =IF(OR(GradeSheet!$I12="W (Withdrawn)", GradeSheet!$I12="I (Incomplete)"), 0, IF(AW17>=65%, 1, 0)) -> 0 | BJ17: =IF(OR(GradeSheet!$I12="W (Withdrawn)", GradeSheet!$I12="I (Incomplete)"), 0, IF(AX17>=65%, 1, 0)) -> 0 | BK17: =IF(OR(GradeSheet!$I12="W (Withdrawn)", GradeSheet!$I12="I (Incomplete)"), 0, IF(AY17>=65%, 1, 0)) -> 0 | BL17: =IF(OR(GradeSheet!$I12="W (Withdrawn)", GradeSheet!$I12="I (Incomplete)"), 0, IF(AZ17>=65%, 1, 0)) -> 0 | BM17: =IF(OR(GradeSheet!$I12="W (Withdrawn)", GradeSheet!$I12="I (Incomplete)"), 0, IF(BA17>=65%, 1, 0)) -> 0 | BN17: =IF(OR(GradeSheet!$I12="W (Withdrawn)", GradeSheet!$I12="I (Incomplete)"), 0, IF(BB17>=65%, 1, 0)) -> 0 | ... BR17: =IF(OR(GradeSheet!$I12="W (Withdrawn)", GradeSheet!$I12="I (Incomplete)"), 0, IF(BF17>=65%, 1, 0)) -> 0
A18: 4 | B18: 221014111 | C18: Abdullah Bin Noor Tazim | D18: =ROUNDUP((GradeSheet!D13/30)*12,0) -> 5 | E18: =GradeSheet!D13-D18 -> 6 | J18: =INT(GradeSheet!E13/2) -> 15 | K18: =GradeSheet!E13-J18 -> 15 | P18: =ROUNDUP((RawMarks!M5/30)*10,0) -> 8 | Q18: =GradeSheet!F13-P18 -> 16 | AB18: =SUM(P18,D18,J18) -> 28 | AC18: =SUM(W18,E18,K18,Q18) -> 37 | AD18: =SUM(X18,F18,L18) -> 0 | AE18: =SUM(Y18,G18,M18) -> 0 | AF18: =SUM(T18,H18,N18) -> 0 | AG18: =SUM(AA18,I18,O18) -> 0 | AH18: =IF(AB18 = 0, 0, AB18/AB$14) -> 0.66666667 | AI18: =IF(AC18 = 0, 0, AC18/AC$14) -> 0.63793103 | AJ18: =IF(AD18 = 0, 0, AD18/AD$14) -> 0 | AK18: =IF(AE18 = 0, 0, AE18/AE$14) -> 0 | AL18: =IF(AF18 = 0, 0, AF18/AF$14) -> 0 | AM18: =IF(AG18 = 0, 0, AG18/AG$14) -> 0 | AN18: =IF(OR(GradeSheet!$I13="W (Withdrawn)", GradeSheet!$I13="I (Incomplete)"), 0, IF(AH18>=55%, 1, 0)) -> 1 | AO18: =IF(OR(GradeSheet!$I13="W (Withdrawn)", GradeSheet!$I13="I (Incomplete)"), 0, IF(AI18>=55%, 1, 0)) -> 1 | AP18: =IF(OR(GradeSheet!$I13="W (Withdrawn)", GradeSheet!$I13="I (Incomplete)"), 0, IF(AJ18>=55%, 1, 0)) -> 0 | AQ18: =IF(OR(GradeSheet!$I13="W (Withdrawn)", GradeSheet!$I13="I (Incomplete)"), 0, IF(AK18>=55%, 1, 0)) -> 0 | AR18: =IF(OR(GradeSheet!$I13="W (Withdrawn)", GradeSheet!$I13="I (Incomplete)"), 0, IF(AL18>=55%, 1, 0)) -> 0 | AS18: =IF(OR(GradeSheet!$I13="W (Withdrawn)", GradeSheet!$I13="I (Incomplete)"), 0, IF(AM18>=55%, 1, 0)) -> 0 | AU18: =IF($AT$9=0,0,MMULT($AH18:$AM18, AT$3:AT$8)/$AT$9) -> 0 | AV18: =IF($AU$9=0,0,MMULT($AH18:$AM18, AU$3:AU$8)/$AU$9) -> 0 | AW18: {=IF($AV$9=0,0,MMULT($AH18:$AM18, AV$3:AV$8)/$AV$9)} -> 0 | AX18: {=IF($AW$9=0,0,MMULT($AH18:$AM18, AW$3:AW$8)/$AW$9)} -> 0 | AY18: =IF($AX$9=0,0,MMULT($AH18:$AM18, AX$3:AX$8)/$AX$9) -> 0 | AZ18: {=IF($AY$9=0,0,MMULT($AH18:$AM18, AY$3:AY$8)/$AY$9)} -> 0 | BA18: {=IF($AZ$9=0,0,MMULT($AH18:$AM18, AZ$3:AZ$8)/$AZ$9)} -> 0 | BB18: {=IF($BA$9=0,0,MMULT($AH18:$AM18, BA$3:BA$8)/$BA$9)} -> 0 | BC18: {=IF($BB$9=0,0,MMULT($AH18:$AM18, BB$3:BB$8)/$BB$9)} -> 0 | BD18: {=IF($BC$9=0,0,MMULT($AH18:$AM18, BC$3:BC$8)/$BC$9)} -> 0 | BE18: =IF($BD$9=0,0,MMULT($AH18:$AM18, BD$3:BD$8)/$BD$9) -> 0 | BF18: =IF($BE$9=0,0,MMULT($AH18:$AM18, BE$3:BE$8)/$BE$9) -> 0 | BG18: =IF(OR(GradeSheet!$I13="W (Withdrawn)", GradeSheet!$I13="I (Incomplete)"), 0, IF(AU18>=65%, 1, 0)) -> 0 | BH18: =IF(OR(GradeSheet!$I13="W (Withdrawn)", GradeSheet!$I13="I (Incomplete)"), 0, IF(AV18>=65%, 1, 0)) -> 0 | BI18: =IF(OR(GradeSheet!$I13="W (Withdrawn)", GradeSheet!$I13="I (Incomplete)"), 0, IF(AW18>=65%, 1, 0)) -> 0 | BJ18: =IF(OR(GradeSheet!$I13="W (Withdrawn)", GradeSheet!$I13="I (Incomplete)"), 0, IF(AX18>=65%, 1, 0)) -> 0 | BK18: =IF(OR(GradeSheet!$I13="W (Withdrawn)", GradeSheet!$I13="I (Incomplete)"), 0, IF(AY18>=65%, 1, 0)) -> 0 | BL18: =IF(OR(GradeSheet!$I13="W (Withdrawn)", GradeSheet!$I13="I (Incomplete)"), 0, IF(AZ18>=65%, 1, 0)) -> 0 | BM18: =IF(OR(GradeSheet!$I13="W (Withdrawn)", GradeSheet!$I13="I (Incomplete)"), 0, IF(BA18>=65%, 1, 0)) -> 0 | BN18: =IF(OR(GradeSheet!$I13="W (Withdrawn)", GradeSheet!$I13="I (Incomplete)"), 0, IF(BB18>=65%, 1, 0)) -> 0 | ... BR18: =IF(OR(GradeSheet!$I13="W (Withdrawn)", GradeSheet!$I13="I (Incomplete)"), 0, IF(BF18>=65%, 1, 0)) -> 0
A19: 5 | B19: 221014129 | C19: Fuyad Hasan Bhoyan | D19: =ROUNDUP((GradeSheet!D14/30)*12,0) -> 2 | E19: =GradeSheet!D14-D19 -> 2 | J19: =INT(GradeSheet!E14/2) -> 0 | K19: =GradeSheet!E14-J19 -> 0 | P19: =ROUNDUP((RawMarks!M6/30)*10,0) -> 0 | Q19: =GradeSheet!F14-P19 -> 0 | AB19: =SUM(P19,D19,J19) -> 2 | AC19: =SUM(W19,E19,K19,Q19) -> 2 | AD19: =SUM(X19,F19,L19) -> 0 | AE19: =SUM(Y19,G19,M19) -> 0 | AF19: =SUM(T19,H19,N19) -> 0 | AG19: =SUM(AA19,I19,O19) -> 0 | AH19: =IF(AB19 = 0, 0, AB19/AB$14) -> 0.047619048 | AI19: =IF(AC19 = 0, 0, AC19/AC$14) -> 0.034482759 | AJ19: =IF(AD19 = 0, 0, AD19/AD$14) -> 0 | AK19: =IF(AE19 = 0, 0, AE19/AE$14) -> 0 | AL19: =IF(AF19 = 0, 0, AF19/AF$14) -> 0 | AM19: =IF(AG19 = 0, 0, AG19/AG$14) -> 0 | AN19: =IF(OR(GradeSheet!$I14="W (Withdrawn)", GradeSheet!$I14="I (Incomplete)"), 0, IF(AH19>=55%, 1, 0)) -> 0 | AO19: =IF(OR(GradeSheet!$I14="W (Withdrawn)", GradeSheet!$I14="I (Incomplete)"), 0, IF(AI19>=55%, 1, 0)) -> 0 | AP19: =IF(OR(GradeSheet!$I14="W (Withdrawn)", GradeSheet!$I14="I (Incomplete)"), 0, IF(AJ19>=55%, 1, 0)) -> 0 | AQ19: =IF(OR(GradeSheet!$I14="W (Withdrawn)", GradeSheet!$I14="I (Incomplete)"), 0, IF(AK19>=55%, 1, 0)) -> 0 | AR19: =IF(OR(GradeSheet!$I14="W (Withdrawn)", GradeSheet!$I14="I (Incomplete)"), 0, IF(AL19>=55%, 1, 0)) -> 0 | AS19: =IF(OR(GradeSheet!$I14="W (Withdrawn)", GradeSheet!$I14="I (Incomplete)"), 0, IF(AM19>=55%, 1, 0)) -> 0 | AU19: =IF($AT$9=0,0,MMULT($AH19:$AM19, AT$3:AT$8)/$AT$9) -> 0 | AV19: =IF($AU$9=0,0,MMULT($AH19:$AM19, AU$3:AU$8)/$AU$9) -> 0 | AW19: {=IF($AV$9=0,0,MMULT($AH19:$AM19, AV$3:AV$8)/$AV$9)} -> 0 | AX19: {=IF($AW$9=0,0,MMULT($AH19:$AM19, AW$3:AW$8)/$AW$9)} -> 0 | AY19: =IF($AX$9=0,0,MMULT($AH19:$AM19, AX$3:AX$8)/$AX$9) -> 0 | AZ19: {=IF($AY$9=0,0,MMULT($AH19:$AM19, AY$3:AY$8)/$AY$9)} -> 0 | BA19: {=IF($AZ$9=0,0,MMULT($AH19:$AM19, AZ$3:AZ$8)/$AZ$9)} -> 0 | BB19: {=IF($BA$9=0,0,MMULT($AH19:$AM19, BA$3:BA$8)/$BA$9)} -> 0 | BC19: {=IF($BB$9=0,0,MMULT($AH19:$AM19, BB$3:BB$8)/$BB$9)} -> 0 | BD19: {=IF($BC$9=0,0,MMULT($AH19:$AM19, BC$3:BC$8)/$BC$9)} -> 0 | BE19: =IF($BD$9=0,0,MMULT($AH19:$AM19, BD$3:BD$8)/$BD$9) -> 0 | BF19: =IF($BE$9=0,0,MMULT($AH19:$AM19, BE$3:BE$8)/$BE$9) -> 0 | BG19: =IF(OR(GradeSheet!$I14="W (Withdrawn)", GradeSheet!$I14="I (Incomplete)"), 0, IF(AU19>=65%, 1, 0)) -> 0 | BH19: =IF(OR(GradeSheet!$I14="W (Withdrawn)", GradeSheet!$I14="I (Incomplete)"), 0, IF(AV19>=65%, 1, 0)) -> 0 | BI19: =IF(OR(GradeSheet!$I14="W (Withdrawn)", GradeSheet!$I14="I (Incomplete)"), 0, IF(AW19>=65%, 1, 0)) -> 0 | BJ19: =IF(OR(GradeSheet!$I14="W (Withdrawn)", GradeSheet!$I14="I (Incomplete)"), 0, IF(AX19>=65%, 1, 0)) -> 0 | BK19: =IF(OR(GradeSheet!$I14="W (Withdrawn)", GradeSheet!$I14="I (Incomplete)"), 0, IF(AY19>=65%, 1, 0)) -> 0 | BL19: =IF(OR(GradeSheet!$I14="W (Withdrawn)", GradeSheet!$I14="I (Incomplete)"), 0, IF(AZ19>=65%, 1, 0)) -> 0 | BM19: =IF(OR(GradeSheet!$I14="W (Withdrawn)", GradeSheet!$I14="I (Incomplete)"), 0, IF(BA19>=65%, 1, 0)) -> 0 | BN19: =IF(OR(GradeSheet!$I14="W (Withdrawn)", GradeSheet!$I14="I (Incomplete)"), 0, IF(BB19>=65%, 1, 0)) -> 0 | ... BR19: =IF(OR(GradeSheet!$I14="W (Withdrawn)", GradeSheet!$I14="I (Incomplete)"), 0, IF(BF19>=65%, 1, 0)) -> 0
A20: 6 | B20: 221014136 | C20: Prashanta Sarker | D20: =ROUNDUP((GradeSheet!D15/30)*12,0) -> 11 | E20: =GradeSheet!D15-D20 -> 16 | J20: =INT(GradeSheet!E15/2) -> 15 | K20: =GradeSheet!E15-J20 -> 15 | P20: =ROUNDUP((RawMarks!M7/30)*10,0) -> 10 | Q20: =GradeSheet!F15-P20 -> 18 | AB20: =SUM(P20,D20,J20) -> 36 | AC20: =SUM(W20,E20,K20,Q20) -> 49 | AD20: =SUM(X20,F20,L20) -> 0 | AE20: =SUM(Y20,G20,M20) -> 0 | AF20: =SUM(T20,H20,N20) -> 0 | AG20: =SUM(AA20,I20,O20) -> 0 | AH20: =IF(AB20 = 0, 0, AB20/AB$14) -> 0.85714286 | AI20: =IF(AC20 = 0, 0, AC20/AC$14) -> 0.84482759 | AJ20: =IF(AD20 = 0, 0, AD20/AD$14) -> 0 | AK20: =IF(AE20 = 0, 0, AE20/AE$14) -> 0 | AL20: =IF(AF20 = 0, 0, AF20/AF$14) -> 0 | AM20: =IF(AG20 = 0, 0, AG20/AG$14) -> 0 | AN20: =IF(OR(GradeSheet!$I15="W (Withdrawn)", GradeSheet!$I15="I (Incomplete)"), 0, IF(AH20>=55%, 1, 0)) -> 1 | AO20: =IF(OR(GradeSheet!$I15="W (Withdrawn)", GradeSheet!$I15="I (Incomplete)"), 0, IF(AI20>=55%, 1, 0)) -> 1 | AP20: =IF(OR(GradeSheet!$I15="W (Withdrawn)", GradeSheet!$I15="I (Incomplete)"), 0, IF(AJ20>=55%, 1, 0)) -> 0 | AQ20: =IF(OR(GradeSheet!$I15="W (Withdrawn)", GradeSheet!$I15="I (Incomplete)"), 0, IF(AK20>=55%, 1, 0)) -> 0 | AR20: =IF(OR(GradeSheet!$I15="W (Withdrawn)", GradeSheet!$I15="I (Incomplete)"), 0, IF(AL20>=55%, 1, 0)) -> 0 | AS20: =IF(OR(GradeSheet!$I15="W (Withdrawn)", GradeSheet!$I15="I (Incomplete)"), 0, IF(AM20>=55%, 1, 0)) -> 0 | AU20: =IF($AT$9=0,0,MMULT($AH20:$AM20, AT$3:AT$8)/$AT$9) -> 0 | AV20: =IF($AU$9=0,0,MMULT($AH20:$AM20, AU$3:AU$8)/$AU$9) -> 0 | AW20: {=IF($AV$9=0,0,MMULT($AH20:$AM20, AV$3:AV$8)/$AV$9)} -> 0 | AX20: {=IF($AW$9=0,0,MMULT($AH20:$AM20, AW$3:AW$8)/$AW$9)} -> 0 | AY20: =IF($AX$9=0,0,MMULT($AH20:$AM20, AX$3:AX$8)/$AX$9) -> 0 | AZ20: {=IF($AY$9=0,0,MMULT($AH20:$AM20, AY$3:AY$8)/$AY$9)} -> 0 | BA20: {=IF($AZ$9=0,0,MMULT($AH20:$AM20, AZ$3:AZ$8)/$AZ$9)} -> 0 | BB20: {=IF($BA$9=0,0,MMULT($AH20:$AM20, BA$3:BA$8)/$BA$9)} -> 0 | BC20: {=IF($BB$9=0,0,MMULT($AH20:$AM20, BB$3:BB$8)/$BB$9)} -> 0 | BD20: {=IF($BC$9=0,0,MMULT($AH20:$AM20, BC$3:BC$8)/$BC$9)} -> 0 | BE20: =IF($BD$9=0,0,MMULT($AH20:$AM20, BD$3:BD$8)/$BD$9) -> 0 | BF20: =IF($BE$9=0,0,MMULT($AH20:$AM20, BE$3:BE$8)/$BE$9) -> 0 | BG20: =IF(OR(GradeSheet!$I15="W (Withdrawn)", GradeSheet!$I15="I (Incomplete)"), 0, IF(AU20>=65%, 1, 0)) -> 0 | BH20: =IF(OR(GradeSheet!$I15="W (Withdrawn)", GradeSheet!$I15="I (Incomplete)"), 0, IF(AV20>=65%, 1, 0)) -> 0 | BI20: =IF(OR(GradeSheet!$I15="W (Withdrawn)", GradeSheet!$I15="I (Incomplete)"), 0, IF(AW20>=65%, 1, 0)) -> 0 | BJ20: =IF(OR(GradeSheet!$I15="W (Withdrawn)", GradeSheet!$I15="I (Incomplete)"), 0, IF(AX20>=65%, 1, 0)) -> 0 | BK20: =IF(OR(GradeSheet!$I15="W (Withdrawn)", GradeSheet!$I15="I (Incomplete)"), 0, IF(AY20>=65%, 1, 0)) -> 0 | BL20: =IF(OR(GradeSheet!$I15="W (Withdrawn)", GradeSheet!$I15="I (Incomplete)"), 0, IF(AZ20>=65%, 1, 0)) -> 0 | BM20: =IF(OR(GradeSheet!$I15="W (Withdrawn)", GradeSheet!$I15="I (Incomplete)"), 0, IF(BA20>=65%, 1, 0)) -> 0 | BN20: =IF(OR(GradeSheet!$I15="W (Withdrawn)", GradeSheet!$I15="I (Incomplete)"), 0, IF(BB20>=65%, 1, 0)) -> 0 | ... BR20: =IF(OR(GradeSheet!$I15="W (Withdrawn)", GradeSheet!$I15="I (Incomplete)"), 0, IF(BF20>=65%, 1, 0)) -> 0
A21: 7 | B21: 222014021 | C21: Rasel Rahman | D21: =ROUNDUP((GradeSheet!D16/30)*12,0) -> 6 | E21: =GradeSheet!D16-D21 -> 8 | J21: =INT(GradeSheet!E16/2) -> 12 | K21: =GradeSheet!E16-J21 -> 13 | P21: =ROUNDUP((RawMarks!M8/30)*10,0) -> 8 | Q21: =GradeSheet!F16-P21 -> 14 | AB21: =SUM(P21,D21,J21) -> 26 | AC21: =SUM(W21,E21,K21,Q21) -> 35 | AD21: =SUM(X21,F21,L21) -> 0 | AE21: =SUM(Y21,G21,M21) -> 0 | AF21: =SUM(T21,H21,N21) -> 0 | AG21: =SUM(AA21,I21,O21) -> 0 | AH21: =IF(AB21 = 0, 0, AB21/AB$14) -> 0.61904762 | AI21: =IF(AC21 = 0, 0, AC21/AC$14) -> 0.60344828 | AJ21: =IF(AD21 = 0, 0, AD21/AD$14) -> 0 | AK21: =IF(AE21 = 0, 0, AE21/AE$14) -> 0 | AL21: =IF(AF21 = 0, 0, AF21/AF$14) -> 0 | AM21: =IF(AG21 = 0, 0, AG21/AG$14) -> 0 | AN21: =IF(OR(GradeSheet!$I16="W (Withdrawn)", GradeSheet!$I16="I (Incomplete)"), 0, IF(AH21>=55%, 1, 0)) -> 1 | AO21: =IF(OR(GradeSheet!$I16="W (Withdrawn)", GradeSheet!$I16="I (Incomplete)"), 0, IF(AI21>=55%, 1, 0)) -> 1 | AP21: =IF(OR(GradeSheet!$I16="W (Withdrawn)", GradeSheet!$I16="I (Incomplete)"), 0, IF(AJ21>=55%, 1, 0)) -> 0 | AQ21: =IF(OR(GradeSheet!$I16="W (Withdrawn)", GradeSheet!$I16="I (Incomplete)"), 0, IF(AK21>=55%, 1, 0)) -> 0 | AR21: =IF(OR(GradeSheet!$I16="W (Withdrawn)", GradeSheet!$I16="I (Incomplete)"), 0, IF(AL21>=55%, 1, 0)) -> 0 | AS21: =IF(OR(GradeSheet!$I16="W (Withdrawn)", GradeSheet!$I16="I (Incomplete)"), 0, IF(AM21>=55%, 1, 0)) -> 0 | AU21: =IF($AT$9=0,0,MMULT($AH21:$AM21, AT$3:AT$8)/$AT$9) -> 0 | AV21: =IF($AU$9=0,0,MMULT($AH21:$AM21, AU$3:AU$8)/$AU$9) -> 0 | AW21: {=IF($AV$9=0,0,MMULT($AH21:$AM21, AV$3:AV$8)/$AV$9)} -> 0 | AX21: {=IF($AW$9=0,0,MMULT($AH21:$AM21, AW$3:AW$8)/$AW$9)} -> 0 | AY21: =IF($AX$9=0,0,MMULT($AH21:$AM21, AX$3:AX$8)/$AX$9) -> 0 | AZ21: {=IF($AY$9=0,0,MMULT($AH21:$AM21, AY$3:AY$8)/$AY$9)} -> 0 | BA21: {=IF($AZ$9=0,0,MMULT($AH21:$AM21, AZ$3:AZ$8)/$AZ$9)} -> 0 | BB21: {=IF($BA$9=0,0,MMULT($AH21:$AM21, BA$3:BA$8)/$BA$9)} -> 0 | BC21: {=IF($BB$9=0,0,MMULT($AH21:$AM21, BB$3:BB$8)/$BB$9)} -> 0 | BD21: {=IF($BC$9=0,0,MMULT($AH21:$AM21, BC$3:BC$8)/$BC$9)} -> 0 | BE21: =IF($BD$9=0,0,MMULT($AH21:$AM21, BD$3:BD$8)/$BD$9) -> 0 | BF21: =IF($BE$9=0,0,MMULT($AH21:$AM21, BE$3:BE$8)/$BE$9) -> 0 | BG21: =IF(OR(GradeSheet!$I16="W (Withdrawn)", GradeSheet!$I16="I (Incomplete)"), 0, IF(AU21>=65%, 1, 0)) -> 0 | BH21: =IF(OR(GradeSheet!$I16="W (Withdrawn)", GradeSheet!$I16="I (Incomplete)"), 0, IF(AV21>=65%, 1, 0)) -> 0 | BI21: =IF(OR(GradeSheet!$I16="W (Withdrawn)", GradeSheet!$I16="I (Incomplete)"), 0, IF(AW21>=65%, 1, 0)) -> 0 | BJ21: =IF(OR(GradeSheet!$I16="W (Withdrawn)", GradeSheet!$I16="I (Incomplete)"), 0, IF(AX21>=65%, 1, 0)) -> 0 | BK21: =IF(OR(GradeSheet!$I16="W (Withdrawn)", GradeSheet!$I16="I (Incomplete)"), 0, IF(AY21>=65%, 1, 0)) -> 0 | BL21: =IF(OR(GradeSheet!$I16="W (Withdrawn)", GradeSheet!$I16="I (Incomplete)"), 0, IF(AZ21>=65%, 1, 0)) -> 0 | BM21: =IF(OR(GradeSheet!$I16="W (Withdrawn)", GradeSheet!$I16="I (Incomplete)"), 0, IF(BA21>=65%, 1, 0)) -> 0 | BN21: =IF(OR(GradeSheet!$I16="W (Withdrawn)", GradeSheet!$I16="I (Incomplete)"), 0, IF(BB21>=65%, 1, 0)) -> 0 | ... BR21: =IF(OR(GradeSheet!$I16="W (Withdrawn)", GradeSheet!$I16="I (Incomplete)"), 0, IF(BF21>=65%, 1, 0)) -> 0
A22: 8 | B22: 222014031 | C22: Raian Zaman | D22: =ROUNDUP((GradeSheet!D17/30)*12,0) -> 12 | E22: =GradeSheet!D17-D22 -> 17 | J22: =INT(GradeSheet!E17/2) -> 17 | K22: =GradeSheet!E17-J22 -> 18 | P22: =ROUNDUP((RawMarks!M9/30)*10,0) -> 9 | Q22: =GradeSheet!F17-P22 -> 17 | AB22: =SUM(P22,D22,J22) -> 38 | AC22: =SUM(W22,E22,K22,Q22) -> 52 | AD22: =SUM(X22,F22,L22) -> 0 | AE22: =SUM(Y22,G22,M22) -> 0 | AF22: =SUM(T22,H22,N22) -> 0 | AG22: =SUM(AA22,I22,O22) -> 0 | AH22: =IF(AB22 = 0, 0, AB22/AB$14) -> 0.9047619 | AI22: =IF(AC22 = 0, 0, AC22/AC$14) -> 0.89655172 | AJ22: =IF(AD22 = 0, 0, AD22/AD$14) -> 0 | AK22: =IF(AE22 = 0, 0, AE22/AE$14) -> 0 | AL22: =IF(AF22 = 0, 0, AF22/AF$14) -> 0 | AM22: =IF(AG22 = 0, 0, AG22/AG$14) -> 0 | AN22: =IF(OR(GradeSheet!$I17="W (Withdrawn)", GradeSheet!$I17="I (Incomplete)"), 0, IF(AH22>=55%, 1, 0)) -> 1 | AO22: =IF(OR(GradeSheet!$I17="W (Withdrawn)", GradeSheet!$I17="I (Incomplete)"), 0, IF(AI22>=55%, 1, 0)) -> 1 | AP22: =IF(OR(GradeSheet!$I17="W (Withdrawn)", GradeSheet!$I17="I (Incomplete)"), 0, IF(AJ22>=55%, 1, 0)) -> 0 | AQ22: =IF(OR(GradeSheet!$I17="W (Withdrawn)", GradeSheet!$I17="I (Incomplete)"), 0, IF(AK22>=55%, 1, 0)) -> 0 | AR22: =IF(OR(GradeSheet!$I17="W (Withdrawn)", GradeSheet!$I17="I (Incomplete)"), 0, IF(AL22>=55%, 1, 0)) -> 0 | AS22: =IF(OR(GradeSheet!$I17="W (Withdrawn)", GradeSheet!$I17="I (Incomplete)"), 0, IF(AM22>=55%, 1, 0)) -> 0 | AU22: =IF($AT$9=0,0,MMULT($AH22:$AM22, AT$3:AT$8)/$AT$9) -> 0 | AV22: =IF($AU$9=0,0,MMULT($AH22:$AM22, AU$3:AU$8)/$AU$9) -> 0 | AW22: {=IF($AV$9=0,0,MMULT($AH22:$AM22, AV$3:AV$8)/$AV$9)} -> 0 | AX22: {=IF($AW$9=0,0,MMULT($AH22:$AM22, AW$3:AW$8)/$AW$9)} -> 0 | AY22: =IF($AX$9=0,0,MMULT($AH22:$AM22, AX$3:AX$8)/$AX$9) -> 0 | AZ22: {=IF($AY$9=0,0,MMULT($AH22:$AM22, AY$3:AY$8)/$AY$9)} -> 0 | BA22: {=IF($AZ$9=0,0,MMULT($AH22:$AM22, AZ$3:AZ$8)/$AZ$9)} -> 0 | BB22: {=IF($BA$9=0,0,MMULT($AH22:$AM22, BA$3:BA$8)/$BA$9)} -> 0 | BC22: {=IF($BB$9=0,0,MMULT($AH22:$AM22, BB$3:BB$8)/$BB$9)} -> 0 | BD22: {=IF($BC$9=0,0,MMULT($AH22:$AM22, BC$3:BC$8)/$BC$9)} -> 0 | BE22: =IF($BD$9=0,0,MMULT($AH22:$AM22, BD$3:BD$8)/$BD$9) -> 0 | BF22: =IF($BE$9=0,0,MMULT($AH22:$AM22, BE$3:BE$8)/$BE$9) -> 0 | BG22: =IF(OR(GradeSheet!$I17="W (Withdrawn)", GradeSheet!$I17="I (Incomplete)"), 0, IF(AU22>=65%, 1, 0)) -> 0 | BH22: =IF(OR(GradeSheet!$I17="W (Withdrawn)", GradeSheet!$I17="I (Incomplete)"), 0, IF(AV22>=65%, 1, 0)) -> 0 | BI22: =IF(OR(GradeSheet!$I17="W (Withdrawn)", GradeSheet!$I17="I (Incomplete)"), 0, IF(AW22>=65%, 1, 0)) -> 0 | BJ22: =IF(OR(GradeSheet!$I17="W (Withdrawn)", GradeSheet!$I17="I (Incomplete)"), 0, IF(AX22>=65%, 1, 0)) -> 0 | BK22: =IF(OR(GradeSheet!$I17="W (Withdrawn)", GradeSheet!$I17="I (Incomplete)"), 0, IF(AY22>=65%, 1, 0)) -> 0 | BL22: =IF(OR(GradeSheet!$I17="W (Withdrawn)", GradeSheet!$I17="I (Incomplete)"), 0, IF(AZ22>=65%, 1, 0)) -> 0 | BM22: =IF(OR(GradeSheet!$I17="W (Withdrawn)", GradeSheet!$I17="I (Incomplete)"), 0, IF(BA22>=65%, 1, 0)) -> 0 | BN22: =IF(OR(GradeSheet!$I17="W (Withdrawn)", GradeSheet!$I17="I (Incomplete)"), 0, IF(BB22>=65%, 1, 0)) -> 0 | ... BR22: =IF(OR(GradeSheet!$I17="W (Withdrawn)", GradeSheet!$I17="I (Incomplete)"), 0, IF(BF22>=65%, 1, 0)) -> 0
A23: 9 | B23: 222014057 | C23: Nur Shahad Srabon | D23: =ROUNDUP((GradeSheet!D18/30)*12,0) -> 0 | E23: =GradeSheet!D18-D23 -> 0 | J23: =INT(GradeSheet!E18/2) -> 0 | K23: =GradeSheet!E18-J23 -> 0 | P23: =ROUNDUP((RawMarks!M10/30)*10,0) -> 0 | Q23: =GradeSheet!F18-P23 -> 0 | AB23: =SUM(P23,D23,J23) -> 0 | AC23: =SUM(W23,E23,K23,Q23) -> 0 | AD23: =SUM(X23,F23,L23) -> 0 | AE23: =SUM(Y23,G23,M23) -> 0 | AF23: =SUM(T23,H23,N23) -> 0 | AG23: =SUM(AA23,I23,O23) -> 0 | AH23: =IF(AB23 = 0, 0, AB23/AB$14) -> 0 | AI23: =IF(AC23 = 0, 0, AC23/AC$14) -> 0 | AJ23: =IF(AD23 = 0, 0, AD23/AD$14) -> 0 | AK23: =IF(AE23 = 0, 0, AE23/AE$14) -> 0 | AL23: =IF(AF23 = 0, 0, AF23/AF$14) -> 0 | AM23: =IF(AG23 = 0, 0, AG23/AG$14) -> 0 | AN23: =IF(OR(GradeSheet!$I18="W (Withdrawn)", GradeSheet!$I18="I (Incomplete)"), 0, IF(AH23>=55%, 1, 0)) -> 0 | AO23: =IF(OR(GradeSheet!$I18="W (Withdrawn)", GradeSheet!$I18="I (Incomplete)"), 0, IF(AI23>=55%, 1, 0)) -> 0 | AP23: =IF(OR(GradeSheet!$I18="W (Withdrawn)", GradeSheet!$I18="I (Incomplete)"), 0, IF(AJ23>=55%, 1, 0)) -> 0 | AQ23: =IF(OR(GradeSheet!$I18="W (Withdrawn)", GradeSheet!$I18="I (Incomplete)"), 0, IF(AK23>=55%, 1, 0)) -> 0 | AR23: =IF(OR(GradeSheet!$I18="W (Withdrawn)", GradeSheet!$I18="I (Incomplete)"), 0, IF(AL23>=55%, 1, 0)) -> 0 | AS23: =IF(OR(GradeSheet!$I18="W (Withdrawn)", GradeSheet!$I18="I (Incomplete)"), 0, IF(AM23>=55%, 1, 0)) -> 0 | AU23: =IF($AT$9=0,0,MMULT($AH23:$AM23, AT$3:AT$8)/$AT$9) -> 0 | AV23: =IF($AU$9=0,0,MMULT($AH23:$AM23, AU$3:AU$8)/$AU$9) -> 0 | AW23: {=IF($AV$9=0,0,MMULT($AH23:$AM23, AV$3:AV$8)/$AV$9)} -> 0 | AX23: {=IF($AW$9=0,0,MMULT($AH23:$AM23, AW$3:AW$8)/$AW$9)} -> 0 | AY23: =IF($AX$9=0,0,MMULT($AH23:$AM23, AX$3:AX$8)/$AX$9) -> 0 | AZ23: {=IF($AY$9=0,0,MMULT($AH23:$AM23, AY$3:AY$8)/$AY$9)} -> 0 | BA23: {=IF($AZ$9=0,0,MMULT($AH23:$AM23, AZ$3:AZ$8)/$AZ$9)} -> 0 | BB23: {=IF($BA$9=0,0,MMULT($AH23:$AM23, BA$3:BA$8)/$BA$9)} -> 0 | BC23: {=IF($BB$9=0,0,MMULT($AH23:$AM23, BB$3:BB$8)/$BB$9)} -> 0 | BD23: {=IF($BC$9=0,0,MMULT($AH23:$AM23, BC$3:BC$8)/$BC$9)} -> 0 | BE23: =IF($BD$9=0,0,MMULT($AH23:$AM23, BD$3:BD$8)/$BD$9) -> 0 | BF23: =IF($BE$9=0,0,MMULT($AH23:$AM23, BE$3:BE$8)/$BE$9) -> 0 | BG23: =IF(OR(GradeSheet!$I18="W (Withdrawn)", GradeSheet!$I18="I (Incomplete)"), 0, IF(AU23>=65%, 1, 0)) -> 0 | BH23: =IF(OR(GradeSheet!$I18="W (Withdrawn)", GradeSheet!$I18="I (Incomplete)"), 0, IF(AV23>=65%, 1, 0)) -> 0 | BI23: =IF(OR(GradeSheet!$I18="W (Withdrawn)", GradeSheet!$I18="I (Incomplete)"), 0, IF(AW23>=65%, 1, 0)) -> 0 | BJ23: =IF(OR(GradeSheet!$I18="W (Withdrawn)", GradeSheet!$I18="I (Incomplete)"), 0, IF(AX23>=65%, 1, 0)) -> 0 | BK23: =IF(OR(GradeSheet!$I18="W (Withdrawn)", GradeSheet!$I18="I (Incomplete)"), 0, IF(AY23>=65%, 1, 0)) -> 0 | BL23: =IF(OR(GradeSheet!$I18="W (Withdrawn)", GradeSheet!$I18="I (Incomplete)"), 0, IF(AZ23>=65%, 1, 0)) -> 0 | BM23: =IF(OR(GradeSheet!$I18="W (Withdrawn)", GradeSheet!$I18="I (Incomplete)"), 0, IF(BA23>=65%, 1, 0)) -> 0 | BN23: =IF(OR(GradeSheet!$I18="W (Withdrawn)", GradeSheet!$I18="I (Incomplete)"), 0, IF(BB23>=65%, 1, 0)) -> 0 | ... BR23: =IF(OR(GradeSheet!$I18="W (Withdrawn)", GradeSheet!$I18="I (Incomplete)"), 0, IF(BF23>=65%, 1, 0)) -> 0
A24: 10 | B24: 222014059 | C24: Sohan Sheikh | D24: =ROUNDUP((GradeSheet!D19/30)*12,0) -> 0 | E24: =GradeSheet!D19-D24 -> 0 | J24: =INT(GradeSheet!E19/2) -> 0 | K24: =GradeSheet!E19-J24 -> 0 | P24: =ROUNDUP((RawMarks!M11/30)*10,0) -> 0 | Q24: =GradeSheet!F19-P24 -> 0 | AB24: =SUM(P24,D24,J24) -> 0 | AC24: =SUM(W24,E24,K24,Q24) -> 0 | AD24: =SUM(X24,F24,L24) -> 0 | AE24: =SUM(Y24,G24,M24) -> 0 | AF24: =SUM(T24,H24,N24) -> 0 | AG24: =SUM(AA24,I24,O24) -> 0 | AH24: =IF(AB24 = 0, 0, AB24/AB$14) -> 0 | AI24: =IF(AC24 = 0, 0, AC24/AC$14) -> 0 | AJ24: =IF(AD24 = 0, 0, AD24/AD$14) -> 0 | AK24: =IF(AE24 = 0, 0, AE24/AE$14) -> 0 | AL24: =IF(AF24 = 0, 0, AF24/AF$14) -> 0 | AM24: =IF(AG24 = 0, 0, AG24/AG$14) -> 0 | AN24: =IF(OR(GradeSheet!$I19="W (Withdrawn)", GradeSheet!$I19="I (Incomplete)"), 0, IF(AH24>=55%, 1, 0)) -> 0 | AO24: =IF(OR(GradeSheet!$I19="W (Withdrawn)", GradeSheet!$I19="I (Incomplete)"), 0, IF(AI24>=55%, 1, 0)) -> 0 | AP24: =IF(OR(GradeSheet!$I19="W (Withdrawn)", GradeSheet!$I19="I (Incomplete)"), 0, IF(AJ24>=55%, 1, 0)) -> 0 | AQ24: =IF(OR(GradeSheet!$I19="W (Withdrawn)", GradeSheet!$I19="I (Incomplete)"), 0, IF(AK24>=55%, 1, 0)) -> 0 | AR24: =IF(OR(GradeSheet!$I19="W (Withdrawn)", GradeSheet!$I19="I (Incomplete)"), 0, IF(AL24>=55%, 1, 0)) -> 0 | AS24: =IF(OR(GradeSheet!$I19="W (Withdrawn)", GradeSheet!$I19="I (Incomplete)"), 0, IF(AM24>=55%, 1, 0)) -> 0 | AU24: =IF($AT$9=0,0,MMULT($AH24:$AM24, AT$3:AT$8)/$AT$9) -> 0 | AV24: =IF($AU$9=0,0,MMULT($AH24:$AM24, AU$3:AU$8)/$AU$9) -> 0 | AW24: {=IF($AV$9=0,0,MMULT($AH24:$AM24, AV$3:AV$8)/$AV$9)} -> 0 | AX24: {=IF($AW$9=0,0,MMULT($AH24:$AM24, AW$3:AW$8)/$AW$9)} -> 0 | AY24: =IF($AX$9=0,0,MMULT($AH24:$AM24, AX$3:AX$8)/$AX$9) -> 0 | AZ24: {=IF($AY$9=0,0,MMULT($AH24:$AM24, AY$3:AY$8)/$AY$9)} -> 0 | BA24: {=IF($AZ$9=0,0,MMULT($AH24:$AM24, AZ$3:AZ$8)/$AZ$9)} -> 0 | BB24: {=IF($BA$9=0,0,MMULT($AH24:$AM24, BA$3:BA$8)/$BA$9)} -> 0 | BC24: {=IF($BB$9=0,0,MMULT($AH24:$AM24, BB$3:BB$8)/$BB$9)} -> 0 | BD24: {=IF($BC$9=0,0,MMULT($AH24:$AM24, BC$3:BC$8)/$BC$9)} -> 0 | BE24: =IF($BD$9=0,0,MMULT($AH24:$AM24, BD$3:BD$8)/$BD$9) -> 0 | BF24: =IF($BE$9=0,0,MMULT($AH24:$AM24, BE$3:BE$8)/$BE$9) -> 0 | BG24: =IF(OR(GradeSheet!$I19="W (Withdrawn)", GradeSheet!$I19="I (Incomplete)"), 0, IF(AU24>=65%, 1, 0)) -> 0 | BH24: =IF(OR(GradeSheet!$I19="W (Withdrawn)", GradeSheet!$I19="I (Incomplete)"), 0, IF(AV24>=65%, 1, 0)) -> 0 | BI24: =IF(OR(GradeSheet!$I19="W (Withdrawn)", GradeSheet!$I19="I (Incomplete)"), 0, IF(AW24>=65%, 1, 0)) -> 0 | BJ24: =IF(OR(GradeSheet!$I19="W (Withdrawn)", GradeSheet!$I19="I (Incomplete)"), 0, IF(AX24>=65%, 1, 0)) -> 0 | BK24: =IF(OR(GradeSheet!$I19="W (Withdrawn)", GradeSheet!$I19="I (Incomplete)"), 0, IF(AY24>=65%, 1, 0)) -> 0 | BL24: =IF(OR(GradeSheet!$I19="W (Withdrawn)", GradeSheet!$I19="I (Incomplete)"), 0, IF(AZ24>=65%, 1, 0)) -> 0 | BM24: =IF(OR(GradeSheet!$I19="W (Withdrawn)", GradeSheet!$I19="I (Incomplete)"), 0, IF(BA24>=65%, 1, 0)) -> 0 | BN24: =IF(OR(GradeSheet!$I19="W (Withdrawn)", GradeSheet!$I19="I (Incomplete)"), 0, IF(BB24>=65%, 1, 0)) -> 0 | ... BR24: =IF(OR(GradeSheet!$I19="W (Withdrawn)", GradeSheet!$I19="I (Incomplete)"), 0, IF(BF24>=65%, 1, 0)) -> 0
A25: 11 | B25: 222014090 | C25: Asifuzzaman Shishir | D25: =ROUNDUP((GradeSheet!D20/30)*12,0) -> 5 | E25: =GradeSheet!D20-D25 -> 7 | J25: =INT(GradeSheet!E20/2) -> 12 | K25: =GradeSheet!E20-J25 -> 13 | P25: =ROUNDUP((RawMarks!M12/30)*10,0) -> 8 | Q25: =GradeSheet!F20-P25 -> 16 | AB25: =SUM(P25,D25,J25) -> 25 | AC25: =SUM(W25,E25,K25,Q25) -> 36 | AD25: =SUM(X25,F25,L25) -> 0 | AE25: =SUM(Y25,G25,M25) -> 0 | AF25: =SUM(T25,H25,N25) -> 0 | AG25: =SUM(AA25,I25,O25) -> 0 | AH25: =IF(AB25 = 0, 0, AB25/AB$14) -> 0.5952381 | AI25: =IF(AC25 = 0, 0, AC25/AC$14) -> 0.62068966 | AJ25: =IF(AD25 = 0, 0, AD25/AD$14) -> 0 | AK25: =IF(AE25 = 0, 0, AE25/AE$14) -> 0 | AL25: =IF(AF25 = 0, 0, AF25/AF$14) -> 0 | AM25: =IF(AG25 = 0, 0, AG25/AG$14) -> 0 | AN25: =IF(OR(GradeSheet!$I20="W (Withdrawn)", GradeSheet!$I20="I (Incomplete)"), 0, IF(AH25>=55%, 1, 0)) -> 1 | AO25: =IF(OR(GradeSheet!$I20="W (Withdrawn)", GradeSheet!$I20="I (Incomplete)"), 0, IF(AI25>=55%, 1, 0)) -> 1 | AP25: =IF(OR(GradeSheet!$I20="W (Withdrawn)", GradeSheet!$I20="I (Incomplete)"), 0, IF(AJ25>=55%, 1, 0)) -> 0 | AQ25: =IF(OR(GradeSheet!$I20="W (Withdrawn)", GradeSheet!$I20="I (Incomplete)"), 0, IF(AK25>=55%, 1, 0)) -> 0 | AR25: =IF(OR(GradeSheet!$I20="W (Withdrawn)", GradeSheet!$I20="I (Incomplete)"), 0, IF(AL25>=55%, 1, 0)) -> 0 | AS25: =IF(OR(GradeSheet!$I20="W (Withdrawn)", GradeSheet!$I20="I (Incomplete)"), 0, IF(AM25>=55%, 1, 0)) -> 0 | AU25: =IF($AT$9=0,0,MMULT($AH25:$AM25, AT$3:AT$8)/$AT$9) -> 0 | AV25: =IF($AU$9=0,0,MMULT($AH25:$AM25, AU$3:AU$8)/$AU$9) -> 0 | AW25: {=IF($AV$9=0,0,MMULT($AH25:$AM25, AV$3:AV$8)/$AV$9)} -> 0 | AX25: {=IF($AW$9=0,0,MMULT($AH25:$AM25, AW$3:AW$8)/$AW$9)} -> 0 | AY25: =IF($AX$9=0,0,MMULT($AH25:$AM25, AX$3:AX$8)/$AX$9) -> 0 | AZ25: {=IF($AY$9=0,0,MMULT($AH25:$AM25, AY$3:AY$8)/$AY$9)} -> 0 | BA25: {=IF($AZ$9=0,0,MMULT($AH25:$AM25, AZ$3:AZ$8)/$AZ$9)} -> 0 | BB25: {=IF($BA$9=0,0,MMULT($AH25:$AM25, BA$3:BA$8)/$BA$9)} -> 0 | BC25: {=IF($BB$9=0,0,MMULT($AH25:$AM25, BB$3:BB$8)/$BB$9)} -> 0 | BD25: {=IF($BC$9=0,0,MMULT($AH25:$AM25, BC$3:BC$8)/$BC$9)} -> 0 | BE25: =IF($BD$9=0,0,MMULT($AH25:$AM25, BD$3:BD$8)/$BD$9) -> 0 | BF25: =IF($BE$9=0,0,MMULT($AH25:$AM25, BE$3:BE$8)/$BE$9) -> 0 | BG25: =IF(OR(GradeSheet!$I20="W (Withdrawn)", GradeSheet!$I20="I (Incomplete)"), 0, IF(AU25>=65%, 1, 0)) -> 0 | BH25: =IF(OR(GradeSheet!$I20="W (Withdrawn)", GradeSheet!$I20="I (Incomplete)"), 0, IF(AV25>=65%, 1, 0)) -> 0 | BI25: =IF(OR(GradeSheet!$I20="W (Withdrawn)", GradeSheet!$I20="I (Incomplete)"), 0, IF(AW25>=65%, 1, 0)) -> 0 | BJ25: =IF(OR(GradeSheet!$I20="W (Withdrawn)", GradeSheet!$I20="I (Incomplete)"), 0, IF(AX25>=65%, 1, 0)) -> 0 | BK25: =IF(OR(GradeSheet!$I20="W (Withdrawn)", GradeSheet!$I20="I (Incomplete)"), 0, IF(AY25>=65%, 1, 0)) -> 0 | BL25: =IF(OR(GradeSheet!$I20="W (Withdrawn)", GradeSheet!$I20="I (Incomplete)"), 0, IF(AZ25>=65%, 1, 0)) -> 0 | BM25: =IF(OR(GradeSheet!$I20="W (Withdrawn)", GradeSheet!$I20="I (Incomplete)"), 0, IF(BA25>=65%, 1, 0)) -> 0 | BN25: =IF(OR(GradeSheet!$I20="W (Withdrawn)", GradeSheet!$I20="I (Incomplete)"), 0, IF(BB25>=65%, 1, 0)) -> 0 | ... BR25: =IF(OR(GradeSheet!$I20="W (Withdrawn)", GradeSheet!$I20="I (Incomplete)"), 0, IF(BF25>=65%, 1, 0)) -> 0
A26: 12 | B26: 222014097 | C26: Md Abul Hashem | D26: =ROUNDUP((GradeSheet!D21/30)*12,0) -> 6 | E26: =GradeSheet!D21-D26 -> 7 | J26: =INT(GradeSheet!E21/2) -> 12 | K26: =GradeSheet!E21-J26 -> 13 | P26: =ROUNDUP((RawMarks!M13/30)*10,0) -> 5 | Q26: =GradeSheet!F21-P26 -> 9 | AB26: =SUM(P26,D26,J26) -> 23 | AC26: =SUM(W26,E26,K26,Q26) -> 29 | AD26: =SUM(X26,F26,L26) -> 0 | AE26: =SUM(Y26,G26,M26) -> 0 | AF26: =SUM(T26,H26,N26) -> 0 | AG26: =SUM(AA26,I26,O26) -> 0 | AH26: =IF(AB26 = 0, 0, AB26/AB$14) -> 0.54761905 | AI26: =IF(AC26 = 0, 0, AC26/AC$14) -> 0.5 | AJ26: =IF(AD26 = 0, 0, AD26/AD$14) -> 0 | AK26: =IF(AE26 = 0, 0, AE26/AE$14) -> 0 | AL26: =IF(AF26 = 0, 0, AF26/AF$14) -> 0 | AM26: =IF(AG26 = 0, 0, AG26/AG$14) -> 0 | AN26: =IF(OR(GradeSheet!$I21="W (Withdrawn)", GradeSheet!$I21="I (Incomplete)"), 0, IF(AH26>=55%, 1, 0)) -> 0 | AO26: =IF(OR(GradeSheet!$I21="W (Withdrawn)", GradeSheet!$I21="I (Incomplete)"), 0, IF(AI26>=55%, 1, 0)) -> 0 | AP26: =IF(OR(GradeSheet!$I21="W (Withdrawn)", GradeSheet!$I21="I (Incomplete)"), 0, IF(AJ26>=55%, 1, 0)) -> 0 | AQ26: =IF(OR(GradeSheet!$I21="W (Withdrawn)", GradeSheet!$I21="I (Incomplete)"), 0, IF(AK26>=55%, 1, 0)) -> 0 | AR26: =IF(OR(GradeSheet!$I21="W (Withdrawn)", GradeSheet!$I21="I (Incomplete)"), 0, IF(AL26>=55%, 1, 0)) -> 0 | AS26: =IF(OR(GradeSheet!$I21="W (Withdrawn)", GradeSheet!$I21="I (Incomplete)"), 0, IF(AM26>=55%, 1, 0)) -> 0 | AU26: =IF($AT$9=0,0,MMULT($AH26:$AM26, AT$3:AT$8)/$AT$9) -> 0 | AV26: =IF($AU$9=0,0,MMULT($AH26:$AM26, AU$3:AU$8)/$AU$9) -> 0 | AW26: {=IF($AV$9=0,0,MMULT($AH26:$AM26, AV$3:AV$8)/$AV$9)} -> 0 | AX26: {=IF($AW$9=0,0,MMULT($AH26:$AM26, AW$3:AW$8)/$AW$9)} -> 0 | AY26: =IF($AX$9=0,0,MMULT($AH26:$AM26, AX$3:AX$8)/$AX$9) -> 0 | AZ26: {=IF($AY$9=0,0,MMULT($AH26:$AM26, AY$3:AY$8)/$AY$9)} -> 0 | BA26: {=IF($AZ$9=0,0,MMULT($AH26:$AM26, AZ$3:AZ$8)/$AZ$9)} -> 0 | BB26: {=IF($BA$9=0,0,MMULT($AH26:$AM26, BA$3:BA$8)/$BA$9)} -> 0 | BC26: {=IF($BB$9=0,0,MMULT($AH26:$AM26, BB$3:BB$8)/$BB$9)} -> 0 | BD26: {=IF($BC$9=0,0,MMULT($AH26:$AM26, BC$3:BC$8)/$BC$9)} -> 0 | BE26: =IF($BD$9=0,0,MMULT($AH26:$AM26, BD$3:BD$8)/$BD$9) -> 0 | BF26: =IF($BE$9=0,0,MMULT($AH26:$AM26, BE$3:BE$8)/$BE$9) -> 0 | BG26: =IF(OR(GradeSheet!$I21="W (Withdrawn)", GradeSheet!$I21="I (Incomplete)"), 0, IF(AU26>=65%, 1, 0)) -> 0 | BH26: =IF(OR(GradeSheet!$I21="W (Withdrawn)", GradeSheet!$I21="I (Incomplete)"), 0, IF(AV26>=65%, 1, 0)) -> 0 | BI26: =IF(OR(GradeSheet!$I21="W (Withdrawn)", GradeSheet!$I21="I (Incomplete)"), 0, IF(AW26>=65%, 1, 0)) -> 0 | BJ26: =IF(OR(GradeSheet!$I21="W (Withdrawn)", GradeSheet!$I21="I (Incomplete)"), 0, IF(AX26>=65%, 1, 0)) -> 0 | BK26: =IF(OR(GradeSheet!$I21="W (Withdrawn)", GradeSheet!$I21="I (Incomplete)"), 0, IF(AY26>=65%, 1, 0)) -> 0 | BL26: =IF(OR(GradeSheet!$I21="W (Withdrawn)", GradeSheet!$I21="I (Incomplete)"), 0, IF(AZ26>=65%, 1, 0)) -> 0 | BM26: =IF(OR(GradeSheet!$I21="W (Withdrawn)", GradeSheet!$I21="I (Incomplete)"), 0, IF(BA26>=65%, 1, 0)) -> 0 | BN26: =IF(OR(GradeSheet!$I21="W (Withdrawn)", GradeSheet!$I21="I (Incomplete)"), 0, IF(BB26>=65%, 1, 0)) -> 0 | ... BR26: =IF(OR(GradeSheet!$I21="W (Withdrawn)", GradeSheet!$I21="I (Incomplete)"), 0, IF(BF26>=65%, 1, 0)) -> 0
