Workbook

Sheet GradeSheet
G2: Course Code | H2: 0613-014-1202 | J2: Section | K2: 2
G3: Course Title | H3: Structured Programming Lab | J3: Semester | K3: Spring 2026
G4: Credit | H4: 1
G5: Instructor | H5: Suravi Akhter
A7: =CONCATENATE("Grade Sheet of ",GradeSheet!$H$2, " [",GradeSheet!$H$3, "] ", "(Section ",GradeSheet!$K$2, ") ", "[Semester - ",GradeSheet!$K$3,"]" ) -> Grade Sheet of 0613-014-1202 [Structured Programming Lab] (Section 2) [Semester - Spring 2026]
O8: Attendance | P8: Presentation | Q8: Quiz | R8: Assignment 1 | S8: Assignment 2 | T8: Assignment 3 | U8: Assignment 4 | V8: OEL 1 | W8: Lab Final
A9: No. | B9: Student ID | C9: Name | D9: =CONCATENATE("Attendance (",GradeSheet!$C$49, ")") -> Attendance (0) | E9: =CONCATENATE("Presentation (",GradeSheet!$C$50, ")") -> Presentation (0) | F9: =CONCATENATE("Quiz (",GradeSheet!$C$51, ")") -> Quiz (0) | G9: =CONCATENATE("Assignment (",GradeSheet!$C$52, ")") -> Assignment (30) | H9: OEL 1(40) | I9: =CONCATENATE("Lab Final (",GradeSheet!$C$54, ")") -> Lab Final (30) | J9: Exam Total (100) | K9: Percent Total (100%) | L9: Grade | O9: 0 | P9: 0 | Q9: 0 | R9: 6 | S9: 7 | T9: 7 | U9: 10 | V9: 40 | W9: 30 | X9: Student ID | Y9: Name
A10: 1 | B10: 251014052 | C10: Md. Tahfimul Tasin | D10: =O10 -> 0 | E10: 0 | F10: 0 | G10: =SUM(R10:U10) -> 30 | H10: =V10 -> 33.333333 | I10: =W10 -> 12 | J10: =ROUNDUP(SUM(D10:I10),0) -> 76 | K10: =J10/100 -> 0.76 | L10: =VLOOKUP(J10,GradingPolicy!$B$2:$C$11,2) -> B+ (Plus) | O10: 0 | P10: 0 | Q10: =0 -> 0 | R10: 6 | S10: 7 | T10: 7 | U10: 10 | V10: =(SUM(CO_PO_AttainmentAnalysis!D21:F21)/12)*40 -> 33.333333 | W10: 12 | X10: 251014052 | Y10: Md. Tahfimul Tasin
A11: 2 | B11: 251014053 | C11: Md. Nafij Iqbal Sazid | D11: =O11 -> 0 | E11: 0 | F11: 0 | G11: =SUM(R11:U11) -> 30 | H11: =V11 -> 33.333333 | I11: =W11 -> 14 | J11: =ROUNDUP(SUM(D11:I11),0) -> 78 | K11: =J11/100 -> 0.78 | L11: =VLOOKUP(J11,GradingPolicy!$B$2:$C$11,2) -> B+ (Plus) | O11: 0 | P11: 0 | Q11: =0 -> 0 | R11: 6 | S11: 7 | T11: 7 | U11: 10 | V11: =(SUM(CO_PO_AttainmentAnalysis!D22:F22)/12)*40 -> 33.333333 | W11: 14 | X11: 251014053 | Y11: Md. Nafij Iqbal Sazid
A12: 3 | B12: 251014059 | C12: Najni Nawar Supti | D12: =O12 -> 0 | E12: 0 | F12: 0 | G12: =SUM(R12:U12) -> 30 | H12: =V12 -> 33.333333 | I12: =W12 -> 16 | J12: =ROUNDUP(SUM(D12:I12),0) -> 80 | K12: =J12/100 -> 0.8 | L12: =VLOOKUP(J12,GradingPolicy!$B$2:$C$11,2) -> A- (Minus) | O12: 0 | P12: 0 | Q12: =0 -> 0 | R12: 6 | S12: 7 | T12: 7 | U12: 10 | V12: =(SUM(CO_PO_AttainmentAnalysis!D23:F23)/12)*40 -> 33.333333 | W12: 16 | X12: 251014059 | Y12: Najni Nawar Supti
A13: 4 | B13: 252014038 | C13: Md. Ishfaq Alam | D13: =O13 -> 0 | E13: 0 | F13: 0 | G13: =SUM(R13:U13) -> 23 | H13: =V13 -> 40 | I13: =W13 -> 22 | J13: =ROUNDUP(SUM(D13:I13),0) -> 85 | K13: =J13/100 -> 0.85 | L13: =VLOOKUP(J13,GradingPolicy!$B$2:$C$11,2) -> A (Plain) | O13: 0 | P13: 0 | Q13: =0 -> 0 | R13: 6 | S13: 0 | T13: 7 | U13: 10 | V13: =(SUM(CO_PO_AttainmentAnalysis!D24:F24)/12)*40 -> 40 | W13: 22 | X13: 252014038 | Y13: Md. Ishfaq Alam
A14: 5 | B14: 252014076 | C14: Pavel Ahamed Sarkar | D14: =O14 -> 0 | E14: 0 | F14: 0 | G14: =SUM(R14:U14) -> 13 | H14: =V14 -> 40 | I14: =W14 -> 22 | J14: =ROUNDUP(SUM(D14:I14),0) -> 75 | K14: =J14/100 -> 0.75 | L14: =VLOOKUP(J14,GradingPolicy!$B$2:$C$11,2) -> B+ (Plus) | O14: 0 | P14: 0 | Q14: =0 -> 0 | R14: 6 | S14: 7 | T14: 0 | U14: 0 | V14: =(SUM(CO_PO_AttainmentAnalysis!D25:F25)/12)*40 -> 40 | W14: 22 | X14: 252014076 | Y14: Pavel Ahamed Sarkar
A15: 6 | B15: 252014084 | C15: Nusrat Jahan Autoshi | D15: =O15 -> 0 | E15: 0 | F15: 0 | G15: =SUM(R15:U15) -> 30 | H15: =V15 -> 0 | I15: =W15 -> 0 | J15: =ROUNDUP(SUM(D15:I15),0) -> 30 | K15: =J15/100 -> 0.3 | L15: =VLOOKUP(J15,GradingPolicy!$B$2:$C$11,2) -> F (Fail) | O15: 0 | P15: 0 | Q15: =0 -> 0 | R15: 6 | S15: 7 | T15: 7 | U15: 10 | V15: =(SUM(CO_PO_AttainmentAnalysis!D26:F26)/12)*40 -> 0 | W15: 0 | X15: 252014084 | Y15: Nusrat Jahan Autoshi
A16: 7 | B16: 252014086 | C16: Avro Mostafi Hassan | D16: =O16 -> 0 | E16: 0 | F16: 0 | G16: =SUM(R16:U16) -> 30 | H16: =V16 -> 40 | I16: =W16 -> 10 | J16: =ROUNDUP(SUM(D16:I16),0) -> 80 | K16: =J16/100 -> 0.8 | L16: =VLOOKUP(J16,GradingPolicy!$B$2:$C$11,2) -> A- (Minus) | O16: 0 | P16: 0 | Q16: =0 -> 0 | R16: 6 | S16: 7 | T16: 7 | U16: 10 | V16: =(SUM(CO_PO_AttainmentAnalysis!D27:F27)/12)*40 -> 40 | W16: 10 | X16: 252014086 | Y16: Avro Mostafi Hassan
A17: 8 | B17: 252014106 | C17: Md. Abu Ashraf Patwary Noor | D17: =O17 -> 0 | E17: 0 | F17: 0 | G17: =SUM(R17:U17) -> 30 | H17: =V17 -> 33.333333 | I17: =W17 -> 16 | J17: =ROUNDUP(SUM(D17:I17),0) -> 80 | K17: =J17/100 -> 0.8 | L17: =VLOOKUP(J17,GradingPolicy!$B$2:$C$11,2) -> A- (Minus) | O17: 0 | P17: 0 | Q17: =0 -> 0 | R17: 6 | S17: 7 | T17: 7 | U17: 10 | V17: =(SUM(CO_PO_AttainmentAnalysis!D28:F28)/12)*40 -> 33.333333 | W17: 16 | X17: 252014106 | Y17: Md. Abu Ashraf Patwary Noor
A18: 9 | B18: 253014001 | C18: * Md. Minhajur Rahman | D18: =O18 -> 0 | E18: 0 | F18: 0 | G18: =SUM(R18:U18) -> 30 | H18: =V18 -> 33.333333 | I18: =W18 -> 16 | J18: =ROUNDUP(SUM(D18:I18),0) -> 80 | K18: =J18/100 -> 0.8 | L18: =VLOOKUP(J18,GradingPolicy!$B$2:$C$11,2) -> A- (Minus) | O18: 0 | P18: 0 | Q18: =0 -> 0 | R18: 6 | S18: 7 | T18: 7 | U18: 10 | V18: =(SUM(CO_PO_AttainmentAnalysis!D29:F29)/12)*40 -> 33.333333 | W18: 16 | X18: 253014001 | Y18: * Md. Minhajur Rahman
A19: 10 | B19: 253014005 | C19: Md. Mahadi Hasan | D19: =O19 -> 0 | E19: 0 | F19: 0 | G19: =SUM(R19:U19) -> 24 | H19: =V19 -> 40 | I19: =W19 -> 21 | J19: =ROUNDUP(SUM(D19:I19),0) -> 85 | K19: =J19/100 -> 0.85 | L19: =VLOOKUP(J19,GradingPolicy!$B$2:$C$11,2) -> A (Plain) | O19: 0 | P19: 0 | Q19: =0 -> 0 | R19: 0 | S19: 7 | T19: 7 | U19: 10 | V19: =(SUM(CO_PO_AttainmentAnalysis!D30:F30)/12)*40 -> 40 | W19: 21 | X19: 253014005 | Y19: Md. Mahadi Hasan
A20: 11 | B20: 253014006 | C20: Mohammad Jubayed Islam Jihad | D20: =O20 -> 0 | E20: 0 | F20: 0 | G20: =SUM(R20:U20) -> 30 | H20: =V20 -> 40 | I20: =W20 -> 26 | J20: =ROUNDUP(SUM(D20:I20),0) -> 96 | K20: =J20/100 -> 0.96 | L20: =VLOOKUP(J20,GradingPolicy!$B$2:$C$11,2) -> A+ (Plus) | O20: 0 | P20: 0 | Q20: =0 -> 0 | R20: 6 | S20: 7 | T20: 7 | U20: 10 | V20: =(SUM(CO_PO_AttainmentAnalysis!D31:F31)/12)*40 -> 40 | W20: 26 | X20: 253014006 | Y20: Mohammad Jubayed Islam Jihad
A21: 12 | B21: 253014010 | C21: Md. Abdul Hamid | D21: =O21 -> 0 | E21: 0 | F21: 0 | G21: =SUM(R21:U21) -> 30 | H21: =V21 -> 40 | I21: =W21 -> 20 | J21: =ROUNDUP(SUM(D21:I21),0) -> 90 | K21: =J21/100 -> 0.9 | L21: =VLOOKUP(J21,GradingPolicy!$B$2:$C$11,2) -> A (Plain) | O21: 0 | P21: 0 | Q21: =0 -> 0 | R21: 6 | S21: 7 | T21: 7 | U21: 10 | V21: =(SUM(CO_PO_AttainmentAnalysis!D32:F32)/12)*40 -> 40 | W21: 20 | X21: 253014010 | Y21: Md. Abdul Hamid
... A45: 36 | B45: 253014094 | C45: MD. Mahadi Hassan | D45: =O45 -> 0 | E45: 0 | F45: 0 | G45: =SUM(R45:U45) -> 20 | H45: =V45 -> 33.333333 | I45: =W45 -> 11 | J45: =ROUNDUP(SUM(D45:I45),0) -> 65 | K45: =J45/100 -> 0.65 | L45: =VLOOKUP(J45,GradingPolicy!$B$2:$C$11,2) -> B- (Minus) | O45: 0 | P45: 0 | Q45: =0 -> 0 | R45: 6 | S45: 7 | T45: 7 | U45: 0 | V45: =(SUM(CO_PO_AttainmentAnalysis!D56:F56)/12)*40 -> 33.333333 | W45: 11 | X45: 253014094 | Y45: MD. Mahadi Hassan
B48: Assessment | C48: Marks Distribution | F48: Numerical Grade | G48: Letter Grade | H48: Freq
B49: Attendance | C49: 0 | F49: 95% and above | G49: A+ | H49: =COUNTIF(L10:L45, "A+ (Plus)") -> 3 | N49: MAX | O49: =MAX(O10:O45) -> 0 | P49: =MAX(P10:P45) -> 0 | Q49: =MAX(Q10:Q45) -> 0 | R49: =MAX(R10:R45) -> 6 | S49: =MAX(S10:S45) -> 7 | T49: =MAX(T10:T45) -> 7 | U49: =MAX(U10:U45) -> 10 | V49: =MAX(V10:V45) -> 40 | W49: =MAX(W10:W45) -> 30
B50: Presentation | C50: 0 | F50: 85% to 94% | G50: A | H50: =COUNTIF(L10:L45, "A (Plain)") -> 7 | N50: AVG | O50: =AVERAGE(O10:O45) -> 0 | P50: =AVERAGE(P10:P45) -> 0 | Q50: =AVERAGE(Q10:Q45) -> 0 | R50: =AVERAGE(R10:R45) -> 5.1666667 | S50: =AVERAGE(S10:S45) -> 6.0277778 | T50: =AVERAGE(T10:T45) -> 6.4166667 | U50: =AVERAGE(U10:U45) -> 8.0555556 | V50: =AVERAGE(V10:V45) -> 29.62963 | W50: =AVERAGE(W10:W45) -> 15.583333
B51: Quiz | C51: 0 | F51: 80% to 84% | G51: A- | H51: =COUNTIF(L10:L45, "A- (Minus)") -> 6 | N51: MIN | O51: =MIN(O10:O45) -> 0 | P51: =MIN(P10:P45) -> 0 | Q51: =MIN(Q10:Q45) -> 0 | R51: =MIN(R10:R45) -> 0 | S51: =MIN(S10:S45) -> 0 | T51: =MIN(T10:T45) -> 0 | U51: =MIN(U10:U45) -> 0 | V51: =MIN(V10:V45) -> 0 | W51: =MIN(W10:W45) -> 0
B52: Assignment | C52: 30 | F52: 75% to 79% | G52: B+ | H52: =COUNTIF(L10:L45, "B+ (Plus)") -> 8
B53: Open Ended Lab 1 | C53: 40 | F53: 70% to 74% | G53: B | H53: =COUNTIF(L10:L45, "B (Plain)") -> 2
B54: Lab Final | C54: 30 | F54: 65% to 69% | G54: B- | H54: =COUNTIF(L10:L45, "B- (Minus)") -> 2
B55: Project | C55: 0 | F55: 60% to 64% | G55: C+ | H55: =COUNTIF(L10:L45, "C+ (Plus)") -> 1
B56: Total | C56: =SUM(C49:C55) -> 100 | F56: 55% to 59% | G56: C | H56: =COUNTIF(L10:L45, "C (Plain)") -> 0
F57: 50% to 54% | G57: D | H57: =COUNTIF(L10:L45, "D (Plain)") -> 3
F58: Below 50% | G58: F | H58: =COUNTIF(L10:L45, "F (Fail)") -> 4
F59: No exam | G59: I | H59: =COUNTIF(L10:L45, "I (Incomplete)") -> 0
B60: =GradeSheet!$H$5 -> Suravi Akhter | F60: Withdrawn | G60: W | H60: =COUNTIF(L10:L45, "W (Withdrawn)") -> 0
B61: Lecturer | F61: No of students | H61: =SUM(H49:H60) -> 36
B62: Department of CSE, ULAB

Sheet Sheet1
A1: Ahmed-El-Alam | B1: A- (Minus)
A2: Munshi Abir Hossain | B2: B+ (Plus)
A3: Imtiaz Ahmed Siam | B3: B (Plain)
A4: Mohammad Azizul Hoque Alsami | B4: F (Fail)
A5: Ariful Islam Ohid | B5: C (Plain)
A6: Shoheb Ahmed Khan | B6: F (Fail)
A7: Jannatul Takowa Tasnova | B7: F (Fail)
A8: kamroun Nahar Keya | B8: B- (Minus)
A9: Jannatun Nayem | B9: F (Fail)
A10: Argha Kanti Sheel | B10: C+ (Plus)
A11: Md. Alvi Hossain | B11: B- (Minus)
A12: Salma | B12: A (Plain)
... A35: Mahabub Rushed | B35: B- (Minus)

Sheet GradingPolicy
A1: Numerical Grade | B1: Minimum Number | C1: Letter Grade
A2: Below 50% | B2: 0 | C2: F (Fail)
A3: 50% to 54% | B3: 50 | C3: D (Plain)
A4: 55% to 59% | B4: 55 | C4: C (Plain)
A5: 60% to 64% | B5: 60 | C5: C+ (Plus)
A6: 65% to 69% | B6: 65 | C6: B- (Minus)
A7: 70% to 74% | B7: 70 | C7: B (Plain)
A8: 75% to 79% | B8: 75 | C8: B+ (Plus)
A9: 80% to 84% | B9: 80 | C9: A- (Minus)
A10: 85% to 94% | B10: 85 | C10: A (Plain)
A11: 95% and above | B11: 95 | C11: A+ (Plus)

Sheet CO_PO_AttainmentAnalysis
N2: CO-PO Attainment Analysis Form
AS7: Mapping of COs to POs
C8: Assessment Items | D8: CO1 | E8: CO2 | F8: CO3 | G8: CO4 | H8: CO5 | I8: CO6 | AT8: PO1 | AU8: PO2 | AV8: PO3 | AW8: PO4 | AX8: PO5 | AY8: PO6 | AZ8: PO7 | BA8: PO8 | BB8: PO9 | BC8: PO10 | BD8: PO11 | BE8: PO12
C9: Open Ended Lab 1 | D9: 6 | E9: 6 | AS9: CO1 | AT9: 0 | AU9: 0 | AV9: 0 | AW9: 0 | AX9: 0 | AY9: 0 | AZ9: 0 | BA9: 0 | BB9: 0 | BC9: 0 | BD9: 0 | BE9: 0
C10: Open Ended Lab 2 | AS10: CO2 | AT10: 0 | AU10: 0 | AV10: 0 | AW10: 0 | AX10: 0 | AY10: 0 | AZ10: 0 | BA10: 0 | BB10: 0 | BC10: 0 | BD10: 0 | BE10: 0
C11: Assignment | AS11: CO3 | AT11: 0 | AU11: 0 | AV11: 0 | AW11: 0 | AX11: 0 | AY11: 0 | AZ11: 0 | BA11: 0 | BB11: 0 | BC11: 0 | BD11: 0 | BE11: 0
C12: Project | AS12: CO4 | AT12: 0 | AU12: 0 | AV12: 0 | AW12: 0 | AX12: 0 | AY12: 0 | AZ12: 0 | BA12: 0 | BB12: 0 | BC12: 0 | BD12: 0 | BE12: 0
C13: Total | D13: =SUM(D9:D12) -> 6 | E13: =SUM(E9:E12) -> 6 | F13: =SUM(F9:F12) -> 0 | G13: =SUM(G9:G12) -> 0 | H13: =SUM(H9:H12) -> 0 | I13: =SUM(I9:I12) -> 0 | AS13: CO5 | AT13: 0 | AU13: 0 | AV13: 0 | AW13: 0 | AX13: 0 | AY13: 0 | AZ13: 0 | BA13: 0 | BB13: 0 | BC13: 0 | BD13: 0 | BE13: 0
AS14: CO6 | AT14: 0 | AU14: 0 | AV14: 0 | AW14: 0 | AX14: 0 | AY14: 0 | AZ14: 0 | BA14: 0 | BB14: 0 | BC14: 0 | BD14: 0 | BE14: 0
AS15: Total | AT15: =SUM(AT9:AT14) -> 0 | AU15: =SUM(AU9:AU14) -> 0 | AV15: =SUM(AV9:AV14) -> 0 | AW15: =SUM(AW9:AW14) -> 0 | AX15: =SUM(AX9:AX14) -> 0 | AY15: =SUM(AY9:AY14) -> 0 | AZ15: =SUM(AZ9:AZ14) -> 0 | BA15: =SUM(BA9:BA14) -> 0 | ... BE15: =SUM(BE9:BE14) -> 0
A17: =CONCATENATE("Course Outcome (CO) Attainment Analysis of ",GradeSheet!$H$2, " [",GradeSheet!$H$3, "] ", "(Section ",GradeSheet!$K$2, ") ", "[Semester - ",GradeSheet!$K$3,"]" ) -> Course Outcome (CO) Attainment Analysis of 0613-014-1202 [Structured Programming Lab] (Section 2) [Semester - Spring 2026] | AB17: CO Attainment Analysis | AU17: PO Attainment Analysis
D18: =C9 -> Open Ended Lab 1 | J18: =C10 -> Open Ended Lab 2 | P18: =C11 -> Assignment | V18: =C12 -> Project | AB18: Total Marks | AH18: Percentage | AN18: CO Attainment | AU18: Percentage | BG18: PO Attainment
D19: CO1 | E19: CO2 | F19: CO3 | G19: CO4 | H19: CO5 | I19: CO6 | J19: CO1 | K19: CO2 | L19: CO3 | M19: CO4 | N19: CO5 | O19: CO6 | P19: CO1 | Q19: CO2 | R19: CO3 | S19: CO4 | T19: CO5 | U19: CO6 | V19: CO1 | W19: CO2 | X19: CO3 | Y19: CO4 | Z19: CO5 | AA19: CO6 | AB19: CO1 | AC19: CO2 | AD19: CO3 | AE19: CO4 | AF19: CO5 | AG19: CO6 | AH19: CO1 | AI19: CO2 | AJ19: CO3 | AK19: CO4 | AL19: CO5 | AM19: CO6 | AN19: CO1 | AO19: CO2 | AP19: CO3 | AQ19: CO4 | AR19: CO5 | AS19: CO6 | AU19: PO1 | AV19: PO2 | AW19: PO3 | AX19: PO4 | AY19: PO5 | AZ19: PO6 | BA19: PO7 | BB19: PO8 | BC19: PO9 | BD19: PO10 | BE19: PO11 | BF19: PO12 | BG19: PO1 | BH19: PO2 | BI19: PO3 | BJ19: PO4 | BK19: PO5 | BL19: PO6 | BM19: PO7 | BN19: PO8 | BO19: PO9 | BP19: PO10 | BQ19: PO11 | BR19: PO12
A20: S/N | B20: Student ID | C20: Name | D20: 6 | E20: 6 | F20: =F9 | G20: =G9 | H20: =H9 | I20: =I9 | M20: =G10 | N20: =H10 | O20: =I10 | P20: =D11 | Q20: =E11 | R20: =F11 | S20: =G11 | T20: =H11 | U20: =I11 | V20: =D12 | W20: =E12 | X20: =F12 | Y20: =G12 | Z20: =H12 | AA20: =I12 | AB20: =SUM(D20,J20,P20,V20) -> 6 | AC20: =SUM(E20,K20,Q20,W20) -> 6 | AD20: =SUM(F20,L20,R20,X20) -> 0 | AE20: =SUM(G20,M20,S20,Y20) -> 0 | AF20: =SUM(H20,N20,T20,Z20) -> 0 | AG20: =SUM(I20,O20,U20,AA20) -> 0 | AH20: 1 | AI20: 1 | AJ20: 0 | AK20: 0 | AL20: 0 | AM20: 0 | AN20: If CO achieved (≥65%) then 1, else 0 | AU20: 1 | AV20: 1 | AW20: 1 | AX20: 1 | AY20: 1 | AZ20: 1 | BA20: 1 | BB20: 1 | BC20: 1 | BD20: 1 | BE20: 1 | BF20: 1 | BG20: If PO achieved (≥65%) then 1, else 0
A21: 1 | B21: 251014052 | C21: Md. Tahfimul Tasin | D21: 6 | E21: 4 | F21: 0 | G21: 0 | H21: 0 | I21: 0 | J21: 0 | K21: 0 | L21: 0 | M21: 0 | N21: 0 | O21: 0 | P21: 0 | Q21: 0 | R21: 0 | S21: 0 | T21: 0 | U21: 0 | V21: 0 | W21: 0 | X21: 0 | Y21: 0 | Z21: 0 | AA21: 0 | AB21: =SUM(D21,J21,P21,V21) -> 6 | AC21: =SUM(E21,K21,Q21,W21) -> 4 | AD21: =SUM(F21,L21,R21,X21) -> 0 | AE21: =SUM(G21,M21,S21,Y21) -> 0 | AF21: =SUM(H21,N21,T21,Z21) -> 0 | AG21: =SUM(I21,O21,U21,AA21) -> 0 | AH21: =IF(AB21 = 0, 0, AB21/AB$20) -> 1 | AI21: =IF(AC21 = 0, 0, AC21/AC$20) -> 0.66666667 | AJ21: =IF(AD21 = 0, 0, AD21/AD$20) -> 0 | AK21: =IF(AE21 = 0, 0, AE21/AE$20) -> 0 | AL21: =IF(AF21 = 0, 0, AF21/AF$20) -> 0 | AM21: =IF(AG21 = 0, 0,#REF!/ AG$20) -> 0 | AN21: =IF(OR(GradeSheet!$L10="W (Withdrawn)", GradeSheet!$L10="I (Incomplete)"), 0, IF(AH21>=55%, 1, 0)) -> 1 | AO21: =IF(OR(GradeSheet!$L10="W (Withdrawn)", GradeSheet!$L10="I (Incomplete)"), 0, IF(AI21>=55%, 1, 0)) -> 1 | AP21: =IF(OR(GradeSheet!$L10="W (Withdrawn)", GradeSheet!$L10="I (Incomplete)"), 0, IF(AJ21>=55%, 1, 0)) -> 0 | AQ21: =IF(OR(GradeSheet!$L10="W (Withdrawn)", GradeSheet!$L10="I (Incomplete)"), 0, IF(AK21>=55%, 1, 0)) -> 0 | AR21: =IF(OR(GradeSheet!$L10="W (Withdrawn)", GradeSheet!$L10="I (Incomplete)"), 0, IF(AL21>=55%, 1, 0)) -> 0 | AS21: =IF(OR(GradeSheet!$L10="W (Withdrawn)", GradeSheet!$L10="I (Incomplete)"), 0, IF(AM21>=55%, 1, 0)) -> 0 | AU21: {=IF($AT$15=0,0,MMULT($AH21:$AM21, AT$9:AT$14)/$AT$15)} -> 0 | AV21: {=IF($AT$15=0,0,MMULT($AH21:$AM21, AU$9:AU$14)/$AT$15)} -> 0 | AW21: {=IF($AT$15=0,0,MMULT($AH21:$AM21, AV$9:AV$14)/$AT$15)} -> 0 | AX21: {=IF($AT$15=0,0,MMULT($AH21:$AM21, AW$9:AW$14)/$AT$15)} -> 0 | AY21: {=IF($AT$15=0,0,MMULT($AH21:$AM21, AX$9:AX$14)/$AT$15)} -> 0 | AZ21: {=IF($AT$15=0,0,MMULT($AH21:$AM21, AY$9:AY$14)/$AT$15)} -> 0 | BA21: {=IF($AT$15=0,0,MMULT($AH21:$AM21, AZ$9:AZ$14)/$AT$15)} -> 0 | BB21: {=IF($AT$15=0,0,MMULT($AH21:$AM21, BA$9:BA$14)/$AT$15)} -> 0 | ... BF21: {=IF($AT$15=0,0,MMULT($AH21:$AM21, BE$9:BE$14)/$AT$15)} -> 0 | BG21: =IF(OR(GradeSheet!$L10="W (Withdrawn)", GradeSheet!$L10="I (Incomplete)"), 0, IF(AU21>=65%, 1, 0)) -> 0 | BH21: =IF(OR(GradeSheet!$L10="W (Withdrawn)", GradeSheet!$L10="I (Incomplete)"), 0, IF(AV21>=65%, 1, 0)) -> 0 | BI21: =IF(OR(GradeSheet!$L10="W (Withdrawn)", GradeSheet!$L10="I (Incomplete)"), 0, IF(AW21>=65%, 1, 0)) -> 0 | BJ21: =IF(OR(GradeSheet!$L10="W (Withdrawn)", GradeSheet!$L10="I (Incomplete)"), 0, IF(AX21>=65%, 1, 0)) -> 0 | BK21: =IF(OR(GradeSheet!$L10="W (Withdrawn)", GradeSheet!$L10="I (Incomplete)"), 0, IF(AY21>=65%, 1, 0)) -> 0 | BL21: =IF(OR(GradeSheet!$L10="W (Withdrawn)", GradeSheet!$L10="I (Incomplete)"), 0, IF(AZ21>=65%, 1, 0)) -> 0 | BM21: =IF(OR(GradeSheet!$L10="W (Withdrawn)", GradeSheet!$L10="I (Incomplete)"), 0, IF(BA21>=65%, 1, 0)) -> 0 | BN21: =IF(OR(GradeSheet!$L10="W (Withdrawn)", GradeSheet!$L10="I (Incomplete)"), 0, IF(BB21>=65%, 1, 0)) -> 0 | ... BR21: =IF(OR(GradeSheet!$L10="W (Withdrawn)", GradeSheet!$L10="I (Incomplete)"), 0, IF(BF21>=65%, 1, 0)) -> 0
A22: 2 | B22: 251014053 | C22: Md. Nafij Iqbal Sazid | D22: 6 | E22: 4 | F22: 0 | G22: 0 | H22: 0 | I22: 0 | J22: 0 | K22: 0 | L22: 0 | M22: 0 | N22: 0 | O22: 0 | P22: 0 | Q22: 0 | R22: 0 | S22: 0 | T22: 0 | U22: 0 | V22: 0 | W22: 0 | X22: 0 | Y22: 0 | Z22: 0 | AA22: 0 | AB22: =SUM(D22,J22,P22,V22) -> 6 | AC22: =SUM(E22,K22,Q22,W22) -> 4 | AD22: =SUM(F22,L22,R22,X22) -> 0 | AE22: =SUM(G22,M22,S22,Y22) -> 0 | AF22: =SUM(H22,N22,T22,Z22) -> 0 | AG22: =SUM(I22,O22,U22,AA22) -> 0 | AH22: =IF(AB22 = 0, 0, AB22/AB$20) -> 1 | AI22: =IF(AC22 = 0, 0, AC22/AC$20) -> 0.66666667 | AJ22: =IF(AD22 = 0, 0, AD22/AD$20) -> 0 | AK22: =IF(AE22 = 0, 0, AE22/AE$20) -> 0 | AL22: =IF(AF22 = 0, 0, AF22/AF$20) -> 0 | AM22: =IF(AG22 = 0, 0,#REF!/ AG$20) -> 0 | AN22: =IF(OR(GradeSheet!$L11="W (Withdrawn)", GradeSheet!$L11="I (Incomplete)"), 0, IF(AH22>=55%, 1, 0)) -> 1 | AO22: =IF(OR(GradeSheet!$L11="W (Withdrawn)", GradeSheet!$L11="I (Incomplete)"), 0, IF(AI22>=55%, 1, 0)) -> 1 | AP22: =IF(OR(GradeSheet!$L11="W (Withdrawn)", GradeSheet!$L11="I (Incomplete)"), 0, IF(AJ22>=55%, 1, 0)) -> 0 | AQ22: =IF(OR(GradeSheet!$L11="W (Withdrawn)", GradeSheet!$L11="I (Incomplete)"), 0, IF(AK22>=55%, 1, 0)) -> 0 | AR22: =IF(OR(GradeSheet!$L11="W (Withdrawn)", GradeSheet!$L11="I (Incomplete)"), 0, IF(AL22>=55%, 1, 0)) -> 0 | AS22: =IF(OR(GradeSheet!$L11="W (Withdrawn)", GradeSheet!$L11="I (Incomplete)"), 0, IF(AM22>=55%, 1, 0)) -> 0 | AU22: {=IF($AT$15=0,0,MMULT($AH22:$AM22, AT$9:AT$14)/$AT$15)} -> 0 | AV22: {=IF($AT$15=0,0,MMULT($AH22:$AM22, AU$9:AU$14)/$AT$15)} -> 0 | AW22: {=IF($AT$15=0,0,MMULT($AH22:$AM22, AV$9:AV$14)/$AT$15)} -> 0 | AX22: {=IF($AT$15=0,0,MMULT($AH22:$AM22, AW$9:AW$14)/$AT$15)} -> 0 | AY22: {=IF($AT$15=0,0,MMULT($AH22:$AM22, AX$9:AX$14)/$AT$15)} -> 0 | AZ22: {=IF($AT$15=0,0,MMULT($AH22:$AM22, AY$9:AY$14)/$AT$15)} -> 0 | BA22: {=IF($AT$15=0,0,MMULT($AH22:$AM22, AZ$9:AZ$14)/$AT$15)} -> 0 | BB22: {=IF($AT$15=0,0,MMULT($AH22:$AM22, BA$9:BA$14)/$AT$15)} -> 0 | ... BF22: {=IF($AT$15=0,0,MMULT($AH22:$AM22, BE$9:BE$14)/$AT$15)} -> 0 | BG22: =IF(OR(GradeSheet!$L11="W (Withdrawn)", GradeSheet!$L11="I (Incomplete)"), 0, IF(AU22>=65%, 1, 0)) -> 0 | BH22: =IF(OR(GradeSheet!$L11="W (Withdrawn)", GradeSheet!$L11="I (Incomplete)"), 0, IF(AV22>=65%, 1, 0)) -> 0 | BI22: =IF(OR(GradeSheet!$L11="W (Withdrawn)", GradeSheet!$L11="I (Incomplete)"), 0, IF(AW22>=65%, 1, 0)) -> 0 | BJ22: =IF(OR(GradeSheet!$L11="W (Withdrawn)", GradeSheet!$L11="I (Incomplete)"), 0, IF(AX22>=65%, 1, 0)) -> 0 | BK22: =IF(OR(GradeSheet!$L11="W (Withdrawn)", GradeSheet!$L11="I (Incomplete)"), 0, IF(AY22>=65%, 1, 0)) -> 0 | BL22: =IF(OR(GradeSheet!$L11="W (Withdrawn)", GradeSheet!$L11="I (Incomplete)"), 0, IF(AZ22>=65%, 1, 0)) -> 0 | BM22: =IF(OR(GradeSheet!$L11="W (Withdrawn)", GradeSheet!$L11="I (Incomplete)"), 0, IF(BA22>=65%, 1, 0)) -> 0 | BN22: =IF(OR(GradeSheet!$L11="W (Withdrawn)", GradeSheet!$L11="I (Incomplete)"), 0, IF(BB22>=65%, 1, 0)) -> 0 | ... BR22: =IF(OR(GradeSheet!$L11="W (Withdrawn)", GradeSheet!$L11="I (Incomplete)"), 0, IF(BF22>=65%, 1, 0)) -> 0
A23: 3 | B23: 251014059 | C23: Najni Nawar Supti | D23: 6 | E23: 4 | F23: 0 | G23: 0 | H23: 0 | I23: 0 | J23: 0 | K23: 0 | L23: 0 | M23: 0 | N23: 0 | O23: 0 | P23: 0 | Q23: 0 | R23: 0 | S23: 0 | T23: 0 | U23: 0 | V23: 0 | W23: 0 | X23: 0 | Y23: 0 | Z23: 0 | AA23: 0 | AB23: =SUM(D23,J23,P23,V23) -> 6 | AC23: =SUM(E23,K23,Q23,W23) -> 4 | AD23: =SUM(F23,L23,R23,X23) -> 0 | AE23: =SUM(G23,M23,S23,Y23) -> 0 | AF23: =SUM(H23,N23,T23,Z23) -> 0 | AG23: =SUM(I23,O23,U23,AA23) -> 0 | AH23: =IF(AB23 = 0, 0, AB23/AB$20) -> 1 | AI23: =IF(AC23 = 0, 0, AC23/AC$20) -> 0.66666667 | AJ23: =IF(AD23 = 0, 0, AD23/AD$20) -> 0 | AK23: =IF(AE23 = 0, 0, AE23/AE$20) -> 0 | AL23: =IF(AF23 = 0, 0, AF23/AF$20) -> 0 | AM23: =IF(AG23 = 0, 0,#REF!/ AG$20) -> 0 | AN23: =IF(OR(GradeSheet!$L12="W (Withdrawn)", GradeSheet!$L12="I (Incomplete)"), 0, IF(AH23>=55%, 1, 0)) -> 1 | AO23: =IF(OR(GradeSheet!$L12="W (Withdrawn)", GradeSheet!$L12="I (Incomplete)"), 0, IF(AI23>=55%, 1, 0)) -> 1 | AP23: =IF(OR(GradeSheet!$L12="W (Withdrawn)", GradeSheet!$L12="I (Incomplete)"), 0, IF(AJ23>=55%, 1, 0)) -> 0 | AQ23: =IF(OR(GradeSheet!$L12="W (Withdrawn)", GradeSheet!$L12="I (Incomplete)"), 0, IF(AK23>=55%, 1, 0)) -> 0 | AR23: =IF(OR(GradeSheet!$L12="W (Withdrawn)", GradeSheet!$L12="I (Incomplete)"), 0, IF(AL23>=55%, 1, 0)) -> 0 | AS23: =IF(OR(GradeSheet!$L12="W (Withdrawn)", GradeSheet!$L12="I (Incomplete)"), 0, IF(AM23>=55%, 1, 0)) -> 0 | AU23: {=IF($AT$15=0,0,MMULT($AH23:$AM23, AT$9:AT$14)/$AT$15)} -> 0 | AV23: {=IF($AT$15=0,0,MMULT($AH23:$AM23, AU$9:AU$14)/$AT$15)} -> 0 | AW23: {=IF($AT$15=0,0,MMULT($AH23:$AM23, AV$9:AV$14)/$AT$15)} -> 0 | AX23: {=IF($AT$15=0,0,MMULT($AH23:$AM23, AW$9:AW$14)/$AT$15)} -> 0 | AY23: {=IF($AT$15=0,0,MMULT($AH23:$AM23, AX$9:AX$14)/$AT$15)} -> 0 | AZ23: {=IF($AT$15=0,0,MMULT($AH23:$AM23, AY$9:AY$14)/$AT$15)} -> 0 | BA23: {=IF($AT$15=0,0,MMULT($AH23:$AM23, AZ$9:AZ$14)/$AT$15)} -> 0 | BB23: {=IF($AT$15=0,0,MMULT($AH23:$AM23, BA$9:BA$14)/$AT$15)} -> 0 | ... BF23: {=IF($AT$15=0,0,MMULT($AH23:$AM23, BE$9:BE$14)/$AT$15)} -> 0 | BG23: =IF(OR(GradeSheet!$L12="W (Withdrawn)", GradeSheet!$L12="I (Incomplete)"), 0, IF(AU23>=65%, 1, 0)) -> 0 | BH23: =IF(OR(GradeSheet!$L12="W (Withdrawn)", GradeSheet!$L12="I (Incomplete)"), 0, IF(AV23>=65%, 1, 0)) -> 0 | BI23: =IF(OR(GradeSheet!$L12="W (Withdrawn)", GradeSheet!$L12="I (Incomplete)"), 0, IF(AW23>=65%, 1, 0)) -> 0 | BJ23: =IF(OR(GradeSheet!$L12="W (Withdrawn)", GradeSheet!$L12="I (Incomplete)"), 0, IF(AX23>=65%, 1, 0)) -> 0 | BK23: =IF(OR(GradeSheet!$L12="W (Withdrawn)", GradeSheet!$L12="I (Incomplete)"), 0, IF(AY23>=65%, 1, 0)) -> 0 | BL23: =IF(OR(GradeSheet!$L12="W (Withdrawn)", GradeSheet!$L12="I (Incomplete)"), 0, IF(AZ23>=65%, 1, 0)) -> 0 | BM23: =IF(OR(GradeSheet!$L12="W (Withdrawn)", GradeSheet!$L12="I (Incomplete)"), 0, IF(BA23>=65%, 1, 0)) -> 0 | BN23: =IF(OR(GradeSheet!$L12="W (Withdrawn)", GradeSheet!$L12="I (Incomplete)"), 0, IF(BB23>=65%, 1, 0)) -> 0 | ... BR23: =IF(OR(GradeSheet!$L12="W (Withdrawn)", GradeSheet!$L12="I (Incomplete)"), 0, IF(BF23>=65%, 1, 0)) -> 0
A24: 4 | B24: 252014038 | C24: Md. Ishfaq Alam | D24: 6 | E24: 6 | F24: 0 | G24: 0 | H24: 0 | I24: 0 | J24: 0 | K24: 0 | L24: 0 | M24: 0 | N24: 0 | O24: 0 | P24: 0 | Q24: 0 | R24: 0 | S24: 0 | T24: 0 | U24: 0 | V24: 0 | W24: 0 | X24: 0 | Y24: 0 | Z24: 0 | AA24: 0 | AB24: =SUM(D24,J24,P24,V24) -> 6 | AC24: =SUM(E24,K24,Q24,W24) -> 6 | AD24: =SUM(F24,L24,R24,X24) -> 0 | AE24: =SUM(G24,M24,S24,Y24) -> 0 | AF24: =SUM(H24,N24,T24,Z24) -> 0 | AG24: =SUM(I24,O24,U24,AA24) -> 0 | AH24: =IF(AB24 = 0, 0, AB24/AB$20) -> 1 | AI24: =IF(AC24 = 0, 0, AC24/AC$20) -> 1 | AJ24: =IF(AD24 = 0, 0, AD24/AD$20) -> 0 | AK24: =IF(AE24 = 0, 0, AE24/AE$20) -> 0 | AL24: =IF(AF24 = 0, 0, AF24/AF$20) -> 0 | AM24: =IF(AG24 = 0, 0,#REF!/ AG$20) -> 0 | AN24: =IF(OR(GradeSheet!$L13="W (Withdrawn)", GradeSheet!$L13="I (Incomplete)"), 0, IF(AH24>=55%, 1, 0)) -> 1 | AO24: =IF(OR(GradeSheet!$L13="W (Withdrawn)", GradeSheet!$L13="I (Incomplete)"), 0, IF(AI24>=55%, 1, 0)) -> 1 | AP24: =IF(OR(GradeSheet!$L13="W (Withdrawn)", GradeSheet!$L13="I (Incomplete)"), 0, IF(AJ24>=55%, 1, 0)) -> 0 | AQ24: =IF(OR(GradeSheet!$L13="W (Withdrawn)", GradeSheet!$L13="I (Incomplete)"), 0, IF(AK24>=55%, 1, 0)) -> 0 | AR24: =IF(OR(GradeSheet!$L13="W (Withdrawn)", GradeSheet!$L13="I (Incomplete)"), 0, IF(AL24>=55%, 1, 0)) -> 0 | AS24: =IF(OR(GradeSheet!$L13="W (Withdrawn)", GradeSheet!$L13="I (Incomplete)"), 0, IF(AM24>=55%, 1, 0)) -> 0 | AU24: {=IF($AT$15=0,0,MMULT($AH24:$AM24, AT$9:AT$14)/$AT$15)} -> 0 | AV24: {=IF($AT$15=0,0,MMULT($AH24:$AM24, AU$9:AU$14)/$AT$15)} -> 0 | AW24: {=IF($AT$15=0,0,MMULT($AH24:$AM24, AV$9:AV$14)/$AT$15)} -> 0 | AX24: {=IF($AT$15=0,0,MMULT($AH24:$AM24, AW$9:AW$14)/$AT$15)} -> 0 | AY24: {=IF($AT$15=0,0,MMULT($AH24:$AM24, AX$9:AX$14)/$AT$15)} -> 0 | AZ24: {=IF($AT$15=0,0,MMULT($AH24:$AM24, AY$9:AY$14)/$AT$15)} -> 0 | BA24: {=IF($AT$15=0,0,MMULT($AH24:$AM24, AZ$9:AZ$14)/$AT$15)} -> 0 | BB24: {=IF($AT$15=0,0,MMULT($AH24:$AM24, BA$9:BA$14)/$AT$15)} -> 0 | ... BF24: {=IF($AT$15=0,0,MMULT($AH24:$AM24, BE$9:BE$14)/$AT$15)} -> 0 | BG24: =IF(OR(GradeSheet!$L13="W (Withdrawn)", GradeSheet!$L13="I (Incomplete)"), 0, IF(AU24>=65%, 1, 0)) -> 0 | BH24: =IF(OR(GradeSheet!$L13="W (Withdrawn)", GradeSheet!$L13="I (Incomplete)"), 0, IF(AV24>=65%, 1, 0)) -> 0 | BI24: =IF(OR(GradeSheet!$L13="W (Withdrawn)", GradeSheet!$L13="I (Incomplete)"), 0, IF(AW24>=65%, 1, 0)) -> 0 | BJ24: =IF(OR(GradeSheet!$L13="W (Withdrawn)", GradeSheet!$L13="I (Incomplete)"), 0, IF(AX24>=65%, 1, 0)) -> 0 | BK24: =IF(OR(GradeSheet!$L13="W (Withdrawn)", GradeSheet!$L13="I (Incomplete)"), 0, IF(AY24>=65%, 1, 0)) -> 0 | BL24: =IF(OR(GradeSheet!$L13="W (Withdrawn)", GradeSheet!$L13="I (Incomplete)"), 0, IF(AZ24>=65%, 1, 0)) -> 0 | BM24: =IF(OR(GradeSheet!$L13="W (Withdrawn)", GradeSheet!$L13="I (Incomplete)"), 0, IF(BA24>=65%, 1, 0)) -> 0 | BN24: =IF(OR(GradeSheet!$L13="W (Withdrawn)", GradeSheet!$L13="I (Incomplete)"), 0, IF(BB24>=65%, 1, 0)) -> 0 | ... BR24: =IF(OR(GradeSheet!$L13="W (Withdrawn)", GradeSheet!$L13="I (Incomplete)"), 0, IF(BF24>=65%, 1, 0)) -> 0
A25: 5 | B25: 252014076 | C25: Pavel Ahamed Sarkar | D25: 6 | E25: 6 | F25: 0 | G25: 0 | H25: 0 | I25: 0 | J25: 0 | K25: 0 | L25: 0 | M25: 0 | N25: 0 | O25: 0 | P25: 0 | Q25: 0 | R25: 0 | S25: 0 | T25: 0 | U25: 0 | V25: 0 | W25: 0 | X25: 0 | Y25: 0 | Z25: 0 | AA25: 0 | AB25: =SUM(D25,J25,P25,V25) -> 6 | AC25: =SUM(E25,K25,Q25,W25) -> 6 | AD25: =SUM(F25,L25,R25,X25) -> 0 | AE25: =SUM(G25,M25,S25,Y25) -> 0 | AF25: =SUM(H25,N25,T25,Z25) -> 0 | AG25: =SUM(I25,O25,U25,AA25) -> 0 | AH25: =IF(AB25 = 0, 0, AB25/AB$20) -> 1 | AI25: =IF(AC25 = 0, 0, AC25/AC$20) -> 1 | AJ25: =IF(AD25 = 0, 0, AD25/AD$20) -> 0 | AK25: =IF(AE25 = 0, 0, AE25/AE$20) -> 0 | AL25: =IF(AF25 = 0, 0, AF25/AF$20) -> 0 | AM25: =IF(AG25 = 0, 0,#REF!/ AG$20) -> 0 | AN25: =IF(OR(GradeSheet!$L14="W (Withdrawn)", GradeSheet!$L14="I (Incomplete)"), 0, IF(AH25>=55%, 1, 0)) -> 1 | AO25: =IF(OR(GradeSheet!$L14="W (Withdrawn)", GradeSheet!$L14="I (Incomplete)"), 0, IF(AI25>=55%, 1, 0)) -> 1 | AP25: =IF(OR(GradeSheet!$L14="W (Withdrawn)", GradeSheet!$L14="I (Incomplete)"), 0, IF(AJ25>=55%, 1, 0)) -> 0 | AQ25: =IF(OR(GradeSheet!$L14="W (Withdrawn)", GradeSheet!$L14="I (Incomplete)"), 0, IF(AK25>=55%, 1, 0)) -> 0 | AR25: =IF(OR(GradeSheet!$L14="W (Withdrawn)", GradeSheet!$L14="I (Incomplete)"), 0, IF(AL25>=55%, 1, 0)) -> 0 | AS25: =IF(OR(GradeSheet!$L14="W (Withdrawn)", GradeSheet!$L14="I (Incomplete)"), 0, IF(AM25>=55%, 1, 0)) -> 0 | AU25: {=IF($AT$15=0,0,MMULT($AH25:$AM25, AT$9:AT$14)/$AT$15)} -> 0 | AV25: {=IF($AT$15=0,0,MMULT($AH25:$AM25, AU$9:AU$14)/$AT$15)} -> 0 | AW25: {=IF($AT$15=0,0,MMULT($AH25:$AM25, AV$9:AV$14)/$AT$15)} -> 0 | AX25: {=IF($AT$15=0,0,MMULT($AH25:$AM25, AW$9:AW$14)/$AT$15)} -> 0 | AY25: {=IF($AT$15=0,0,MMULT($AH25:$AM25, AX$9:AX$14)/$AT$15)} -> 0 | AZ25: {=IF($AT$15=0,0,MMULT($AH25:$AM25, AY$9:AY$14)/$AT$15)} -> 0 | BA25: {=IF($AT$15=0,0,MMULT($AH25:$AM25, AZ$9:AZ$14)/$AT$15)} -> 0 | BB25: {=IF($AT$15=0,0,MMULT($AH25:$AM25, BA$9:BA$14)/$AT$15)} -> 0 | ... BF25: {=IF($AT$15=0,0,MMULT($AH25:$AM25, BE$9:BE$14)/$AT$15)} -> 0 | BG25: =IF(OR(GradeSheet!$L14="W (Withdrawn)", GradeSheet!$L14="I (Incomplete)"), 0, IF(AU25>=65%, 1, 0)) -> 0 | BH25: =IF(OR(GradeSheet!$L14="W (Withdrawn)", GradeSheet!$L14="I (Incomplete)"), 0, IF(AV25>=65%, 1, 0)) -> 0 | BI25: =IF(OR(GradeSheet!$L14="W (Withdrawn)", GradeSheet!$L14="I (Incomplete)"), 0, IF(AW25>=65%, 1, 0)) -> 0 | BJ25: =IF(OR(GradeSheet!$L14="W (Withdrawn)", GradeSheet!$L14="I (Incomplete)"), 0, IF(AX25>=65%, 1, 0)) -> 0 | BK25: =IF(OR(GradeSheet!$L14="W (Withdrawn)", GradeSheet!$L14="I (Incomplete)"), 0, IF(AY25>=65%, 1, 0)) -> 0 | BL25: =IF(OR(GradeSheet!$L14="W (Withdrawn)", GradeSheet!$L14="I (Incomplete)"), 0, IF(AZ25>=65%, 1, 0)) -> 0 | BM25: =IF(OR(GradeSheet!$L14="W (Withdrawn)", GradeSheet!$L14="I (Incomplete)"), 0, IF(BA25>=65%, 1, 0)) -> 0 | BN25: =IF(OR(GradeSheet!$L14="W (Withdrawn)", GradeSheet!$L14="I (Incomplete)"), 0, IF(BB25>=65%, 1, 0)) -> 0 | ... BR25: =IF(OR(GradeSheet!$L14="W (Withdrawn)", GradeSheet!$L14="I (Incomplete)"), 0, IF(BF25>=65%, 1, 0)) -> 0
A26: 6 | B26: 252014084 | C26: Nusrat Jahan Autoshi | D26: 0 | E26: 0 | F26: 0 | G26: 0 | H26: 0 | I26: 0 | J26: 0 | K26: 0 | L26: 0 | M26: 0 | N26: 0 | O26: 0 | P26: 0 | Q26: 0 | R26: 0 | S26: 0 | T26: 0 | U26: 0 | V26: 0 | W26: 0 | X26: 0 | Y26: 0 | Z26: 0 | AA26: 0 | AB26: =SUM(D26,J26,P26,V26) -> 0 | AC26: =SUM(E26,K26,Q26,W26) -> 0 | AD26: =SUM(F26,L26,R26,X26) -> 0 | AE26: =SUM(G26,M26,S26,Y26) -> 0 | AF26: =SUM(H26,N26,T26,Z26) -> 0 | AG26: =SUM(I26,O26,U26,AA26) -> 0 | AH26: =IF(AB26 = 0, 0, AB26/AB$20) -> 0 | AI26: =IF(AC26 = 0, 0, AC26/AC$20) -> 0 | AJ26: =IF(AD26 = 0, 0, AD26/AD$20) -> 0 | AK26: =IF(AE26 = 0, 0, AE26/AE$20) -> 0 | AL26: =IF(AF26 = 0, 0, AF26/AF$20) -> 0 | AM26: =IF(AG26 = 0, 0,#REF!/ AG$20) -> 0 | AN26: =IF(OR(GradeSheet!$L15="W (Withdrawn)", GradeSheet!$L15="I (Incomplete)"), 0, IF(AH26>=55%, 1, 0)) -> 0 | AO26: =IF(OR(GradeSheet!$L15="W (Withdrawn)", GradeSheet!$L15="I (Incomplete)"), 0, IF(AI26>=55%, 1, 0)) -> 0 | AP26: =IF(OR(GradeSheet!$L15="W (Withdrawn)", GradeSheet!$L15="I (Incomplete)"), 0, IF(AJ26>=55%, 1, 0)) -> 0 | AQ26: =IF(OR(GradeSheet!$L15="W (Withdrawn)", GradeSheet!$L15="I (Incomplete)"), 0, IF(AK26>=55%, 1, 0)) -> 0 | AR26: =IF(OR(GradeSheet!$L15="W (Withdrawn)", GradeSheet!$L15="I (Incomplete)"), 0, IF(AL26>=55%, 1, 0)) -> 0 | AS26: =IF(OR(GradeSheet!$L15="W (Withdrawn)", GradeSheet!$L15="I (Incomplete)"), 0, IF(AM26>=55%, 1, 0)) -> 0 | AU26: {=IF($AT$15=0,0,MMULT($AH26:$AM26, AT$9:AT$14)/$AT$15)} -> 0 | AV26: {=IF($AT$15=0,0,MMULT($AH26:$AM26, AU$9:AU$14)/$AT$15)} -> 0 | AW26: {=IF($AT$15=0,0,MMULT($AH26:$AM26, AV$9:AV$14)/$AT$15)} -> 0 | AX26: {=IF($AT$15=0,0,MMULT($AH26:$AM26, AW$9:AW$14)/$AT$15)} -> 0 | AY26: {=IF($AT$15=0,0,MMULT($AH26:$AM26, AX$9:AX$14)/$AT$15)} -> 0 | AZ26: {=IF($AT$15=0,0,MMULT($AH26:$AM26, AY$9:AY$14)/$AT$15)} -> 0 | BA26: {=IF($AT$15=0,0,MMULT($AH26:$AM26, AZ$9:AZ$14)/$AT$15)} -> 0 | BB26: {=IF($AT$15=0,0,MMULT($AH26:$AM26, BA$9:BA$14)/$AT$15)} -> 0 | ... BF26: {=IF($AT$15=0,0,MMULT($AH26:$AM26, BE$9:BE$14)/$AT$15)} -> 0 | BG26: =IF(OR(GradeSheet!$L15="W (Withdrawn)", GradeSheet!$L15="I (Incomplete)"), 0, IF(AU26>=65%, 1, 0)) -> 0 | BH26: =IF(OR(GradeSheet!$L15="W (Withdrawn)", GradeSheet!$L15="I (Incomplete)"), 0, IF(AV26>=65%, 1, 0)) -> 0 | BI26: =IF(OR(GradeSheet!$L15="W (Withdrawn)", GradeSheet!$L15="I (Incomplete)"), 0, IF(AW26>=65%, 1, 0)) -> 0 | BJ26: =IF(OR(GradeSheet!$L15="W (Withdrawn)", GradeSheet!$L15="I (Incomplete)"), 0, IF(AX26>=65%, 1, 0)) -> 0 | BK26: =IF(OR(GradeSheet!$L15="W (Withdrawn)", GradeSheet!$L15="I (Incomplete)"), 0, IF(AY26>=65%, 1, 0)) -> 0 | BL26: =IF(OR(GradeSheet!$L15="W (Withdrawn)", GradeSheet!$L15="I (Incomplete)"), 0, IF(AZ26>=65%, 1, 0)) -> 0 | BM26: =IF(OR(GradeSheet!$L15="W (Withdrawn)", GradeSheet!$L15="I (Incomplete)"), 0, IF(BA26>=65%, 1, 0)) -> 0 | BN26: =IF(OR(GradeSheet!$L15="W (Withdrawn)", GradeSheet!$L15="I (Incomplete)"), 0, IF(BB26>=65%, 1, 0)) -> 0 | ... BR26: =IF(OR(GradeSheet!$L15="W (Withdrawn)", GradeSheet!$L15="I (Incomplete)"), 0, IF(BF26>=65%, 1, 0)) -> 0
A27: 7 | B27: 252014086 | C27: Avro Mostafi Hassan | D27: 6 | E27: 6 | F27: 0 | G27: 0 | H27: 0 | I27: 0 | J27: 0 | K27: 0 | L27: 0 | M27: 0 | N27: 0 | O27: 0 | P27: 0 | Q27: 0 | R27: 0 | S27: 0 | T27: 0 | U27: 0 | V27: 0 | W27: 0 | X27: 0 | Y27: 0 | Z27: 0 | AA27: 0 | AB27: =SUM(D27,J27,P27,V27) -> 6 | AC27: =SUM(E27,K27,Q27,W27) -> 6 | AD27: =SUM(F27,L27,R27,X27) -> 0 | AE27: =SUM(G27,M27,S27,Y27) -> 0 | AF27: =SUM(H27,N27,T27,Z27) -> 0 | AG27: =SUM(I27,O27,U27,AA27) -> 0 | AH27: =IF(AB27 = 0, 0, AB27/AB$20) -> 1 | AI27: =IF(AC27 = 0, 0, AC27/AC$20) -> 1 | AJ27: =IF(AD27 = 0, 0, AD27/AD$20) -> 0 | AK27: =IF(AE27 = 0, 0, AE27/AE$20) -> 0 | AL27: =IF(AF27 = 0, 0, AF27/AF$20) -> 0 | AM27: =IF(AG27 = 0, 0,#REF!/ AG$20) -> 0 | AN27: =IF(OR(GradeSheet!$L16="W (Withdrawn)", GradeSheet!$L16="I (Incomplete)"), 0, IF(AH27>=55%, 1, 0)) -> 1 | AO27: =IF(OR(GradeSheet!$L16="W (Withdrawn)", GradeSheet!$L16="I (Incomplete)"), 0, IF(AI27>=55%, 1, 0)) -> 1 | AP27: =IF(OR(GradeSheet!$L16="W (Withdrawn)", GradeSheet!$L16="I (Incomplete)"), 0, IF(AJ27>=55%, 1, 0)) -> 0 | AQ27: =IF(OR(GradeSheet!$L16="W (Withdrawn)", GradeSheet!$L16="I (Incomplete)"), 0, IF(AK27>=55%, 1, 0)) -> 0 | AR27: =IF(OR(GradeSheet!$L16="W (Withdrawn)", GradeSheet!$L16="I (Incomplete)"), 0, IF(AL27>=55%, 1, 0)) -> 0 | AS27: =IF(OR(GradeSheet!$L16="W (Withdrawn)", GradeSheet!$L16="I (Incomplete)"), 0, IF(AM27>=55%, 1, 0)) -> 0 | AU27: {=IF($AT$15=0,0,MMULT($AH27:$AM27, AT$9:AT$14)/$AT$15)} -> 0 | AV27: {=IF($AT$15=0,0,MMULT($AH27:$AM27, AU$9:AU$14)/$AT$15)} -> 0 | AW27: {=IF($AT$15=0,0,MMULT($AH27:$AM27, AV$9:AV$14)/$AT$15)} -> 0 | AX27: {=IF($AT$15=0,0,MMULT($AH27:$AM27, AW$9:AW$14)/$AT$15)} -> 0 | AY27: {=IF($AT$15=0,0,MMULT($AH27:$AM27, AX$9:AX$14)/$AT$15)} -> 0 | AZ27: {=IF($AT$15=0,0,MMULT($AH27:$AM27, AY$9:AY$14)/$AT$15)} -> 0 | BA27: {=IF($AT$15=0,0,MMULT($AH27:$AM27, AZ$9:AZ$14)/$AT$15)} -> 0 | BB27: {=IF($AT$15=0,0,MMULT($AH27:$AM27, BA$9:BA$14)/$AT$15)} -> 0 | ... BF27: {=IF($AT$15=0,0,MMULT($AH27:$AM27, BE$9:BE$14)/$AT$15)} -> 0 | BG27: =IF(OR(GradeSheet!$L16="W (Withdrawn)", GradeSheet!$L16="I (Incomplete)"), 0, IF(AU27>=65%, 1, 0)) -> 0 | BH27: =IF(OR(GradeSheet!$L16="W (Withdrawn)", GradeSheet!$L16="I (Incomplete)"), 0, IF(AV27>=65%, 1, 0)) -> 0 | BI27: =IF(OR(GradeSheet!$L16="W (Withdrawn)", GradeSheet!$L16="I (Incomplete)"), 0, IF(AW27>=65%, 1, 0)) -> 0 | BJ27: =IF(OR(GradeSheet!$L16="W (Withdrawn)", GradeSheet!$L16="I (Incomplete)"), 0, IF(AX27>=65%, 1, 0)) -> 0 | BK27: =IF(OR(GradeSheet!$L16="W (Withdrawn)", GradeSheet!$L16="I (Incomplete)"), 0, IF(AY27>=65%, 1, 0)) -> 0 | BL27: =IF(OR(GradeSheet!$L16="W (Withdrawn)", GradeSheet!$L16="I (Incomplete)"), 0, IF(AZ27>=65%, 1, 0)) -> 0 | BM27: =IF(OR(GradeSheet!$L16="W (Withdrawn)", GradeSheet!$L16="I (Incomplete)"), 0, IF(BA27>=65%, 1, 0)) -> 0 | BN27: =IF(OR(GradeSheet!$L16="W (Withdrawn)", GradeSheet!$L16="I (Incomplete)"), 0, IF(BB27>=65%, 1, 0)) -> 0 | ... BR27: =IF(OR(GradeSheet!$L16="W (Withdrawn)", GradeSheet!$L16="I (Incomplete)"), 0, IF(BF27>=65%, 1, 0)) -> 0
A28: 8 | B28: 252014106 | C28: Md. Abu Ashraf Patwary Noor | D28: 6 | E28: 4 | F28: 0 | G28: 0 | H28: 0 | I28: 0 | J28: 0 | K28: 0 | L28: 0 | M28: 0 | N28: 0 | O28: 0 | P28: 0 | Q28: 0 | R28: 0 | S28: 0 | T28: 0 | U28: 0 | V28: 0 | W28: 0 | X28: 0 | Y28: 0 | Z28: 0 | AA28: 0 | AB28: =SUM(D28,J28,P28,V28) -> 6 | AC28: =SUM(E28,K28,Q28,W28) -> 4 | AD28: =SUM(F28,L28,R28,X28) -> 0 | AE28: =SUM(G28,M28,S28,Y28) -> 0 | AF28: =SUM(H28,N28,T28,Z28) -> 0 | AG28: =SUM(I28,O28,U28,AA28) -> 0 | AH28: =IF(AB28 = 0, 0, AB28/AB$20) -> 1 | AI28: =IF(AC28 = 0, 0, AC28/AC$20) -> 0.66666667 | AJ28: =IF(AD28 = 0, 0, AD28/AD$20) -> 0 | AK28: =IF(AE28 = 0, 0, AE28/AE$20) -> 0 | AL28: =IF(AF28 = 0, 0, AF28/AF$20) -> 0 | AM28: =IF(AG28 = 0, 0,#REF!/ AG$20) -> 0 | AN28: =IF(OR(GradeSheet!$L17="W (Withdrawn)", GradeSheet!$L17="I (Incomplete)"), 0, IF(AH28>=55%, 1, 0)) -> 1 | AO28: =IF(OR(GradeSheet!$L17="W (Withdrawn)", GradeSheet!$L17="I (Incomplete)"), 0, IF(AI28>=55%, 1, 0)) -> 1 | AP28: =IF(OR(GradeSheet!$L17="W (Withdrawn)", GradeSheet!$L17="I (Incomplete)"), 0, IF(AJ28>=55%, 1, 0)) -> 0 | AQ28: =IF(OR(GradeSheet!$L17="W (Withdrawn)", GradeSheet!$L17="I (Incomplete)"), 0, IF(AK28>=55%, 1, 0)) -> 0 | AR28: =IF(OR(GradeSheet!$L17="W (Withdrawn)", GradeSheet!$L17="I (Incomplete)"), 0, IF(AL28>=55%, 1, 0)) -> 0 | AS28: =IF(OR(GradeSheet!$L17="W (Withdrawn)", GradeSheet!$L17="I (Incomplete)"), 0, IF(AM28>=55%, 1, 0)) -> 0 | AU28: {=IF($AT$15=0,0,MMULT($AH28:$AM28, AT$9:AT$14)/$AT$15)} -> 0 | AV28: {=IF($AT$15=0,0,MMULT($AH28:$AM28, AU$9:AU$14)/$AT$15)} -> 0 | AW28: {=IF($AT$15=0,0,MMULT($AH28:$AM28, AV$9:AV$14)/$AT$15)} -> 0 | AX28: {=IF($AT$15=0,0,MMULT($AH28:$AM28, AW$9:AW$14)/$AT$15)} -> 0 | AY28: {=IF($AT$15=0,0,MMULT($AH28:$AM28, AX$9:AX$14)/$AT$15)} -> 0 | AZ28: {=IF($AT$15=0,0,MMULT($AH28:$AM28, AY$9:AY$14)/$AT$15)} -> 0 | BA28: {=IF($AT$15=0,0,MMULT($AH28:$AM28, AZ$9:AZ$14)/$AT$15)} -> 0 | BB28: {=IF($AT$15=0,0,MMULT($AH28:$AM28, BA$9:BA$14)/$AT$15)} -> 0 | ... BF28: {=IF($AT$15=0,0,MMULT($AH28:$AM28, BE$9:BE$14)/$AT$15)} -> 0 | BG28: =IF(OR(GradeSheet!$L17="W (Withdrawn)", GradeSheet!$L17="I (Incomplete)"), 0, IF(AU28>=65%, 1, 0)) -> 0 | BH28: =IF(OR(GradeSheet!$L17="W (Withdrawn)", GradeSheet!$L17="I (Incomplete)"), 0, IF(AV28>=65%, 1, 0)) -> 0 | BI28: =IF(OR(GradeSheet!$L17="W (Withdrawn)", GradeSheet!$L17="I (Incomplete)"), 0, IF(AW28>=65%, 1, 0)) -> 0 | BJ28: =IF(OR(GradeSheet!$L17="W (Withdrawn)", GradeSheet!$L17="I (Incomplete)"), 0, IF(AX28>=65%, 1, 0)) -> 0 | BK28: =IF(OR(GradeSheet!$L17="W (Withdrawn)", GradeSheet!$L17="I (Incomplete)"), 0, IF(AY28>=65%, 1, 0)) -> 0 | BL28: =IF(OR(GradeSheet!$L17="W (Withdrawn)", GradeSheet!$L17="I (Incomplete)"), 0, IF(AZ28>=65%, 1, 0)) -> 0 | BM28: =IF(OR(GradeSheet!$L17="W (Withdrawn)", GradeSheet!$L17="I (Incomplete)"), 0, IF(BA28>=65%, 1, 0)) -> 0 | BN28: =IF(OR(GradeSheet!$L17="W (Withdrawn)", GradeSheet!$L17="I (Incomplete)"), 0, IF(BB28>=65%, 1, 0)) -> 0 | ... BR28: =IF(OR(GradeSheet!$L17="W (Withdrawn)", GradeSheet!$L17="I (Incomplete)"), 0, IF(BF28>=65%, 1, 0)) -> 0
A29: 9 | B29: 253014001 | C29: * Md. Minhajur Rahman | D29: 6 | E29: 4 | F29: 0 | G29: 0 | H29: 0 | I29: 0 | J29: 0 | K29: 0 | L29: 0 | M29: 0 | N29: 0 | O29: 0 | P29: 0 | Q29: 0 | R29: 0 | S29: 0 | T29: 0 | U29: 0 | V29: 0 | W29: 0 | X29: 0 | Y29: 0 | Z29: 0 | AA29: 0 | AB29: =SUM(D29,J29,P29,V29) -> 6 | AC29: =SUM(E29,K29,Q29,W29) -> 4 | AD29: =SUM(F29,L29,R29,X29) -> 0 | AE29: =SUM(G29,M29,S29,Y29) -> 0 | AF29: =SUM(H29,N29,T29,Z29) -> 0 | AG29: =SUM(I29,O29,U29,AA29) -> 0 | AH29: =IF(AB29 = 0, 0, AB29/AB$20) -> 1 | AI29: =IF(AC29 = 0, 0, AC29/AC$20) -> 0.66666667 | AJ29: =IF(AD29 = 0, 0, AD29/AD$20) -> 0 | AK29: =IF(AE29 = 0, 0, AE29/AE$20) -> 0 | AL29: =IF(AF29 = 0, 0, AF29/AF$20) -> 0 | AM29: =IF(AG29 = 0, 0,#REF!/ AG$20) -> 0 | AN29: =IF(OR(GradeSheet!$L18="W (Withdrawn)", GradeSheet!$L18="I (Incomplete)"), 0, IF(AH29>=55%, 1, 0)) -> 1 | AO29: =IF(OR(GradeSheet!$L18="W (Withdrawn)", GradeSheet!$L18="I (Incomplete)"), 0, IF(AI29>=55%, 1, 0)) -> 1 | AP29: =IF(OR(GradeSheet!$L18="W (Withdrawn)", GradeSheet!$L18="I (Incomplete)"), 0, IF(AJ29>=55%, 1, 0)) -> 0 | AQ29: =IF(OR(GradeSheet!$L18="W (Withdrawn)", GradeSheet!$L18="I (Incomplete)"), 0, IF(AK29>=55%, 1, 0)) -> 0 | AR29: =IF(OR(GradeSheet!$L18="W (Withdrawn)", GradeSheet!$L18="I (Incomplete)"), 0, IF(AL29>=55%, 1, 0)) -> 0 | AS29: =IF(OR(GradeSheet!$L18="W (Withdrawn)", GradeSheet!$L18="I (Incomplete)"), 0, IF(AM29>=55%, 1, 0)) -> 0 | AU29: {=IF($AT$15=0,0,MMULT($AH29:$AM29, AT$9:AT$14)/$AT$15)} -> 0 | AV29: {=IF($AT$15=0,0,MMULT($AH29:$AM29, AU$9:AU$14)/$AT$15)} -> 0 | AW29: {=IF($AT$15=0,0,MMULT($AH29:$AM29, AV$9:AV$14)/$AT$15)} -> 0 | AX29: {=IF($AT$15=0,0,MMULT($AH29:$AM29, AW$9:AW$14)/$AT$15)} -> 0 | AY29: {=IF($AT$15=0,0,MMULT($AH29:$AM29, AX$9:AX$14)/$AT$15)} -> 0 | AZ29: {=IF($AT$15=0,0,MMULT($AH29:$AM29, AY$9:AY$14)/$AT$15)} -> 0 | BA29: {=IF($AT$15=0,0,MMULT($AH29:$AM29, AZ$9:AZ$14)/$AT$15)} -> 0 | BB29: {=IF($AT$15=0,0,MMULT($AH29:$AM29, BA$9:BA$14)/$AT$15)} -> 0 | ... BF29: {=IF($AT$15=0,0,MMULT($AH29:$AM29, BE$9:BE$14)/$AT$15)} -> 0 | BG29: =IF(OR(GradeSheet!$L18="W (Withdrawn)", GradeSheet!$L18="I (Incomplete)"), 0, IF(AU29>=65%, 1, 0)) -> 0 | BH29: =IF(OR(GradeSheet!$L18="W (Withdrawn)", GradeSheet!$L18="I (Incomplete)"), 0, IF(AV29>=65%, 1, 0)) -> 0 | BI29: =IF(OR(GradeSheet!$L18="W (Withdrawn)", GradeSheet!$L18="I (Incomplete)"), 0, IF(AW29>=65%, 1, 0)) -> 0 | BJ29: =IF(OR(GradeSheet!$L18="W (Withdrawn)", GradeSheet!$L18="I (Incomplete)"), 0, IF(AX29>=65%, 1, 0)) -> 0 | BK29: =IF(OR(GradeSheet!$L18="W (Withdrawn)", GradeSheet!$L18="I (Incomplete)"), 0, IF(AY29>=65%, 1, 0)) -> 0 | BL29: =IF(OR(GradeSheet!$L18="W (Withdrawn)", GradeSheet!$L18="I (Incomplete)"), 0, IF(AZ29>=65%, 1, 0)) -> 0 | BM29: =IF(OR(GradeSheet!$L18="W (Withdrawn)", GradeSheet!$L18="I (Incomplete)"), 0, IF(BA29>=65%, 1, 0)) -> 0 | BN29: =IF(OR(GradeSheet!$L18="W (Withdrawn)", GradeSheet!$L18="I (Incomplete)"), 0, IF(BB29>=65%, 1, 0)) -> 0 | ... BR29: =IF(OR(GradeSheet!$L18="W (Withdrawn)", GradeSheet!$L18="I (Incomplete)"), 0, IF(BF29>=65%, 1, 0)) -> 0
A30: 10 | B30: 253014005 | C30: Md. Mahadi Hasan | D30: 6 | E30: 6 | F30: 0 | G30: 0 | H30: 0 | I30: 0 | J30: 0 | K30: 0 | L30: 0 | M30: 0 | N30: 0 | O30: 0 | P30: 0 | Q30: 0 | R30: 0 | S30: 0 | T30: 0 | U30: 0 | V30: 0 | W30: 0 | X30: 0 | Y30: 0 | Z30: 0 | AA30: 0 | AB30: =SUM(D30,J30,P30,V30) -> 6 | AC30: =SUM(E30,K30,Q30,W30) -> 6 | AD30: =SUM(F30,L30,R30,X30) -> 0 | AE30: =SUM(G30,M30,S30,Y30) -> 0 | AF30: =SUM(H30,N30,T30,Z30) -> 0 | AG30: =SUM(I30,O30,U30,AA30) -> 0 | AH30: =IF(AB30 = 0, 0, AB30/AB$20) -> 1 | AI30: =IF(AC30 = 0, 0, AC30/AC$20) -> 1 | AJ30: =IF(AD30 = 0, 0, AD30/AD$20) -> 0 | AK30: =IF(AE30 = 0, 0, AE30/AE$20) -> 0 | AL30: =IF(AF30 = 0, 0, AF30/AF$20) -> 0 | AM30: =IF(AG30 = 0, 0,#REF!/ AG$20) -> 0 | AN30: =IF(OR(GradeSheet!$L19="W (Withdrawn)", GradeSheet!$L19="I (Incomplete)"), 0, IF(AH30>=55%, 1, 0)) -> 1 | AO30: =IF(OR(GradeSheet!$L19="W (Withdrawn)", GradeSheet!$L19="I (Incomplete)"), 0, IF(AI30>=55%, 1, 0)) -> 1 | AP30: =IF(OR(GradeSheet!$L19="W (Withdrawn)", GradeSheet!$L19="I (Incomplete)"), 0, IF(AJ30>=55%, 1, 0)) -> 0 | AQ30: =IF(OR(GradeSheet!$L19="W (Withdrawn)", GradeSheet!$L19="I (Incomplete)"), 0, IF(AK30>=55%, 1, 0)) -> 0 | AR30: =IF(OR(GradeSheet!$L19="W (Withdrawn)", GradeSheet!$L19="I (Incomplete)"), 0, IF(AL30>=55%, 1, 0)) -> 0 | AS30: =IF(OR(GradeSheet!$L19="W (Withdrawn)", GradeSheet!$L19="I (Incomplete)"), 0, IF(AM30>=55%, 1, 0)) -> 0 | AU30: {=IF($AT$15=0,0,MMULT($AH30:$AM30, AT$9:AT$14)/$AT$15)} -> 0 | AV30: {=IF($AT$15=0,0,MMULT($AH30:$AM30, AU$9:AU$14)/$AT$15)} -> 0 | AW30: {=IF($AT$15=0,0,MMULT($AH30:$AM30, AV$9:AV$14)/$AT$15)} -> 0 | AX30: {=IF($AT$15=0,0,MMULT($AH30:$AM30, AW$9:AW$14)/$AT$15)} -> 0 | AY30: {=IF($AT$15=0,0,MMULT($AH30:$AM30, AX$9:AX$14)/$AT$15)} -> 0 | AZ30: {=IF($AT$15=0,0,MMULT($AH30:$AM30, AY$9:AY$14)/$AT$15)} -> 0 | BA30: {=IF($AT$15=0,0,MMULT($AH30:$AM30, AZ$9:AZ$14)/$AT$15)} -> 0 | BB30: {=IF($AT$15=0,0,MMULT($AH30:$AM30, BA$9:BA$14)/$AT$15)} -> 0 | ... BF30: {=IF($AT$15=0,0,MMULT($AH30:$AM30, BE$9:BE$14)/$AT$15)} -> 0 | BG30: =IF(OR(GradeSheet!$L19="W (Withdrawn)", GradeSheet!$L19="I (Incomplete)"), 0, IF(AU30>=65%, 1, 0)) -> 0 | BH30: =IF(OR(GradeSheet!$L19="W (Withdrawn)", GradeSheet!$L19="I (Incomplete)"), 0, IF(AV30>=65%, 1, 0)) -> 0 | BI30: =IF(OR(GradeSheet!$L19="W (Withdrawn)", GradeSheet!$L19="I (Incomplete)"), 0, IF(AW30>=65%, 1, 0)) -> 0 | BJ30: =IF(OR(GradeSheet!$L19="W (Withdrawn)", GradeSheet!$L19="I (Incomplete)"), 0, IF(AX30>=65%, 1, 0)) -> 0 | BK30: =IF(OR(GradeSheet!$L19="W (Withdrawn)", GradeSheet!$L19="I (Incomplete)"), 0, IF(AY30>=65%, 1, 0)) -> 0 | BL30: =IF(OR(GradeSheet!$L19="W (Withdrawn)", GradeSheet!$L19="I (Incomplete)"), 0, IF(AZ30>=65%, 1, 0)) -> 0 | BM30: =IF(OR(GradeSheet!$L19="W (Withdrawn)", GradeSheet!$L19="I (Incomplete)"), 0, IF(BA30>=65%, 1, 0)) -> 0 | BN30: =IF(OR(GradeSheet!$L19="W (Withdrawn)", GradeSheet!$L19="I (Incomplete)"), 0, IF(BB30>=65%, 1, 0)) -> 0 | ... BR30: =IF(OR(GradeSheet!$L19="W (Withdrawn)", GradeSheet!$L19="I (Incomplete)"), 0, IF(BF30>=65%, 1, 0)) -> 0
A31: 11 | B31: 253014006 | C31: Mohammad Jubayed Islam Jihad | D31: 6 | E31: 6 | F31: 0 | G31: 0 | H31: 0 | I31: 0 | J31: 0 | K31: 0 | L31: 0 | M31: 0 | N31: 0 | O31: 0 | P31: 0 | Q31: 0 | R31: 0 | S31: 0 | T31: 0 | U31: 0 | V31: 0 | W31: 0 | X31: 0 | Y31: 0 | Z31: 0 | AA31: 0 | AB31: =SUM(D31,J31,P31,V31) -> 6 | AC31: =SUM(E31,K31,Q31,W31) -> 6 | AD31: =SUM(F31,L31,R31,X31) -> 0 | AE31: =SUM(G31,M31,S31,Y31) -> 0 | AF31: =SUM(H31,N31,T31,Z31) -> 0 | AG31: =SUM(I31,O31,U31,AA31) -> 0 | AH31: =IF(AB31 = 0, 0, AB31/AB$20) -> 1 | AI31: =IF(AC31 = 0, 0, AC31/AC$20) -> 1 | AJ31: =IF(AD31 = 0, 0, AD31/AD$20) -> 0 | AK31: =IF(AE31 = 0, 0, AE31/AE$20) -> 0 | AL31: =IF(AF31 = 0, 0, AF31/AF$20) -> 0 | AM31: =IF(AG31 = 0, 0,#REF!/ AG$20) -> 0 | AN31: =IF(OR(GradeSheet!$L20="W (Withdrawn)", GradeSheet!$L20="I (Incomplete)"), 0, IF(AH31>=55%, 1, 0)) -> 1 | AO31: =IF(OR(GradeSheet!$L20="W (Withdrawn)", GradeSheet!$L20="I (Incomplete)"), 0, IF(AI31>=55%, 1, 0)) -> 1 | AP31: =IF(OR(GradeSheet!$L20="W (Withdrawn)", GradeSheet!$L20="I (Incomplete)"), 0, IF(AJ31>=55%, 1, 0)) -> 0 | AQ31: =IF(OR(GradeSheet!$L20="W (Withdrawn)", GradeSheet!$L20="I (Incomplete)"), 0, IF(AK31>=55%, 1, 0)) -> 0 | AR31: =IF(OR(GradeSheet!$L20="W (Withdrawn)", GradeSheet!$L20="I (Incomplete)"), 0, IF(AL31>=55%, 1, 0)) -> 0 | AS31: =IF(OR(GradeSheet!$L20="W (Withdrawn)", GradeSheet!$L20="I (Incomplete)"), 0, IF(AM31>=55%, 1, 0)) -> 0 | AU31: {=IF($AT$15=0,0,MMULT($AH31:$AM31, AT$9:AT$14)/$AT$15)} -> 0 | AV31: {=IF($AT$15=0,0,MMULT($AH31:$AM31, AU$9:AU$14)/$AT$15)} -> 0 | AW31: {=IF($AT$15=0,0,MMULT($AH31:$AM31, AV$9:AV$14)/$AT$15)} -> 0 | AX31: {=IF($AT$15=0,0,MMULT($AH31:$AM31, AW$9:AW$14)/$AT$15)} -> 0 | AY31: {=IF($AT$15=0,0,MMULT($AH31:$AM31, AX$9:AX$14)/$AT$15)} -> 0 | AZ31: {=IF($AT$15=0,0,MMULT($AH31:$AM31, AY$9:AY$14)/$AT$15)} -> 0 | BA31: {=IF($AT$15=0,0,MMULT($AH31:$AM31, AZ$9:AZ$14)/$AT$15)} -> 0 | BB31: {=IF($AT$15=0,0,MMULT($AH31:$AM31, BA$9:BA$14)/$AT$15)} -> 0 | ... BF31: {=IF($AT$15=0,0,MMULT($AH31:$AM31, BE$9:BE$14)/$AT$15)} -> 0 | BG31: =IF(OR(GradeSheet!$L20="W (Withdrawn)", GradeSheet!$L20="I (Incomplete)"), 0, IF(AU31>=65%, 1, 0)) -> 0 | BH31: =IF(OR(GradeSheet!$L20="W (Withdrawn)", GradeSheet!$L20="I (Incomplete)"), 0, IF(AV31>=65%, 1, 0)) -> 0 | BI31: =IF(OR(GradeSheet!$L20="W (Withdrawn)", GradeSheet!$L20="I (Incomplete)"), 0, IF(AW31>=65%, 1, 0)) -> 0 | BJ31: =IF(OR(GradeSheet!$L20="W (Withdrawn)", GradeSheet!$L20="I (Incomplete)"), 0, IF(AX31>=65%, 1, 0)) -> 0 | BK31: =IF(OR(GradeSheet!$L20="W (Withdrawn)", GradeSheet!$L20="I (Incomplete)"), 0, IF(AY31>=65%, 1, 0)) -> 0 | BL31: =IF(OR(GradeSheet!$L20="W (Withdrawn)", GradeSheet!$L20="I (Incomplete)"), 0, IF(AZ31>=65%, 1, 0)) -> 0 | BM31: =IF(OR(GradeSheet!$L20="W (Withdrawn)", GradeSheet!$L20="I (Incomplete)"), 0, IF(BA31>=65%, 1, 0)) -> 0 | BN31: =IF(OR(GradeSheet!$L20="W (Withdrawn)", GradeSheet!$L20="I (Incomplete)"), 0, IF(BB31>=65%, 1, 0)) -> 0 | ... BR31: =IF(OR(GradeSheet!$L20="W (Withdrawn)", GradeSheet!$L20="I (Incomplete)"), 0, IF(BF31>=65%, 1, 0)) -> 0
A32: 12 | B32: 253014010 | C32: Md. Abdul Hamid | D32: 6 | E32: 6 | F32: 0 | G32: 0 | H32: 0 | I32: 0 | J32: 0 | K32: 0 | L32: 0 | M32: 0 | N32: 0 | O32: 0 | P32: 0 | Q32: 0 | R32: 0 | S32: 0 | T32: 0 | U32: 0 | V32: 0 | W32: 0 | X32: 0 | Y32: 0 | Z32: 0 | AA32: 0 | AB32: =SUM(D32,J32,P32,V32) -> 6 | AC32: =SUM(E32,K32,Q32,W32) -> 6 | AD32: =SUM(F32,L32,R32,X32) -> 0 | AE32: =SUM(G32,M32,S32,Y32) -> 0 | AF32: =SUM(H32,N32,T32,Z32) -> 0 | AG32: =SUM(I32,O32,U32,AA32) -> 0 | AH32: =IF(AB32 = 0, 0, AB32/AB$20) -> 1 | AI32: =IF(AC32 = 0, 0, AC32/AC$20) -> 1 | AJ32: =IF(AD32 = 0, 0, AD32/AD$20) -> 0 | AK32: =IF(AE32 = 0, 0, AE32/AE$20) -> 0 | AL32: =IF(AF32 = 0, 0, AF32/AF$20) -> 0 | AM32: =IF(AG32 = 0, 0,#REF!/ AG$20) -> 0 | AN32: =IF(OR(GradeSheet!$L21="W (Withdrawn)", GradeSheet!$L21="I (Incomplete)"), 0, IF(AH32>=55%, 1, 0)) -> 1 | AO32: =IF(OR(GradeSheet!$L21="W (Withdrawn)", GradeSheet!$L21="I (Incomplete)"), 0, IF(AI32>=55%, 1, 0)) -> 1 | AP32: =IF(OR(GradeSheet!$L21="W (Withdrawn)", GradeSheet!$L21="I (Incomplete)"), 0, IF(AJ32>=55%, 1, 0)) -> 0 | AQ32: =IF(OR(GradeSheet!$L21="W (Withdrawn)", GradeSheet!$L21="I (Incomplete)"), 0, IF(AK32>=55%, 1, 0)) -> 0 | AR32: =IF(OR(GradeSheet!$L21="W (Withdrawn)", GradeSheet!$L21="I (Incomplete)"), 0, IF(AL32>=55%, 1, 0)) -> 0 | AS32: =IF(OR(GradeSheet!$L21="W (Withdrawn)", GradeSheet!$L21="I (Incomplete)"), 0, IF(AM32>=55%, 1, 0)) -> 0 | AU32: {=IF($AT$15=0,0,MMULT($AH32:$AM32, AT$9:AT$14)/$AT$15)} -> 0 | AV32: {=IF($AT$15=0,0,MMULT($AH32:$AM32, AU$9:AU$14)/$AT$15)} -> 0 | AW32: {=IF($AT$15=0,0,MMULT($AH32:$AM32, AV$9:AV$14)/$AT$15)} -> 0 | AX32: {=IF($AT$15=0,0,MMULT($AH32:$AM32, AW$9:AW$14)/$AT$15)} -> 0 | AY32: {=IF($AT$15=0,0,MMULT($AH32:$AM32, AX$9:AX$14)/$AT$15)} -> 0 | AZ32: {=IF($AT$15=0,0,MMULT($AH32:$AM32, AY$9:AY$14)/$AT$15)} -> 0 | BA32: {=IF($AT$15=0,0,MMULT($AH32:$AM32, AZ$9:AZ$14)/$AT$15)} -> 0 | BB32: {=IF($AT$15=0,0,MMULT($AH32:$AM32, BA$9:BA$14)/$AT$15)} -> 0 | ... BF32: {=IF($AT$15=0,0,MMULT($AH32:$AM32, BE$9:BE$14)/$AT$15)} -> 0 | BG32: =IF(OR(GradeSheet!$L21="W (Withdrawn)", GradeSheet!$L21="I (Incomplete)"), 0, IF(AU32>=65%, 1, 0)) -> 0 | BH32: =IF(OR(GradeSheet!$L21="W (Withdrawn)", GradeSheet!$L21="I (Incomplete)"), 0, IF(AV32>=65%, 1, 0)) -> 0 | BI32: =IF(OR(GradeSheet!$L21="W (Withdrawn)", GradeSheet!$L21="I (Incomplete)"), 0, IF(AW32>=65%, 1, 0)) -> 0 | BJ32: =IF(OR(GradeSheet!$L21="W (Withdrawn)", GradeSheet!$L21="I (Incomplete)"), 0, IF(AX32>=65%, 1, 0)) -> 0 | BK32: =IF(OR(GradeSheet!$L21="W (Withdrawn)", GradeSheet!$L21="I (Incomplete)"), 0, IF(AY32>=65%, 1, 0)) -> 0 | BL32: =IF(OR(GradeSheet!$L21="W (Withdrawn)", GradeSheet!$L21="I (Incomplete)"), 0, IF(AZ32>=65%, 1, 0)) -> 0 | BM32: =IF(OR(GradeSheet!$L21="W (Withdrawn)", GradeSheet!$L21="I (Incomplete)"), 0, IF(BA32>=65%, 1, 0)) -> 0 | BN32: =IF(OR(GradeSheet!$L21="W (Withdrawn)", GradeSheet!$L21="I (Incomplete)"), 0, IF(BB32>=65%, 1, 0)) -> 0 | ... BR32: =IF(OR(GradeSheet!$L21="W (Withdrawn)", GradeSheet!$L21="I (Incomplete)"), 0, IF(BF32>=65%, 1, 0)) -> 0
... A54: 34 | B54: 253014090 | C54: Anam Shahriar | D54: 6 | E54: 6 | F54: 0 | G54: 0 | H54: 0 | I54: 0 | J54: 0 | K54: 0 | L54: 0 | M54: 0 | N54: 0 | O54: 0 | P54: 0 | Q54: 0 | R54: 0 | S54: 0 | T54: 0 | U54: 0 | V54: 0 | W54: 0 | X54: 0 | Y54: 0 | Z54: 0 | AA54: 0 | AB54: =SUM(D54,J54,P54,V54) -> 6 | AC54: =SUM(E54,K54,Q54,W54) -> 6 | AD54: =SUM(F54,L54,R54,X54) -> 0 | AE54: =SUM(G54,M54,S54,Y54) -> 0 | AF54: =SUM(H54,N54,T54,Z54) -> 0 | AG54: =SUM(I54,O54,U54,AA54) -> 0 | AH54: =IF(AB54 = 0, 0, AB54/AB$20) -> 1 | AI54: =IF(AC54 = 0, 0, AC54/AC$20) -> 1 | AJ54: =IF(AD54 = 0, 0, AD54/AD$20) -> 0 | AK54: =IF(AE54 = 0, 0, AE54/AE$20) -> 0 | AL54: =IF(AF54 = 0, 0, AF54/AF$20) -> 0 | AM54: =IF(AG54 = 0, 0,#REF!/ AG$20) -> 0 | AN54: =IF(OR(GradeSheet!$L43="W (Withdrawn)", GradeSheet!$L43="I (Incomplete)"), 0, IF(AH54>=55%, 1, 0)) -> 1 | AO54: =IF(OR(GradeSheet!$L43="W (Withdrawn)", GradeSheet!$L43="I (Incomplete)"), 0, IF(AI54>=55%, 1, 0)) -> 1 | AP54: =IF(OR(GradeSheet!$L43="W (Withdrawn)", GradeSheet!$L43="I (Incomplete)"), 0, IF(AJ54>=55%, 1, 0)) -> 0 | AQ54: =IF(OR(GradeSheet!$L43="W (Withdrawn)", GradeSheet!$L43="I (Incomplete)"), 0, IF(AK54>=55%, 1, 0)) -> 0 | AR54: =IF(OR(GradeSheet!$L43="W (Withdrawn)", GradeSheet!$L43="I (Incomplete)"), 0, IF(AL54>=55%, 1, 0)) -> 0 | AS54: =IF(OR(GradeSheet!$L43="W (Withdrawn)", GradeSheet!$L43="I (Incomplete)"), 0, IF(AM54>=55%, 1, 0)) -> 0 | AU54: {=IF($AT$15=0,0,MMULT($AH54:$AM54, AT$9:AT$14)/$AT$15)} -> 0 | AV54: {=IF($AT$15=0,0,MMULT($AH54:$AM54, AU$9:AU$14)/$AT$15)} -> 0 | AW54: {=IF($AT$15=0,0,MMULT($AH54:$AM54, AV$9:AV$14)/$AT$15)} -> 0 | AX54: {=IF($AT$15=0,0,MMULT($AH54:$AM54, AW$9:AW$14)/$AT$15)} -> 0 | AY54: {=IF($AT$15=0,0,MMULT($AH54:$AM54, AX$9:AX$14)/$AT$15)} -> 0 | AZ54: {=IF($AT$15=0,0,MMULT($AH54:$AM54, AY$9:AY$14)/$AT$15)} -> 0 | BA54: {=IF($AT$15=0,0,MMULT($AH54:$AM54, AZ$9:AZ$14)/$AT$15)} -> 0 | BB54: {=IF($AT$15=0,0,MMULT($AH54:$AM54, BA$9:BA$14)/$AT$15)} -> 0 | ... BF54: {=IF($AT$15=0,0,MMULT($AH54:$AM54, BE$9:BE$14)/$AT$15)} -> 0 | BG54: =IF(OR(GradeSheet!$L43="W (Withdrawn)", GradeSheet!$L43="I (Incomplete)"), 0, IF(AU54>=65%, 1, 0)) -> 0 | BH54: =IF(OR(GradeSheet!$L43="W (Withdrawn)", GradeSheet!$L43="I (Incomplete)"), 0, IF(AV54>=65%, 1, 0)) -> 0 | BI54: =IF(OR(GradeSheet!$L43="W (Withdrawn)", GradeSheet!$L43="I (Incomplete)"), 0, IF(AW54>=65%, 1, 0)) -> 0 | BJ54: =IF(OR(GradeSheet!$L43="W (Withdrawn)", GradeSheet!$L43="I (Incomplete)"), 0, IF(AX54>=65%, 1, 0)) -> 0 | BK54: =IF(OR(GradeSheet!$L43="W (Withdrawn)", GradeSheet!$L43="I (Incomplete)"), 0, IF(AY54>=65%, 1, 0)) -> 0 | BL54: =IF(OR(GradeSheet!$L43="W (Withdrawn)", GradeSheet!$L43="I (Incomplete)"), 0, IF(AZ54>=65%, 1, 0)) -> 0 | BM54: =IF(OR(GradeSheet!$L43="W (Withdrawn)", GradeSheet!$L43="I (Incomplete)"), 0, IF(BA54>=65%, 1, 0)) -> 0 | BN54: =IF(OR(GradeSheet!$L43="W (Withdrawn)", GradeSheet!$L43="I (Incomplete)"), 0, IF(BB54>=65%, 1, 0)) -> 0 | ... BR54: =IF(OR(GradeSheet!$L43="W (Withdrawn)", GradeSheet!$L43="I (Incomplete)"), 0, IF(BF54>=65%, 1, 0)) -> 0
A55: 35 | B55: 253014093 | C55: Md Saad Sadik Jashim | D55: 6 | E55: 6 | F55: 0 | G55: 0 | H55: 0 | I55: 0
A56: 36 | B56: 253014094 | C56: MD. Mahadi Hassan | D56: 6 | E56: 4 | F56: 0 | G56: 0 | H56: 0 | I56: 0 | J56: 0 | K56: 0 | L56: 0 | M56: 0 | N56: 0 | O56: 0 | P56: 0 | Q56: 0 | R56: 0 | S56: 0 | T56: 0 | U56: 0 | V56: 0 | W56: 0 | X56: 0 | Y56: 0 | Z56: 0 | AA56: 0 | AB56: =SUM(D56,J56,P56,V56) -> 6 | AC56: =SUM(E56,K56,Q56,W56) -> 4 | AD56: =SUM(F56,L56,R56,X56) -> 0 | AE56: =SUM(G56,M56,S56,Y56) -> 0 | AF56: =SUM(H56,N56,T56,Z56) -> 0 | AG56: =SUM(I56,O56,U56,AA56) -> 0 | AH56: =IF(AB56 = 0, 0, AB56/AB$20) -> 1 | AI56: =IF(AC56 = 0, 0, AC56/AC$20) -> 0.66666667 | AJ56: =IF(AD56 = 0, 0, AD56/AD$20) -> 0 | AK56: =IF(AE56 = 0, 0, AE56/AE$20) -> 0 | AL56: =IF(AF56 = 0, 0, AF56/AF$20) -> 0 | AM56: =IF(AG56 = 0, 0,#REF!/ AG$20) -> 0 | AN56: =IF(OR(GradeSheet!$L45="W (Withdrawn)", GradeSheet!$L45="I (Incomplete)"), 0, IF(AH56>=55%, 1, 0)) -> 1 | AO56: =IF(OR(GradeSheet!$L45="W (Withdrawn)", GradeSheet!$L45="I (Incomplete)"), 0, IF(AI56>=55%, 1, 0)) -> 1 | AP56: =IF(OR(GradeSheet!$L45="W (Withdrawn)", GradeSheet!$L45="I (Incomplete)"), 0, IF(AJ56>=55%, 1, 0)) -> 0 | AQ56: =IF(OR(GradeSheet!$L45="W (Withdrawn)", GradeSheet!$L45="I (Incomplete)"), 0, IF(AK56>=55%, 1, 0)) -> 0 | AR56: =IF(OR(GradeSheet!$L45="W (Withdrawn)", GradeSheet!$L45="I (Incomplete)"), 0, IF(AL56>=55%, 1, 0)) -> 0 | AS56: =IF(OR(GradeSheet!$L45="W (Withdrawn)", GradeSheet!$L45="I (Incomplete)"), 0, IF(AM56>=55%, 1, 0)) -> 0 | AU56: {=IF($AT$15=0,0,MMULT($AH56:$AM56, AT$9:AT$14)/$AT$15)} -> 0 | AV56: {=IF($AT$15=0,0,MMULT($AH56:$AM56, AU$9:AU$14)/$AT$15)} -> 0 | AW56: {=IF($AT$15=0,0,MMULT($AH56:$AM56, AV$9:AV$14)/$AT$15)} -> 0 | AX56: {=IF($AT$15=0,0,MMULT($AH56:$AM56, AW$9:AW$14)/$AT$15)} -> 0 | AY56: {=IF($AT$15=0,0,MMULT($AH56:$AM56, AX$9:AX$14)/$AT$15)} -> 0 | AZ56: {=IF($AT$15=0,0,MMULT($AH56:$AM56, AY$9:AY$14)/$AT$15)} -> 0 | BA56: {=IF($AT$15=0,0,MMULT($AH56:$AM56, AZ$9:AZ$14)/$AT$15)} -> 0 | BB56: {=IF($AT$15=0,0,MMULT($AH56:$AM56, BA$9:BA$14)/$AT$15)} -> 0 | ... BF56: {=IF($AT$15=0,0,MMULT($AH56:$AM56, BE$9:BE$14)/$AT$15)} -> 0 | BG56: =IF(OR(GradeSheet!$L45="W (Withdrawn)", GradeSheet!$L45="I (Incomplete)"), 0, IF(AU56>=65%, 1, 0)) -> 0 | BH56: =IF(OR(GradeSheet!$L45="W (Withdrawn)", GradeSheet!$L45="I (Incomplete)"), 0, IF(AV56>=65%, 1, 0)) -> 0 | BI56: =IF(OR(GradeSheet!$L45="W (Withdrawn)", GradeSheet!$L45="I (Incomplete)"), 0, IF(AW56>=65%, 1, 0)) -> 0 | BJ56: =IF(OR(GradeSheet!$L45="W (Withdrawn)", GradeSheet!$L45="I (Incomplete)"), 0, IF(AX56>=65%, 1, 0)) -> 0 | BK56: =IF(OR(GradeSheet!$L45="W (Withdrawn)", GradeSheet!$L45="I (Incomplete)"), 0, IF(AY56>=65%, 1, 0)) -> 0 | BL56: =IF(OR(GradeSheet!$L45="W (Withdrawn)", GradeSheet!$L45="I (Incomplete)"), 0, IF(AZ56>=65%, 1, 0)) -> 0 | BM56: =IF(OR(GradeSheet!$L45="W (Withdrawn)", GradeSheet!$L45="I (Incomplete)"), 0, IF(BA56>=65%, 1, 0)) -> 0 | BN56: =IF(OR(GradeSheet!$L45="W (Withdrawn)", GradeSheet!$L45="I (Incomplete)"), 0, IF(BB56>=65%, 1, 0)) -> 0 | ... BR56: =IF(OR(GradeSheet!$L45="W (Withdrawn)", GradeSheet!$L45="I (Incomplete)"), 0, IF(BF56>=65%, 1, 0)) -> 0
AN57: Number of Students Achieveing CO | BG57: Number of Students Achieveing PO
