Workbook

Sheet GradeSheet
G2: Course Code | H2: CSE | K2: Section | L2: 1 | W2: W (Withdrawn)
G3: Course Title | H3: Operating Systems | K3: Semester | L3: Spring 2025
G4: Credit | H4: 3
G5: Instructor | H5: Rubaiya Hafiz
A7: =CONCATENATE("Grade Sheet of ",GradeSheet!$H$2, " [",GradeSheet!$H$3, "] ", "(Section ",GradeSheet!$L$2, ") ", "[Semester - ",GradeSheet!$L$3,"]" ) -> Grade Sheet of CSE [Operating Systems] (Section 1) [Semester - Spring 2025]
P8: Attendance | Q8: Performance | R8: Quiz | S8: Assignment | T8: Mid | U8: Project | V8: Final
A9: No. | B9: Student ID | C9: Name | D9: =CONCATENATE("Attendance (",GradeSheet!$C$64, ")") -> Attendance (0) | E9: =CONCATENATE("Performance (",GradeSheet!$C$65, ")") -> Performance (0) | F9: =CONCATENATE("Quiz (",GradeSheet!$C$66, ")") -> Quiz (0) | G9: =CONCATENATE("Assignment (",GradeSheet!$C$67, ")") -> Assignment (0) | H9: =CONCATENATE("Midterm (",GradeSheet!$C$68, ")") -> Midterm (0) | I9: =CONCATENATE("Project (",GradeSheet!$C$69, ")") -> Project (0) | J9: =CONCATENATE("Final (",GradeSheet!$C$70, ")") -> Final (0) | K9: Exam Total (100) | L9: Percent Total (100%) | M9: Grade | P9: =C64 -> 0 | Q9: =C65 -> 0 | R9: =C66 -> 0 | S9: =C67 -> 0 | T9: =C68 -> 0 | U9: =C69 -> 0 | V9: 40 | W9: Name | X9: Student ID
A10: 1 | B10: =X10 -> 0 | C10: =W10 -> 0 | D10: =P10 -> 0 | E10: =Q10 -> 0 | F10: =R10 -> 0 | G10: =S10 -> 0 | H10: =T10 -> 0 | I10: =U10 -> 0 | J10: =V10 -> 0 | K10: =ROUND(SUM(D10:J10),0) -> 0 | L10: =K10/100 -> 0 | M10: =VLOOKUP(K10,GradingPolicy!$B$2:$C$11,2) -> F (Fail)
A11: 2 | B11: =X11 -> 0 | C11: =W11 -> 0 | D11: =P11 -> 0 | E11: =Q11 -> 0 | F11: =R11 -> 0 | G11: =S11 -> 0 | H11: =T11 -> 0 | I11: =U11 -> 0 | J11: =V11 -> 0 | K11: =ROUND(SUM(D11:J11),0) -> 0 | L11: =K11/100 -> 0 | M11: =VLOOKUP(K11,GradingPolicy!$B$2:$C$11,2) -> F (Fail)
A12: 3 | B12: =X12 -> 0 | C12: =W12 -> 0 | D12: =P12 -> 0 | E12: =Q12 -> 0 | F12: =R12 -> 0 | G12: =S12 -> 0 | H12: =T12 -> 0 | I12: =U12 -> 0 | J12: =V12 -> 0 | K12: =ROUND(SUM(D12:J12),0) -> 0 | L12: =K12/100 -> 0 | M12: =VLOOKUP(K12,GradingPolicy!$B$2:$C$11,2) -> F (Fail)
A13: 4 | B13: =X13 -> 0 | C13: =W13 -> 0 | D13: =P13 -> 0 | E13: =Q13 -> 0 | F13: =R13 -> 0 | G13: =S13 -> 0 | H13: =T13 -> 0 | I13: =U13 -> 0 | J13: =V13 -> 0 | K13: =ROUND(SUM(D13:J13),0) -> 0 | L13: =K13/100 -> 0 | M13: =VLOOKUP(K13,GradingPolicy!$B$2:$C$11,2) -> F (Fail)
A14: 5 | B14: =X14 -> 0 | C14: =W14 -> 0 | D14: =P14 -> 0 | E14: =Q14 -> 0 | F14: =R14 -> 0 | G14: =S14 -> 0 | H14: =T14 -> 0 | I14: =U14 -> 0 | J14: =V14 -> 0 | K14: =ROUND(SUM(D14:J14),0) -> 0 | L14: =K14/100 -> 0 | M14: =VLOOKUP(K14,GradingPolicy!$B$2:$C$11,2) -> F (Fail)
A15: 6 | B15: =X15 -> 0 | C15: =W15 -> 0 | D15: =P15 -> 0 | E15: =Q15 -> 0 | F15: =R15 -> 0 | G15: =S15 -> 0 | H15: =T15 -> 0 | I15: =U15 -> 0 | J15: =V15 -> 0 | K15: =ROUND(SUM(D15:J15),0) -> 0 | L15: =K15/100 -> 0 | M15: =VLOOKUP(K15,GradingPolicy!$B$2:$C$11,2) -> F (Fail)
A16: 7 | B16: =X16 -> 0 | C16: =W16 -> 0 | D16: =P16 -> 0 | E16: =Q16 -> 0 | F16: =R16 -> 0 | G16: =S16 -> 0 | H16: =T16 -> 0 | I16: =U16 -> 0 | J16: =V16 -> 0 | K16: =ROUND(SUM(D16:J16),0) -> 0 | L16: =K16/100 -> 0 | M16: =VLOOKUP(K16,GradingPolicy!$B$2:$C$11,2) -> F (Fail)
A17: 8 | B17: =X17 -> 0 | C17: =W17 -> 0 | D17: =P17 -> 0 | E17: =Q17 -> 0 | F17: =R17 -> 0 | G17: =S17 -> 0 | H17: =T17 -> 0 | I17: =U17 -> 0 | J17: =V17 -> 0 | K17: =ROUND(SUM(D17:J17),0) -> 0 | L17: =K17/100 -> 0 | M17: =VLOOKUP(K17,GradingPolicy!$B$2:$C$11,2) -> F (Fail)
A18: 9 | B18: =X18 -> 0 | C18: =W18 -> 0 | D18: =P18 -> 0 | E18: =Q18 -> 0 | F18: =R18 -> 0 | G18: =S18 -> 0 | H18: =T18 -> 0 | I18: =U18 -> 0 | J18: =V18 -> 0 | K18: =ROUND(SUM(D18:J18),0) -> 0 | L18: =K18/100 -> 0 | M18: =VLOOKUP(K18,GradingPolicy!$B$2:$C$11,2) -> F (Fail)
A19: 10 | B19: =X19 -> 0 | C19: =W19 -> 0 | D19: =P19 -> 0 | E19: =Q19 -> 0 | F19: =R19 -> 0 | G19: =S19 -> 0 | H19: =T19 -> 0 | I19: =U19 -> 0 | J19: =V19 -> 0 | K19: =ROUND(SUM(D19:J19),0) -> 0 | L19: =K19/100 -> 0 | M19: =VLOOKUP(K19,GradingPolicy!$B$2:$C$11,2) -> F (Fail)
A20: 11 | B20: =X20 -> 0 | C20: =W20 -> 0 | D20: =P20 -> 0 | E20: =Q20 -> 0 | F20: =R20 -> 0 | G20: =S20 -> 0 | H20: =T20 -> 0 | I20: =U20 -> 0 | J20: =V20 -> 0 | K20: =ROUND(SUM(D20:J20),0) -> 0 | L20: =K20/100 -> 0 | M20: =VLOOKUP(K20,GradingPolicy!$B$2:$C$11,2) -> F (Fail)
A21: 12 | B21: =X21 -> 0 | C21: =W21 -> 0 | D21: =P21 -> 0 | E21: =Q21 -> 0 | F21: =R21 -> 0 | G21: =S21 -> 0 | H21: =T21 -> 0 | I21: =U21 -> 0 | J21: =V21 -> 0 | K21: =ROUND(SUM(D21:J21),0) -> 0 | L21: =K21/100 -> 0 | M21: =VLOOKUP(K21,GradingPolicy!$B$2:$C$11,2) -> F (Fail)
... A59: 50 | B59: =X59 -> 0 | C59: =W59 -> 0 | D59: =P59 -> 0 | E59: =Q59 -> 0 | F59: =R59 -> 0 | G59: =S59 -> 0 | H59: =T59 -> 0 | I59: =U59 -> 0 | J59: =V59 -> 0 | K59: =ROUND(SUM(D59:J59),0) -> 0 | L59: =K59/100 -> 0 | M59: =VLOOKUP(K59,GradingPolicy!$B$2:$C$11,2) -> F (Fail)
B63: Assessment | C63: Marks Distribution | F63: Numerical Grade | G63: Letter Grade | H63: Freq
B64: Attendance | C64: 0 | F64: 95% and above | G64: A+ | H64: =COUNTIFS(M10:M59,"A+ (Plus)",B10:B59,"<>0") -> 0 | O64: MAX | P64: =MAX(P10:P49) -> 0 | Q64: =MAX(Q10:Q49) -> 0 | R64: =MAX(R10:R49) -> 0 | S64: =MAX(S10:S49) -> 0 | T64: =MAX(T10:T49) -> 0 | U64: =MAX(U10:U49) -> 0 | V64: =MAX(V10:V49) -> 0
B65: Performance | C65: 0 | F65: 90% to 94% | G65: A | H65: =COUNTIFS(M10:M59,"A (Plain)",B10:B59,"<>0") -> 0 | O65: AVG | P65: =AVERAGE(P10:P49) -> #DIV/0! | Q65: =AVERAGE(Q10:Q49) -> #DIV/0! | R65: =AVERAGE(R10:R49) -> #DIV/0! | S65: =AVERAGE(S10:S49) -> #DIV/0! | T65: =AVERAGE(T10:T49) -> #DIV/0! | U65: =AVERAGE(U10:U49) -> #DIV/0! | V65: =AVERAGE(V10:V49) -> #DIV/0!
B66: Quiz | C66: 0 | F66: 85% to 89% | G66: A- | H66: =COUNTIFS(M10:M59,"A- (Minus)",B10:B59,"<>0") -> 0 | O66: MIN | P66: =MIN(P10:P49) -> 0 | Q66: =MIN(Q10:Q49) -> 0 | R66: =MIN(R10:R49) -> 0 | S66: =MIN(S10:S49) -> 0 | T66: =MIN(T10:T49) -> 0 | U66: =MIN(U10:U49) -> 0 | V66: =MIN(V10:V49) -> 0
B67: Assignment | C67: 0 | F67: 80% to 84% | G67: B+ | H67: =COUNTIFS(M10:M59,"B+ (Plus)",B10:B59,"<>0") -> 0
B68: Midterm Exam | C68: 0 | F68: 75% to 79% | G68: B | H68: =COUNTIFS(M10:M59,"B (Plain)",B10:B59,"<>0") -> 0
B69: Project | C69: 0 | F69: 70% to 74% | G69: B- | H69: =COUNTIFS(M10:M59,"B- (Minus)",B10:B59,"<>0") -> 0
B70: Final Exam | C70: 0 | F70: 65% to 69% | G70: C+ | H70: =COUNTIFS(M10:M59,"C+ (Plus)",B10:B59,"<>0") -> 0
B71: Total | C71: =SUM(C64:C70) -> 0 | F71: 60% to 64% | G71: C | H71: =COUNTIFS(M10:M59,"C (Plain)",B10:B59,"<>0") -> 0
F72: 50% to 59% | G72: D | H72: =COUNTIFS(M10:M59,"D (Plain)",B10:B59,"<>0") -> 0
F73: Below 50% | G73: F | H73: =COUNTIFS(M10:M59,"F (Fail)",B10:B59,"<>0") -> 0
F74: No exam | G74: I | H74: =COUNTIFS(M10:M59,"I (Incomplete)",B10:B59,"<>0") -> 0
B75: =GradeSheet!$H$5 -> Rubaiya Hafiz | F75: Withdrawn | G75: W | H75: =COUNTIFS(M10:M59,"W (Withdrawn)",B10:B59,"<>0") -> 0
B76: Senior Lecturer | F76: No of students | H76: =SUM(H64:H75) -> 0
B77: Department of CSE, ULAB

Sheet GradingPolicy
A1: Numerical Grade | B1: Minimum Number | C1: Letter Grade
A2: Below 50% | B2: 0 | C2: F (Fail)
A3: 50% to 59% | B3: 50 | C3: D (Plain)
A4: 60% to 64% | B4: 60 | C4: C (Plain)
A5: 65% to 69% | B5: 65 | C5: C+ (Plus)
A6: 70% to 74% | B6: 70 | C6: B- (Minus)
A7: 75% to 79% | B7: 75 | C7: B (Plain)
A8: 80% to 84% | B8: 80 | C8: B+ (Plus)
A9: 85% to 89% | B9: 85 | C9: A- (Minus)
A10: 90% to 94% | B10: 90 | C10: A (Plain)
A11: 95% and above | B11: 95 | C11: A+ (Plus)

Sheet CourseSummary
B2: Course Code | E2: =GradeSheet!$H$2 -> CSE | O2: =CONCATENATE("Section ", GradeSheet!$L$2,) -> Section 1 | T2: Course Topic/Content Covered
B3: Course Title | E3: =GradeSheet!$H$3 -> Operating Systems | O3: =CONCATENATE(GradeSheet!$H$76," students") -> 0 students | T3: Topics Taught (based on course outline) | AG3: Number of Sessions
B4: Credit | E4: =GradeSheet!$H$4 -> 3 | O4: =GradeSheet!$L$3 -> Spring 2025 | T4: 1 | AG4: 4
T5: 2 | AG5: 4
T6: 3 | AG6: 5
T7: 4 | AG7: 5
T8: 5 | AG8: 6
T14: What percentage of topics/content planned were actually taught?
U15: a. | V15: >90% | Y15: √ | AB15: b. | AC15: 70%-90% | AJ15: c. | AK15: <70%
T16: If <70%, please write the reason for not teaching all topics/content planned
T21: Teaching and Learning Methods
B22: Grade Distribution | T22: Teaching Methods | AG22: Number of Sessions | AL22: Percentage
B23: A+ | C23: A | D23: A- | E23: B+ | F23: B | G23: B- | H23: C+ | I23: C | J23: D | K23: F | L23: I | M23: W | N23: Total | T23: Lectures | AG23: 20 | AL23: =AG23/P33 -> 1.0526316
B24: =GradeSheet!$H$64 -> 0 | C24: =GradeSheet!$H$65 -> 0 | D24: =GradeSheet!$H$66 -> 0 | E24: =GradeSheet!$H$67 -> 0 | F24: =GradeSheet!$H$68 -> 0 | G24: =GradeSheet!$H$69 -> 0 | H24: =GradeSheet!$H$70 -> 0 | I24: =GradeSheet!$H$71 -> 0 | J24: =GradeSheet!$H$72 -> 0 | K24: =GradeSheet!$H$73 -> 0 | L24: =GradeSheet!$H$74 -> 0 | M24: =GradeSheet!$H$75 -> 0 | N24: =SUM(B24:M24) -> 0 | T24: Group Discussion | AG24: 10 | AL24: =AG24/P33 -> 0.52631579
B25: =B24/GradeSheet!$H$76 -> #DIV/0! | C25: =C24/GradeSheet!$H$76 -> #DIV/0! | D25: =D24/GradeSheet!$H$76 -> #DIV/0! | E25: =E24/GradeSheet!$H$76 -> #DIV/0! | F25: =F24/GradeSheet!$H$76 -> #DIV/0! | G25: =G24/GradeSheet!$H$76 -> #DIV/0! | H25: =H24/GradeSheet!$H$76 -> #DIV/0! | I25: =I24/GradeSheet!$H$76 -> #DIV/0! | ... M25: =M24/GradeSheet!$H$76 -> #DIV/0! | N25: =SUM(B25:M25) -> #DIV/0! | T25: Presentation | AG25: 0 | AL25: =AG25/P33 -> 0
T26: Classwork | AG26: 8 | AL26: =AG26/P33 -> 0.42105263
B27: Statistical Information
G29: No. | H29: % | P29: No | Q29: %
B30: Students enrolled | G30: =GradeSheet!$H$76 -> 0 | H30: =G30/G30 -> #DIV/0! | J30: Session Planned | P30: 20 | Q30: =P30/P30 -> 1 | T30: Active Learning | AG30: Number of Sessions | AL30: Percentage
B31: Students who withdrew | G31: =GradeSheet!$H$75 -> 0 | H31: =G31/G30 -> #DIV/0! | J31: Sessions Missed | P31: 0 | Q31: =P31/P30 -> 0 | T31: Classwork | AG31: 8 | AL31: =AG31/P33 -> 0.42105263
B32: Students who took final exam | G32: 41 | H32: =G32/G30 -> #DIV/0! | J32: Sessions Made Up | P32: 0 | Q32: =P32/P30 -> 0 | T32: Group Discussion | AG32: 10 | AL32: =AG32/P33 -> 0.52631579
B33: Students passed | G33: =GradeSheet!$H$76-(GradeSheet!$H$73+GradeSheet!$H$74+GradeSheet!$H$75) -> 0 | H33: =G33/G30 -> #DIV/0! | J33: Total Sessions Conducted (excluding midterm and final exams) | P33: 19 | Q33: =P33/P30 -> 0.95
B37: Average Number Per Session | P37: No | T37: Teaching Aids | AG37: Number of Sessions | AL37: Percentage
B38: Tardy Students | G38: 2 | J38: Guest Lectures Invited | P38: N/A | T38: Whiteboard | AG38: 0 | AL38: =AG38/P33 -> 0
B39: Absent Students | G39: 3 | J39: Field Trips Taken | P39: N/A | T39: Computer | AG39: 20 | AL39: =AG39/P33 -> 1.0526316
T40: Handout | AG40: 12 | AL40: =AG40/P33 -> 0.63157895
T41: Video and Audio | AG41: 0 | AL41: =AG41/P33 -> 0
X46: =GradeSheet!$H$5 -> Rubaiya Hafiz
U47: Signature of the Course Instructor
B51: Course Code | E51: =GradeSheet!$H$2 -> CSE | O51: =CONCATENATE("Section ", GradeSheet!$L$2,) -> Section 1
B52: Course Title | E52: =GradeSheet!$H$3 -> Operating Systems | O52: =CONCATENATE(GradeSheet!$H$76," students") -> 0 students
B53: Credit | E53: =GradeSheet!$H$4 -> 3 | O53: =GradeSheet!$L$3 -> Spring 2025
E57: Summary of Cos
H58: CO1 | I58: CO2 | J58: CO3 | K58: CO4 | L58: CO5 | M58: CO6
E59: Number of Studens | H59: =CO_PO_AttainmentAnalysis!AN67 -> 0 | I59: =CO_PO_AttainmentAnalysis!AO67 -> 0 | J59: =CO_PO_AttainmentAnalysis!AP67 -> 0 | K59: =CO_PO_AttainmentAnalysis!AQ67 -> 0 | L59: =CO_PO_AttainmentAnalysis!AR67 -> 0 | M59: =CO_PO_AttainmentAnalysis!AS67 -> 0
E60: Average Score | H60: =CO_PO_AttainmentAnalysis!AH67 -> 0.5 | I60: =CO_PO_AttainmentAnalysis!AI67 -> 0.5 | J60: =CO_PO_AttainmentAnalysis!AJ67 -> 0.5 | K60: =CO_PO_AttainmentAnalysis!AK67 -> 0.5 | L60: =CO_PO_AttainmentAnalysis!AL67 -> 0.5 | M60: =CO_PO_AttainmentAnalysis!AM67 -> 0.5

Sheet CO_PO_AttainmentAnalysis
AU1: Mapping of COs to POs
C2: Assessment Items | D2: CO1 | E2: CO2 | F2: CO3 | G2: CO4 | H2: CO5 | I2: CO6 | AT2: PO1 | AU2: PO2 | AV2: PO3 | AW2: PO4 | AX2: PO5 | AY2: PO6 | AZ2: PO7 | BA2: PO8 | BB2: PO9 | BC2: PO10 | BD2: PO11 | BE2: PO12
C3: Midterm Exam | D3: 0 | E3: 0 | F3: 0 | G3: 0 | H3: 0 | I3: 0 | AS3: CO1 | AT3: 0 | AU3: 0 | AV3: 0 | AW3: 0 | AX3: 0 | AY3: 0 | AZ3: 0 | BA3: 0 | BB3: 0 | BC3: 0 | BD3: 0 | BE3: 0
C4: Final Exam | D4: 0 | E4: 0 | F4: 0 | G4: 0 | H4: 0 | I4: 0 | AS4: CO2 | AT4: 0 | AU4: 0 | AV4: 0 | AW4: 0 | AX4: 0 | AY4: 0 | AZ4: 0 | BA4: 0 | BB4: 0 | BC4: 0 | BD4: 0 | BE4: 0
C5: Project | D5: 0 | E5: 0 | F5: 0 | G5: 0 | H5: 0 | I5: 0 | AS5: CO3 | AT5: 0 | AU5: 0 | AV5: 0 | AW5: 0 | AX5: 0 | AY5: 0 | AZ5: 0 | BA5: 0 | BB5: 0 | BC5: 0 | BD5: 0 | BE5: 0
C6: Presentation | D6: 0 | E6: 0 | F6: 0 | G6: 0 | H6: 0 | I6: 0 | AS6: CO4 | AT6: 0 | AU6: 0 | AV6: 0 | AW6: 0 | AX6: 0 | AY6: 0 | AZ6: 0 | BA6: 0 | BB6: 0 | BC6: 0 | BD6: 0 | BE6: 0
C7: Total | D7: =SUM(D3:D6) -> 0 | E7: =SUM(E3:E6) -> 0 | F7: =SUM(F3:F6) -> 0 | G7: =SUM(G3:G6) -> 0 | H7: =SUM(H3:H6) -> 0 | I7: =SUM(I3:I6) -> 0 | AS7: CO5 | AT7: 0 | AU7: 0 | AV7: 0 | AW7: 0 | AX7: 0 | AY7: 0 | AZ7: 0 | BA7: 0 | BB7: 0 | BC7: 0 | BD7: 0 | BE7: 0
AS8: CO6 | AT8: 0 | AU8: 0 | AV8: 0 | AW8: 0 | AX8: 0 | AY8: 0 | AZ8: 0 | BA8: 0 | BB8: 0 | BC8: 0 | BD8: 0 | BE8: 0
AS9: Total | AT9: =SUM(AT3:AT8) -> 0 | AU9: =SUM(AU3:AU8) -> 0 | AV9: =SUM(AV3:AV8) -> 0 | AW9: =SUM(AW3:AW8) -> 0 | AX9: =SUM(AX3:AX8) -> 0 | AY9: =SUM(AY3:AY8) -> 0 | AZ9: =SUM(AZ3:AZ8) -> 0 | BA9: =SUM(BA3:BA8) -> 0 | ... BE9: =SUM(BE3:BE8) -> 0
A11: =CONCATENATE("Course Outcome (CO) Attainment Analysis of ",GradeSheet!$H$2, " [",GradeSheet!$H$3, "] ", "(Section ",GradeSheet!$L$2, ") ", "[Semester - ",GradeSheet!$L$3,"]" ) -> Course Outcome (CO) Attainment Analysis of CSE [Operating Systems] (Section 1) [Semester - Spring 2025] | AB11: CO Attainment Analysis | AU11: PO Attainment Analysis
D12: =C3 -> Midterm Exam | J12: =C4 -> Final Exam | P12: Project | V12: =C6 -> Presentation | AB12: Total Marks | AH12: Percentage | AN12: CO Attainment | AU12: Percentage | BG12: PO Attainment
D13: CO1 | E13: CO2 | F13: CO3 | G13: CO4 | H13: CO5 | I13: CO6 | J13: CO1 | K13: CO2 | L13: CO3 | M13: CO4 | N13: CO5 | O13: CO6 | P13: CO1 | Q13: CO2 | R13: CO3 | S13: CO4 | T13: CO5 | U13: CO6 | V13: CO1 | W13: CO2 | X13: CO3 | Y13: CO4 | Z13: CO5 | AA13: CO6 | AB13: CO1 | AC13: CO2 | AD13: CO3 | AE13: CO4 | AF13: CO5 | AG13: CO6 | AH13: CO1 | AI13: CO2 | AJ13: CO3 | AK13: CO4 | AL13: CO5 | AM13: CO6 | AN13: CO1 | AO13: CO2 | AP13: CO3 | AQ13: CO4 | AR13: CO5 | AS13: CO6 | AU13: PO1 | AV13: PO2 | AW13: PO3 | AX13: PO4 | AY13: PO5 | AZ13: PO6 | BA13: PO7 | BB13: PO8 | BC13: PO9 | BD13: PO10 | BE13: PO11 | BF13: PO12 | BG13: PO1 | BH13: PO2 | BI13: PO3 | BJ13: PO4 | BK13: PO5 | BL13: PO6 | BM13: PO7 | BN13: PO8 | BO13: PO9 | BP13: PO10 | BQ13: PO11 | BR13: PO12
A14: S/N | B14: Student ID | C14: Name | D14: =D3 -> 0 | E14: =E3 -> 0 | F14: =F3 -> 0 | G14: =G3 -> 0 | H14: =H3 -> 0 | I14: =I3 -> 0 | J14: =D4 -> 0 | K14: =E4 -> 0 | L14: =F4 -> 0 | M14: =G4 -> 0 | N14: =H4 -> 0 | O14: =I4 -> 0 | P14: =D5 -> 0 | Q14: =E5 -> 0 | R14: =F5 -> 0 | S14: =G5 -> 0 | T14: =H5 -> 0 | U14: =I5 -> 0 | V14: =D6 -> 0 | W14: =E6 -> 0 | X14: =F6 -> 0 | Y14: =G6 -> 0 | Z14: =H6 -> 0 | AA14: =I6 -> 0 | AB14: =SUM(P14,D14,J14) -> 0 | AC14: =SUM(K14,E14,Q14) -> 0 | AD14: =SUM(L14,F14,R14) -> 0 | AE14: =SUM(M14,G14,S14) -> 0 | AF14: =SUM(N14,H14,T14) -> 0 | AG14: =SUM(O14,I14,U14) -> 0 | AH14: 1 | AI14: 1 | AJ14: 1 | AK14: 1 | AL14: 1 | AM14: 1 | AN14: If CO achieved (≥55%) then 1, else 0 | AU14: 1 | AV14: 1 | AW14: 1 | AX14: 1 | AY14: 1 | AZ14: 1 | BA14: 1 | BB14: 1 | BC14: 1 | BD14: 1 | BE14: 1 | BF14: 1 | BG14: If PO achieved (≥55%) then 1, else 0
A15: 1 | B15: =GradeSheet!X10 -> 0 | C15: =GradeSheet!W10 -> 0 | D15: 0 | E15: 0 | F15: 0 | G15: 0 | H15: 0 | I15: 0 | J15: 0 | K15: 0 | L15: 0 | M15: 0 | N15: 0 | O15: 0 | P15: 0 | Q15: 0 | R15: 0 | S15: 0 | T15: 0 | U15: 0 | V15: 0 | W15: 0 | X15: 0 | Y15: 0 | Z15: 0 | AA15: 0 | AB15: =SUM(V15,D15,J15, P15) -> 0 | AC15: =SUM(W15,E15,K15, Q15) -> 0 | AD15: =SUM(X15,F15,L15, R15) -> 0 | AE15: =SUM(Y15,G15,M15, S15) -> 0 | AF15: =SUM(T15,H15,N15, Z15) -> 0 | AG15: =SUM(AA15,I15,O15, U15) -> 0 | AH15: =IF(AB15 = 0, 0, AB15/AB$14) -> 0 | AI15: =IF(AC15 = 0, 0, AC15/AC$14) -> 0 | AJ15: =IF(AD15 = 0, 0, AD15/AD$14) -> 0 | AK15: =IF(AE15 = 0, 0, AE15/AE$14) -> 0 | AL15: =IF(AF15 = 0, 0, AF15/AF$14) -> 0 | AM15: =IF(AG15 = 0, 0, AG15/AG$14) -> 0 | AN15: =IF(OR(GradeSheet!$M10="W (Withdrawn)", GradeSheet!$M10="I (Incomplete)"), 0, IF(AH15>=55%, 1, 0)) -> 0 | AO15: =IF(OR(GradeSheet!$M10="W (Withdrawn)", GradeSheet!$M10="I (Incomplete)"), 0, IF(AI15>=55%, 1, 0)) -> 0 | AP15: =IF(OR(GradeSheet!$M10="W (Withdrawn)", GradeSheet!$M10="I (Incomplete)"), 0, IF(AJ15>=55%, 1, 0)) -> 0 | AQ15: =IF(OR(GradeSheet!$M10="W (Withdrawn)", GradeSheet!$M10="I (Incomplete)"), 0, IF(AK15>=55%, 1, 0)) -> 0 | AR15: =IF(OR(GradeSheet!$M10="W (Withdrawn)", GradeSheet!$M10="I (Incomplete)"), 0, IF(AL15>=55%, 1, 0)) -> 0 | AS15: =IF(OR(GradeSheet!$M10="W (Withdrawn)", GradeSheet!$M10="I (Incomplete)"), 0, IF(AM15>=55%, 1, 0)) -> 0 | AU15: =IF($AT$9=0,0,MMULT($AH15:$AM15, AT$3:AT$8)/$AT$9) -> 0 | AV15: =IF($AU$9=0,0,MMULT($AH15:$AM15, AU$3:AU$8)/$AU$9) -> 0 | AW15: {=IF($AV$9=0,0,MMULT($AH15:$AM15, AV$3:AV$8)/$AV$9)} -> 0 | AX15: {=IF($AW$9=0,0,MMULT($AH15:$AM15, AW$3:AW$8)/$AW$9)} -> 0 | AY15: =IF($AX$9=0,0,MMULT($AH15:$AM15, AX$3:AX$8)/$AX$9) -> 0 | AZ15: {=IF($AY$9=0,0,MMULT($AH15:$AM15, AY$3:AY$8)/$AY$9)} -> 0 | BA15: {=IF($AZ$9=0,0,MMULT($AH15:$AM15, AZ$3:AZ$8)/$AZ$9)} -> 0 | BB15: {=IF($BA$9=0,0,MMULT($AH15:$AM15, BA$3:BA$8)/$BA$9)} -> 0 | BC15: {=IF($BB$9=0,0,MMULT($AH15:$AM15, BB$3:BB$8)/$BB$9)} -> 0 | BD15: {=IF($BC$9=0,0,MMULT($AH15:$AM15, BC$3:BC$8)/$BC$9)} -> 0 | BE15: =IF($BD$9=0,0,MMULT($AH15:$AM15, BD$3:BD$8)/$BD$9) -> 0 | BF15: =IF($BE$9=0,0,MMULT($AH15:$AM15, BE$3:BE$8)/$BE$9) -> 0 | BG15: =IF(OR(GradeSheet!$M10="W (Withdrawn)", GradeSheet!$M10="I (Incomplete)"), 0, IF(AU15>=65%, 1, 0)) -> 0 | BH15: =IF(OR(GradeSheet!$M10="W (Withdrawn)", GradeSheet!$M10="I (Incomplete)"), 0, IF(AV15>=65%, 1, 0)) -> 0 | BI15: =IF(OR(GradeSheet!$M10="W (Withdrawn)", GradeSheet!$M10="I (Incomplete)"), 0, IF(AW15>=65%, 1, 0)) -> 0 | BJ15: =IF(OR(GradeSheet!$M10="W (Withdrawn)", GradeSheet!$M10="I (Incomplete)"), 0, IF(AX15>=65%, 1, 0)) -> 0 | BK15: =IF(OR(GradeSheet!$M10="W (Withdrawn)", GradeSheet!$M10="I (Incomplete)"), 0, IF(AY15>=65%, 1, 0)) -> 0 | BL15: =IF(OR(GradeSheet!$M10="W (Withdrawn)", GradeSheet!$M10="I (Incomplete)"), 0, IF(AZ15>=65%, 1, 0)) -> 0 | BM15: =IF(OR(GradeSheet!$M10="W (Withdrawn)", GradeSheet!$M10="I (Incomplete)"), 0, IF(BA15>=65%, 1, 0)) -> 0 | BN15: =IF(OR(GradeSheet!$M10="W (Withdrawn)", GradeSheet!$M10="I (Incomplete)"), 0, IF(BB15>=65%, 1, 0)) -> 0 | ... BR15: =IF(OR(GradeSheet!$M10="W (Withdrawn)", GradeSheet!$M10="I (Incomplete)"), 0, IF(BF15>=65%, 1, 0)) -> 0
A16: 2 | B16: =GradeSheet!X11 -> 0 | C16: =GradeSheet!W11 -> 0 | D16: 0 | E16: 0 | F16: 0 | G16: 0 | H16: 0 | I16: 0 | J16: 0 | K16: 0 | L16: 0 | M16: 0 | N16: 0 | O16: 0 | P16: 0 | Q16: 0 | R16: 0 | S16: 0 | T16: 0 | U16: 0 | V16: 0 | W16: 0 | X16: 0 | Y16: 0 | Z16: 0 | AA16: 0 | AB16: =SUM(V16,D16,J16, P16) -> 0 | AC16: =SUM(W16,E16,K16, Q16) -> 0 | AD16: =SUM(X16,F16,L16, R16) -> 0 | AE16: =SUM(Y16,G16,M16, S16) -> 0 | AF16: =SUM(T16,H16,N16) -> 0 | AG16: =SUM(AA16,I16,O16) -> 0 | AH16: =IF(AB16 = 0, 0, AB16/AB$14) -> 0 | AI16: =IF(AC16 = 0, 0, AC16/AC$14) -> 0 | AJ16: =IF(AD16 = 0, 0, AD16/AD$14) -> 0 | AK16: =IF(AE16 = 0, 0, AE16/AE$14) -> 0 | AL16: =IF(AF16 = 0, 0, AF16/AF$14) -> 0 | AM16: =IF(AG16 = 0, 0, AG16/AG$14) -> 0 | AN16: =IF(OR(GradeSheet!$M11="W (Withdrawn)", GradeSheet!$M11="I (Incomplete)"), 0, IF(AH16>=55%, 1, 0)) -> 0 | AO16: =IF(OR(GradeSheet!$M11="W (Withdrawn)", GradeSheet!$M11="I (Incomplete)"), 0, IF(AI16>=55%, 1, 0)) -> 0 | AP16: =IF(OR(GradeSheet!$M11="W (Withdrawn)", GradeSheet!$M11="I (Incomplete)"), 0, IF(AJ16>=55%, 1, 0)) -> 0 | AQ16: =IF(OR(GradeSheet!$M11="W (Withdrawn)", GradeSheet!$M11="I (Incomplete)"), 0, IF(AK16>=55%, 1, 0)) -> 0 | AR16: =IF(OR(GradeSheet!$M11="W (Withdrawn)", GradeSheet!$M11="I (Incomplete)"), 0, IF(AL16>=55%, 1, 0)) -> 0 | AS16: =IF(OR(GradeSheet!$M11="W (Withdrawn)", GradeSheet!$M11="I (Incomplete)"), 0, IF(AM16>=55%, 1, 0)) -> 0 | AU16: =IF($AT$9=0,0,MMULT($AH16:$AM16, AT$3:AT$8)/$AT$9) -> 0 | AV16: =IF($AU$9=0,0,MMULT($AH16:$AM16, AU$3:AU$8)/$AU$9) -> 0 | AW16: {=IF($AV$9=0,0,MMULT($AH16:$AM16, AV$3:AV$8)/$AV$9)} -> 0 | AX16: {=IF($AW$9=0,0,MMULT($AH16:$AM16, AW$3:AW$8)/$AW$9)} -> 0 | AY16: =IF($AX$9=0,0,MMULT($AH16:$AM16, AX$3:AX$8)/$AX$9) -> 0 | AZ16: {=IF($AY$9=0,0,MMULT($AH16:$AM16, AY$3:AY$8)/$AY$9)} -> 0 | BA16: {=IF($AZ$9=0,0,MMULT($AH16:$AM16, AZ$3:AZ$8)/$AZ$9)} -> 0 | BB16: {=IF($BA$9=0,0,MMULT($AH16:$AM16, BA$3:BA$8)/$BA$9)} -> 0 | BC16: {=IF($BB$9=0,0,MMULT($AH16:$AM16, BB$3:BB$8)/$BB$9)} -> 0 | BD16: {=IF($BC$9=0,0,MMULT($AH16:$AM16, BC$3:BC$8)/$BC$9)} -> 0 | BE16: =IF($BD$9=0,0,MMULT($AH16:$AM16, BD$3:BD$8)/$BD$9) -> 0 | BF16: =IF($BE$9=0,0,MMULT($AH16:$AM16, BE$3:BE$8)/$BE$9) -> 0 | BG16: =IF(OR(GradeSheet!$M11="W (Withdrawn)", GradeSheet!$M11="I (Incomplete)"), 0, IF(AU16>=65%, 1, 0)) -> 0 | BH16: =IF(OR(GradeSheet!$M11="W (Withdrawn)", GradeSheet!$M11="I (Incomplete)"), 0, IF(AV16>=65%, 1, 0)) -> 0 | BI16: =IF(OR(GradeSheet!$M11="W (Withdrawn)", GradeSheet!$M11="I (Incomplete)"), 0, IF(AW16>=65%, 1, 0)) -> 0 | BJ16: =IF(OR(GradeSheet!$M11="W (Withdrawn)", GradeSheet!$M11="I (Incomplete)"), 0, IF(AX16>=65%, 1, 0)) -> 0 | BK16: =IF(OR(GradeSheet!$M11="W (Withdrawn)", GradeSheet!$M11="I (Incomplete)"), 0, IF(AY16>=65%, 1, 0)) -> 0 | BL16: =IF(OR(GradeSheet!$M11="W (Withdrawn)", GradeSheet!$M11="I (Incomplete)"), 0, IF(AZ16>=65%, 1, 0)) -> 0 | BM16: =IF(OR(GradeSheet!$M11="W (Withdrawn)", GradeSheet!$M11="I (Incomplete)"), 0, IF(BA16>=65%, 1, 0)) -> 0 | BN16: =IF(OR(GradeSheet!$M11="W (Withdrawn)", GradeSheet!$M11="I (Incomplete)"), 0, IF(BB16>=65%, 1, 0)) -> 0 | ... BR16: =IF(OR(GradeSheet!$M11="W (Withdrawn)", GradeSheet!$M11="I (Incomplete)"), 0, IF(BF16>=65%, 1, 0)) -> 0
A17: 3 | B17: =GradeSheet!X12 -> 0 | C17: =GradeSheet!W12 -> 0 | D17: 0 | E17: 0 | F17: 0 | G17: 0 | H17: 0 | I17: 0 | J17: 0 | K17: 0 | L17: 0 | M17: 0 | N17: 0 | O17: 0 | P17: 0 | Q17: 0 | R17: 0 | S17: 0 | T17: 0 | U17: 0 | V17: 0 | W17: 0 | X17: 0 | Y17: 0 | Z17: 0 | AA17: 0 | AB17: =SUM(V17,D17,J17, P17) -> 0 | AC17: =SUM(W17,E17,K17, Q17) -> 0 | AD17: =SUM(X17,F17,L17, R17) -> 0 | AE17: =SUM(Y17,G17,M17, S17) -> 0 | AF17: =SUM(T17,H17,N17) -> 0 | AG17: =SUM(AA17,I17,O17) -> 0 | AH17: =IF(AB17 = 0, 0, AB17/AB$14) -> 0 | AI17: =IF(AC17 = 0, 0, AC17/AC$14) -> 0 | AJ17: =IF(AD17 = 0, 0, AD17/AD$14) -> 0 | AK17: =IF(AE17 = 0, 0, AE17/AE$14) -> 0 | AL17: =IF(AF17 = 0, 0, AF17/AF$14) -> 0 | AM17: =IF(AG17 = 0, 0, AG17/AG$14) -> 0 | AN17: =IF(OR(GradeSheet!$M12="W (Withdrawn)", GradeSheet!$M12="I (Incomplete)"), 0, IF(AH17>=55%, 1, 0)) -> 0 | AO17: =IF(OR(GradeSheet!$M12="W (Withdrawn)", GradeSheet!$M12="I (Incomplete)"), 0, IF(AI17>=55%, 1, 0)) -> 0 | AP17: =IF(OR(GradeSheet!$M12="W (Withdrawn)", GradeSheet!$M12="I (Incomplete)"), 0, IF(AJ17>=55%, 1, 0)) -> 0 | AQ17: =IF(OR(GradeSheet!$M12="W (Withdrawn)", GradeSheet!$M12="I (Incomplete)"), 0, IF(AK17>=55%, 1, 0)) -> 0 | AR17: =IF(OR(GradeSheet!$M12="W (Withdrawn)", GradeSheet!$M12="I (Incomplete)"), 0, IF(AL17>=55%, 1, 0)) -> 0 | AS17: =IF(OR(GradeSheet!$M12="W (Withdrawn)", GradeSheet!$M12="I (Incomplete)"), 0, IF(AM17>=55%, 1, 0)) -> 0 | AU17: =IF($AT$9=0,0,MMULT($AH17:$AM17, AT$3:AT$8)/$AT$9) -> 0 | AV17: =IF($AU$9=0,0,MMULT($AH17:$AM17, AU$3:AU$8)/$AU$9) -> 0 | AW17: {=IF($AV$9=0,0,MMULT($AH17:$AM17, AV$3:AV$8)/$AV$9)} -> 0 | AX17: {=IF($AW$9=0,0,MMULT($AH17:$AM17, AW$3:AW$8)/$AW$9)} -> 0 | AY17: =IF($AX$9=0,0,MMULT($AH17:$AM17, AX$3:AX$8)/$AX$9) -> 0 | AZ17: {=IF($AY$9=0,0,MMULT($AH17:$AM17, AY$3:AY$8)/$AY$9)} -> 0 | BA17: {=IF($AZ$9=0,0,MMULT($AH17:$AM17, AZ$3:AZ$8)/$AZ$9)} -> 0 | BB17: {=IF($BA$9=0,0,MMULT($AH17:$AM17, BA$3:BA$8)/$BA$9)} -> 0 | BC17: {=IF($BB$9=0,0,MMULT($AH17:$AM17, BB$3:BB$8)/$BB$9)} -> 0 | BD17: {=IF($BC$9=0,0,MMULT($AH17:$AM17, BC$3:BC$8)/$BC$9)} -> 0 | BE17: =IF($BD$9=0,0,MMULT($AH17:$AM17, BD$3:BD$8)/$BD$9) -> 0 | BF17: =IF($BE$9=0,0,MMULT($AH17:$AM17, BE$3:BE$8)/$BE$9) -> 0 | BG17: =IF(OR(GradeSheet!$M12="W (Withdrawn)", GradeSheet!$M12="I (Incomplete)"), 0, IF(AU17>=65%, 1, 0)) -> 0 | BH17: =IF(OR(GradeSheet!$M12="W (Withdrawn)", GradeSheet!$M12="I (Incomplete)"), 0, IF(AV17>=65%, 1, 0)) -> 0 | BI17: =IF(OR(GradeSheet!$M12="W (Withdrawn)", GradeSheet!$M12="I (Incomplete)"), 0, IF(AW17>=65%, 1, 0)) -> 0 | BJ17: =IF(OR(GradeSheet!$M12="W (Withdrawn)", GradeSheet!$M12="I (Incomplete)"), 0, IF(AX17>=65%, 1, 0)) -> 0 | BK17: =IF(OR(GradeSheet!$M12="W (Withdrawn)", GradeSheet!$M12="I (Incomplete)"), 0, IF(AY17>=65%, 1, 0)) -> 0 | BL17: =IF(OR(GradeSheet!$M12="W (Withdrawn)", GradeSheet!$M12="I (Incomplete)"), 0, IF(AZ17>=65%, 1, 0)) -> 0 | BM17: =IF(OR(GradeSheet!$M12="W (Withdrawn)", GradeSheet!$M12="I (Incomplete)"), 0, IF(BA17>=65%, 1, 0)) -> 0 | BN17: =IF(OR(GradeSheet!$M12="W (Withdrawn)", GradeSheet!$M12="I (Incomplete)"), 0, IF(BB17>=65%, 1, 0)) -> 0 | ... BR17: =IF(OR(GradeSheet!$M12="W (Withdrawn)", GradeSheet!$M12="I (Incomplete)"), 0, IF(BF17>=65%, 1, 0)) -> 0
A18: 4 | B18: =GradeSheet!X13 -> 0 | C18: =GradeSheet!W13 -> 0 | D18: 0 | E18: 0 | F18: 0 | G18: 0 | H18: 0 | I18: 0 | J18: 0 | K18: 0 | L18: 0 | M18: 0 | N18: 0 | O18: 0 | P18: 0 | Q18: 0 | R18: 0 | S18: 0 | T18: 0 | U18: 0 | V18: 0 | W18: 0 | X18: 0 | Y18: 0 | Z18: 0 | AA18: 0 | AB18: =SUM(V18,D18,J18, P18) -> 0 | AC18: =SUM(W18,E18,K18, Q18) -> 0 | AD18: =SUM(X18,F18,L18, R18) -> 0 | AE18: =SUM(Y18,G18,M18, S18) -> 0 | AF18: =SUM(T18,H18,N18) -> 0 | AG18: =SUM(AA18,I18,O18) -> 0 | AH18: =IF(AB18 = 0, 0, AB18/AB$14) -> 0 | AI18: =IF(AC18 = 0, 0, AC18/AC$14) -> 0 | AJ18: =IF(AD18 = 0, 0, AD18/AD$14) -> 0 | AK18: =IF(AE18 = 0, 0, AE18/AE$14) -> 0 | AL18: =IF(AF18 = 0, 0, AF18/AF$14) -> 0 | AM18: =IF(AG18 = 0, 0, AG18/AG$14) -> 0 | AN18: =IF(OR(GradeSheet!$M13="W (Withdrawn)", GradeSheet!$M13="I (Incomplete)"), 0, IF(AH18>=55%, 1, 0)) -> 0 | AO18: =IF(OR(GradeSheet!$M13="W (Withdrawn)", GradeSheet!$M13="I (Incomplete)"), 0, IF(AI18>=55%, 1, 0)) -> 0 | AP18: =IF(OR(GradeSheet!$M13="W (Withdrawn)", GradeSheet!$M13="I (Incomplete)"), 0, IF(AJ18>=55%, 1, 0)) -> 0 | AQ18: =IF(OR(GradeSheet!$M13="W (Withdrawn)", GradeSheet!$M13="I (Incomplete)"), 0, IF(AK18>=55%, 1, 0)) -> 0 | AR18: =IF(OR(GradeSheet!$M13="W (Withdrawn)", GradeSheet!$M13="I (Incomplete)"), 0, IF(AL18>=55%, 1, 0)) -> 0 | AS18: =IF(OR(GradeSheet!$M13="W (Withdrawn)", GradeSheet!$M13="I (Incomplete)"), 0, IF(AM18>=55%, 1, 0)) -> 0 | AU18: =IF($AT$9=0,0,MMULT($AH18:$AM18, AT$3:AT$8)/$AT$9) -> 0 | AV18: =IF($AU$9=0,0,MMULT($AH18:$AM18, AU$3:AU$8)/$AU$9) -> 0 | AW18: {=IF($AV$9=0,0,MMULT($AH18:$AM18, AV$3:AV$8)/$AV$9)} -> 0 | AX18: {=IF($AW$9=0,0,MMULT($AH18:$AM18, AW$3:AW$8)/$AW$9)} -> 0 | AY18: =IF($AX$9=0,0,MMULT($AH18:$AM18, AX$3:AX$8)/$AX$9) -> 0 | AZ18: {=IF($AY$9=0,0,MMULT($AH18:$AM18, AY$3:AY$8)/$AY$9)} -> 0 | BA18: {=IF($AZ$9=0,0,MMULT($AH18:$AM18, AZ$3:AZ$8)/$AZ$9)} -> 0 | BB18: {=IF($BA$9=0,0,MMULT($AH18:$AM18, BA$3:BA$8)/$BA$9)} -> 0 | BC18: {=IF($BB$9=0,0,MMULT($AH18:$AM18, BB$3:BB$8)/$BB$9)} -> 0 | BD18: {=IF($BC$9=0,0,MMULT($AH18:$AM18, BC$3:BC$8)/$BC$9)} -> 0 | BE18: =IF($BD$9=0,0,MMULT($AH18:$AM18, BD$3:BD$8)/$BD$9) -> 0 | BF18: =IF($BE$9=0,0,MMULT($AH18:$AM18, BE$3:BE$8)/$BE$9) -> 0 | BG18: =IF(OR(GradeSheet!$M13="W (Withdrawn)", GradeSheet!$M13="I (Incomplete)"), 0, IF(AU18>=65%, 1, 0)) -> 0 | BH18: =IF(OR(GradeSheet!$M13="W (Withdrawn)", GradeSheet!$M13="I (Incomplete)"), 0, IF(AV18>=65%, 1, 0)) -> 0 | BI18: =IF(OR(GradeSheet!$M13="W (Withdrawn)", GradeSheet!$M13="I (Incomplete)"), 0, IF(AW18>=65%, 1, 0)) -> 0 | BJ18: =IF(OR(GradeSheet!$M13="W (Withdrawn)", GradeSheet!$M13="I (Incomplete)"), 0, IF(AX18>=65%, 1, 0)) -> 0 | BK18: =IF(OR(GradeSheet!$M13="W (Withdrawn)", GradeSheet!$M13="I (Incomplete)"), 0, IF(AY18>=65%, 1, 0)) -> 0 | BL18: =IF(OR(GradeSheet!$M13="W (Withdrawn)", GradeSheet!$M13="I (Incomplete)"), 0, IF(AZ18>=65%, 1, 0)) -> 0 | BM18: =IF(OR(GradeSheet!$M13="W (Withdrawn)", GradeSheet!$M13="I (Incomplete)"), 0, IF(BA18>=65%, 1, 0)) -> 0 | BN18: =IF(OR(GradeSheet!$M13="W (Withdrawn)", GradeSheet!$M13="I (Incomplete)"), 0, IF(BB18>=65%, 1, 0)) -> 0 | ... BR18: =IF(OR(GradeSheet!$M13="W (Withdrawn)", GradeSheet!$M13="I (Incomplete)"), 0, IF(BF18>=65%, 1, 0)) -> 0
A19: 5 | B19: =GradeSheet!X14 -> 0 | C19: =GradeSheet!W14 -> 0 | D19: 0 | E19: 0 | F19: 0 | G19: 0 | H19: 0 | I19: 0 | J19: 0 | K19: 0 | L19: 0 | M19: 0 | N19: 0 | O19: 0 | P19: 0 | Q19: 0 | R19: 0 | S19: 0 | T19: 0 | U19: 0 | V19: 0 | W19: 0 | X19: 0 | Y19: 0 | Z19: 0 | AA19: 0 | AB19: =SUM(V19,D19,J19, P19) -> 0 | AC19: =SUM(W19,E19,K19, Q19) -> 0 | AD19: =SUM(X19,F19,L19, R19) -> 0 | AE19: =SUM(Y19,G19,M19, S19) -> 0 | AF19: =SUM(T19,H19,N19) -> 0 | AG19: =SUM(AA19,I19,O19) -> 0 | AH19: =IF(AB19 = 0, 0, AB19/AB$14) -> 0 | AI19: =IF(AC19 = 0, 0, AC19/AC$14) -> 0 | AJ19: =IF(AD19 = 0, 0, AD19/AD$14) -> 0 | AK19: =IF(AE19 = 0, 0, AE19/AE$14) -> 0 | AL19: =IF(AF19 = 0, 0, AF19/AF$14) -> 0 | AM19: =IF(AG19 = 0, 0, AG19/AG$14) -> 0 | AN19: =IF(OR(GradeSheet!$M14="W (Withdrawn)", GradeSheet!$M14="I (Incomplete)"), 0, IF(AH19>=55%, 1, 0)) -> 0 | AO19: =IF(OR(GradeSheet!$M14="W (Withdrawn)", GradeSheet!$M14="I (Incomplete)"), 0, IF(AI19>=55%, 1, 0)) -> 0 | AP19: =IF(OR(GradeSheet!$M14="W (Withdrawn)", GradeSheet!$M14="I (Incomplete)"), 0, IF(AJ19>=55%, 1, 0)) -> 0 | AQ19: =IF(OR(GradeSheet!$M14="W (Withdrawn)", GradeSheet!$M14="I (Incomplete)"), 0, IF(AK19>=55%, 1, 0)) -> 0 | AR19: =IF(OR(GradeSheet!$M14="W (Withdrawn)", GradeSheet!$M14="I (Incomplete)"), 0, IF(AL19>=55%, 1, 0)) -> 0 | AS19: =IF(OR(GradeSheet!$M14="W (Withdrawn)", GradeSheet!$M14="I (Incomplete)"), 0, IF(AM19>=55%, 1, 0)) -> 0 | AU19: =IF($AT$9=0,0,MMULT($AH19:$AM19, AT$3:AT$8)/$AT$9) -> 0 | AV19: =IF($AU$9=0,0,MMULT($AH19:$AM19, AU$3:AU$8)/$AU$9) -> 0 | AW19: {=IF($AV$9=0,0,MMULT($AH19:$AM19, AV$3:AV$8)/$AV$9)} -> 0 | AX19: {=IF($AW$9=0,0,MMULT($AH19:$AM19, AW$3:AW$8)/$AW$9)} -> 0 | AY19: =IF($AX$9=0,0,MMULT($AH19:$AM19, AX$3:AX$8)/$AX$9) -> 0 | AZ19: {=IF($AY$9=0,0,MMULT($AH19:$AM19, AY$3:AY$8)/$AY$9)} -> 0 | BA19: {=IF($AZ$9=0,0,MMULT($AH19:$AM19, AZ$3:AZ$8)/$AZ$9)} -> 0 | BB19: {=IF($BA$9=0,0,MMULT($AH19:$AM19, BA$3:BA$8)/$BA$9)} -> 0 | BC19: {=IF($BB$9=0,0,MMULT($AH19:$AM19, BB$3:BB$8)/$BB$9)} -> 0 | BD19: {=IF($BC$9=0,0,MMULT($AH19:$AM19, BC$3:BC$8)/$BC$9)} -> 0 | BE19: =IF($BD$9=0,0,MMULT($AH19:$AM19, BD$3:BD$8)/$BD$9) -> 0 | BF19: =IF($BE$9=0,0,MMULT($AH19:$AM19, BE$3:BE$8)/$BE$9) -> 0 | BG19: =IF(OR(GradeSheet!$M14="W (Withdrawn)", GradeSheet!$M14="I (Incomplete)"), 0, IF(AU19>=65%, 1, 0)) -> 0 | BH19: =IF(OR(GradeSheet!$M14="W (Withdrawn)", GradeSheet!$M14="I (Incomplete)"), 0, IF(AV19>=65%, 1, 0)) -> 0 | BI19: =IF(OR(GradeSheet!$M14="W (Withdrawn)", GradeSheet!$M14="I (Incomplete)"), 0, IF(AW19>=65%, 1, 0)) -> 0 | BJ19: =IF(OR(GradeSheet!$M14="W (Withdrawn)", GradeSheet!$M14="I (Incomplete)"), 0, IF(AX19>=65%, 1, 0)) -> 0 | BK19: =IF(OR(GradeSheet!$M14="W (Withdrawn)", GradeSheet!$M14="I (Incomplete)"), 0, IF(AY19>=65%, 1, 0)) -> 0 | BL19: =IF(OR(GradeSheet!$M14="W (Withdrawn)", GradeSheet!$M14="I (Incomplete)"), 0, IF(AZ19>=65%, 1, 0)) -> 0 | BM19: =IF(OR(GradeSheet!$M14="W (Withdrawn)", GradeSheet!$M14="I (Incomplete)"), 0, IF(BA19>=65%, 1, 0)) -> 0 | BN19: =IF(OR(GradeSheet!$M14="W (Withdrawn)", GradeSheet!$M14="I (Incomplete)"), 0, IF(BB19>=65%, 1, 0)) -> 0 | ... BR19: =IF(OR(GradeSheet!$M14="W (Withdrawn)", GradeSheet!$M14="I (Incomplete)"), 0, IF(BF19>=65%, 1, 0)) -> 0
A20: 6 | B20: =GradeSheet!X15 -> 0 | C20: =GradeSheet!W15 -> 0 | D20: 0 | E20: 0 | F20: 0 | G20: 0 | H20: 0 | I20: 0 | J20: 0 | K20: 0 | L20: 0 | M20: 0 | N20: 0 | O20: 0 | P20: 0 | Q20: 0 | R20: 0 | S20: 0 | T20: 0 | U20: 0 | V20: 0 | W20: 0 | X20: 0 | Y20: 0 | Z20: 0 | AA20: 0 | AB20: =SUM(V20,D20,J20, P20) -> 0 | AC20: =SUM(W20,E20,K20, Q20) -> 0 | AD20: =SUM(X20,F20,L20, R20) -> 0 | AE20: =SUM(Y20,G20,M20, S20) -> 0 | AF20: =SUM(T20,H20,N20) -> 0 | AG20: =SUM(AA20,I20,O20) -> 0 | AH20: =IF(AB20 = 0, 0, AB20/AB$14) -> 0 | AI20: =IF(AC20 = 0, 0, AC20/AC$14) -> 0 | AJ20: =IF(AD20 = 0, 0, AD20/AD$14) -> 0 | AK20: =IF(AE20 = 0, 0, AE20/AE$14) -> 0 | AL20: =IF(AF20 = 0, 0, AF20/AF$14) -> 0 | AM20: =IF(AG20 = 0, 0, AG20/AG$14) -> 0 | AN20: =IF(OR(GradeSheet!$M15="W (Withdrawn)", GradeSheet!$M15="I (Incomplete)"), 0, IF(AH20>=55%, 1, 0)) -> 0 | AO20: =IF(OR(GradeSheet!$M15="W (Withdrawn)", GradeSheet!$M15="I (Incomplete)"), 0, IF(AI20>=55%, 1, 0)) -> 0 | AP20: =IF(OR(GradeSheet!$M15="W (Withdrawn)", GradeSheet!$M15="I (Incomplete)"), 0, IF(AJ20>=55%, 1, 0)) -> 0 | AQ20: =IF(OR(GradeSheet!$M15="W (Withdrawn)", GradeSheet!$M15="I (Incomplete)"), 0, IF(AK20>=55%, 1, 0)) -> 0 | AR20: =IF(OR(GradeSheet!$M15="W (Withdrawn)", GradeSheet!$M15="I (Incomplete)"), 0, IF(AL20>=55%, 1, 0)) -> 0 | AS20: =IF(OR(GradeSheet!$M15="W (Withdrawn)", GradeSheet!$M15="I (Incomplete)"), 0, IF(AM20>=55%, 1, 0)) -> 0 | AU20: =IF($AT$9=0,0,MMULT($AH20:$AM20, AT$3:AT$8)/$AT$9) -> 0 | AV20: =IF($AU$9=0,0,MMULT($AH20:$AM20, AU$3:AU$8)/$AU$9) -> 0 | AW20: {=IF($AV$9=0,0,MMULT($AH20:$AM20, AV$3:AV$8)/$AV$9)} -> 0 | AX20: {=IF($AW$9=0,0,MMULT($AH20:$AM20, AW$3:AW$8)/$AW$9)} -> 0 | AY20: =IF($AX$9=0,0,MMULT($AH20:$AM20, AX$3:AX$8)/$AX$9) -> 0 | AZ20: {=IF($AY$9=0,0,MMULT($AH20:$AM20, AY$3:AY$8)/$AY$9)} -> 0 | BA20: {=IF($AZ$9=0,0,MMULT($AH20:$AM20, AZ$3:AZ$8)/$AZ$9)} -> 0 | BB20: {=IF($BA$9=0,0,MMULT($AH20:$AM20, BA$3:BA$8)/$BA$9)} -> 0 | BC20: {=IF($BB$9=0,0,MMULT($AH20:$AM20, BB$3:BB$8)/$BB$9)} -> 0 | BD20: {=IF($BC$9=0,0,MMULT($AH20:$AM20, BC$3:BC$8)/$BC$9)} -> 0 | BE20: =IF($BD$9=0,0,MMULT($AH20:$AM20, BD$3:BD$8)/$BD$9) -> 0 | BF20: =IF($BE$9=0,0,MMULT($AH20:$AM20, BE$3:BE$8)/$BE$9) -> 0 | BG20: =IF(OR(GradeSheet!$M15="W (Withdrawn)", GradeSheet!$M15="I (Incomplete)"), 0, IF(AU20>=65%, 1, 0)) -> 0 | BH20: =IF(OR(GradeSheet!$M15="W (Withdrawn)", GradeSheet!$M15="I (Incomplete)"), 0, IF(AV20>=65%, 1, 0)) -> 0 | BI20: =IF(OR(GradeSheet!$M15="W (Withdrawn)", GradeSheet!$M15="I (Incomplete)"), 0, IF(AW20>=65%, 1, 0)) -> 0 | BJ20: =IF(OR(GradeSheet!$M15="W (Withdrawn)", GradeSheet!$M15="I (Incomplete)"), 0, IF(AX20>=65%, 1, 0)) -> 0 | BK20: =IF(OR(GradeSheet!$M15="W (Withdrawn)", GradeSheet!$M15="I (Incomplete)"), 0, IF(AY20>=65%, 1, 0)) -> 0 | BL20: =IF(OR(GradeSheet!$M15="W (Withdrawn)", GradeSheet!$M15="I (Incomplete)"), 0, IF(AZ20>=65%, 1, 0)) -> 0 | BM20: =IF(OR(GradeSheet!$M15="W (Withdrawn)", GradeSheet!$M15="I (Incomplete)"), 0, IF(BA20>=65%, 1, 0)) -> 0 | BN20: =IF(OR(GradeSheet!$M15="W (Withdrawn)", GradeSheet!$M15="I (Incomplete)"), 0, IF(BB20>=65%, 1, 0)) -> 0 | ... BR20: =IF(OR(GradeSheet!$M15="W (Withdrawn)", GradeSheet!$M15="I (Incomplete)"), 0, IF(BF20>=65%, 1, 0)) -> 0
A21: 7 | B21: =GradeSheet!X16 -> 0 | C21: =GradeSheet!W16 -> 0 | D21: 0 | E21: 0 | F21: 0 | G21: 0 | H21: 0 | I21: 0 | J21: 0 | K21: 0 | L21: 0 | M21: 0 | N21: 0 | O21: 0 | P21: 0 | Q21: 0 | R21: 0 | S21: 0 | T21: 0 | U21: 0 | V21: 0 | W21: 0 | X21: 0 | Y21: 0 | Z21: 0 | AA21: 0 | AB21: =SUM(V21,D21,J21, P21) -> 0 | AC21: =SUM(W21,E21,K21, Q21) -> 0 | AD21: =SUM(X21,F21,L21, R21) -> 0 | AE21: =SUM(Y21,G21,M21, S21) -> 0 | AF21: =SUM(T21,H21,N21) -> 0 | AG21: =SUM(AA21,I21,O21) -> 0 | AH21: =IF(AB21 = 0, 0, AB21/AB$14) -> 0 | AI21: =IF(AC21 = 0, 0, AC21/AC$14) -> 0 | AJ21: =IF(AD21 = 0, 0, AD21/AD$14) -> 0 | AK21: =IF(AE21 = 0, 0, AE21/AE$14) -> 0 | AL21: =IF(AF21 = 0, 0, AF21/AF$14) -> 0 | AM21: =IF(AG21 = 0, 0, AG21/AG$14) -> 0 | AN21: =IF(OR(GradeSheet!$M16="W (Withdrawn)", GradeSheet!$M16="I (Incomplete)"), 0, IF(AH21>=55%, 1, 0)) -> 0 | AO21: =IF(OR(GradeSheet!$M16="W (Withdrawn)", GradeSheet!$M16="I (Incomplete)"), 0, IF(AI21>=55%, 1, 0)) -> 0 | AP21: =IF(OR(GradeSheet!$M16="W (Withdrawn)", GradeSheet!$M16="I (Incomplete)"), 0, IF(AJ21>=55%, 1, 0)) -> 0 | AQ21: =IF(OR(GradeSheet!$M16="W (Withdrawn)", GradeSheet!$M16="I (Incomplete)"), 0, IF(AK21>=55%, 1, 0)) -> 0 | AR21: =IF(OR(GradeSheet!$M16="W (Withdrawn)", GradeSheet!$M16="I (Incomplete)"), 0, IF(AL21>=55%, 1, 0)) -> 0 | AS21: =IF(OR(GradeSheet!$M16="W (Withdrawn)", GradeSheet!$M16="I (Incomplete)"), 0, IF(AM21>=55%, 1, 0)) -> 0 | AU21: =IF($AT$9=0,0,MMULT($AH21:$AM21, AT$3:AT$8)/$AT$9) -> 0 | AV21: =IF($AU$9=0,0,MMULT($AH21:$AM21, AU$3:AU$8)/$AU$9) -> 0 | AW21: {=IF($AV$9=0,0,MMULT($AH21:$AM21, AV$3:AV$8)/$AV$9)} -> 0 | AX21: {=IF($AW$9=0,0,MMULT($AH21:$AM21, AW$3:AW$8)/$AW$9)} -> 0 | AY21: =IF($AX$9=0,0,MMULT($AH21:$AM21, AX$3:AX$8)/$AX$9) -> 0 | AZ21: {=IF($AY$9=0,0,MMULT($AH21:$AM21, AY$3:AY$8)/$AY$9)} -> 0 | BA21: {=IF($AZ$9=0,0,MMULT($AH21:$AM21, AZ$3:AZ$8)/$AZ$9)} -> 0 | BB21: {=IF($BA$9=0,0,MMULT($AH21:$AM21, BA$3:BA$8)/$BA$9)} -> 0 | BC21: {=IF($BB$9=0,0,MMULT($AH21:$AM21, BB$3:BB$8)/$BB$9)} -> 0 | BD21: {=IF($BC$9=0,0,MMULT($AH21:$AM21, BC$3:BC$8)/$BC$9)} -> 0 | BE21: =IF($BD$9=0,0,MMULT($AH21:$AM21, BD$3:BD$8)/$BD$9) -> 0 | BF21: =IF($BE$9=0,0,MMULT($AH21:$AM21, BE$3:BE$8)/$BE$9) -> 0 | BG21: =IF(OR(GradeSheet!$M16="W (Withdrawn)", GradeSheet!$M16="I (Incomplete)"), 0, IF(AU21>=65%, 1, 0)) -> 0 | BH21: =IF(OR(GradeSheet!$M16="W (Withdrawn)", GradeSheet!$M16="I (Incomplete)"), 0, IF(AV21>=65%, 1, 0)) -> 0 | BI21: =IF(OR(GradeSheet!$M16="W (Withdrawn)", GradeSheet!$M16="I (Incomplete)"), 0, IF(AW21>=65%, 1, 0)) -> 0 | BJ21: =IF(OR(GradeSheet!$M16="W (Withdrawn)", GradeSheet!$M16="I (Incomplete)"), 0, IF(AX21>=65%, 1, 0)) -> 0 | BK21: =IF(OR(GradeSheet!$M16="W (Withdrawn)", GradeSheet!$M16="I (Incomplete)"), 0, IF(AY21>=65%, 1, 0)) -> 0 | BL21: =IF(OR(GradeSheet!$M16="W (Withdrawn)", GradeSheet!$M16="I (Incomplete)"), 0, IF(AZ21>=65%, 1, 0)) -> 0 | BM21: =IF(OR(GradeSheet!$M16="W (Withdrawn)", GradeSheet!$M16="I (Incomplete)"), 0, IF(BA21>=65%, 1, 0)) -> 0 | BN21: =IF(OR(GradeSheet!$M16="W (Withdrawn)", GradeSheet!$M16="I (Incomplete)"), 0, IF(BB21>=65%, 1, 0)) -> 0 | ... BR21: =IF(OR(GradeSheet!$M16="W (Withdrawn)", GradeSheet!$M16="I (Incomplete)"), 0, IF(BF21>=65%, 1, 0)) -> 0
A22: 8 | B22: =GradeSheet!X17 -> 0 | C22: =GradeSheet!W17 -> 0 | D22: 0 | E22: 0 | F22: 0 | G22: 0 | H22: 0 | I22: 0 | J22: 0 | K22: 0 | L22: 0 | M22: 0 | N22: 0 | O22: 0 | P22: 0 | Q22: 0 | R22: 0 | S22: 0 | T22: 0 | U22: 0 | V22: 0 | W22: 0 | X22: 0 | Y22: 0 | Z22: 0 | AA22: 0 | AB22: =SUM(V22,D22,J22, P22) -> 0 | AC22: =SUM(W22,E22,K22, Q22) -> 0 | AD22: =SUM(X22,F22,L22, R22) -> 0 | AE22: =SUM(Y22,G22,M22, S22) -> 0 | AF22: =SUM(T22,H22,N22) -> 0 | AG22: =SUM(AA22,I22,O22) -> 0 | AH22: =IF(AB22 = 0, 0, AB22/AB$14) -> 0 | AI22: =IF(AC22 = 0, 0, AC22/AC$14) -> 0 | AJ22: =IF(AD22 = 0, 0, AD22/AD$14) -> 0 | AK22: =IF(AE22 = 0, 0, AE22/AE$14) -> 0 | AL22: =IF(AF22 = 0, 0, AF22/AF$14) -> 0 | AM22: =IF(AG22 = 0, 0, AG22/AG$14) -> 0 | AN22: =IF(OR(GradeSheet!$M17="W (Withdrawn)", GradeSheet!$M17="I (Incomplete)"), 0, IF(AH22>=55%, 1, 0)) -> 0 | AO22: =IF(OR(GradeSheet!$M17="W (Withdrawn)", GradeSheet!$M17="I (Incomplete)"), 0, IF(AI22>=55%, 1, 0)) -> 0 | AP22: =IF(OR(GradeSheet!$M17="W (Withdrawn)", GradeSheet!$M17="I (Incomplete)"), 0, IF(AJ22>=55%, 1, 0)) -> 0 | AQ22: =IF(OR(GradeSheet!$M17="W (Withdrawn)", GradeSheet!$M17="I (Incomplete)"), 0, IF(AK22>=55%, 1, 0)) -> 0 | AR22: =IF(OR(GradeSheet!$M17="W (Withdrawn)", GradeSheet!$M17="I (Incomplete)"), 0, IF(AL22>=55%, 1, 0)) -> 0 | AS22: =IF(OR(GradeSheet!$M17="W (Withdrawn)", GradeSheet!$M17="I (Incomplete)"), 0, IF(AM22>=55%, 1, 0)) -> 0 | AU22: =IF($AT$9=0,0,MMULT($AH22:$AM22, AT$3:AT$8)/$AT$9) -> 0 | AV22: =IF($AU$9=0,0,MMULT($AH22:$AM22, AU$3:AU$8)/$AU$9) -> 0 | AW22: {=IF($AV$9=0,0,MMULT($AH22:$AM22, AV$3:AV$8)/$AV$9)} -> 0 | AX22: {=IF($AW$9=0,0,MMULT($AH22:$AM22, AW$3:AW$8)/$AW$9)} -> 0 | AY22: =IF($AX$9=0,0,MMULT($AH22:$AM22, AX$3:AX$8)/$AX$9) -> 0 | AZ22: {=IF($AY$9=0,0,MMULT($AH22:$AM22, AY$3:AY$8)/$AY$9)} -> 0 | BA22: {=IF($AZ$9=0,0,MMULT($AH22:$AM22, AZ$3:AZ$8)/$AZ$9)} -> 0 | BB22: {=IF($BA$9=0,0,MMULT($AH22:$AM22, BA$3:BA$8)/$BA$9)} -> 0 | BC22: {=IF($BB$9=0,0,MMULT($AH22:$AM22, BB$3:BB$8)/$BB$9)} -> 0 | BD22: {=IF($BC$9=0,0,MMULT($AH22:$AM22, BC$3:BC$8)/$BC$9)} -> 0 | BE22: =IF($BD$9=0,0,MMULT($AH22:$AM22, BD$3:BD$8)/$BD$9) -> 0 | BF22: =IF($BE$9=0,0,MMULT($AH22:$AM22, BE$3:BE$8)/$BE$9) -> 0 | BG22: =IF(OR(GradeSheet!$M17="W (Withdrawn)", GradeSheet!$M17="I (Incomplete)"), 0, IF(AU22>=65%, 1, 0)) -> 0 | BH22: =IF(OR(GradeSheet!$M17="W (Withdrawn)", GradeSheet!$M17="I (Incomplete)"), 0, IF(AV22>=65%, 1, 0)) -> 0 | BI22: =IF(OR(GradeSheet!$M17="W (Withdrawn)", GradeSheet!$M17="I (Incomplete)"), 0, IF(AW22>=65%, 1, 0)) -> 0 | BJ22: =IF(OR(GradeSheet!$M17="W (Withdrawn)", GradeSheet!$M17="I (Incomplete)"), 0, IF(AX22>=65%, 1, 0)) -> 0 | BK22: =IF(OR(GradeSheet!$M17="W (Withdrawn)", GradeSheet!$M17="I (Incomplete)"), 0, IF(AY22>=65%, 1, 0)) -> 0 | BL22: =IF(OR(GradeSheet!$M17="W (Withdrawn)", GradeSheet!$M17="I (Incomplete)"), 0, IF(AZ22>=65%, 1, 0)) -> 0 | BM22: =IF(OR(GradeSheet!$M17="W (Withdrawn)", GradeSheet!$M17="I (Incomplete)"), 0, IF(BA22>=65%, 1, 0)) -> 0 | BN22: =IF(OR(GradeSheet!$M17="W (Withdrawn)", GradeSheet!$M17="I (Incomplete)"), 0, IF(BB22>=65%, 1, 0)) -> 0 | ... BR22: =IF(OR(GradeSheet!$M17="W (Withdrawn)", GradeSheet!$M17="I (Incomplete)"), 0, IF(BF22>=65%, 1, 0)) -> 0
A23: 9 | B23: =GradeSheet!X18 -> 0 | C23: =GradeSheet!W18 -> 0 | D23: 0 | E23: 0 | F23: 0 | G23: 0 | H23: 0 | I23: 0 | J23: 0 | K23: 0 | L23: 0 | M23: 0 | N23: 0 | O23: 0 | P23: 0 | Q23: 0 | R23: 0 | S23: 0 | T23: 0 | U23: 0 | V23: 0 | W23: 0 | X23: 0 | Y23: 0 | Z23: 0 | AA23: 0 | AB23: =SUM(V23,D23,J23, P23) -> 0 | AC23: =SUM(W23,E23,K23, Q23) -> 0 | AD23: =SUM(X23,F23,L23, R23) -> 0 | AE23: =SUM(Y23,G23,M23, S23) -> 0 | AF23: =SUM(T23,H23,N23) -> 0 | AG23: =SUM(AA23,I23,O23) -> 0 | AH23: =IF(AB23 = 0, 0, AB23/AB$14) -> 0 | AI23: =IF(AC23 = 0, 0, AC23/AC$14) -> 0 | AJ23: =IF(AD23 = 0, 0, AD23/AD$14) -> 0 | AK23: =IF(AE23 = 0, 0, AE23/AE$14) -> 0 | AL23: =IF(AF23 = 0, 0, AF23/AF$14) -> 0 | AM23: =IF(AG23 = 0, 0, AG23/AG$14) -> 0 | AN23: =IF(OR(GradeSheet!$M18="W (Withdrawn)", GradeSheet!$M18="I (Incomplete)"), 0, IF(AH23>=55%, 1, 0)) -> 0 | AO23: =IF(OR(GradeSheet!$M18="W (Withdrawn)", GradeSheet!$M18="I (Incomplete)"), 0, IF(AI23>=55%, 1, 0)) -> 0 | AP23: =IF(OR(GradeSheet!$M18="W (Withdrawn)", GradeSheet!$M18="I (Incomplete)"), 0, IF(AJ23>=55%, 1, 0)) -> 0 | AQ23: =IF(OR(GradeSheet!$M18="W (Withdrawn)", GradeSheet!$M18="I (Incomplete)"), 0, IF(AK23>=55%, 1, 0)) -> 0 | AR23: =IF(OR(GradeSheet!$M18="W (Withdrawn)", GradeSheet!$M18="I (Incomplete)"), 0, IF(AL23>=55%, 1, 0)) -> 0 | AS23: =IF(OR(GradeSheet!$M18="W (Withdrawn)", GradeSheet!$M18="I (Incomplete)"), 0, IF(AM23>=55%, 1, 0)) -> 0 | AU23: =IF($AT$9=0,0,MMULT($AH23:$AM23, AT$3:AT$8)/$AT$9) -> 0 | AV23: =IF($AU$9=0,0,MMULT($AH23:$AM23, AU$3:AU$8)/$AU$9) -> 0 | AW23: {=IF($AV$9=0,0,MMULT($AH23:$AM23, AV$3:AV$8)/$AV$9)} -> 0 | AX23: {=IF($AW$9=0,0,MMULT($AH23:$AM23, AW$3:AW$8)/$AW$9)} -> 0 | AY23: =IF($AX$9=0,0,MMULT($AH23:$AM23, AX$3:AX$8)/$AX$9) -> 0 | AZ23: {=IF($AY$9=0,0,MMULT($AH23:$AM23, AY$3:AY$8)/$AY$9)} -> 0 | BA23: {=IF($AZ$9=0,0,MMULT($AH23:$AM23, AZ$3:AZ$8)/$AZ$9)} -> 0 | BB23: {=IF($BA$9=0,0,MMULT($AH23:$AM23, BA$3:BA$8)/$BA$9)} -> 0 | BC23: {=IF($BB$9=0,0,MMULT($AH23:$AM23, BB$3:BB$8)/$BB$9)} -> 0 | BD23: {=IF($BC$9=0,0,MMULT($AH23:$AM23, BC$3:BC$8)/$BC$9)} -> 0 | BE23: =IF($BD$9=0,0,MMULT($AH23:$AM23, BD$3:BD$8)/$BD$9) -> 0 | BF23: =IF($BE$9=0,0,MMULT($AH23:$AM23, BE$3:BE$8)/$BE$9) -> 0 | BG23: =IF(OR(GradeSheet!$M18="W (Withdrawn)", GradeSheet!$M18="I (Incomplete)"), 0, IF(AU23>=65%, 1, 0)) -> 0 | BH23: =IF(OR(GradeSheet!$M18="W (Withdrawn)", GradeSheet!$M18="I (Incomplete)"), 0, IF(AV23>=65%, 1, 0)) -> 0 | BI23: =IF(OR(GradeSheet!$M18="W (Withdrawn)", GradeSheet!$M18="I (Incomplete)"), 0, IF(AW23>=65%, 1, 0)) -> 0 | BJ23: =IF(OR(GradeSheet!$M18="W (Withdrawn)", GradeSheet!$M18="I (Incomplete)"), 0, IF(AX23>=65%, 1, 0)) -> 0 | BK23: =IF(OR(GradeSheet!$M18="W (Withdrawn)", GradeSheet!$M18="I (Incomplete)"), 0, IF(AY23>=65%, 1, 0)) -> 0 | BL23: =IF(OR(GradeSheet!$M18="W (Withdrawn)", GradeSheet!$M18="I (Incomplete)"), 0, IF(AZ23>=65%, 1, 0)) -> 0 | BM23: =IF(OR(GradeSheet!$M18="W (Withdrawn)", GradeSheet!$M18="I (Incomplete)"), 0, IF(BA23>=65%, 1, 0)) -> 0 | BN23: =IF(OR(GradeSheet!$M18="W (Withdrawn)", GradeSheet!$M18="I (Incomplete)"), 0, IF(BB23>=65%, 1, 0)) -> 0 | ... BR23: =IF(OR(GradeSheet!$M18="W (Withdrawn)", GradeSheet!$M18="I (Incomplete)"), 0, IF(BF23>=65%, 1, 0)) -> 0
A24: 10 | B24: =GradeSheet!X19 -> 0 | C24: =GradeSheet!W19 -> 0 | D24: 0 | E24: 0 | F24: 0 | G24: 0 | H24: 0 | I24: 0 | J24: 0 | K24: 0 | L24: 0 | M24: 0 | N24: 0 | O24: 0 | P24: 0 | Q24: 0 | R24: 0 | S24: 0 | T24: 0 | U24: 0 | V24: 0 | W24: 0 | X24: 0 | Y24: 0 | Z24: 0 | AA24: 0 | AB24: =SUM(V24,D24,J24, P24) -> 0 | AC24: =SUM(W24,E24,K24, Q24) -> 0 | AD24: =SUM(X24,F24,L24, R24) -> 0 | AE24: =SUM(Y24,G24,M24, S24) -> 0 | AF24: =SUM(T24,H24,N24) -> 0 | AG24: =SUM(AA24,I24,O24) -> 0 | AH24: =IF(AB24 = 0, 0, AB24/AB$14) -> 0 | AI24: =IF(AC24 = 0, 0, AC24/AC$14) -> 0 | AJ24: =IF(AD24 = 0, 0, AD24/AD$14) -> 0 | AK24: =IF(AE24 = 0, 0, AE24/AE$14) -> 0 | AL24: =IF(AF24 = 0, 0, AF24/AF$14) -> 0 | AM24: =IF(AG24 = 0, 0, AG24/AG$14) -> 0 | AN24: =IF(OR(GradeSheet!$M19="W (Withdrawn)", GradeSheet!$M19="I (Incomplete)"), 0, IF(AH24>=55%, 1, 0)) -> 0 | AO24: =IF(OR(GradeSheet!$M19="W (Withdrawn)", GradeSheet!$M19="I (Incomplete)"), 0, IF(AI24>=55%, 1, 0)) -> 0 | AP24: =IF(OR(GradeSheet!$M19="W (Withdrawn)", GradeSheet!$M19="I (Incomplete)"), 0, IF(AJ24>=55%, 1, 0)) -> 0 | AQ24: =IF(OR(GradeSheet!$M19="W (Withdrawn)", GradeSheet!$M19="I (Incomplete)"), 0, IF(AK24>=55%, 1, 0)) -> 0 | AR24: =IF(OR(GradeSheet!$M19="W (Withdrawn)", GradeSheet!$M19="I (Incomplete)"), 0, IF(AL24>=55%, 1, 0)) -> 0 | AS24: =IF(OR(GradeSheet!$M19="W (Withdrawn)", GradeSheet!$M19="I (Incomplete)"), 0, IF(AM24>=55%, 1, 0)) -> 0 | AU24: =IF($AT$9=0,0,MMULT($AH24:$AM24, AT$3:AT$8)/$AT$9) -> 0 | AV24: =IF($AU$9=0,0,MMULT($AH24:$AM24, AU$3:AU$8)/$AU$9) -> 0 | AW24: {=IF($AV$9=0,0,MMULT($AH24:$AM24, AV$3:AV$8)/$AV$9)} -> 0 | AX24: {=IF($AW$9=0,0,MMULT($AH24:$AM24, AW$3:AW$8)/$AW$9)} -> 0 | AY24: =IF($AX$9=0,0,MMULT($AH24:$AM24, AX$3:AX$8)/$AX$9) -> 0 | AZ24: {=IF($AY$9=0,0,MMULT($AH24:$AM24, AY$3:AY$8)/$AY$9)} -> 0 | BA24: {=IF($AZ$9=0,0,MMULT($AH24:$AM24, AZ$3:AZ$8)/$AZ$9)} -> 0 | BB24: {=IF($BA$9=0,0,MMULT($AH24:$AM24, BA$3:BA$8)/$BA$9)} -> 0 | BC24: {=IF($BB$9=0,0,MMULT($AH24:$AM24, BB$3:BB$8)/$BB$9)} -> 0 | BD24: {=IF($BC$9=0,0,MMULT($AH24:$AM24, BC$3:BC$8)/$BC$9)} -> 0 | BE24: =IF($BD$9=0,0,MMULT($AH24:$AM24, BD$3:BD$8)/$BD$9) -> 0 | BF24: =IF($BE$9=0,0,MMULT($AH24:$AM24, BE$3:BE$8)/$BE$9) -> 0 | BG24: =IF(OR(GradeSheet!$M19="W (Withdrawn)", GradeSheet!$M19="I (Incomplete)"), 0, IF(AU24>=65%, 1, 0)) -> 0 | BH24: =IF(OR(GradeSheet!$M19="W (Withdrawn)", GradeSheet!$M19="I (Incomplete)"), 0, IF(AV24>=65%, 1, 0)) -> 0 | BI24: =IF(OR(GradeSheet!$M19="W (Withdrawn)", GradeSheet!$M19="I (Incomplete)"), 0, IF(AW24>=65%, 1, 0)) -> 0 | BJ24: =IF(OR(GradeSheet!$M19="W (Withdrawn)", GradeSheet!$M19="I (Incomplete)"), 0, IF(AX24>=65%, 1, 0)) -> 0 | BK24: =IF(OR(GradeSheet!$M19="W (Withdrawn)", GradeSheet!$M19="I (Incomplete)"), 0, IF(AY24>=65%, 1, 0)) -> 0 | BL24: =IF(OR(GradeSheet!$M19="W (Withdrawn)", GradeSheet!$M19="I (Incomplete)"), 0, IF(AZ24>=65%, 1, 0)) -> 0 | BM24: =IF(OR(GradeSheet!$M19="W (Withdrawn)", GradeSheet!$M19="I (Incomplete)"), 0, IF(BA24>=65%, 1, 0)) -> 0 | BN24: =IF(OR(GradeSheet!$M19="W (Withdrawn)", GradeSheet!$M19="I (Incomplete)"), 0, IF(BB24>=65%, 1, 0)) -> 0 | ... BR24: =IF(OR(GradeSheet!$M19="W (Withdrawn)", GradeSheet!$M19="I (Incomplete)"), 0, IF(BF24>=65%, 1, 0)) -> 0
A25: 11 | B25: =GradeSheet!X20 -> 0 | C25: =GradeSheet!W20 -> 0 | D25: 0 | E25: 0 | F25: 0 | G25: 0 | H25: 0 | I25: 0 | J25: 0 | K25: 0 | L25: 0 | M25: 0 | N25: 0 | O25: 0 | P25: 0 | Q25: 0 | R25: 0 | S25: 0 | T25: 0 | U25: 0 | V25: 0 | W25: 0 | X25: 0 | Y25: 0 | Z25: 0 | AA25: 0 | AB25: =SUM(V25,D25,J25, P25) -> 0 | AC25: =SUM(W25,E25,K25, Q25) -> 0 | AD25: =SUM(X25,F25,L25, R25) -> 0 | AE25: =SUM(Y25,G25,M25, S25) -> 0 | AF25: =SUM(T25,H25,N25) -> 0 | AG25: =SUM(AA25,I25,O25) -> 0 | AH25: =IF(AB25 = 0, 0, AB25/AB$14) -> 0 | AI25: =IF(AC25 = 0, 0, AC25/AC$14) -> 0 | AJ25: =IF(AD25 = 0, 0, AD25/AD$14) -> 0 | AK25: =IF(AE25 = 0, 0, AE25/AE$14) -> 0 | AL25: =IF(AF25 = 0, 0, AF25/AF$14) -> 0 | AM25: =IF(AG25 = 0, 0, AG25/AG$14) -> 0 | AN25: 1 | AO25: =IF(OR(GradeSheet!$M20="W (Withdrawn)", GradeSheet!$M20="I (Incomplete)"), 0, IF(AI25>=55%, 1, 0)) -> 0 | AP25: =IF(OR(GradeSheet!$M20="W (Withdrawn)", GradeSheet!$M20="I (Incomplete)"), 0, IF(AJ25>=55%, 1, 0)) -> 0 | AQ25: =IF(OR(GradeSheet!$M20="W (Withdrawn)", GradeSheet!$M20="I (Incomplete)"), 0, IF(AK25>=55%, 1, 0)) -> 0 | AR25: =IF(OR(GradeSheet!$M20="W (Withdrawn)", GradeSheet!$M20="I (Incomplete)"), 0, IF(AL25>=55%, 1, 0)) -> 0 | AS25: =IF(OR(GradeSheet!$M20="W (Withdrawn)", GradeSheet!$M20="I (Incomplete)"), 0, IF(AM25>=55%, 1, 0)) -> 0 | AU25: =IF($AT$9=0,0,MMULT($AH25:$AM25, AT$3:AT$8)/$AT$9) -> 0 | AV25: =IF($AU$9=0,0,MMULT($AH25:$AM25, AU$3:AU$8)/$AU$9) -> 0 | AW25: {=IF($AV$9=0,0,MMULT($AH25:$AM25, AV$3:AV$8)/$AV$9)} -> 0 | AX25: {=IF($AW$9=0,0,MMULT($AH25:$AM25, AW$3:AW$8)/$AW$9)} -> 0 | AY25: =IF($AX$9=0,0,MMULT($AH25:$AM25, AX$3:AX$8)/$AX$9) -> 0 | AZ25: {=IF($AY$9=0,0,MMULT($AH25:$AM25, AY$3:AY$8)/$AY$9)} -> 0 | BA25: {=IF($AZ$9=0,0,MMULT($AH25:$AM25, AZ$3:AZ$8)/$AZ$9)} -> 0 | BB25: {=IF($BA$9=0,0,MMULT($AH25:$AM25, BA$3:BA$8)/$BA$9)} -> 0 | BC25: {=IF($BB$9=0,0,MMULT($AH25:$AM25, BB$3:BB$8)/$BB$9)} -> 0 | BD25: {=IF($BC$9=0,0,MMULT($AH25:$AM25, BC$3:BC$8)/$BC$9)} -> 0 | BE25: =IF($BD$9=0,0,MMULT($AH25:$AM25, BD$3:BD$8)/$BD$9) -> 0 | BF25: =IF($BE$9=0,0,MMULT($AH25:$AM25, BE$3:BE$8)/$BE$9) -> 0 | BG25: =IF(OR(GradeSheet!$M20="W (Withdrawn)", GradeSheet!$M20="I (Incomplete)"), 0, IF(AU25>=65%, 1, 0)) -> 0 | BH25: =IF(OR(GradeSheet!$M20="W (Withdrawn)", GradeSheet!$M20="I (Incomplete)"), 0, IF(AV25>=65%, 1, 0)) -> 0 | BI25: =IF(OR(GradeSheet!$M20="W (Withdrawn)", GradeSheet!$M20="I (Incomplete)"), 0, IF(AW25>=65%, 1, 0)) -> 0 | BJ25: =IF(OR(GradeSheet!$M20="W (Withdrawn)", GradeSheet!$M20="I (Incomplete)"), 0, IF(AX25>=65%, 1, 0)) -> 0 | BK25: =IF(OR(GradeSheet!$M20="W (Withdrawn)", GradeSheet!$M20="I (Incomplete)"), 0, IF(AY25>=65%, 1, 0)) -> 0 | BL25: =IF(OR(GradeSheet!$M20="W (Withdrawn)", GradeSheet!$M20="I (Incomplete)"), 0, IF(AZ25>=65%, 1, 0)) -> 0 | BM25: =IF(OR(GradeSheet!$M20="W (Withdrawn)", GradeSheet!$M20="I (Incomplete)"), 0, IF(BA25>=65%, 1, 0)) -> 0 | BN25: =IF(OR(GradeSheet!$M20="W (Withdrawn)", GradeSheet!$M20="I (Incomplete)"), 0, IF(BB25>=65%, 1, 0)) -> 0 | ... BR25: =IF(OR(GradeSheet!$M20="W (Withdrawn)", GradeSheet!$M20="I (Incomplete)"), 0, IF(BF25>=65%, 1, 0)) -> 0
A26: 12 | B26: =GradeSheet!X21 -> 0 | C26: =GradeSheet!W21 -> 0 | D26: 0 | E26: 0 | F26: 0 | G26: 0 | H26: 0 | I26: 0 | J26: 0 | K26: 0 | L26: 0 | M26: 0 | N26: 0 | O26: 0 | P26: 0 | Q26: 0 | R26: 0 | S26: 0 | T26: 0 | U26: 0 | V26: 0 | W26: 0 | X26: 0 | Y26: 0 | Z26: 0 | AA26: 0 | AB26: =SUM(V26,D26,J26, P26) -> 0 | AC26: =SUM(W26,E26,K26, Q26) -> 0 | AD26: =SUM(X26,F26,L26, R26) -> 0 | AE26: =SUM(Y26,G26,M26, S26) -> 0 | AF26: =SUM(T26,H26,N26) -> 0 | AG26: =SUM(AA26,I26,O26) -> 0 | AH26: =IF(AB26 = 0, 0, AB26/AB$14) -> 0 | AI26: =IF(AC26 = 0, 0, AC26/AC$14) -> 0 | AJ26: =IF(AD26 = 0, 0, AD26/AD$14) -> 0 | AK26: =IF(AE26 = 0, 0, AE26/AE$14) -> 0 | AL26: =IF(AF26 = 0, 0, AF26/AF$14) -> 0 | AM26: =IF(AG26 = 0, 0, AG26/AG$14) -> 0 | AN26: 1 | AO26: =IF(OR(GradeSheet!$M21="W (Withdrawn)", GradeSheet!$M21="I (Incomplete)"), 0, IF(AI26>=55%, 1, 0)) -> 0 | AP26: =IF(OR(GradeSheet!$M21="W (Withdrawn)", GradeSheet!$M21="I (Incomplete)"), 0, IF(AJ26>=55%, 1, 0)) -> 0 | AQ26: =IF(OR(GradeSheet!$M21="W (Withdrawn)", GradeSheet!$M21="I (Incomplete)"), 0, IF(AK26>=55%, 1, 0)) -> 0 | AR26: =IF(OR(GradeSheet!$M21="W (Withdrawn)", GradeSheet!$M21="I (Incomplete)"), 0, IF(AL26>=55%, 1, 0)) -> 0 | AS26: =IF(OR(GradeSheet!$M21="W (Withdrawn)", GradeSheet!$M21="I (Incomplete)"), 0, IF(AM26>=55%, 1, 0)) -> 0 | AU26: =IF($AT$9=0,0,MMULT($AH26:$AM26, AT$3:AT$8)/$AT$9) -> 0 | AV26: =IF($AU$9=0,0,MMULT($AH26:$AM26, AU$3:AU$8)/$AU$9) -> 0 | AW26: {=IF($AV$9=0,0,MMULT($AH26:$AM26, AV$3:AV$8)/$AV$9)} -> 0 | AX26: {=IF($AW$9=0,0,MMULT($AH26:$AM26, AW$3:AW$8)/$AW$9)} -> 0 | AY26: =IF($AX$9=0,0,MMULT($AH26:$AM26, AX$3:AX$8)/$AX$9) -> 0 | AZ26: {=IF($AY$9=0,0,MMULT($AH26:$AM26, AY$3:AY$8)/$AY$9)} -> 0 | BA26: {=IF($AZ$9=0,0,MMULT($AH26:$AM26, AZ$3:AZ$8)/$AZ$9)} -> 0 | BB26: {=IF($BA$9=0,0,MMULT($AH26:$AM26, BA$3:BA$8)/$BA$9)} -> 0 | BC26: {=IF($BB$9=0,0,MMULT($AH26:$AM26, BB$3:BB$8)/$BB$9)} -> 0 | BD26: {=IF($BC$9=0,0,MMULT($AH26:$AM26, BC$3:BC$8)/$BC$9)} -> 0 | BE26: =IF($BD$9=0,0,MMULT($AH26:$AM26, BD$3:BD$8)/$BD$9) -> 0 | BF26: =IF($BE$9=0,0,MMULT($AH26:$AM26, BE$3:BE$8)/$BE$9) -> 0 | BG26: =IF(OR(GradeSheet!$M21="W (Withdrawn)", GradeSheet!$M21="I (Incomplete)"), 0, IF(AU26>=65%, 1, 0)) -> 0 | BH26: =IF(OR(GradeSheet!$M21="W (Withdrawn)", GradeSheet!$M21="I (Incomplete)"), 0, IF(AV26>=65%, 1, 0)) -> 0 | BI26: =IF(OR(GradeSheet!$M21="W (Withdrawn)", GradeSheet!$M21="I (Incomplete)"), 0, IF(AW26>=65%, 1, 0)) -> 0 | BJ26: =IF(OR(GradeSheet!$M21="W (Withdrawn)", GradeSheet!$M21="I (Incomplete)"), 0, IF(AX26>=65%, 1, 0)) -> 0 | BK26: =IF(OR(GradeSheet!$M21="W (Withdrawn)", GradeSheet!$M21="I (Incomplete)"), 0, IF(AY26>=65%, 1, 0)) -> 0 | BL26: =IF(OR(GradeSheet!$M21="W (Withdrawn)", GradeSheet!$M21="I (Incomplete)"), 0, IF(AZ26>=65%, 1, 0)) -> 0 | BM26: =IF(OR(GradeSheet!$M21="W (Withdrawn)", GradeSheet!$M21="I (Incomplete)"), 0, IF(BA26>=65%, 1, 0)) -> 0 | BN26: =IF(OR(GradeSheet!$M21="W (Withdrawn)", GradeSheet!$M21="I (Incomplete)"), 0, IF(BB26>=65%, 1, 0)) -> 0 | ... BR26: =IF(OR(GradeSheet!$M21="W (Withdrawn)", GradeSheet!$M21="I (Incomplete)"), 0, IF(BF26>=65%, 1, 0)) -> 0
A27: 13 | B27: =GradeSheet!X22 -> 0 | C27: =GradeSheet!W22 -> 0 | D27: 0 | E27: 0 | F27: 0 | G27: 0 | H27: 0 | I27: 0 | J27: 0 | K27: 0 | L27: 0 | M27: 0 | N27: 0 | O27: 0 | P27: 0 | Q27: 0 | R27: 0 | S27: 0 | T27: 0 | U27: 0 | V27: 0 | W27: 0 | X27: 0 | Y27: 0 | Z27: 0 | AA27: 0 | AB27: =SUM(V27,D27,J27, P27) -> 0 | AC27: =SUM(W27,E27,K27, Q27) -> 0 | AD27: =SUM(X27,F27,L27, R27) -> 0 | AE27: =SUM(Y27,G27,M27, S27) -> 0 | AF27: =SUM(T27,H27,N27) -> 0 | AG27: =SUM(AA27,I27,O27) -> 0 | AH27: =IF(AB27 = 0, 0, AB27/AB$14) -> 0 | AI27: =IF(AC27 = 0, 0, AC27/AC$14) -> 0 | AJ27: =IF(AD27 = 0, 0, AD27/AD$14) -> 0 | AK27: =IF(AE27 = 0, 0, AE27/AE$14) -> 0 | AL27: =IF(AF27 = 0, 0, AF27/AF$14) -> 0 | AM27: =IF(AG27 = 0, 0, AG27/AG$14) -> 0 | AN27: =IF(OR(GradeSheet!$M22="W (Withdrawn)", GradeSheet!$M22="I (Incomplete)"), 0, IF(AH27>=55%, 1, 0)) -> 0 | AO27: =IF(OR(GradeSheet!$M22="W (Withdrawn)", GradeSheet!$M22="I (Incomplete)"), 0, IF(AI27>=55%, 1, 0)) -> 0 | AP27: =IF(OR(GradeSheet!$M22="W (Withdrawn)", GradeSheet!$M22="I (Incomplete)"), 0, IF(AJ27>=55%, 1, 0)) -> 0 | AQ27: =IF(OR(GradeSheet!$M22="W (Withdrawn)", GradeSheet!$M22="I (Incomplete)"), 0, IF(AK27>=55%, 1, 0)) -> 0 | AR27: =IF(OR(GradeSheet!$M22="W (Withdrawn)", GradeSheet!$M22="I (Incomplete)"), 0, IF(AL27>=55%, 1, 0)) -> 0 | AS27: =IF(OR(GradeSheet!$M22="W (Withdrawn)", GradeSheet!$M22="I (Incomplete)"), 0, IF(AM27>=55%, 1, 0)) -> 0 | AU27: =IF($AT$9=0,0,MMULT($AH27:$AM27, AT$3:AT$8)/$AT$9) -> 0 | AV27: =IF($AU$9=0,0,MMULT($AH27:$AM27, AU$3:AU$8)/$AU$9) -> 0 | AW27: {=IF($AV$9=0,0,MMULT($AH27:$AM27, AV$3:AV$8)/$AV$9)} -> 0 | AX27: {=IF($AW$9=0,0,MMULT($AH27:$AM27, AW$3:AW$8)/$AW$9)} -> 0 | AY27: =IF($AX$9=0,0,MMULT($AH27:$AM27, AX$3:AX$8)/$AX$9) -> 0 | AZ27: {=IF($AY$9=0,0,MMULT($AH27:$AM27, AY$3:AY$8)/$AY$9)} -> 0 | BA27: {=IF($AZ$9=0,0,MMULT($AH27:$AM27, AZ$3:AZ$8)/$AZ$9)} -> 0 | BB27: {=IF($BA$9=0,0,MMULT($AH27:$AM27, BA$3:BA$8)/$BA$9)} -> 0 | BC27: {=IF($BB$9=0,0,MMULT($AH27:$AM27, BB$3:BB$8)/$BB$9)} -> 0 | BD27: {=IF($BC$9=0,0,MMULT($AH27:$AM27, BC$3:BC$8)/$BC$9)} -> 0 | BE27: =IF($BD$9=0,0,MMULT($AH27:$AM27, BD$3:BD$8)/$BD$9) -> 0 | BF27: =IF($BE$9=0,0,MMULT($AH27:$AM27, BE$3:BE$8)/$BE$9) -> 0 | BG27: =IF(OR(GradeSheet!$M22="W (Withdrawn)", GradeSheet!$M22="I (Incomplete)"), 0, IF(AU27>=65%, 1, 0)) -> 0 | BH27: =IF(OR(GradeSheet!$M22="W (Withdrawn)", GradeSheet!$M22="I (Incomplete)"), 0, IF(AV27>=65%, 1, 0)) -> 0 | BI27: =IF(OR(GradeSheet!$M22="W (Withdrawn)", GradeSheet!$M22="I (Incomplete)"), 0, IF(AW27>=65%, 1, 0)) -> 0 | BJ27: =IF(OR(GradeSheet!$M22="W (Withdrawn)", GradeSheet!$M22="I (Incomplete)"), 0, IF(AX27>=65%, 1, 0)) -> 0 | BK27: =IF(OR(GradeSheet!$M22="W (Withdrawn)", GradeSheet!$M22="I (Incomplete)"), 0, IF(AY27>=65%, 1, 0)) -> 0 | BL27: =IF(OR(GradeSheet!$M22="W (Withdrawn)", GradeSheet!$M22="I (Incomplete)"), 0, IF(AZ27>=65%, 1, 0)) -> 0 | BM27: =IF(OR(GradeSheet!$M22="W (Withdrawn)", GradeSheet!$M22="I (Incomplete)"), 0, IF(BA27>=65%, 1, 0)) -> 0 | BN27: =IF(OR(GradeSheet!$M22="W (Withdrawn)", GradeSheet!$M22="I (Incomplete)"), 0, IF(BB27>=65%, 1, 0)) -> 0 | ... BR27: =IF(OR(GradeSheet!$M22="W (Withdrawn)", GradeSheet!$M22="I (Incomplete)"), 0, IF(BF27>=65%, 1, 0)) -> 0
